Workbook

Sheet DF
B1: Batch Sequential | D1: Pipe and Filter | F1: Process Control
B2: Effects | C2: Justification | D2: Effects | E2: Justification | F2: Effects | G2: Justification
A3: Availability | B3: ='Detailed Reasoning'!B$3 | C3: ='Detailed Reasoning'!C$3 | D3: ='Detailed Reasoning'!D$3 | E3: ='Detailed Reasoning'!E$3 | F3: ='Detailed Reasoning'!F$3 | G3: ='Detailed Reasoning'!G$3
A4: 1조 | B4: ='1조'!B$3 -> - | C4: ='1조'!C3 -> [+] 기능 분리: 처리 단계가 구분되어 있어 장애가 발생한 단계와 원인을 파악하기 쉽고, 수정·복구 대상을 좁힐 수 있다. [--] 순차적 실행 의존: 앞 단계가 완료되지 않으면 모든 후속 단계가 진행되지 못하므로, 한 단계의 장애가 전체 처리 결과의 제공을 막을 수 있다. [-] 실시간 장애 복구 불가: 배치 작업 중단 시 즉시 서비스 재개가 어려움. | D4: ='1조'!D$3 -> - | E4: ='1조'!E3 -> [+] 역할 분리: 필터를 별도 실행 단위로 구성하면 장애가 발생한 필터를 구분하고 개별적으로 복구·재시작할 수 있는 경계가 생긴다. 다만 해당 필터의 재시작만으로 전체 처리 상태까지 자동 복구되는 것은 아니다. [--] 필수 처리 경로의 의존: 최종 결과 생성에 필요한 필터나 연결 파이프가 중단되고 대체 경로가 없으면, 해당 경로의 정상 결과를 계속 생성하기 어렵다. 따라서 개별 필터의 독립성이 전체 처리의 무중단을 보장하지는 않는다. | F4: ='1조'!F$3 -> - | G4: ='1조'!G3 -> [+] 피드백에 의한 정상 상태 유지: 외부 교란으로 상태가 목표값에서 벗어나면 측정값을 바탕으로 조정하므로, 정상 운전 상태를 유지하는 데 도움이 된다. [--] 핵심 제어 요소 의존: 제어부나 처리부가 고장 나면 피드백 루프를 정상적으로 수행하지 못하므로, 전체 제어 기능이 중단될 수 있다.
A5: 2조 | B5: ='2조'!B$3 -> -- | C5: ='2조'!C$3 -> 앞 단계가 끝나야 다음이 시작되므로 한 단계가 멈추면 전체가 멈춘다. 교안( "가용성이 제한된다") | D5: ='2조'!D$3 -> - | E5: ='2조'!E$3 -> Filter 하나가 죽으면 그 뒤 흐름이 끊긴다. 교안이 fault tolerance 가 낮다는 것을 약점으로 든다 | F5: ='2조'!F$3 -> - | G5: ='2조'!G$3 -> AI2에서 "Closed Loop 피드백을 통해 시스템을 정상 운용 상태로 자동 복구·지속 유지시킴." 라고 표현하였는데, 애초에 복구 수단이 해당 Architecture Style 정의 안에 없음. 자동차의 크루즈 기능을 Process Control Architecture Style의 대표 예로 볼 수 있는데, 정상 동작 중에는 외란이 와도 목표값을 지켜내지만, 부품이 고장 났을 때는 대응 수단이 없다. 그래서 Availability가 낮다고 평가한 AI1을 따랐다. (크루즈 기능 자체로만 보면 Availability가 낮은것이 맞고 (센서 하나가 이상이면 기능이 즉시 해제되고 돌아오지 않음), 자동차 전체로 보면 가용성은 멀쩡하다. 크루즈가 풀려도 차는 그대로 굴러가기 때문.)
A6: 3조 | B6: ='3조'!B$3 -> -- | C6: ='3조'!C$3 -> 각 처리 단계가 완전 종료(Run to completion)되어야 다음 단계가 실행되므로, 중간 프로세싱 스텝 하나만 실패해도 전체 파이프라인이 정지되는 단일 실패 취약 구조입니다. | D6: ='3조'!D$3 -> - | E6: ='3조'!E$3 -> Pipe and Filter는 Filter들이 독립적이지만 전체 결과는 Data Source→Pipe→Filter→Data Sink 흐름이 유지되어야 나온다. 특정 Filter나 Pipe가 멈추면 downstream 처리가 막히고, 자료에서도 fault tolerance가 낮다고 하므로 availability에는 불리하게 본다. | F6: ='3조'!F$3 -> + | G6: ='3조'!G$3 -> Process Control은 Set Point와 Controlled Variable의 차이를 feedback으로 계산해 Manipulated Variable을 계속 조정하는 closed loop 구조이다. 외부 disturbance가 있어도 목표 상태를 유지하도록 설계되므로 availability/reliability 측면에 유리하다.
A7: 4조 | B7: ='4조'!B$3 -> - | C7: ='4조'!C$3 -> 한 단계에서 장애가 발생하면 뒤 단계가 모두 진행되지 못한다. 전체 처리 흐름이 직렬로 연결되어 있어 특정 단계의 실패가 전체 서비스 중단으로 이어지기 쉽다. | D7: ='4조'!D$3 -> 0 | E7: ='4조'!E$3 -> Filter들이 독립적이라 일부를 교체·복구하기는 쉽지만, 파이프라인 중 하나의 Filter가 멈추면 전체 흐름이 막힐 수 있다. 장단점이 모두 존재한다. | F7: ='4조'!F$3 -> + | G7: ='4조'!G$3 -> 시스템 상태를 지속적으로 감시하고 피드백을 통해 이상 상태를 보정할 수 있다. 다만 센서나 Controller 같은 핵심 요소가 고장 나면 전체 제어에 영향을 줄 수 있다.
A8: 5조 | B8: ='5조'!B$3 -> - | C8: ='5조'!C$3 -> 한 단계가 실패하면 중간부터 재시작 가능하다고 하더라도 뒤 단계가 모두 대기하거나 재시작 해야 하는 것이 치명적 | D8: ='5조'!D$3 -> - | E8: ='5조'!E$3 -> Filter별 독립적 행동이 보장되므로 문제가 발생하더라도 전체 system에 영향성 적으나 Pipe에 고장이 나면 뒤에 연결된 Filter도 사용할 수 없게 되므로 좋진 않음 | F8: ='5조'!F$3 -> + | G8: ='5조'!G$3 -> 피드백 루프가 상태 변화를 감지해 보정할 수 있어 일부 환경 변화나 구성요소 편차에 대응하기 쉽다.
A9: 6조 | B9: ='6조'!B$3 -> -- | C9: ='6조'!C$3 -> 순차적 파이프라인 구조상 특정 단계에서 장애나 에러가 발생하면 후속 단계가 진행되지 못하고 전체 데이터 흐름이 중단되며, 오류 복구 및 재수행에도 오랜 시간이 소요됨. | D9: ='6조'!D$3 -> + | E9: ='6조'!E$3 -> Pipe에 Buffer/Queue를 적용하면 장애 격리 및 재처리 가능 | F9: ='6조'!F$3 -> 0 | G9: ='6조'!G$3 -> 장애시 피드백 루프 자체는 동작 가능하지만, 컨트롤러 장애 시 제어 불능 상태가 됨
A10: 7조 | B10: ='7조'!B$3 | C10: ='7조'!C$3 -> 7조 - Batch Sequential - Availability | D10: ='7조'!D$3 | E10: ='7조'!E$3 -> 7조 - Pipe and Filter - Availability | F10: ='7조'!F$3 | G10: ='7조'!G$3 -> 7조 - Process Control - Availability
A11: 8조 | B11: ='8조'!B$3 | C11: ='8조'!C$3 -> 8조 - Batch Sequential - Availability | D11: ='8조'!D$3 | E11: ='8조'!E$3 -> 8조 - Pipe and Filter - Availability | F11: ='8조'!F$3 | G11: ='8조'!G$3 -> 8조 - Process Control - Availability
A12: 9조 | B12: ='9조'!B$3 | C12: ='9조'!C$3 -> 9조 - Batch Sequential - Availability | D12: ='9조'!D$3 | E12: ='9조'!E$3 -> 9조 - Pipe and Filter - Availability | F12: ='9조'!F$3 | G12: ='9조'!G$3 -> 9조 - Process Control - Availability
A14: Deployability | B14: ='Detailed Reasoning'!B$4 | C14: ='Detailed Reasoning'!C$4 | D14: ='Detailed Reasoning'!D$4 | E14: ='Detailed Reasoning'!E$4 | F14: ='Detailed Reasoning'!F$4 | G14: ='Detailed Reasoning'!G$4
A15: 1조 | B15: ='1조'!B$4 -> 0 | C15: ='1조'!C4 -> [+] 단계별 교체: 입출력 데이터 형식이 유지되면 변경된 처리 단계를 교체하기 쉬워, 변경 사항을 반영할 대상을 구분하기 쉽다. [-] 데이터 형식 의존: 단계 사이의 데이터 형식이 바뀌면 데이터를 생성하는 단계와 사용하는 단계의 버전을 함께 맞춰 배포해야 한다. | D15: ='1조'!D$4 -> + | E15: ='1조'!E4 -> [+] 개별 배포 단위: 필터를 별도 배포 단위로 구성하면 변경된 필터를 중심으로 배포·교체할 수 있어 전체 시스템을 함께 교체해야 하는 범위를 줄일 수 있다. [+] 입출력 계약 유지: 필터의 입출력 형식과 의미가 유지되면 연결된 필터의 구현을 수정하지 않고 해당 필터의 새 버전을 반영하기 쉽다. [-] 계약 변경의 배포 조정: 입출력 계약이 바뀌면 연결된 필터들의 버전 호환성을 확인하고 배포를 조정해야 한다. 필터가 독립적이라는 사실만으로 실행 중 무중단 교체가 보장되지는 않는다. | F15: ='1조'!F$4 -> - | G15: ='1조'!G4 -> [-] 의미적·시간적 계약의 결합 — 해석: 제어 변수의 의미나 전달 시점이 바뀌면 제어부와 처리부가 함께 맞춰져야 하므로, 관련 변경을 조정하여 배포해야 한다. [-] 제어 중단의 영향 — 해석: 실행 중인 제어 요소를 교체하면서 루프가 중단되면 목표 상태 유지에 영향을 줄 수 있어, 배포 시 운영 중단의 영향을 고려해야 한다.
A16: 2조 | B16: ='2조'!B$4 -> 0 | C16: ='2조'!C$4 -> 개별 프로그램 단위 빌드/배포는 가능하나, 데이터 포맷 변경 시 관련 배치 프로그램을 일괄 배포해야 함. | D16: ='2조'!D$4 -> + | E16: ='2조'!E$4 -> Filter 가 독립적이라 하나씩 따로 배포·교체할 수 있다 | F16: ='2조'!F$4 -> - | G16: ='2조'!G$4 -> 제어 루프가 돌고 있는 상태에서 일부만 바꿔 올리기 어렵다. 설계가 복잡해 배포 절차도 무겁다
A17: 3조 | B17: ='3조'!B$4 -> - | C17: ='3조'!C$4 -> 각 단계가 파일 규격 및 배치 실행 흐름에 강하게 묶여 있어 개별 단계를 독립적으로 분리 배포하거나 무중단 롤백하기 어렵습니다. | D17: ='3조'!D$4 -> + | E17: ='3조'!E$4 -> Pipe and Filter는 Filter가 독립적인 component이고 Pipe의 입출력 형식만 맞으면 Filter를 교체·추가할 수 있다. 따라서 특정 처리 단계 단위로 수정·교체·배포하기 쉬워 deployability에 유리하다. | F17: ='3조'!F$4 -> - | G17: ='3조'!G$4 -> Process Control은 Controller, Processing Unit, Sensor/Actuator, 제어 변수들이 feedback loop로 함께 동작한다. 한 요소 변경이 제어 안정성·timing·전체 loop에 영향을 주므로 독립 배포가 어렵다.
A18: 4조 | B18: ='4조'!B$4 -> + | C18: ='4조'!C$4 -> 각 처리 단계를 별도의 프로그램/모듈로 구성할 수 있어 단계별 배포가 비교적 쉽다. 다만 단계 간 데이터 형식이 바뀌면 연쇄적인 수정이 필요할 수 있다. | D18: ='4조'!D$4 -> + | E18: ='4조'!E$4 -> Filter가 독립된 처리 단위이므로 개별 Filter를 수정·배포하기 비교적 쉽다. 단, Pipe의 데이터 형식 호환성은 유지해야 한다. | F18: ='4조'!F$4 -> - | G18: ='4조'!G$4 -> 센서·Controller·Actuator 등 실제 장비와 밀접하게 연결되어 있어 단순 소프트웨어처럼 독립적으로 배포하기 어렵다. 배포 후 보정이나 Calibration도 필요할 수 있다.
A19: 5조 | B19: ='5조'!B$4 -> + | C19: ='5조'!C$4 -> 구조가 단순한 것이 가장 큰 이점, 배포 시 개발자들에게 porting 등의 O/H가 적을 것으로 예상. | D19: ='5조'!D$4 -> + | E19: ='5조'!E$4 -> 필터는 서로 독립적인 개체이므로 개별 구성요소 별로 배포하기 쉬운 편이다. | F19: ='5조'!F$4 -> - | G19: ='5조'!G$4 -> 개별 구성요소를 독립 배포하기 어렵다.
A20: 6조 | B20: ='6조'!B$4 -> + | C20: ='6조'!C$4 -> 단계별 경계와 중간 산출물이 명확하여 결합도가 낮을 경우 개별 배치 프로그램을 독립적으로 배포·교체하기 용이함. 다만 전체 파이프라인이 하나로 묶여 관리되는 환경에서는 부분 배포 및 롤백이 어려울 수 있음. | D20: ='6조'!D$4 -> ++ | E20: ='6조'!E$4 -> 각 필터가 독립적인 컴포넌트로 분리되어 있고, 파이프의 표준 인터페이스를 준수하므로 특정 필터만 개별적으로 무중단 배포하기 용이함 | F20: ='6조'!F$4 -> - | G20: ='6조'!G$4 -> 하드웨어(센서/액추에이터)와 제어 로직이 긴밀히 결합되어 있어 독립 배포가 어려움
A21: 7조 | B21: ='7조'!B$4 | C21: ='7조'!C$4 -> 7조 - Batch Sequential - Deployability | D21: ='7조'!D$4 | E21: ='7조'!E$4 -> 7조 - Pipe and Filter - Deployability | F21: ='7조'!F$4 | G21: ='7조'!G$4 -> 7조 - Process Control - Deployability
A22: 8조 | B22: ='8조'!B$4 | C22: ='8조'!C$4 -> 8조 - Batch Sequential - Deployability | D22: ='8조'!D$4 | E22: ='8조'!E$4 -> 8조 - Pipe and Filter - Deployability | F22: ='8조'!F$4 | G22: ='8조'!G$4 -> 8조 - Process Control - Deployability
A23: 9조 | B23: ='9조'!B$4 | C23: ='9조'!C$4 -> 9조 - Batch Sequential - Deployability | D23: ='9조'!D$4 | E23: ='9조'!E$4 -> 9조 - Pipe and Filter - Deployability | F23: ='9조'!F$4 | G23: ='9조'!G$4 -> 9조 - Process Control - Deployability
A25: Integrability | B25: ='Detailed Reasoning'!B$5 | C25: ='Detailed Reasoning'!C$5 | D25: ='Detailed Reasoning'!D$5 | E25: ='Detailed Reasoning'!E$5 | F25: ='Detailed Reasoning'!F$5 | G25: ='Detailed Reasoning'!G$5
A26: 1조 | B26: ='1조'!B$5 -> + | C26: ='1조'!C5 -> [+] 데이터 규격 공유: 중간 파일/DB 포맷만 맞추면 타 시스템과 연동 가능함. [-] 상호작용 방식의 제약: 처리 도중 요청과 응답을 반복해야 하는 구성요소는 단계 전체가 완료된 후 다음 단계로 넘어가는 방식에 맞추기 어렵다. | D26: ='1조'!D$5 -> + | E26: ='1조'!E5 -> [++] 명확한 연결 계약: 필터의 입력·출력 포트와 스트림 계약이 구분되어 있어, 계약이 맞는 새로운 필터를 기존 처리 흐름에 연결하기 쉽다. [+] 필터 재사용: 기존 필터의 내부 구현을 변경하지 않고 다른 처리 흐름에 조합하여 사용할 수 있어, 새로운 기능을 통합할 때의 구현 노력을 줄일 수 있다. [-] 데이터 계약 정합성: 데이터 형식이나 의미, 점진적 처리 방식이 맞지 않는 구성요소는 그대로 연결할 수 없으므로, 계약을 맞추는 변환 기능의 구현과 통합 검증이 필요하다. | F26: ='1조'!F$5 -> - | G26: ='1조'!G5 -> [-] 시간적 결합: 연결된 요소의 응답 시점이 전체 피드백 동작에 영향을 주므로, 기능적으로 연결되는 것 외에 시간적인 적합성도 검토해야 한다.
A27: 2조 | B27: ='2조'!B$5 -> + | C27: ='2조'!C$5 -> 입출력 데이터 형식만 맞으면 처리 단계를 쉽게 교체·연결할 수 있다 | D27: ='2조'!D$5 -> ++ | E27: ='2조'!E$5 -> 표준 입출력 스트림 규격(예: Unix Pipe)을 준수하는 외부 서드파티 도구나 기존 컴포넌트를 파이프라인 사이에 어댑터 없이 즉시 결합할 수 있어 상호운용성(Interoperability)이 탁월함. | F27: ='2조'!F$5 -> - | G27: ='2조'!G$5 -> 센서·구동기·제어기가 특정 물리 환경에 맞춰져 있어 다른 시스템과 붙이기 어렵다
A28: 3조 | B28: ='3조'!B$5 -> + | C28: ='3조'!C$5 -> 표준 입출력 파일(Batch File, CSV, DB 덤프 등)을 매개로 단계가 연결되므로, 이기종 도구 간 파일 연동 관점의 통합은 비교적 단순합니다. | D28: ='3조'!D$5 -> ++ | E28: ='3조'!E$5 -> 표준 데이터 포맷과 일관된 파이프 커넥터 인터페이스를 지원하므로, 새로운 외부 필터를 기존 파이프라인 사이에 끼워 넣는 통합이 매우 뛰어납니다. | F28: ='3조'!F$5 -> - | G28: ='3조'!G$5 -> Process Control에서 새 센서·actuator·제어 알고리즘을 추가하면 Set Point, Controlled Variable, Manipulated Variable의 관계와 feedback 안정성을 함께 재검토해야 한다. 단순 연결이 아니라 제어 모델 통합이 필요하므로 integrability에 불리하다.
A29: 4조 | B29: ='4조'!B$5 -> + | C29: ='4조'!C$5 -> 단계 사이의 입력/출력이 파일이나 명확한 데이터 형식으로 정의되므로 다른 시스템이나 모듈을 연결하기 비교적 쉽다. | D29: ='4조'!D$5 -> ++ | E29: ='4조'!E$5 -> Filter 간 연결이 명확한 입출력 인터페이스로 이루어져 새로운 Filter를 추가하거나 기존 Filter를 다른 컴포넌트로 교체하기 쉽다. | F29: ='4조'!F$5 -> - | G29: ='4조'!G$5 -> 센서, 액추에이터, 제어 장치마다 통신 방식이나 데이터 형식이 다를 수 있어 외부 시스템을 추가하거나 교체하기 어렵다.
A30: 5조 | B30: ='5조'!B$5 -> 0 | C30: ='5조'!C$5 -> 별도의 개발 자체는 쉽지만, 각 컴포넌트간 Input / Output 일관성이 필요하여 상쇄 | D30: ='5조'!D$5 -> ++ | E30: ='5조'!E$5 -> 표준화된 connector를 사용해서, 새로운 필터를 연결하기 매우 쉽다. | F30: ='5조'!F$5 -> - | G30: ='5조'!G$5 -> componenet에 따라 인터페이스가 달라 통합이 어렵다.
A31: 6조 | B31: ='6조'!B$5 -> + | C31: ='6조'!C$5 -> 각 단계 간 입력/출력 데이터 파일 포맷만 표준화되어 있으면 새로운 컴포넌트를 연계하거나 교체하기 용이함. 반면, 강한 실행 순서 및 데이터 의존성 때문에 파이프라인 중간에 임의의 컴포넌트를 동적으로 삽입하기는 까다롭다는 지적도 존재함. | D31: ='6조'!D$5 -> ++ | E31: ='6조'!E$5 -> 파이프를 흐르는 데이터의 인터페이스가 표준화되어 있어, 서로 다른 언어/기술로 작성된 새로운 필터나 외부 시스템을 파이프라인 중간에 쉽게 끼워 넣을 수 있음 | F31: ='6조'!F$5 -> 0 | G31: ='6조'!G$5 -> 하드웨어(센서/액추에이터)가 표준 인터페이스를 따르면 교체 가능하나, 제어 루프의 재구성은 쉽지 않음
A32: 7조 | B32: ='7조'!B$5 | C32: ='7조'!C$5 -> 7조 - Batch Sequential - Integrability | D32: ='7조'!D$5 | E32: ='7조'!E$5 -> 7조 - Pipe and Filter - Integrability | F32: ='7조'!F$5 | G32: ='7조'!G$5 -> 7조 - Process Control - Integrability
A33: 8조 | B33: ='8조'!B$5 | C33: ='8조'!C$5 -> 8조 - Batch Sequential - Integrability | D33: ='8조'!D$5 | E33: ='8조'!E$5 -> 8조 - Pipe and Filter - Integrability | F33: ='8조'!F$5 | G33: ='8조'!G$5 -> 8조 - Process Control - Integrability
A34: 9조 | B34: ='9조'!B$5 | C34: ='9조'!C$5 -> 9조 - Batch Sequential - Integrability | D34: ='9조'!D$5 | E34: ='9조'!E$5 -> 9조 - Pipe and Filter - Integrability | F34: ='9조'!F$5 | G34: ='9조'!G$5 -> 9조 - Process Control - Integrability
A36: Energy Efficiency | B36: ='Detailed Reasoning'!B$6 | C36: ='Detailed Reasoning'!C$6 | D36: ='Detailed Reasoning'!D$6 | E36: ='Detailed Reasoning'!E$6 | F36: ='Detailed Reasoning'!F$6 | G36: ='Detailed Reasoning'!G$6
A37: 1조 | B37: ='1조'!B$6 -> - | C37: ='1조'!C6 -> [+] 자원 집약 처리: 특정 시간에 컴퓨팅 자원을 100% 활용하고 유휴 시간에는 끄기 쉬움. [-] 디스크 I/O 소모: 중간 결과를 디스크/파일로 저장하는 과정에서 전력 소모가 발생함." | D37: ='1조'!D$6 -> - | E37: ='1조'!E6 -> [-] 실행 단위 유지 비용: 필터를 별도 프로세스로 실행하는 구성에서는 각 프로세스의 기본 자원과 실행 전환에 필요한 비용이 발생한다. [-] 데이터 전달 비용: 필터 사이의 데이터 전달과 프로세스 간 통신에 추가 자원이 필요하며, 필터와 연결이 많아지면 이러한 비용이 누적될 수 있다. [+] 조기 완료 후 유휴 전환 — 조건부: 동시 처리로 전체 작업을 일찍 완료하고 실제로 유휴 상태로 전환할 수 있다면 에너지 절감에 도움이 될 수 있다. 다만 점진적 처리 자체가 절전 동작을 보장하지는 않는다. | F37: ='1조'!F$6 -> 0 | G37: ='1조'!G6 -> [N/A] 목표값 유지와 에너지 최소화의 구분: 이 스타일의 직접적인 목적은 원하는 상태를 유지하는 것이며, 그 목표가 곧 에너지 소비의 최소화를 의미하지는 않는다.
A38: 2조 | B38: ='2조'!B$6 -> + | C38: ='2조'!C$6 -> 한 번에 한 단계만 돌아 자원을 몰아 쓰지 않는다. 대규모 데이터 처리에 효율적이다 | D38: ='2조'!D$6 -> - | E38: ='2조'!E$6 -> 독립 Filter 가 많아지면 데이터를 주고받는 계산 overhead 가 크게 늘어난다 | F38: ='2조'!F$6 -> + | G38: ='2조'!G$6 -> 이 스타일의 에너지 절약은 목표가 아니라 덤이다. 그래서 ++을 주기는 그렇다. 목표값(set point)을 유지하도록 조절하므로 필요 이상으로 자원을 쓰지 않는다.
A39: 3조 | B39: ='3조'!B$6 -> 0 | C39: ='3조'!C$6 -> Batch Sequential은 동시 실행 자원은 적게 쓰지만, 각 단계가 끝날 때까지 다음 단계가 대기하므로 전체 처리 시간이 길어질 수 있다. 에너지 효율을 직접 개선하는 구조적 메커니즘은 아니므로 0으로 본다. | D39: ='3조'!D$6 -> - | E39: ='3조'!E$6 -> Pipe and Filter는 동시·점진 처리로 자원 활용을 높일 수 있으나, 독립 Filter가 많아지면 계산 overhead와 buffering/데이터 변환 비용이 커진다. 자료의 약점도 overhead 증가를 언급하므로 energy efficiency에는 다소 불리하게 본다. | F39: ='3조'!F$6 -> 0 | G39: ='3조'!G$6 -> Process Control은 Set Point와 Controlled Variable의 차이를 줄이도록 Manipulated Variable을 조정해 최적의 process 조건을 유지하는 closed-loop 구조이다. 이 구조가 자원 사용을 조정할 수는 있지만, 에너지 절감을 직접 보장하는 스타일은 아니므로 energy efficiency에 대한 직접 효과는 중립으로 본다. (p.53~58)
A40: 4조 | B40: ='4조'!B$6 -> + | C40: ='4조'!C$6 -> 실시간으로 계속 동작할 필요 없이 필요한 시점에 배치 단위로 실행할 수 있어 유휴 시간의 자원 사용을 줄일 수 있다. | D40: ='4조'!D$6 -> 0 | E40: ='4조'!E$6 -> 스트리밍과 병렬 처리로 자원을 효율적으로 사용할 수 있지만, 여러 Filter의 동시 실행과 Pipe/Buffer 관리에 추가 자원이 필요하다. | F40: ='4조'!F$6 -> + | G40: ='4조'!G$6 -> 현재 상태를 계속 측정하면서 필요한 만큼만 제어할 수 있기 때문에 에너지나 자원을 효율적으로 사용할 수 있다. 예를 들어 목표 온도에 도달하면 히터 출력을 줄일 수 있다.
A41: 5조 | B41: ='5조'!B$6 -> 0 | C41: ='5조'!C$6 -> 1. 에너지, 혹은 처리량 총량의 차이가 있지, 총량 / Energy 값인 효율적 측면은 영향이 없다 | D41: ='5조'!D$6 -> 0 | E41: ='5조'!E$6 -> 데이터 처리 자체는 에너지 효율과 직접적인 연관성이 적다. | F41: ='5조'!F$6 -> + | G41: ='5조'!G$6 -> 필요한 시점에만 동작하므로 자원을 효율적으로 쓸 수 있다.
A42: 6조 | B42: ='6조'!B$6 -> 0 | C42: ='6조'!C$6 -> 특정 시점에 대량 데이터를 한 번에 처리하므로 유휴 상태 없이 컴퓨팅 자원 활용률을 높일 수 있다는 긍정적 측면과, 선행 작업 종료 시까지 후속 작업이 대기하고 순차 실행으로 인해 전체 소요 시간이 늘어나 총 에너지 절감에는 불리하다는 관점이 상충함. | D42: ='6조'!D$6 -> 0 | E42: ='6조'!E$6 -> Filter 병렬화로 처리시간 단축 가능하지만 동시 실행으로 자원 소비 증가 | F42: ='6조'!F$6 -> -- | G42: ='6조'!G$6 -> 지속적인 센싱과 연산이 필요한 구조라 유휴 상태 없이 상시 자원 소모함
A43: 7조 | B43: ='7조'!B$6 | C43: ='7조'!C$6 -> 7조 - Batch Sequential - Energy Efficiency | D43: ='7조'!D$6 | E43: ='7조'!E$6 -> 7조 - Pipe and Filter - Energy Efficiency | F43: ='7조'!F$6 | G43: ='7조'!G$6 -> 7조 - Process Control - Energy Efficiency
...

Sheet DC
A1: Data Centered | B1: Shared Repository | D1: Blackboard
B2: Effects | C2: Justification | D2: Effects | E2: Justification
A3: Availability | B3: ='Detailed Reasoning'!B16 | C3: ='Detailed Reasoning'!C16 | D3: ='Detailed Reasoning'!D16 | E3: ='Detailed Reasoning'!E16
A4: 1조 | B4: ='1조'!B$16 -> - | C4: ='1조'!C16 -> [+] 역할 분리: 클라이언트를 별도 실행 단위로 구성하면 장애 원인을 해당 클라이언트로 좁히고 개별적으로 복구할 수 있다. 다른 클라이언트가 반드시 함께 중단되어야 하는 구조는 아니다. [--] 저장소 의존: 공유 저장소가 중단되고 대체 저장소가 없다면, 이를 사용하는 모든 클라이언트의 데이터 접근이 막혀 관련 기능이 함께 중단될 수 있다. | D4: ='1조'!D$16 -> -- | E4: ='1조'!E16 -> [-] Controller와 Blackboard 간 의존성 때문에 부분 장애 시 전체가 일관되게 동작하기 어렵다. [--] 중앙 Blackboard 또는 Controller의 장애는 전체 추론 진행을 중단시킬 수 있다.
A5: 2조 | B5: ='2조'!B$16 -> -- | C5: ='2조'!C$16 -> 중앙의 Shared Data Store가 전체 시스템의 단일 장애점(SPOF)으로 작용하여, 저장소에 장애가 발생하면 이에 의존하는 모든 클라이언트의 서비스가 일시에 정지됨 | D5: ='2조'!D$16 -> -- | E5: ='2조'!E$16 -> Blackboard와 Controller가 공통 데이터·실행 선택의 중심이므로 이들의 고장은 전체 추론을 멈출 수 있다. Knowledge Source의 독립성만으로 중앙 장애를 견디지는 못한다. [설계 PDF p.62–67]
A6: 3조 | B6: ='3조'!B$16 -> -- | C6: ='3조'!C$16 -> 중앙 데이터 저장소가 명확한 단일 장애점(SPOF)가 되므로, 저장소가 고장나면 전체 component가 데이터를 읽고 쓸 수 없다 | D6: ='3조'!D$16 -> -- | E6: ='3조'!E$16 -> Blackboard/Controller가 KS 실행의 중심이므로, 이 부분이 멈추면 여러 KS 협업도 함께 중단된다.
A7: 4조 | B7: ='4조'!B$16 -> - | C7: ='4조'!C$16 -> 중앙 Repository에 장애가 발생하면 이를 사용하는 여러 컴포넌트가 동시에 영향을 받는다. 저장소가 Single Point of Failure가 되기 쉽다. | D7: ='4조'!D$16 -> - | E7: ='4조'!E$16 -> 중앙 Blackboard가 핵심 공유 지점이므로 Blackboard에 장애가 발생하면 여러 Knowledge Source가 동시에 영향을 받는다. 중앙 저장소 의존성이 크다.
A8: 5조 | B8: ='5조'!B$16 -> -- | C8: ='5조'!C$16 -> 공유 저장소 장애 시 의존하는 모든 Client에 영향 | D8: ='5조'!D$16 -> 0 | E8: ='5조'!E$16 -> 중앙 블랙보드와 컨트롤러가 다운되면 모든 KS가 동작을 멈추지만, KS의 다운은 전체 시스템에 영향을 미치지 않는다.
A9: 6조 | B9: ='6조'!B$16 -> - | C9: ='6조'!C$16 -> Repository에 문제가 생기면 모든 client의 동작이 마비된다. | D9: ='6조'!D$16 -> -- | E9: ='6조'!E$16 -> Orchestrator / Blackboard 마비 시에 모든 Knowledge Source 동작이 마비됨
A10: 7조 | B10: ='7조'!B$16 | C10: ='7조'!C$16 -> 7조 - Shared Respository - Availability | D10: ='7조'!D$16 | E10: ='7조'!E$16 -> 7조 - Blackboard - Availability
A11: 8조 | B11: ='8조'!B$16 | C11: ='8조'!C$16 -> 8조 - Shared Respository - Availability | D11: ='8조'!D$16 | E11: ='8조'!E$16 -> 8조 - Blackboard - Availability
A12: 9조 | B12: ='9조'!B$16 | C12: ='9조'!C$16 -> 9조 - Shared Respository - Availability | D12: ='9조'!D$16 | E12: ='9조'!E$16 -> 9조 - Blackboard - Availability
A14: Deployability | B14: ='Detailed Reasoning'!B17 | C14: ='Detailed Reasoning'!C17 | D14: ='Detailed Reasoning'!D17 | E14: ='Detailed Reasoning'!E17
A15: 1조 | B15: ='1조'!B$17 -> - | C15: ='1조'!C17 -> [+] 클라이언트별 교체: 공유 데이터 구조와 접근 계약이 유지되면, 별도 배포 단위인 클라이언트의 구현을 다른 클라이언트와 분리하여 교체하기 쉽다. [-] 공통 스키마 의존: 저장소의 자료구조가 바뀌면 이를 사용하는 클라이언트들의 호환성을 함께 확인하고 배포 시점을 조정해야 한다. | D15: ='1조'!D$17 -> 0 | E15: ='1조'!E17 -> [+] 지식원별 교체: 공유 데이터와 호출 계약이 유지되면, 별도 배포 단위인 KS의 내부 구현을 다른 KS와 분리하여 교체하기 쉽다. [-] 공통 자료구조 의존: Blackboard의 자료구조를 바꾸면 이를 사용하는 여러 KS의 버전과 호환성을 함께 조정해야 한다. | F15: Data client, KS는 비교적 독립 배포가 가능(+) Data store, Black bd의 스키마 변경은 시스템 전체의 재배포를 요구한다(--)
A16: 2조 | B16: ='2조'!B$17 -> - | C16: ='2조'!C$17 -> client 를 하나씩 따로 올릴 수 있다. 다만 저장소 스키마를 바꾸는 배포는 무겁다 | D16: ='2조'!D$17 -> + | E16: ='2조'!E$17 -> 개별 KS는 모듈화된 지식 단위이므로 독립적인 빌드 및 플러그인 형태의 개별 배포가 용이함. (단, 블랙보드 공통 데이터 구조 변경 시 예외)
A17: 3조 | B17: ='3조'!B$17 -> - | C17: ='3조'!C$17 -> client 기능은 따로 배포할 수 있지만, 중앙 데이터 저장소 구조 의존성은 높다 | D17: ='3조'!D$17 -> + | E17: ='3조'!E$17 -> KS는 직접 연결되지 않고 Blackboard를 통해 협력하므로 KS 단위 추가·교체는 비교적 쉽다. 단, Blackboard/Controller 변경은 영향이 크다.
A18: 4조 | B18: ='4조'!B$17 -> 0 | C18: ='4조'!C$17 -> 각 컴포넌트는 독립적으로 배포할 수 있지만, DB Schema나 Repository 구조가 변경되면 여러 컴포넌트를 함께 수정·배포해야 할 수 있다. | D18: ='4조'!D$17 -> 0 | E18: ='4조'!E$17 -> Knowledge Source는 비교적 독립적으로 추가·배포할 수 있지만, Blackboard의 데이터 표현 방식이나 제어 로직과의 호환성을 맞춰야 한다.
A19: 5조 | B19: ='5조'!B$17 -> - | C19: ='5조'!C$17 -> 스키마 변경 시 관련 Client의 배포 조율 필요 | D19: ='5조'!D$17 -> 0 | E19: ='5조'!E$17 -> KS는 쉽게 변경 가능하나, 중앙 블랙보드와 컨트롤러는 모든 KS와 맞물려있어 제한적이다.
A20: 6조 | B20: ='6조'!B$17 -> - | C20: ='6조'!C$17 -> 한 component의 변경이 시스템 전체에 영향을 미칠 수 있고 배포 용이성에 영향을 미친다. | D20: ='6조'!D$17 -> - | E20: ='6조'!E$17 -> 모든 Knowledge Source가 블랙보드/제어 컴포넌트에 강하게 결합
A21: 7조 | B21: ='7조'!B$17 | C21: ='7조'!C$17 -> 7조 - Shared Respository - Deployability | D21: ='7조'!D$17 | E21: ='7조'!E$17 -> 7조 - Blackboard - Deployability
A22: 8조 | B22: ='8조'!B$17 | C22: ='8조'!C$17 -> 8조 - Shared Respository - Deployability | D22: ='8조'!D$17 | E22: ='8조'!E$17 -> 8조 - Blackboard - Deployability
A23: 9조 | B23: ='9조'!B$17 | C23: ='9조'!C$17 -> 9조 - Shared Respository - Deployability | D23: ='9조'!D$17 | E23: ='9조'!E$17 -> 9조 - Blackboard - Deployability
A25: Integrability | B25: ='Detailed Reasoning'!B18 | C25: ='Detailed Reasoning'!C18 | D25: ='Detailed Reasoning'!D18 | E25: ='Detailed Reasoning'!E18
A26: 1조 | B26: ='1조'!B$18 -> + | C26: ='1조'!C18 -> [++] 공통 데이터 모델: 새로운 클라이언트가 공통 데이터 모델과 접근 계약을 따르면 기존 클라이언트 각각과 직접 연결하지 않고 시스템에 참여할 수 있다. [+] 클라이언트 재사용: 기존 클라이언트의 기능을 유지하면서 같은 데이터 구조를 사용하는 다른 구성에 재사용하기 쉽다. | D26: ='1조'!D$18 -> + | E26: ='1조'!E18 -> [+] 공통 데이터 기반 통합: 새로운 KS가 공통 데이터 모델에 맞게 결과를 읽고 쓰면, 다른 KS와 직접 연결하지 않고 협력에 참여할 수 있다. [+] 지식원 재사용: KS들이 서로 독립적이므로 기존 지식원을 재사용하거나 새로운 판단·처리 기능을 추가하기 쉽다. | F26: 공통) 데이터 스키마만 이해하면 빠르게 통합 가능(+) 반면, 스키마 변경이 전체 시스템에 영향을 미쳐 진화(확장) 시 통합 리스크가 큼(-) Blackboard의 경우 Controller와 KS 간의 의존성이 통합이 리스트가되기도함
A27: 2조 | B27: ='2조'!B$18 -> ++ | C27: ='2조'!C$18 -> 새 data client 나 data store 를 추가하기 쉽다(Scalability). 같은 저장소에 붙이기만 하면 된다 | D27: ='2조'!D$18 -> + | E27: ='2조'!E$18 -> 규칙 기반(Rule-based), 머신러닝(ML), 휴리스틱 등 이종의 추론 기법을 가진 서로 다른 엔진들을 독립된 KS 형태로 블랙보드에 유연하게 결합·통합할 수 있음.
A28: 3조 | B28: ='3조'!B$18 -> + | C28: ='3조'!C$18 -> Repository는 여러 data client가 동일한 중앙 data store와 공통 데이터 모델을 통해 연결된다. 새 client도 data access/procedure call 규약만 맞추면 기존 client와 직접 연결 없이 통합할 수 있다. | D28: ='3조'!D$18 -> + | E28: ='3조'!E$18 -> 새 알고리즘을 KS로 추가해 Blackboard를 읽고 쓰게 하면, 기존 KS와 직접 연결하지 않고도 통합할 수 있다.
A29: 4조 | B29: ='4조'!B$18 -> ++ | C29: ='4조'!C$18 -> 여러 컴포넌트가 동일한 저장소를 통해 데이터를 공유하므로 시스템 간 데이터 통합이 매우 쉽다. 공통 데이터 모델만 맞으면 새로운 컴포넌트도 데이터를 쉽게 활용할 수 있다. | D29: ='4조'!D$18 -> ++ | E29: ='4조'!E$18 -> 새 지식원은 블랙보드 상태에 반응하는 방식으로 통합되며, 다른 지식원에 대한 직접 의존이나 지식이 필요 없다.
A30: 5조 | B30: ='5조'!B$18 -> + | C30: ='5조'!C$18 -> 공통 스키마를 따르는 Client를 저장소에 연결하여 통합 가능 | D30: ='5조'!D$18 -> + | E30: ='5조'!E$18 -> 각각의 KS들이 중앙 블랙보드의 데이터만 바라보므로 중앙 블랙보드 형식만 맞추면 되어 통합하기 쉽다.
A31: 6조 | B31: ='6조'!B$18 -> + | C31: ='6조'!C$18 -> repository의 있는 그대로를 사용하는 client가 추가되는 것이 쉽기 때문에 통합 용이성은 좋다. | D31: ='6조'!D$18 -> + | E31: ='6조'!E$18 -> 외부 컴포넌트도 또다른 Knowledge Source로 추가하기 용이
A32: 7조 | B32: ='7조'!B$18 | C32: ='7조'!C$18 -> 7조 - Shared Respository - Integrability | D32: ='7조'!D$18 | E32: ='7조'!E$18 -> 7조 - Blackboard - Integrability
A33: 8조 | B33: ='8조'!B$18 | C33: ='8조'!C$18 -> 8조 - Shared Respository - Integrability | D33: ='8조'!D$18 | E33: ='8조'!E$18 -> 8조 - Blackboard - Integrability
A34: 9조 | B34: ='9조'!B$18 | C34: ='9조'!C$18 -> 9조 - Shared Respository - Integrability | D34: ='9조'!D$18 | E34: ='9조'!E$18 -> 9조 - Blackboard - Integrability
A36: Energy Efficiency | B36: ='Detailed Reasoning'!B$19 | C36: ='Detailed Reasoning'!C$19 | D36: ='Detailed Reasoning'!D$19 | E36: ='Detailed Reasoning'!E$19
A37: 1조 | B37: ='1조'!B$19 -> 0 | C37: ='1조'!C19 -> [+] 중간 데이터 교환 감소 — 해석: 클라이언트끼리 임시 데이터를 반복해서 전달하는 비용이 줄어들면, 그 전달에 필요한 연산·통신의 에너지 비용도 줄일 수 있다. [-] 실행 단위 유지 비용: 클라이언트와 저장소를 별도 프로세스 등으로 실행하면 각 실행 단위의 기본 자원과 저장소 접근 통신에 비용이 발생한다. | D37: ='1조'!D$19 -> 0 | E37: ='1조'!E19 -> [0]병렬적인 Knowledge Source 동작으로 효율을 얻을 수 있으나 Controller의 중재 오버헤드가 존재한다. | F37: 공통) 동시에 작업이 몰리는 경우 및 지속적인 데이터 모니터링으로 리소스의 소비가 이어지는 점을 고려 해야 한다. Shared Repo의 경우 클라이언트간 작업이 순차적으로 발생하는 경우가 많아 이점은 다소 긍정적이다
A38: 2조 | B38: ='2조'!B$19 -> + | C38: ='2조'!C$19 -> client 사이에 임시 데이터를 주고받는 overhead 가 줄어 중복 전송·중복 저장이 적다 | D38: ='2조'!D$19 -> - | E38: ='2조'!E$19 -> 가설이 수렴할 때까지 다수의 KS가 활성화되어 연산을 반복하고, Controller가 Blackboard를 상시 감시·평가(Loop)하므로 CPU 및 메모리 연산 자원 소모가 매우 큼.
A39: 3조 | B39: ='3조'!B$19 -> + | C39: ='3조'!C$19 -> 데이터가 중앙에 한 번만 저장되어 중복 복제 및 동기화 통신 비용이 발생하지 않으므로 자원 소비 효율이 우수합니다. | D39: ='3조'!D$19 -> - | E39: ='3조'!E$19 -> 상태 감시 loop, 반복 추론, 여러 가설 탐색이 계속 필요해 CPU·메모리 사용이 크게 늘 수 있다.
A40: 4조 | B40: ='4조'!B$19 -> 0 | C40: ='4조'!C$19 -> 데이터를 한곳에 집중시켜 중복 저장을 줄일 수 있지만, 모든 컴포넌트의 읽기·쓰기가 중앙 저장소에 집중되므로 DB 처리 비용도 커질 수 있다. | D40: ='4조'!D$19 -> -- | E40: ='4조'!E$19 -> 기회주의적 활성화 방식이라 많은 지식원이 블랙보드를 계속 살피며 중복 연산을 수행하고, 그 결과 상당수가 버려진다.
A41: 5조 | B41: ='5조'!B$19 -> + | C41: ='5조'!C$19 -> 중복 데이터 복제와 여러 저장소 운영을 줄여 자원 사용을 집중 | D41: ='5조'!D$19 -> - | E41: ='5조'!E$19 -> 컨트롤러가 지속적으로 블랙보드를 모니터링하고 KS를 제어하므로 오버헤드가 크다.
A42: 6조 | B42: ='6조'!B$19 -> + | C42: ='6조'!C$19 -> repository 하나를 공유하며 각 client가 독립적이기 때문에 낭비가 적어 에너지 효율성은 좋을 것 같다. | D42: ='6조'!D$19 -> - | E42: ='6조'!E$19 -> Orchestrator(Controller)의 모니터링 오버헤드로 인한 자원 소모
A43: 7조 | B43: ='7조'!B$19 | C43: ='7조'!C$19 -> 7조 - Shared Respository - Energy Efficiency | D43: ='7조'!D$19 | E43: ='7조'!E$19 -> 7조 - Blackboard - Energy Efficiency
...

Sheet II
A1: Implicit Invocation | B1: Non-Buffered Event Based | D1: Buffered Message Based
B2: Effects | C2: Justification | D2: Effects | E2: Justification
A3: Availability | B3: ='Detailed Reasoning'!B$29 | C3: ='Detailed Reasoning'!C$29 | D3: ='Detailed Reasoning'!D$29 | E3: ='Detailed Reasoning'!E$29
A4: 1조 | B4: ='1조'!B$29 -> + | C4: ='1조'!C29 -> [+] 송수신자 분리: Event Publisher와 Subscriber가 분리되어 특정 Subscriber의 장애가 Publisher나 다른 Subscriber에 직접 영향을 주지 않는다. [-] Event 유실: Subscriber가 장애 상태이거나 Event를 처리할 수 없는 경우 Buffer가 없기 때문에 Event가 유실될 수 있다. | D4: ='1조'!D$29 -> 0 | E4: ='1조'!E29 -> [+] 장애 격리: Producer와 Consumer가 분리되어 Consumer의 일시적인 장애가 Producer에 직접 영향을 주지 않는다. [+] 재처리 가능: 처리에 실패한 Message를 다시 처리하도록 구성할 수 있어 장애 복구에 유리하다. [-] Broker 장애: 중앙 Message Broker 자체에 장애가 발생하면 Message 전달에 영향을 줄 수 있다. | F4: Non-Buff의 강한 결합은 가용성의 문제점이 된다. Buff를 이용한 약한 결합은 장애 점파를 차단 하는 효과가 있다 이벤트 소스의 장애는 전체 시스템 동작에 문제가 된다. 특히 Non-Buff의 경우 치명적이다
A5: 2조 | B5: ='2조'!B$29 -> - | C5: ='2조'!C$29 -> listener 가 없거나 죽으면 그 event 는 처리되지 않고 사라진다 — 버퍼가 없어 되돌릴 수 없다 | D5: ='2조'!D$29 -> ++ | E5: ='2조'!E$29 -> producer 와 consumer 가 시간으로 분리되어(time independence) 한쪽이 멈춰도 message 가 buffer 에 남아 있다
A6: 3조 | B6: ='3조'!B$29 -> - | C6: ='3조'!C$29 -> Buffer 없이 Listener를 동기적으로 호출하므로 Listener의 장애나 지연이 Event 처리 흐름에 직접 영향을 미치며, Receiver 장애 시 Event를 저장하여 나중에 처리하는 기능도 제공하지 않는다. | D6: ='3조'!D$29 -> ++ | E6: ='3조'!E$29 -> producer와 consumer가 decouple 되어 동시에 살아 있지 않아도 되고, 메시지 신뢰성 설정도 가능하므로 Availiability에 유리함
A7: 4조 | B7: ='4조'!B$29 -> - | C7: ='4조'!C$29 -> 받는 기능이 멈춰 있으면 이벤트를 놓칠 수 있고, 복구 후 다시 전달하기 어렵다. | D7: ='4조'!D$29 -> ++ | E7: ='4조'!E$29 -> 큐가 송수신자를 시간적으로 분리해 소비자가 죽어도 메시지가 유실되지 않고 복구 후 처리가 이어진다. 대신 브로커 자체가 이중화가 필요한 핵심 요소가 된다.
A8: 5조 | B8: ='5조'!B$29 -> - | C8: ='5조'!C$29 -> 수신 측이 다운되어 있을 동안 발생한 이벤트가 손실될 가능성이 있다. | D8: ='5조'!D$29 -> ++ | E8: ='5조'!E$29 -> 수신 측이 다운되어 있더라도 메시지가 버퍼에 보존되기 때문에 이벤트 손실의 가능성이 적다.
A9: 6조 | B9: ='6조'!B$29 -> -- | C9: ='6조'!C$29 -> producer가 어느 한 custormer에 잡혀있을 경우 producer 가 블로킹된다. | D9: ='6조'!D$29 -> + | E9: ='6조'!E$29 -> 메시지가 버퍼에 저장되므로 Consumer가 일시적으로 중단되어도 복구 후 처리를 계속할 수 있다.
A10: 7조 | B10: ='7조'!B$29 | C10: ='7조'!C$29 -> 7조 - Non-Buffered Event Based - Availability | D10: ='7조'!D$29 | E10: ='7조'!E$29 -> 7조 - Buffered Message Based - Availability
A11: 8조 | B11: ='8조'!B$29 | C11: ='8조'!C$29 -> 8조 - Non-Buffered Event Based - Availability | D11: ='8조'!D$29 | E11: ='8조'!E$29 -> 8조 - Buffered Message Based - Availability
A12: 9조 | B12: ='9조'!B$29 | C12: ='9조'!C$29 -> 9조 - Non-Buffered Event Based - Availability | D12: ='9조'!D$29 | E12: ='9조'!E$29 -> 9조 - Buffered Message Based - Availability
A14: Deployability | B14: ='Detailed Reasoning'!B$30 | C14: ='Detailed Reasoning'!C$30 | D14: ='Detailed Reasoning'!D$30 | E14: ='Detailed Reasoning'!E$30
A15: 1조 | B15: ='1조'!B$30 -> + | C15: ='1조'!C30 -> [+] 컴포넌트 독립성: Publisher와 Subscriber가 직접 연결되지 않아 개별적으로 변경·배포하기 쉽다. [+] Subscriber 추가: 기존 Publisher를 변경하지 않고 새로운 Subscriber를 추가하여 배포할 수 있다. | D15: ='1조'!D$30 -> - | E15: ='1조'!E30 -> [+] 독립 배포: Producer와 Consumer가 Message Queue를 통해 분리되어 각각 독립적으로 배포하기 쉽다. [-] Broker 관리: Message Broker 자체에 대한 별도의 배포와 운영이 필요하다. | F15: Non-Buff 는 강한 결합이 단일 배포지점을 제공하는 장점이 있지만 이벤트-발생과 소비가 고정되어 확장의 제약이 됨 Buff 의 경우 런타임의 유연한 클라이언트 확장이 가능하다
A16: 2조 | B16: ='2조'!B$30 -> 0 | C16: ='2조'!C$30 -> 대개 단일 애플리케이션(UI 프레임워크, IDE 도구 등) 내부 모듈 단위로 빌드 및 패키징되므로 배포 용이성에 미치는 직접적 영향은 중립적임. | D16: ='2조'!D$30 -> ++ | E16: ='2조'!E$30 -> consumer 를 내렸다 올려도 그 사이 message 가 쌓여 있어 무중단 배포가 쉽다
A17: 3조 | B17: ='3조'!B$30 -> 0 | C17: ='3조'!C$30 -> Listener를 추가·교체하기는 쉽지만 일반적으로 Event Source와 Listener가 동일 프로세스/배포 단위에 포함되므로 독립 배포 효과는 제한적이다. | D17: ='3조'!D$30 -> ++ | E17: ='3조'!E$30 -> producer와 consumer가 decouple 되어, 각각 개별적으로 배포, 업그레이드가 가능하므로 deployability에 유리함
A18: 4조 | B18: ='4조'!B$30 -> 0 | C18: ='4조'!C$30 -> 기능을 분리하기는 좋지만, 각각 따로 배포할 수 있는지는 구현에 따라 다르다. | D18: ='4조'!D$30 -> ++ | E18: ='4조'!E$30 -> 버퍼가 다운타임을 흡수하므로 생산자와 소비자를 독립적으로 배포·재시작·롤백할 수 있다.
A19: 5조 | B19: ='5조'!B$30 -> + | C19: ='5조'!C$30 -> 이벤트 발행자와 구독자가 상호독립적이므로 개별 배포가 용이하다. | D19: ='5조'!D$30 -> ++ | E19: ='5조'!E$30 -> 이벤트 발행자와 이벤트 구독자가 상호독립적이므로 배포에 서로 영향 받지 않는다.
A20: 6조 | B20: ='6조'!B$30 -> + | C20: ='6조'!C$30 -> customer 확장이 자유롭다 | D20: ='6조'!D$30 -> ++ | E20: ='6조'!E$30 -> Producer와 Consumer를 독립적으로 배포·교체할 수 있다.
A21: 7조 | B21: ='7조'!B$30 | C21: ='7조'!C$30 -> 7조 - Non-Buffered Event Based - Deployability | D21: ='7조'!D$30 | E21: ='7조'!E$30 -> 7조 - Buffered Message Based - Deployability
A22: 8조 | B22: ='8조'!B$30 | C22: ='8조'!C$30 -> 8조 - Non-Buffered Event Based - Deployability | D22: ='8조'!D$30 | E22: ='8조'!E$30 -> 8조 - Buffered Message Based - Deployability
A23: 9조 | B23: ='9조'!B$30 | C23: ='9조'!C$30 -> 9조 - Non-Buffered Event Based - Deployability | D23: ='9조'!D$30 | E23: ='9조'!E$30 -> 9조 - Buffered Message Based - Deployability
A25: Integrability | B25: ='Detailed Reasoning'!B$31 | C25: ='Detailed Reasoning'!C$31 | D25: ='Detailed Reasoning'!D$31 | E25: ='Detailed Reasoning'!E$31
A26: 1조 | B26: ='1조'!B$31 -> ++ | C26: ='1조'!C31 -> [+] 낮은 결합도: Publisher는 Event를 누가 처리하는지 알 필요가 없어 새로운 Subscriber를 쉽게 통합할 수 있다. [+] 확장 용이: 기존 Publisher를 수정하지 않고 새로운 Event Subscriber를 추가할 수 있다. | D26: ='1조'!D$31 -> + | E26: ='1조'!E31 -> [+] 낮은 결합도: Producer와 Consumer가 Message를 통해 간접적으로 연결되어 새로운 시스템을 통합하기 쉽다. [+] 독립적 추가: 기존 Producer를 변경하지 않고 새로운 Consumer를 추가할 수 있다. | F26: Non-Buff는 강한 결합이 통합을 어렵게 한다 Buff는 메시지이 규격을 준수하여 유연한 확장이 가능하다
A27: 2조 | B27: ='2조'!B$31 -> + | C27: ='2조'!C$31 -> 기존 event listener 를 나머지 부분에 영향 없이 끼워 넣기 쉽고, Framework(Java AWT·Swing 등)가 풍부하다 | D27: ='2조'!D$31 -> ++ | E27: ='2조'!E$31 -> consumer 는 누가·어디서·언제 만들었는지 몰라도 된다(익명성) — 붙이는 비용이 가장 낮다
A28: 3조 | B28: ='3조'!B$31 -> + | C28: ='3조'!C$31 -> 표준 Event/Listener 인터페이스를 이용하면 기존 Event Source의 변경을 최소화하면서 새로운 Listener를 연결할 수 있어 컴포넌트 통합이 용이하다. | D28: ='3조'!D$31 -> ++ | E28: ='3조'!E$31 -> Queue가 poducer와 consumer를 중재하므로, 여러 이기종 consumer를 podcuer에 변경업이 통합 가능하다.
A29: 4조 | B29: ='4조'!B$31 -> + | C29: ='4조'!C$31 -> 같은 이벤트 규칙을 따르면 새로운 기능을 연결하기 쉽다. | D29: ='4조'!D$31 -> ++ | E29: ='4조'!E$31 -> 새 소비자가 생산자 변경 없이 기존 큐나 토픽에 붙을 수 있고, 이기종 시스템도 메시지 계약으로 통합된다.
A30: 5조 | B30: ='5조'!B$31 -> ++ | C30: ='5조'!C$31 -> 이벤트 발행의 수정 없이도 새로운 구독자를 추가적으로 등록하여 기능 통합에 용이하다. | D30: ='5조'!D$31 -> ++ | E30: ='5조'!E$31 -> 서로 다른 시스템일지라도 메시지 브로커의 프로토콜만 맞는다면 통합하기 용이하다.
A31: 6조 | B31: ='6조'!B$31 -> + | C31: ='6조'!C$31 -> customer 확장이 자유롭다 | D31: ='6조'!D$31 -> + | E31: ='6조'!E$31 -> producer/consumer가 서로의 신원을 몰라도 되는 익명성 덕분에 새로운 서비스를 붙이기 쉽다
A32: 7조 | B32: ='7조'!B$31 | C32: ='7조'!C$31 -> 7조 - Non-Buffered Event Based - Integrability | D32: ='7조'!D$31 | E32: ='7조'!E$31 -> 7조 - Buffered Message Based - Integrability
A33: 8조 | B33: ='8조'!B$31 | C33: ='8조'!C$31 -> 8조 - Non-Buffered Event Based - Integrability | D33: ='8조'!D$31 | E33: ='8조'!E$31 -> 8조 - Buffered Message Based - Integrability
A34: 9조 | B34: ='9조'!B$31 | C34: ='9조'!C$31 -> 9조 - Non-Buffered Event Based - Integrability | D34: ='9조'!D$31 | E34: ='9조'!E$31 -> 9조 - Buffered Message Based - Integrability
A36: Energy Efficiency | B36: ='Detailed Reasoning'!B$32 | C36: ='Detailed Reasoning'!C$32 | D36: ='Detailed Reasoning'!D$32 | E36: ='Detailed Reasoning'!E$32
A37: 1조 | B37: ='1조'!B$32 -> + | C37: ='1조'!C32 -> [+] Event 기반 실행: Event가 발생했을 때만 Subscriber가 동작하도록 구성할 수 있어 불필요한 Polling을 줄일 수 있다. [+] 저장 비용 없음: 별도의 Buffer에 Event를 저장하고 관리하는 자원이 필요하지 않다. | D37: ='1조'!D$32 -> + | E37: ='1조'!E32 -> [+] 비동기 처리: Consumer가 자신의 처리 능력에 맞게 Message를 가져가 처리하여 자원 사용을 조절할 수 있다. [-] Broker 운영: Message Broker를 지속적으로 운영하기 위한 추가적인 에너지가 필요하다. | F37: Non-Buff는 빈발한 이벤트 발생시 자원소비가 증가하게 된다(소스와 리스너가 거이 동시에 구동) Buff는 메시지를 구독하는 동시 구독자가 많아지면 문제가 되지만 일잠적으로 메시지별 구독자는 구분된다
A38: 2조 | B38: ='2조'!B$32 -> ++ | C38: ='2조'!C$32 -> 메시지 브로커 상시 구동, 디스크 큐 I/O, 패킷 전송 오버헤드가 전혀 없으므로 불필요한 시스템 자원 낭비가 없어 에너지 소비 관점에서 가장 우수함. | D38: ='2조'!D$32 -> - | E38: ='2조'!E$32 -> buffer 저장과 전달에 자원이 들고, 간접 호출 overhead 가 있다
A39: 3조 | B39: ='3조'!B$32 -> 0 | C39: ='3조'!C$32 -> Event 발생 시에만 Listener가 실행되어 polling을 줄일 수 있지만 indirect invocation의 추가 overhead도 존재하므로 Energy Efficiency에 대한 전반적인 영향은 구현에 따라 달라진다. | D39: ='3조'!D$32 -> - | E39: ='3조'!E$32 -> Queue 관리를 위해, 네트워크, 디스크 I/O 등 에너지를 추가적으로 사용하므로, energy efficiency에 불리하다.
A40: 4조 | B40: ='4조'!B$32 -> 0 | C40: ='4조'!C$32 -> 이벤트를 저장하는 비용은 없지만, 실제 전력 소모는 실행되는 작업량에 따라 달라진다. | D40: ='4조'!D$32 -> 0 | E40: ='4조'!E$32 -> 배치 처리와 부하 평준화로 자원 사용이 고르게 되어 과잉 프로비저닝을 피하지만, 메시지 영속화와 복제에 추가 저장·I/O 비용이 든다.
A41: 5조 | B41: ='5조'!B$32 -> 0 | C41: ='5조'!C$32 -> 메시지 저장·영속화에 따른 오버헤드는 적지만 이벤트가 발생할 때마다 즉시 처리되므로 Batch 처리나 자원 활성화 횟수 감소 등의 에너지 절감 효과는 보장되지 않아 전체적으로는 중립적이다. | D41: ='5조'!D$32 -> + | E41: ='5조'!E$32 -> 비동기 처리로 component가 항시 대기 필요없고, 메시지 queue도 일괄 처리 가능
A42: 6조 | B42: ='6조'!B$32 -> -- | C42: ='6조'!C$32 -> prooducer 동작 시 customer 가 통신을 받지 않는 이상은 이벤트가 낭비된다. | D42: ='6조'!D$32 -> - | E42: ='6조'!E$32 -> 메시지 저장과 전달, 직렬화·역직렬화, Broker 운영 및 재시도 처리에 추가적인 계산·저장·통신 자원이 필요하다.
A43: 7조 | B43: ='7조'!B$32 | C43: ='7조'!C$32 -> 7조 - Non-Buffered Event Based - Energy Efficiency | D43: ='7조'!D$32 | E43: ='7조'!E$32 -> 7조 - Buffered Message Based - Energy Efficiency
...

Sheet IO
A1: Interaction-Oriented | B1: MVC | D1: PAC
B2: Effects | C2: Justification | D2: Effects | E2: Justification
A3: Availability | B3: ='Detailed Reasoning'!B$42 | C3: ='Detailed Reasoning'!C$42 | D3: ='Detailed Reasoning'!D$42 | E3: ='Detailed Reasoning'!E$42
A4: 1조 | B4: ='1조'!B$42 | C4: ='1조'!C42 -> 1조 - MVC - Availability | D4: ='1조'!D$42 | E4: ='1조'!E42 -> 1조 - PAC - Availability | F4: MVC 모델에 문제가 생기면 전체 시스템에 영향(-) 뷰의 장애는 특정 뷰에만 영향을 미친다(+) PAC agent를 다양한 노드에 배치가 가능하여 전체 시스템 가용성을 높일 수 있음
A5: 2조 | B5: ='2조'!B$42 | C5: ='2조'!C$42 -> 2조 - MVC - Availability | D5: ='2조'!D$42 | E5: ='2조'!E$42 -> 2조 - PAC - Availability
A6: 3조 | B6: ='3조'!B$42 | C6: ='3조'!C$42 -> 3조 - MVC - Availability | D6: ='3조'!D$42 | E6: ='3조'!E$42 -> 3조 - PAC - Availability
A7: 4조 | B7: ='4조'!B$42 | C7: ='4조'!C$42 -> Human - MVC - Availability | D7: ='4조'!D$42 | E7: ='4조'!E$42 -> Human - PAC - Availability
A8: 5조 | B8: ='5조'!B$42 | C8: ='5조'!C$42 -> 5조 - MVC - Availability | D8: ='5조'!D$42 | E8: ='5조'!E$42 -> 5조 - PAC - Availability
A9: 6조 | B9: ='6조'!B$42 | C9: ='6조'!C$42 -> 6조 - MVC - Availability | D9: ='6조'!D$42 | E9: ='6조'!E$42 -> 6조 - PAC - Availability
A10: 7조 | B10: ='7조'!B$42 | C10: ='7조'!C$42 -> 7조 - MVC - Availability | D10: ='7조'!D$42 | E10: ='7조'!E$42 -> 7조 - PAC - Availability
A11: 8조 | B11: ='8조'!B$42 | C11: ='8조'!C$42 -> 8조 - MVC - Availability | D11: ='8조'!D$42 | E11: ='8조'!E$42 -> 8조 - PAC - Availability
A12: 9조 | B12: ='9조'!B$42 | C12: ='9조'!C$42 -> 9조 - MVC - Availability | D12: ='9조'!D$42 | E12: ='9조'!E$42 -> 9조 - PAC - Availability
A14: Deployability | B14: ='Detailed Reasoning'!B$43 | C14: ='Detailed Reasoning'!C$43 | D14: ='Detailed Reasoning'!D$43 | E14: ='Detailed Reasoning'!E$43
A15: 1조 | B15: ='1조'!B$43 | C15: ='1조'!C43 -> 1조 - MVC - Deployability | D15: ='1조'!D$43 | E15: ='1조'!E43 -> 1조 - PAC - Deployability | F15: MVC 역할 분리를 통해 구조적 변경 관리 용이(+) 구성요소 간 강한 의미적 결합은 부분 배포를 제한하는 요소(-) PAC 느슨한 결합을 통해 부분적, 점진적 배포 가능
A16: 2조 | B16: ='2조'!B$43 | C16: ='2조'!C$43 -> 2조 - MVC - Deployability | D16: ='2조'!D$43 | E16: ='2조'!E$43 -> 2조 - PAC - Deployability
A17: 3조 | B17: ='3조'!B$43 | C17: ='3조'!C$43 -> 3조 - MVC - Deployability | D17: ='3조'!D$43 | E17: ='3조'!E$43 -> 3조 - PAC - Deployability
A18: 4조 | B18: ='4조'!B$43 | C18: ='4조'!C$43 -> Human - MVC - Deployability | D18: ='4조'!D$43 | E18: ='4조'!E$43 -> Human - PAC - Deployability
A19: 5조 | B19: ='5조'!B$43 | C19: ='5조'!C$43 -> 5조 - MVC - Deployability | D19: ='5조'!D$43 | E19: ='5조'!E$43 -> 5조 - PAC - Deployability
A20: 6조 | B20: ='6조'!B$43 | C20: ='6조'!C$43 -> 6조 - MVC - Deployability | D20: ='6조'!D$43 | E20: ='6조'!E$43 -> 6조 - PAC - Deployability
A21: 7조 | B21: ='7조'!B$43 | C21: ='7조'!C$43 -> 7조 - MVC - Deployability | D21: ='7조'!D$43 | E21: ='7조'!E$43 -> 7조 - PAC - Deployability
A22: 8조 | B22: ='8조'!B$43 | C22: ='8조'!C$43 -> 8조 - MVC - Deployability | D22: ='8조'!D$43 | E22: ='8조'!E$43 -> 8조 - PAC - Deployability
A23: 9조 | B23: ='9조'!B$43 | C23: ='9조'!C$43 -> 9조 - MVC - Deployability | D23: ='9조'!D$43 | E23: ='9조'!E$43 -> 9조 - PAC - Deployability
A25: Integrability | B25: ='Detailed Reasoning'!B$44 | C25: ='Detailed Reasoning'!C$44 | D25: ='Detailed Reasoning'!D$44 | E25: ='Detailed Reasoning'!E$44
A26: 1조 | B26: ='1조'!B$44 | C26: ='1조'!C44 -> 1조 - MVC - Integrability | D26: ='1조'!D$44 | E26: ='1조'!E44 -> 1조 - PAC - Integrability | F26: MVC Model이 로직과 데이터를 캡슐화, View/Controller의 분리로 외부 시스템(API, 다른 UI, 배치/서비스)과의 통합이 비교적 용이(+) Controller가 복잡해질수록 통합 지점이 Controller에 집중되어 통합 변경 시 영향 범위가 커질 수 있음(-) PAC 약한결합의 에이전트 단위는 유연한 통합이 가능(+) 제어 계층 에이전트가 세분화 되면 통합 구조가 복잡해진다(-)
A27: 2조 | B27: ='2조'!B$44 | C27: ='2조'!C$44 -> 2조 - MVC - Integrability | D27: ='2조'!D$44 | E27: ='2조'!E$44 -> 2조 - PAC - Integrability
A28: 3조 | B28: ='3조'!B$44 | C28: ='3조'!C$44 -> 3조 - MVC - Integrability | D28: ='3조'!D$44 | E28: ='3조'!E$44 -> 3조 - PAC - Integrability
A29: 4조 | B29: ='4조'!B$44 | C29: ='4조'!C$44 -> Human - MVC - Integrability | D29: ='4조'!D$44 | E29: ='4조'!E$44 -> Human - PAC - Integrability
A30: 5조 | B30: ='5조'!B$44 | C30: ='5조'!C$44 -> 5조 - MVC - Integrability | D30: ='5조'!D$44 | E30: ='5조'!E$44 -> 5조 - PAC - Integrability
A31: 6조 | B31: ='6조'!B$44 | C31: ='6조'!C$44 -> 6조 - MVC - Integrability | D31: ='6조'!D$44 | E31: ='6조'!E$44 -> 6조 - PAC - Integrability
A32: 7조 | B32: ='7조'!B$44 | C32: ='7조'!C$44 -> 7조 - MVC - Integrability | D32: ='7조'!D$44 | E32: ='7조'!E$44 -> 7조 - PAC - Integrability
A33: 8조 | B33: ='8조'!B$44 | C33: ='8조'!C$44 -> 8조 - MVC - Integrability | D33: ='8조'!D$44 | E33: ='8조'!E$44 -> 8조 - PAC - Integrability
A34: 9조 | B34: ='9조'!B$44 | C34: ='9조'!C$44 -> 9조 - MVC - Integrability | D34: ='9조'!D$44 | E34: ='9조'!E$44 -> 9조 - PAC - Integrability
A36: Energy Efficiency | B36: ='Detailed Reasoning'!B$45 | C36: ='Detailed Reasoning'!C$45 | D36: ='Detailed Reasoning'!D$45 | E36: ='Detailed Reasoning'!E$45
A37: 1조 | B37: ='1조'!B$45 | C37: ='1조'!C45 -> 1조 - MVC - Energy Efficiency | D37: ='1조'!D$45 | E37: ='1조'!E45 -> 1조 - PAC - Energy Efficiency | F37: MVC UI/로직/데이터 접근을 분리해 불필요한 재계산 및 재렌더링을 최소화(+) 로직/데이터 바인딩이 복잡하고 많아지는 경우 오버헤드로 인하 리소스 사용 증가(-) PAC Agent간 상호작용이 많아질수록 리소스 사용 증가 (동시성과 통신 제어로 인한 리소스)
A38: 2조 | B38: ='2조'!B$45 | C38: ='2조'!C$45 -> 2조 - MVC - Energy Efficiency | D38: ='2조'!D$45 | E38: ='2조'!E$45 -> 2조 - PAC - Energy Efficiency
A39: 3조 | B39: ='3조'!B$45 | C39: ='3조'!C$45 -> 3조 - MVC - Energy Efficiency | D39: ='3조'!D$45 | E39: ='3조'!E$45 -> 3조 - PAC - Energy Efficiency
A40: 4조 | B40: ='4조'!B$45 | C40: ='4조'!C$45 -> Human - MVC - Energy Efficiency | D40: ='4조'!D$45 | E40: ='4조'!E$45 -> Human - PAC - Energy Efficiency
A41: 5조 | B41: ='5조'!B$45 | C41: ='5조'!C$45 -> 5조 - MVC - Energy Efficiency | D41: ='5조'!D$45 | E41: ='5조'!E$45 -> 5조 - PAC - Energy Efficiency
A42: 6조 | B42: ='6조'!B$45 | C42: ='6조'!C$45 -> 6조 - MVC - Energy Efficiency | D42: ='6조'!D$45 | E42: ='6조'!E$45 -> 6조 - PAC - Energy Efficiency
A43: 7조 | B43: ='7조'!B$45 | C43: ='7조'!C$45 -> 7조 - MVC - Energy Efficiency | D43: ='7조'!D$45 | E43: ='7조'!E$45 -> 7조 - PAC - Energy Efficiency
...

Sheet H1
A1: Hierarchical | B1: Main-subroutine | D1: Master-Slave
B2: Effects | C2: Justification | D2: Effects | E2: Justification
A3: Availability | B3: ='Detailed Reasoning'!B$55 | C3: ='Detailed Reasoning'!C$55 | D3: ='Detailed Reasoning'!D$55 | E3: ='Detailed Reasoning'!E$55
A4: 1조 | B4: ='1조'!B$55 -> -- | C4: ='1조'!C$55 -> [+] 구조가 단순하여 단일 모듈 오류 수정 및 복구 용이 [--] 메인 루틴 장애 시 전체 프로그램이 즉시 마비됨 (SPOF) | D4: ='1조'!D$55 -> + | E4: ='1조'!E$55 -> [+] 장애가 발생한 Slave의 작업을 대체 가능한 Slave에 재할당하여 처리를 지속할 수 있다 [-] Master 단일점 장애(SPOF) 발생 시 전체 분산 처리 마비 | F4: Main-subroutine 강한 결합으로 인한 예외전파는 시스템 전반에 영향을 준다 Master-Slave 약한 결합으로 하나의 슬레이브에 문제가 생겨도 복제된 슬레이브로 대응가능하다(++) 마스터에 문제가 생기면 시스템 전반이 영향을 받는다.
A5: 2조 | B5: ='2조'!B$55 -> - | C5: ='2조'!C$55 -> (+) 제어 흐름이 단순하여 오류 분석 용이. / (-) 단일 스레드 구조로 하위 서브루틴 실패 시 전체 프로세스 중단. | D5: ='2조'!D$55 -> + | E5: ='2조'!E$55 -> (+) Slave 실패 시 Master가 작업을 타 Slave에 재할당하여 중단 없이 지속(Fault tolerance). / (-) Master가 SPOF.
A6: 3조 | B6: ='3조'!B$55 -> -- | C6: ='3조'!C$55 -> 단일 제어 흐름으로 인해, 상위 호출 흐름 실패시 전체 실행이 실패한다. | D6: ='3조'!D$55 -> + | E6: ='3조'!E$55 -> 특정 Slave 장애 시 Master가 타 Slave에 작업을 재할당해 서비스가 지속(Fault Tolerance)됩니다. 단, Master 자체는 단일 장애점(SPOF)이 될 수 있습니다.
A7: 4조 | B7: ='4조'!B$55 -> -- | C7: ='4조'!C$55 -> 이중화 없는 단일 프로세스다. 서브루틴 하나가 실패하면 프로그램 전체가 죽고 부분 동작도 불가능하다. | D7: ='4조'!D$55 -> + | E7: ='4조'!E$55 -> 작업을 나누어 일부 작업자의 장애 영향을 줄일 수 있지만 Master 장애는 남는다.
A8: 5조 | B8: ='5조'!B$55 -> - | C8: ='5조'!C$55 -> 중앙 main과 Subroutine간의 강한 coupling으로 인해 main의 장애가 전체 프로그램의 중단으로 이어질 수 있다. | D8: ='5조'!D$55 -> + | E8: ='5조'!E$55 -> 일부 Slave에 장애가 발생해도 다른 Slave가 대신 처리하거나 Master가 해당 Slave만 재시작할 수 있어 가용성이 높음
A9: 6조 | B9: ='6조'!B$55 -> - | C9: ='6조'!C$55 -> Main이 여러 subroutine을 순차적으로 호출하는 구조라서 한 subroutine에 장애가 발생하면 전체 실행 흐름에 영향을 줄 가능성이 높음 | D9: ='6조'!D$55 -> 0 | E9: ='6조'!E$55 -> Fault Tolerence 특징이 있지만 Master 단일 포인트 Fail 시 가용성이 훼손될 수 있다.
A10: 7조 | B10: ='7조'!B$55 | C10: ='7조'!C$55 -> 7조 - Main-subroutine - Availability | D10: ='7조'!D$55 | E10: ='7조'!E$55 -> 7조 - Master-Slave - Availability
A11: 8조 | B11: ='8조'!B$55 | C11: ='8조'!C$55 -> 8조 - Main-subroutine - Availability | D11: ='8조'!D$55 | E11: ='8조'!E$55 -> 8조 - Master-Slave - Availability
A12: 9조 | B12: ='9조'!B$55 | C12: ='9조'!C$55 -> 9조 - Main-subroutine - Availability | D12: ='9조'!D$55 | E12: ='9조'!E$55 -> 9조 - Master-Slave - Availability
A14: Deployability | B14: ='Detailed Reasoning'!B$56 | C14: ='Detailed Reasoning'!C$56 | D14: ='Detailed Reasoning'!D$56 | E14: ='Detailed Reasoning'!E$56
A15: 1조 | B15: ='1조'!B$56 -> - | C15: ='1조'!C$56 -> [+] 단일 실행 파일 빌드로 초기에 단순 배포 가능 [-] 부분 모듈 수정 시 전체 시스템 재컴파일 및 재배포 필요 | D15: ='1조'!D$56 -> - | E15: ='1조'!E$56 -> [+] Slave 노드의 동적 추가 및 독립적 개별 배포 용이 [-] Master와 Slave 간 버전 동기화 배포 관리 필요 | F15: Main-subroutine 강한 결합으로 배포 단위가 단순 (+) 부분, 런타임의 실시간 배포는 불가능 (-) Master-Slave 약한 결합. 런타임의 Slave 단위 독립적 배포가능(++) 단, Master 배포시 시스템의 순간 정지가 필요(-)
A16: 2조 | B16: ='2조'!B$56 -> - | C16: ='2조'!C$56 -> (+) 패키징 구조 단순. / (-) 모듈 간 강결합으로 작은 수정에도 전체를 다시 빌드하고 일괄 재배포해야 함. | D16: ='2조'!D$56 -> + | E16: ='2조'!E$56 -> (+) Slave 컴포넌트의 독립적인 추가, 확장 및 교체 배포 용이. / (-) Master-Slave 간 프로토콜 호환성 유지 필요.
A17: 3조 | B17: ='3조'!B$56 -> -- | C17: ='3조'!C$56 -> 강하게 결합되어 있어, subroutine만 독립적으로 배포가 어렵다. | D17: ='3조'!D$56 -> + | E17: ='3조'!E$56 -> Master-Slave 간 서비스 규격이 분리되어 있어, 시스템 가동 중에도 신규 Slave 인스턴스를 수평 확장(Scale-out) 배포하기 용이합니다.
A18: 4조 | B18: ='4조'!B$56 -> - | C18: ='4조'!C$56 -> 함수들이 같은 실행 프로그램에 묶여 있어 일부만 따로 배포하기 어렵다. | D18: ='4조'!D$56 -> + | E18: ='4조'!E$56 -> 작업자를 분리해 교체하기 좋지만 Master와 주고받는 규칙은 유지해야 한다.
A19: 5조 | B19: ='5조'!B$56 -> - | C19: ='5조'!C$56 -> Procedure끼리의 tight coupling으로 인하여 작은 변경도 재배포가 필요한 경우가 생긴다. | D19: ='5조'!D$56 -> + | E19: ='5조'!E$56 -> 노드/프로세스를 독립적으로 배포하거나 동적으로 노드를 추가/제거할 수 있다
A20: 6조 | B20: ='6조'!B$56 -> - | C20: ='6조'!C$56 -> Main과 subroutine이 하나의 바이너리로 강하게 묶여있어 특정 서브루틴만 독립적 배포 불가. 특정 서브루틴 고치면 전체 시스템 재빌드 및 재배포 필요. 배포시 무중단 배포가 불가능하다. | D20: ='6조'!D$56 -> 0 | E20: ='6조'!E$56 -> Slave를 교체할 때는 배포에 장점이 있지만, Slave-Master와의 호환성 문제가 생길 시 혹은 Master 교체 시 배포용이성이 떨어진다.
A21: 7조 | B21: ='7조'!B$56 | C21: ='7조'!C$56 -> 7조 - Main-subroutine - Deployability | D21: ='7조'!D$56 | E21: ='7조'!E$56 -> 7조 - Master-Slave - Deployability
A22: 8조 | B22: ='8조'!B$56 | C22: ='8조'!C$56 -> 8조 - Main-subroutine - Deployability | D22: ='8조'!D$56 | E22: ='8조'!E$56 -> 8조 - Master-Slave - Deployability
A23: 9조 | B23: ='9조'!B$56 | C23: ='9조'!C$56 -> 9조 - Main-subroutine - Deployability | D23: ='9조'!D$56 | E23: ='9조'!E$56 -> 9조 - Master-Slave - Deployability
A25: Integrability | B25: ='Detailed Reasoning'!B$57 | C25: ='Detailed Reasoning'!C$57 | D25: ='Detailed Reasoning'!D$57 | E25: ='Detailed Reasoning'!E$57
A26: 1조 | B26: ='1조'!B$57 -> - | C26: ='1조'!C$57 -> [+] 표준 라이브러리 및 서브루틴 연동이 직관적임 [-] 강한 결합(Tight Coupling)으로 외부 시스템과의 연동 어려움 | D26: ='1조'!D$57 -> + | E26: ='1조'!E$57 -> [+] 표준 분산 인터페이스를 통한 신규 Slave 확장 용이 | F26: Main-subroutine 강한 결합으로 인한 의존성은 컴포넌트 확장이나 시스템간 연동을 어렵게 한다 Master-Slave 약한 결합으로 인터페이스를 유지하는 경우 유연하게 슬레이브 추가,확장이 용이(+) 마스터 변경이 필요한 경우는 부담이 발생(-)
A27: 2조 | B27: ='2조'!B$57 -> - | C27: ='2조'!C$57 -> (+) 동일 언어 내 라이브러리 연동 용이. / (-) 강한 결합 및 플랫폼 종속성으로 외부 이기종 시스템 통합 어려움. | D27: ='2조'!D$57 -> + | E27: ='2조'!E$57 -> slave 를 추가하면 되므로 확장이 쉽다. master 의 작업 분배 약속만 맞추면 된다
A28: 3조 | B28: ='3조'!B$57 -> - | C28: ='3조'!C$57 -> 함수 호출 구조와 공유 데이터에 의존하기 쉬워 외부 컴포넌트와 느슨하게 통합하기 어렵다. | D28: ='3조'!D$57 -> 0 | E28: ='3조'!E$57 -> Slave 추가는 가능하지만 Master가 호출 방식과 결과 선택을 통제하므로 통합 자유도는 제한적이다.
A29: 4조 | B29: ='4조'!B$57 -> - | C29: ='4조'!C$57 -> 함수별 연결은 쉽지만 호출 규칙과 공통 데이터에 대한 의존성이 있다. | D29: ='4조'!D$57 -> 0 | E29: ='4조'!E$57 -> 같은 규칙의 작업자는 추가하기 쉽지만 다른 방식의 시스템을 연결하려면 조정이 필요하다.
A30: 5조 | B30: ='5조'!B$57 -> - | C30: ='5조'!C$57 -> 강한 결합 기반으로 외부 시스템을 통합 할 때의 flexibility가 떨어진다. | D30: ='5조'!D$57 -> - | E30: ='5조'!E$57 -> Slave가 Master의 작업·결과 규약에 맞아야 함
A31: 6조 | B31: ='6조'!B$57 -> - | C31: ='6조'!C$57 -> Subroutine 간 interface를 통해 통합할 수 있지만, 기본적으로 호출 관계가 강하게 결합되어 있다. 새로운 외부 시스템이나 component를 추가하려면 기존 main/subroutine 구조를 수정해야 할 가능성이 있다. | D31: ='6조'!D$57 -> 0 | E31: ='6조'!E$57 -> 다른 component를 slave로 추가할 componet의 인터페이스, 프로토콜 호환성이 중요하게 작용한다. 같은 규약을 가진 componet의 경우 통합용이성이 좋다.
A32: 7조 | B32: ='7조'!B$57 | C32: ='7조'!C$57 -> 7조 - Main-subroutine - Integrability | D32: ='7조'!D$57 | E32: ='7조'!E$57 -> 7조 - Master-Slave - Integrability
A33: 8조 | B33: ='8조'!B$57 | C33: ='8조'!C$57 -> 8조 - Main-subroutine - Integrability | D33: ='8조'!D$57 | E33: ='8조'!E$57 -> 8조 - Master-Slave - Integrability
A34: 9조 | B34: ='9조'!B$57 | C34: ='9조'!C$57 -> 9조 - Main-subroutine - Integrability | D34: ='9조'!D$57 | E34: ='9조'!E$57 -> 9조 - Master-Slave - Integrability
A36: Energy Efficiency | B36: ='Detailed Reasoning'!B$58 | C36: ='Detailed Reasoning'!C$58 | D36: ='Detailed Reasoning'!D$58 | E36: ='Detailed Reasoning'!E$58
A37: 1조 | B37: ='1조'!B$58 -> 0 | C37: ='1조'!C$58 -> 요청이 여러 계층을 거치면서 추가적인 호출과 데이터 전달·변환이 발생할 수 있어 자원 사용과 에너지 소비가 증가할 수 있다. | D37: ='1조'!D$58 -> - | E37: ='1조'!E$58 -> [-] Master의 지속적 상태 모니터링 및 통신으로 전력 소모 발생 | F37: Main-subroutine 강한 결합. 동기 방식으로 메인과 서브가 모두 활성 상태를 유지하는 불리함이 있음 Master-Slave 동시성. 대기 또는 병렬 동작 중인 슬레이브로 활성화 리소스증가. 슬레이브들의 동기화 통신 과정의 오버해드 역시 리소스를 소비하는 점이
A38: 2조 | B38: ='2조'!B$58 -> ++ | C38: ='2조'!C$58 -> 중간 계층이나 통신이 없어 군더더기가 가장 적다. 직접 호출이라 낭비가 없다 | D38: ='2조'!D$58 -> - | E38: ='2조'!E$58 -> 병렬 처리로 작업 시간 단축 후 유휴 전환 가능하나 다수 Slave 동시 구동 및 통신 비용 증가.
A39: 3조 | B39: ='3조'!B$58 -> + | C39: ='3조'!C$58 -> 단일 흐름의 직접 procedure call 구조라 별도 통신, 직렬화, 동기화 비용이 작다. | D39: ='3조'!D$58 -> - | E39: ='3조'!E$58 -> 여러 Slave 실행, Master-Slave 통신, 결과 수집과 선택 과정이 추가되어 자원 사용량이 커질 수 있다.
A40: 4조 | B40: ='4조'!B$58 -> ++ | C40: ='4조'!C$58 -> 직접 호출하고 정보를 함께 사용하므로 통신과 데이터 복사 비용이 적다. | D40: ='4조'!D$58 -> - | E40: ='4조'!E$58 -> 여러 작업자를 동시에 실행하고 결과를 모으는 데 추가 자원이 든다.
A41: 5조 | B41: ='5조'!B$58 -> ++ | C41: ='5조'!C$58 -> 직접 호출되는 방식으로 procedure간 메시지 전송 등 추가 런타임 오버헤드가 매우 작다. | D41: ='5조'!D$58 -> - | E41: ='5조'!E$58 -> 작업 분배·결과 수집의 통신과 조정에 추가 에너지 소비
A42: 6조 | B42: ='6조'!B$58 -> ++ | C42: ='6조'!C$58 -> 불필요한 communication이나 middleware layer가 거의 없기 때문에 효율적 | D42: ='6조'!D$58 -> - | E42: ='6조'!E$58 -> master-slave간 통신에서 overhead가 발생하여 추가적인 에너지 소모가 있을 수 있다.
A43: 7조 | B43: ='7조'!B$58 | C43: ='7조'!C$58 -> 7조 - Main-subroutine - Energy Efficiency | D43: ='7조'!D$58 | E43: ='7조'!E$58 -> 7조 - Master-Slave - Energy Efficiency
...

Sheet H2
A1: Hierarchical | B1: Layered | D1: Virtual Machine | F1: Microkernel
B2: Effects | C2: Justification | D2: Effects | E2: Justification | F2: Effects | G2: Justification
A3: Availability | B3: ='Detailed Reasoning'!B$68 | C3: ='Detailed Reasoning'!C$68 | D3: ='Detailed Reasoning'!D$68 | E3: ='Detailed Reasoning'!E$68 | F3: ='Detailed Reasoning'!F$68 | G3: ='Detailed Reasoning'!G$68
A4: 1조 | B4: ='1조'!B$68 -> 0 | C4: ='1조'!C$68 -> [+] 계층별 오류 격리 적용 가능 [-] 하위 핵심 레이어 실패 시 전체 중단 | D4: ='1조'!D$68 | E4: ='1조'!E$68 -> 1조 - Virtual Machine - Availability | F4: ='1조'!F$68 | G4: ='1조'!G$68 -> 1조 - Microkernel - Availability | H4: Layer 분리 구조이나 하위레이어의 의존성이 장애발생시 상위에 영향을 준다 VM 격리(분리) 구조로 VM의 오류는 다른 VM에 영향을 주지 않는다. (+) Hypervisor의 장에는 모든 VM에 영향은 준다. Layer의 속성(-) Microkernel 서비스, 어플리케이션의 장애가 다른 서비스,어플리케이션에 전파되지 않는다. 분리 구조(+) 단 커널에 영향을 주게되는 경우 모든 서비스, 어플리케이션이 영향을 받음. Layer의 속성(-)
A5: 2조 | B5: ='2조'!B$68 -> 0 | C5: ='2조'!C$68 -> (+) 계층 경계에서 결함 격리 및 개별 계층 복구 용이. / (-) 하위 기반 계층 장애 시 상위 계층 전체 정지. | D5: ='2조'!D$68 | E5: ='2조'!E$68 -> 2조 - Virtual Machine - Availability | F5: ='2조'!F$68 | G5: ='2조'!G$68 -> 2조 - Microkernel - Availability
A6: 3조 | B6: ='3조'!B$68 -> 0 | C6: ='3조'!C$68 -> 계층화는 장애 복구 구조를 직접 제공하지 않아 availability 효과는 제한적이다. | D6: ='3조'!D$68 | E6: ='3조'!E$68 -> 3조 - Virtual Machine - Availability | F6: ='3조'!F$68 | G6: ='3조'!G$68 -> 3조 - Microkernel - Availability
A7: 4조 | B7: ='4조'!B$68 -> - | C7: ='4조'!C$68 -> 하위 계층의 장애가 위로 전파되어 그 위에 쌓인 모든 것을 무력화한다. 상위 계층이 하위를 우회할 수 없기 때문이다. | D7: ='4조'!D$68 | E7: ='4조'!E$68 -> Human - Virtual Machine - Availability | F7: ='4조'!F$68 | G7: ='4조'!G$68 -> Human - Microkernel - Availability
A8: 5조 | B8: ='5조'!B$68 -> - | C8: ='5조'!C$68 -> 특정 계층 장애가 전체 서비스에 부정적인 영향을 미칠 수 있다. | D8: ='5조'!D$68 | E8: ='5조'!E$68 -> 5조 - Virtual Machine - Availability | F8: ='5조'!F$68 | G8: ='5조'!G$68 -> 5조 - Microkernel - Availability
A9: 6조 | B9: ='6조'!B$68 -> 0 | C9: ='6조'!C$68 -> 계층 분리는 결함의 위치 파악과 복구에 도움이 되지만, 하위 Layer에 장애가 발생하면 이를 사용하는 모든 상위 Layer가 영향을 받는다. | D9: ='6조'!D$68 | E9: ='6조'!E$68 -> 6조 - Virtual Machine - Availability | F9: ='6조'!F$68 | G9: ='6조'!G$68 -> 6조 - Microkernel - Availability
A10: 7조 | B10: ='7조'!B$68 | C10: ='7조'!C$68 -> 7조 - Layered - Availability | D10: ='7조'!D$68 | E10: ='7조'!E$68 -> 7조 - Virtual Machine - Availability | F10: ='7조'!F$68 | G10: ='7조'!G$68 -> 7조 - Microkernel - Availability
A11: 8조 | B11: ='8조'!B$68 | C11: ='8조'!C$68 -> 8조 - Layered - Availability | D11: ='8조'!D$68 | E11: ='8조'!E$68 -> 8조 - Virtual Machine - Availability | F11: ='8조'!F$68 | G11: ='8조'!G$68 -> 8조 - Microkernel - Availability
A12: 9조 | B12: ='9조'!B$68 | C12: ='9조'!C$68 -> 9조 - Layered - Availability | D12: ='9조'!D$68 | E12: ='9조'!E$68 -> 9조 - Virtual Machine - Availability | F12: ='9조'!F$68 | G12: ='9조'!G$68 -> 9조 - Microkernel - Availability
A14: Deployability | B14: ='Detailed Reasoning'!B$69 | C14: ='Detailed Reasoning'!C$69 | D14: ='Detailed Reasoning'!D$69 | E14: ='Detailed Reasoning'!E$69 | F14: ='Detailed Reasoning'!F$69 | G14: ='Detailed Reasoning'!G$69
A15: 1조 | B15: ='1조'!B$69 -> + | C15: ='1조'!C$69 -> [+] 인접 인터페이스 유지 시 개별 레이어 배포 용이 [-] 전 계층 변경 시 전체 동시 배포 필요 | D15: ='1조'!D$69 | E15: ='1조'!E$69 -> 1조 - Virtual Machine - Deployability | F15: ='1조'!F$69 | G15: ='1조'!G$69 -> 1조 - Microkernel - Deployability | H15: Layer 계층 간 명확한 구조로 배포 예측성은 높지만, 하위 계층 변경이 상위 계층 재배포를 유발 (분리에서오는 유리함을 하위 의존성이 상쇄) VM VM 실행 환경의 격리 결합을 차단하여 이식성과 배포 안정성을 크게 높인다(++) 단, VM 계층 자체는 배포 병목이 된다(-) Microkernel 핵심을 안정적으로 고정하고 기능을 플러그인으로 분리. 부분·점진적 배포에 매우 유리
A16: 2조 | B16: ='2조'!B$69 -> + | C16: ='2조'!C$69 -> (+) 계층별 인터페이스만 유지되면 특정 계층만 독립 배포·업데이트 가능. / (-) 의존 방향에 따른 배포 순서 제약. | D16: ='2조'!D$69 | E16: ='2조'!E$69 -> 2조 - Virtual Machine - Deployability | F16: ='2조'!F$69 | G16: ='2조'!G$69 -> 2조 - Microkernel - Deployability
A17: 3조 | B17: ='3조'!B$69 -> + | C17: ='3조'!C$69 -> 각 layer를 독립적으로 배포·유지보수·갱신할 수 있어 deployability에 유리하다. | D17: ='3조'!D$69 | E17: ='3조'!E$69 -> 3조 - Virtual Machine - Deployability | F17: ='3조'!F$69 | G17: ='3조'!G$69 -> 3조 - Microkernel - Deployability
A18: 4조 | B18: ='4조'!B$69 -> 0 | C18: ='4조'!C$69 -> 계층을 나누어도 각각 따로 배포할 수 있는지는 구현에 따라 달라진다. | D18: ='4조'!D$69 | E18: ='4조'!E$69 -> Human - Virtual Machine - Deployability | F18: ='4조'!F$69 | G18: ='4조'!G$69 -> Human - Microkernel - Deployability
A19: 5조 | B19: ='5조'!B$69 -> + | C19: ='5조'!C$69 -> 계층이 분리되어있으므로 특정 계층 독립적으로 배포 가능하다. | D19: ='5조'!D$69 | E19: ='5조'!E$69 -> 5조 - Virtual Machine - Deployability | F19: ='5조'!F$69 | G19: ='5조'!G$69 -> 5조 - Microkernel - Deployability
A20: 6조 | B20: ='6조'!B$69 -> + | C20: ='6조'!C$69 -> 계층별 책임과 인터페이스가 분리되어 있어 변경된 Layer를 비교적 독립적으로 배포·교체할 수 있다. 다만 하위 인터페이스 변경 시 상위 Layer도 함께 배포해야 할 수 있다. | D20: ='6조'!D$69 | E20: ='6조'!E$69 -> 6조 - Virtual Machine - Deployability | F20: ='6조'!F$69 | G20: ='6조'!G$69 -> 6조 - Microkernel - Deployability
A21: 7조 | B21: ='7조'!B$69 | C21: ='7조'!C$69 -> 7조 - Layered - Deployability | D21: ='7조'!D$69 | E21: ='7조'!E$69 -> 7조 - Virtual Machine - Deployability | F21: ='7조'!F$69 | G21: ='7조'!G$69 -> 7조 - Microkernel - Deployability
A22: 8조 | B22: ='8조'!B$69 | C22: ='8조'!C$69 -> 8조 - Layered - Deployability | D22: ='8조'!D$69 | E22: ='8조'!E$69 -> 8조 - Virtual Machine - Deployability | F22: ='8조'!F$69 | G22: ='8조'!G$69 -> 8조 - Microkernel - Deployability
A23: 9조 | B23: ='9조'!B$69 | C23: ='9조'!C$69 -> 9조 - Layered - Deployability | D23: ='9조'!D$69 | E23: ='9조'!E$69 -> 9조 - Virtual Machine - Deployability | F23: ='9조'!F$69 | G23: ='9조'!G$69 -> 9조 - Microkernel - Deployability
A25: Integrability | B25: ='Detailed Reasoning'!B$70 | C25: ='Detailed Reasoning'!C$70 | D25: ='Detailed Reasoning'!D$70 | E25: ='Detailed Reasoning'!E$70 | F25: ='Detailed Reasoning'!F$70 | G25: ='Detailed Reasoning'!G$70
A26: 1조 | B26: ='1조'!B$70 -> + | C26: ='1조'!C$70 -> [+] 상단 API를 통한 이종 시스템 통합 용이 [-] 계층 스킵이 불가능하여 연동 제약 발생 | D26: ='1조'!D$70 | E26: ='1조'!E$70 -> 1조 - Virtual Machine - Integrability | F26: ='1조'!F$70 | G26: ='1조'!G$70 -> 1조 - Microkernel - Integrability | H26: Layer 계층 간 명확한 인터페이스 덕분에 특정 계층에서의 통합은 비교적 쉬움(+) 하위 계층 변경이 상위 통합에 영향을 미침 (-) 하나의 계층을 외부 시스템과의 통합에 필요한 레이어로 구현하여, 통합용이성을 향상(+) VM 표준 실행 환경과 추상 API를 제공하여, 상위 애플리케이션 간 이식성과 간접 통합이 매우 용이(++) 다만 외부 시스템과 장치와의 직접 통합은 VM의 추상 계층(Hypervisor)으로 인한 제약때문에 한계가 있음(-) Microkernel 표준 인터페이스와 프로토콜을 사용하여 커널과 플러그인 간의 상호 작용을 연결하는 구조는 새로운 컴포넌트(플러그인) 일관성 있는 통합에 매우 유리
A27: 2조 | B27: ='2조'!B$70 -> + | C27: ='2조'!C$70 -> layer 가 응집도가 높고 아래 layer 에만 결합되어 재사용·교체·대체가 쉽다 | D27: ='2조'!D$70 | E27: ='2조'!E$70 -> 2조 - Virtual Machine - Integrability | F27: ='2조'!F$70 | G27: ='2조'!G$70 -> 2조 - Microkernel - Integrability
A28: 3조 | B28: ='3조'!B$70 -> + | C28: ='3조'!C$70 -> Layer 간 서비스 사용 관계가 명확해, 정해진 인터페이스를 기준으로 상하 계층을 통합하기 쉽다. | D28: ='3조'!D$70 | E28: ='3조'!E$70 -> 3조 - Virtual Machine - Integrability | F28: ='3조'!F$70 | G28: ='3조'!G$70 -> 3조 - Microkernel - Integrability
A29: 4조 | B29: ='4조'!B$70 -> + | C29: ='4조'!C$70 -> 계층 사이의 연결 규칙이 명확하면 새로운 기능을 연결하기 쉽다. | D29: ='4조'!D$70 | E29: ='4조'!E$70 -> Human - Virtual Machine - Integrability | F29: ='4조'!F$70 | G29: ='4조'!G$70 -> Human - Microkernel - Integrability
A30: 5조 | B30: ='5조'!B$70 -> + | C30: ='5조'!C$70 -> 명확한 계층 인터페이스로 인하여 외부 모듈의 연동이 수월하다. | D30: ='5조'!D$70 | E30: ='5조'!E$70 -> 5조 - Virtual Machine - Integrability | F30: ='5조'!F$70 | G30: ='5조'!G$70 -> 5조 - Microkernel - Integrability
A31: 6조 | B31: ='6조'!B$70 -> + | C31: ='6조'!C$70 -> 각 layer가 정의된 인터페이스로 서비스를 제공하므로(약한 결합), 그 인터페이스만 유지되면 아래 구현을 새 컴포넌트로 교체하거나 다른 시스템과 연동하기 쉽다 | D31: ='6조'!D$70 | E31: ='6조'!E$70 -> 6조 - Virtual Machine - Integrability | F31: ='6조'!F$70 | G31: ='6조'!G$70 -> 6조 - Microkernel - Integrability
A32: 7조 | B32: ='7조'!B$70 | C32: ='7조'!C$70 -> 7조 - Layered - Integrability | D32: ='7조'!D$70 | E32: ='7조'!E$70 -> 7조 - Virtual Machine - Integrability | F32: ='7조'!F$70 | G32: ='7조'!G$70 -> 7조 - Microkernel - Integrability
A33: 8조 | B33: ='8조'!B$70 | C33: ='8조'!C$70 -> 8조 - Layered - Integrability | D33: ='8조'!D$70 | E33: ='8조'!E$70 -> 8조 - Virtual Machine - Integrability | F33: ='8조'!F$70 | G33: ='8조'!G$70 -> 8조 - Microkernel - Integrability
A34: 9조 | B34: ='9조'!B$70 | C34: ='9조'!C$70 -> 9조 - Layered - Integrability | D34: ='9조'!D$70 | E34: ='9조'!E$70 -> 9조 - Virtual Machine - Integrability | F34: ='9조'!F$70 | G34: ='9조'!G$70 -> 9조 - Microkernel - Integrability
A36: Energy Efficiency | B36: ='Detailed Reasoning'!B$71 | C36: ='Detailed Reasoning'!C$71 | D36: ='Detailed Reasoning'!D$71 | E36: ='Detailed Reasoning'!E$71 | F36: ='Detailed Reasoning'!F$71 | G36: ='Detailed Reasoning'!G$71
A37: 1조 | B37: ='1조'!B$71 -> - | C37: ='1조'!C$71 -> 요청이 여러 계층을 거치면서 추가적인 호출과 데이터 전달·변환이 발생할 수 있어 자원 사용과 에너지 소비가 증가할 수 있다. | D37: ='1조'!D$71 | E37: ='1조'!E$71 -> 1조 - Virtual Machine - Energy Efficiency | F37: ='1조'!F$71 | G37: ='1조'!G$71 -> 1조 - Microkernel - Energy Efficiency | H37: Layer 계층이 많아질수로 호출/변환 오버헤드가 증가되어 에너지 효율이 다소 떨어짐 VM VM 증가은 추상화/인터프리팅/가상화 오버헤드로 많은 리소스를 소모 Microkernel 필요한 서비스만 로드가능 하여 유휴 리소스를 줄일 수 있다(+) 단, 빈번한 IPC/컨텍스트 스위칭은 리소스 소모를 증가 시킨다(-)
A38: 2조 | B38: ='2조'!B$71 -> - | C38: ='2조'!C$71 -> 인접 계층 간 메모리 호출 시 효율적이지만, layer 를 하나 지날 때마다 호출과 변환이 생겨 층이 많을수록 오버헤드 발생함. | D38: ='2조'!D$71 | E38: ='2조'!E$71 -> 2조 - Virtual Machine - Energy Efficiency | F38: ='2조'!F$71 | G38: ='2조'!G$71 -> 2조 - Microkernel - Energy Efficiency
A39: 3조 | B39: ='3조'!B$71 -> - | C39: ='3조'!C$71 -> 여러 layer를 거치며 호출과 데이터 전달 overhead가 생겨 자원 사용이 늘 수 있다. | D39: ='3조'!D$71 | E39: ='3조'!E$71 -> 3조 - Virtual Machine - Energy Efficiency | F39: ='3조'!F$71 | G39: ='3조'!G$71 -> 3조 - Microkernel - Energy Efficiency
A40: 4조 | B40: ='4조'!B$71 -> 0 | C40: ='4조'!C$71 -> 계층 수와 호출 방식에 따라 추가 처리 비용이 달라진다. | D40: ='4조'!D$71 | E40: ='4조'!E$71 -> Human - Virtual Machine - Energy Efficiency | F40: ='4조'!F$71 | G40: ='4조'!G$71 -> Human - Microkernel - Energy Efficiency
A41: 5조 | B41: ='5조'!B$71 -> - | C41: ='5조'!C$71 -> 여러 계층을 통과하는 과정에서 호출 및 데이터 변환에 의한 오버헤드가 발생한다. | D41: ='5조'!D$71 | E41: ='5조'!E$71 -> 5조 - Virtual Machine - Energy Efficiency | F41: ='5조'!F$71 | G41: ='5조'!G$71 -> 5조 - Microkernel - Energy Efficiency
A42: 6조 | B42: ='6조'!B$71 -> - | C42: ='6조'!C$71 -> Layer 수가 많을수록 요청이 여러 Layer를 순차적으로 통과하면서 반복적인 호출, 데이터 변환 및 중간 처리에 추가 자원이 소모된다. | D42: ='6조'!D$71 | E42: ='6조'!E$71 -> 6조 - Virtual Machine - Energy Efficiency | F42: ='6조'!F$71 | G42: ='6조'!G$71 -> 6조 - Microkernel - Energy Efficiency
A43: 7조 | B43: ='7조'!B$71 | C43: ='7조'!C$71 -> 7조 - Layered - Energy Efficiency | D43: ='7조'!D$71 | E43: ='7조'!E$71 -> 7조 - Virtual Machine - Energy Efficiency | F43: ='7조'!F$71 | G43: ='7조'!G$71 -> 7조 - Microkernel - Energy Efficiency
...

Sheet DA1
A1: Distributed | B1: Multi-Tier | D1: Client-Server
B2: Effects | C2: Justification | D2: Effects | E2: Justification
A3: Availability | B3: 0 | C3: 0 | D3: 0 | E3: 0
A4: 1조 | B4: ='1조'!B81 -> - | C4: ='1조'!C81 -> [-] 티어 수가 많아짐에 따라 전체 장애 포인트(SPOF) 증가 | D4: ='1조'!D81 -> - | E4: ='1조'!E81 -> [-] 중앙 Server 장애 시 연결된 모든 Client 서비스 중단 | F4: Multi-Tier, Client Server 티어(서버)가의 중지는 서비스 전체으 동작에 여향을 준다(-) 단, 빠른 복구 또는 이중화가 가능(+)
A5: 2조 | B5: ='2조'!B81 -> - | C5: ='2조'!C81 -> Server 가 여러 대로 늘어나면 각 server 의 reliability 와 availability 가 더욱 중요해진다고 교안이 약점으로 든다. 한 tier 가 멈추면 그 위 tier 의 요청이 모두 막힌다 | D5: ='2조'!D81 -> - | E5: ='2조'!E81 -> 클라이언트와 서버의 분리로 장애 파악이 국소화되긴 하지만, 중앙 집중식 서버가 단일 장애점(SPOF)이 되어 서버 장애 시 연결된 모든 클라이언트의 서비스가 일시에 정지된다.
A6: 3조 | B6: ='3조'!B81 -> + | C6: ='3조'!C81 -> Tier 역할별로 분리되어, 특정 Tier 장애를 격리 및 복구하기 쉽다. 다만 핵심 Tier 장애는 전체 서비스에 영향을 줄수 있다. | D6: ='3조'!D81 -> - | E6: ='3조'!E81 -> Server가 요청 처리의 중심이므로 Server 장애 시 여러 Client가 함께 영향을 받는다.
A7: 4조 | B7: ='4조'!B81 -> 0 | C7: ='4조'!C81 -> 역할별 장애를 나누기 좋지만 공통 데이터 계층이 멈추면 여러 기능이 영향을 받는다. | D7: ='4조'!D81 -> 0 | E7: ='4조'!E81 -> Client의 장애는 분리하기 좋지만 공통 Server가 멈추면 여러 사용자가 영향을 받는다.
A8: 5조 | B8: ='5조'!B81 -> - | C8: ='5조'!C81 -> Tier가 증가할 수록 위험성이 증가하여 관리 요소가 늘어날 수 있음. | D8: ='5조'!D81 -> - | E8: ='5조'!E81 -> 서버가 단일 실패점이 될 수 있어 서버 장애 시 전체 시스템 중단될 수 있다.
A9: 6조 | B9: ='6조'!B81 -> + | C9: ='6조'!C81 -> Tier별로 서버를 분리하고 여러 인스턴스를 운영하면 장애를 격리하고 이중화하기 좋다. 특히 Application Tier를 여러 대로 구성하면 일부 서버 장애에도 서비스 지속이 가능하다. 다만 특정 Tier가 단일 장애점(SPOF)이 되면 전체 서비스가 영향을 받을 수 있다. | D9: ='6조'!D81 -> - | E9: ='6조'!E81 -> 서버 이중화로 개선 가능하나, 기본 구조는 서버가 단일 장애점이라서 문제 가능성 있음
A10: 7조 | B10: ='7조'!B81 | C10: ='7조'!C81 -> 7조 - Multi-tier - Availability | D10: ='7조'!D81 | E10: ='7조'!E81 -> 7조 - Client-Server - Availability
A11: 8조 | B11: ='8조'!B81 | C11: ='8조'!C81 -> 8조 - Multi-tier - Availability | D11: ='8조'!D81 | E11: ='8조'!E81 -> 8조 - Client-Server - Availability
A12: 9조 | B12: ='9조'!B81 | C12: ='9조'!C81 -> 9조 - Multi-tier - Availability | D12: ='9조'!D81 | E12: ='9조'!E81 -> 9조 - Client-Server - Availability
A14: Deployability | B14: 0 | C14: 0 | D14: 0 | E14: 0
A15: 1조 | B15: ='1조'!B82 -> + | C15: ='1조'!C82 -> [+] 각 티어를 독립 물리 서버/컨테이너에 분리 배포 극대화 | D15: ='1조'!D82 -> + | E15: ='1조'!E82 -> [+] Server 단독 기능 업데이트 및 배포 단순함 | F15: Multi-Tier 티어 단위의 배포는 가능하나, 티어 간의 계약 변경시 연쇄 배포가 필요함 Client Server Client–Server에서 클라이언트 업데이트가 필요해지는 순간, ‘사용자 디바이스 전체’로 확장되어 급격히 악화된다.(--) 서버 중심의 배포는 비교적 단순하다(+)
A16: 2조 | B16: ='2조'!B82 -> + | C16: ='2조'!C82 -> (+) 물리적 인프라 수준에서 티어가 분리되어 있어 Presentation, Application, Data 티어 단위로 독립 배포 및 롤백이 가능함. / (-) 티어 간 인터페이스 및 데이터 스키마 변경 시 전체 티어의 동시 배포가 강제됨 | D16: ='2조'!D82 -> + | E16: ='2조'!E82 -> 표준 Request/Reply 프로토콜만 유지하면 클라이언트와 독립적으로 서버 컴포넌트만을 교체·배포할 수 있지만, Thick Client 환경의 경우 클라이언트 배포 및 버전 동기화 부담이 크긴 함.
A17: 3조 | B17: ='3조'!B82 -> + | C17: ='3조'!C82 -> UI, Business, Data Tier처럼 배포 단위가 나뉘어 특정 Tier만 갱신하거나 확장 배포하기 쉽다. | D17: ='3조'!D82 -> 0 | E17: ='3조'!E82 -> Client와 Server를 분리 배포할 수는 있지만, Server 변경이 여러 Client 호환성에 영향을 줄 수 있다.
A18: 4조 | B18: ='4조'!B82 -> ++ | C18: ='4조'!C82 -> 티어별로 별도 인프라에서 독립적으로 배포·확장·업그레이드할 수 있다. | D18: ='4조'!D82 -> ++ | E18: ='4조'!E82 -> 서버 측 변경은 한 번 배포하면 모든 클라이언트에 즉시 반영된다. 별도 배포가 필요한 것은 진짜 클라이언트 측 변경뿐이다.
A19: 5조 | B19: ='5조'!B82 -> + | C19: ='5조'!C82 -> 각 Tier별 기능이 나누어져 있으므로 Tier에 해당하는 시스템의 단독 배포가 용이하다. | D19: ='5조'!D82 -> + | E19: ='5조'!E82 -> 클라이언트와 서버를 각각 독립적으로 배포가 가능하다.
