Workbook

Sheet DF
B1: Batch Sequential | D1: Pipe and Filter | F1: Process Control
B2: Effects | C2: Justification | D2: Effects | E2: Justification | F2: Effects | G2: Justification
A3: Availability | B3: ='Detailed Reasoning'!B$3 | C3: ='Detailed Reasoning'!C$3 | D3: ='Detailed Reasoning'!D$3 | E3: ='Detailed Reasoning'!E$3 | F3: ='Detailed Reasoning'!F$3 | G3: ='Detailed Reasoning'!G$3
A4: AI#1 | B4: ='AI#1 (Claude)'!B$3 -> - | C4: ='AI#1 (Claude)'!C3 -> 중간 결과를 사용할 수 없고, 한 단계에서 실패하면 배치 전체를 다시 실행해야 한다. 예약된 실행 사이에는 시스템이 사실상 사용 불가 상태다. | D4: ='AI#1 (Claude)'!D$3 -> 0 | E4: ='AI#1 (Claude)'!E3 -> 필터가 독립적이라 개별 재시작이 가능하지만, 파이프가 끊기면 파이프라인 전체가 멈추고 파이프 안의 처리 중 데이터는 유실된다. | F4: ='AI#1 (Claude)'!F$3 -> ++ | G4: ='AI#1 (Claude)'!G3 -> 연속적인 피드백 루프가 환경 변화에도 설정값을 향해 스스로 보정하며 동작을 유지한다. 연속 운전 시스템에 정확히 필요한 특성이다.
A5: AI#2 | B5: ='AI#2(Gpt)'!B$3 -> - | C5: ='AI#2(Gpt)'!C$3 -> 한 단계에서 장애가 발생하면 뒤 단계가 모두 진행되지 못한다. 전체 처리 흐름이 직렬로 연결되어 있어 특정 단계의 실패가 전체 서비스 중단으로 이어지기 쉽다. | D5: =#REF! -> #REF! | E5: =#REF! -> #REF! | F5: =#REF! -> #REF! | G5: =#REF! -> #REF!
A6: Human | B6: =Human!B$3 -> - | C6: =Human!C$3 -> 한 단계에서 장애가 발생하면 뒤 단계가 모두 진행되지 못한다. 전체 처리 흐름이 직렬로 연결되어 있어 특정 단계의 실패가 전체 서비스 중단으로 이어지기 쉽다. | D6: =Human!D$3 -> 0 | E6: =Human!E$3 -> Filter들이 독립적이라 일부를 교체·복구하기는 쉽지만, 파이프라인 중 하나의 Filter가 멈추면 전체 흐름이 막힐 수 있다. 장단점이 모두 존재한다. | F6: =Human!F$3 -> + | G6: =Human!G$3 -> 시스템 상태를 지속적으로 감시하고 피드백을 통해 이상 상태를 보정할 수 있다. 다만 센서나 Controller 같은 핵심 요소가 고장 나면 전체 제어에 영향을 줄 수 있다.
A8: Deployability | B8: ='Detailed Reasoning'!B$4 | C8: ='Detailed Reasoning'!C$4 | D8: ='Detailed Reasoning'!D$4 | E8: ='Detailed Reasoning'!E$4 | F8: ='Detailed Reasoning'!F$4 | G8: ='Detailed Reasoning'!G$4
A9: AI#1 | B9: ='AI#1 (Claude)'!B$4 -> + | C9: ='AI#1 (Claude)'!C4 -> 각 단계가 파일로만 통신하는 독립 실행 프로그램이므로 개별 설치·스케줄링이 가능하다. 다만 전체 체인의 스케줄을 일관되게 다시 잡아야 한다. | D9: ='AI#1 (Claude)'!D$4 -> + | E9: ='AI#1 (Claude)'!E4 -> 필터가 파이프로만 연결된 개별 배포 단위지만, 파이프라인 토폴로지와 버퍼 설정을 배포 간에 일관되게 유지해야 한다. | F9: ='AI#1 (Claude)'!F$4 -> - | G9: ='AI#1 (Claude)'!G4 -> 특정 센서·액추에이터와 튜닝된 파라미터에 강하게 결합되어 있어 배포마다 현장 보정과 검증이 필요하다.
A10: AI#2 | B10: ='AI#2(Gpt)'!B$4 -> + | C10: ='AI#2(Gpt)'!C$4 -> 각 처리 단계를 별도의 프로그램/모듈로 구성할 수 있어 단계별 배포가 비교적 쉽다. 다만 단계 간 데이터 형식이 바뀌면 연쇄적인 수정이 필요할 수 있다. | D10: =#REF! -> #REF! | E10: =#REF! -> #REF! | F10: =#REF! -> #REF! | G10: =#REF! -> #REF!
A11: Human | B11: =Human!B$4 -> + | C11: =Human!C$4 -> 각 처리 단계를 별도의 프로그램/모듈로 구성할 수 있어 단계별 배포가 비교적 쉽다. 다만 단계 간 데이터 형식이 바뀌면 연쇄적인 수정이 필요할 수 있다. | D11: =Human!D$4 -> + | E11: =Human!E$4 -> Filter가 독립된 처리 단위이므로 개별 Filter를 수정·배포하기 비교적 쉽다. 단, Pipe의 데이터 형식 호환성은 유지해야 한다. | F11: =Human!F$4 -> - | G11: =Human!G$4 -> 센서·Controller·Actuator 등 실제 장비와 밀접하게 연결되어 있어 단순 소프트웨어처럼 독립적으로 배포하기 어렵다. 배포 후 보정이나 Calibration도 필요할 수 있다.
A13: Integrability | B13: ='Detailed Reasoning'!B$5 | C13: ='Detailed Reasoning'!C$5 | D13: ='Detailed Reasoning'!D$5 | E13: ='Detailed Reasoning'!E$5 | F13: ='Detailed Reasoning'!F$5 | G13: ='Detailed Reasoning'!G$5
A14: AI#1 | B14: ='AI#1 (Claude)'!B$5 -> + | C14: ='AI#1 (Claude)'!C5 -> 중간 파일 포맷만 합의하면 되므로 통합이 단순하고 언어 중립적이다. 반면 오프라인·배치 방식 통합만 가능하고 대화형 결합은 불가능하다. | D14: ='AI#1 (Claude)'!D$5 -> ++ | E14: ='AI#1 (Claude)'!E5 -> 파이프 인터페이스가 균일해서 이웃 필터를 고치지 않고도 체인 어디에나 새 필터를 끼워 넣을 수 있다. 한계는 모든 것이 스트림 데이터 모델에 맞아야 한다는 점이다. | F14: ='AI#1 (Claude)'!F$5 -> - | G14: ='AI#1 (Claude)'!G5 -> 구성요소가 공유 제어 변수와 엄격한 타이밍 제약으로 상호작용하므로, 새 요소를 넣는 일이 침습적이고 루프를 불안정하게 만들 수 있다.
A15: AI#2 | B15: ='AI#2(Gpt)'!B$5 -> + | C15: ='AI#2(Gpt)'!C$5 -> 단계 사이의 입력/출력이 파일이나 명확한 데이터 형식으로 정의되므로 다른 시스템이나 모듈을 연결하기 비교적 쉽다. | D15: =#REF! -> #REF! | E15: =#REF! -> #REF! | F15: =#REF! -> #REF! | G15: =#REF! -> #REF!
A16: Human | B16: =Human!B$5 -> + | C16: =Human!C$5 -> 단계 사이의 입력/출력이 파일이나 명확한 데이터 형식으로 정의되므로 다른 시스템이나 모듈을 연결하기 비교적 쉽다. | D16: =Human!D$5 -> ++ | E16: =Human!E$5 -> Filter 간 연결이 명확한 입출력 인터페이스로 이루어져 새로운 Filter를 추가하거나 기존 Filter를 다른 컴포넌트로 교체하기 쉽다. | F16: =Human!F$5 -> - | G16: =Human!G$5 -> 센서, 액추에이터, 제어 장치마다 통신 방식이나 데이터 형식이 다를 수 있어 외부 시스템을 추가하거나 교체하기 어렵다.
A18: Energy Efficiency | B18: ='Detailed Reasoning'!B$6 | C18: ='Detailed Reasoning'!C$6 | D18: ='Detailed Reasoning'!D$6 | E18: ='Detailed Reasoning'!E$6 | F18: ='Detailed Reasoning'!F$6 | G18: ='Detailed Reasoning'!G$6
A19: AI#1 | B19: ='AI#1 (Claude)'!B$6 -> + | C19: ='AI#1 (Claude)'!C6 -> 예약된 시점에 몰아서 처리하므로 상시 폴링 없이 자원이 유휴 상태로 있을 수 있다. 반대로 실행이 실패하면 배치에 이미 투입한 에너지가 모두 낭비된다. | D19: ='AI#1 (Claude)'!D$6 -> 0 | E19: ='AI#1 (Claude)'!E6 -> 스트리밍 방식이라 전체 데이터셋을 메모리나 디스크에 적재하지 않지만, 필터 간 데이터 복사와 직렬화가 계속 발생해 추가 비용이 든다. | F19: ='AI#1 (Claude)'!F$6 -> + | G19: ='AI#1 (Claude)'!G6 -> 피드백 제어가 공정을 최적 동작점에 유지해 오버슈트로 인한 낭비를 막는다. 반면 센싱과 액추에이션이 상시 동작하므로 전력을 계속 소모한다.
A20: AI#2 | B20: ='AI#2(Gpt)'!B$6 -> + | C20: ='AI#2(Gpt)'!C$6 -> 실시간으로 계속 동작할 필요 없이 필요한 시점에 배치 단위로 실행할 수 있어 유휴 시간의 자원 사용을 줄일 수 있다. | D20: =#REF! -> #REF! | E20: =#REF! -> #REF! | F20: =#REF! -> #REF! | G20: =#REF! -> #REF!
A21: Human | B21: =Human!B$6 -> + | C21: =Human!C$6 -> 실시간으로 계속 동작할 필요 없이 필요한 시점에 배치 단위로 실행할 수 있어 유휴 시간의 자원 사용을 줄일 수 있다. | D21: =Human!D$6 -> 0 | E21: =Human!E$6 -> 스트리밍과 병렬 처리로 자원을 효율적으로 사용할 수 있지만, 여러 Filter의 동시 실행과 Pipe/Buffer 관리에 추가 자원이 필요하다. | F21: =Human!F$6 -> + | G21: =Human!G$6 -> 현재 상태를 계속 측정하면서 필요한 만큼만 제어할 수 있기 때문에 에너지나 자원을 효율적으로 사용할 수 있다. 예를 들어 목표 온도에 도달하면 히터 출력을 줄일 수 있다.
A23: Modifiability | B23: ='Detailed Reasoning'!B$7 | C23: ='Detailed Reasoning'!C$7 | D23: ='Detailed Reasoning'!D$7 | E23: ='Detailed Reasoning'!E$7 | F23: ='Detailed Reasoning'!F$7 | G23: ='Detailed Reasoning'!G$7
A24: AI#1 | B24: ='AI#1 (Claude)'!B$7 -> + | C24: ='AI#1 (Claude)'!C7 -> 단계들이 데이터 파일로 분리되어 있어 한 단계만 교체·재작성할 수 있다. 그러나 파일 포맷이 공유 계약이라 포맷 변경은 모든 단계에 파급된다. | D24: ='AI#1 (Claude)'!D$7 -> ++ | E24: ='AI#1 (Claude)'!E7 -> 필터가 느슨하게 결합된 무상태 단위라 다른 필터를 건드리지 않고 순서 변경·교체·제거가 가능하다. | F24: ='AI#1 (Claude)'!F$7 -> - | G24: ='AI#1 (Claude)'!G7 -> 제어 법칙과 튜닝 값이 플랜트 모델과 얽혀 있어 변경할 때마다 루프 전체를 재튜닝하고 재검증해야 한다.
A25: AI#2 | B25: ='AI#2(Gpt)'!B$7 -> + | C25: ='AI#2(Gpt)'!C$7 -> 각 처리 단계가 비교적 독립되어 있어 특정 단계의 알고리즘을 수정하거나 교체하기 쉽다. 단, 입출력 형식 변경 시 주변 단계에도 영향이 갈 수 있다. | D25: =#REF! -> #REF! | E25: =#REF! -> #REF! | F25: =#REF! -> #REF! | G25: =#REF! -> #REF!
A26: Human | B26: =Human!B$7 -> + | C26: =Human!C$7 -> 각 처리 단계가 비교적 독립되어 있어 특정 단계의 알고리즘을 수정하거나 교체하기 쉽다. 단, 입출력 형식 변경 시 주변 단계에도 영향이 갈 수 있다. | D26: =Human!D$7 -> ++ | E26: =Human!E$7 -> 각 Filter가 특정 기능만 담당하고 서로 직접 의존하지 않으므로 Filter 추가·삭제·교체가 쉽다. Pipe and Filter의 대표적인 장점이다. | F26: =Human!F$7 -> - | G26: =Human!G$7 -> Controller의 제어 알고리즘이나 센서 특성을 변경하면 전체 제어 안정성에 영향을 줄 수 있다. 하나를 수정하면 제어 파라미터를 다시 조정해야 할 가능성이 크다.
A28: Performance | B28: ='Detailed Reasoning'!B$8 | C28: ='Detailed Reasoning'!C$8 | D28: ='Detailed Reasoning'!D$8 | E28: ='Detailed Reasoning'!E$8 | F28: ='Detailed Reasoning'!F$8 | G28: ='Detailed Reasoning'!G$8
A29: AI#1 | B29: ='AI#1 (Claude)'!B$8 -> 0 | C29: ='AI#1 (Claude)'!C8 -> 대량 데이터를 묶어 처리하고 I/O 비용을 분산하므로 처리량은 높지만, 배치가 끝나기 전에는 결과가 전혀 없어 지연 시간은 매우 나쁘다. | D29: ='AI#1 (Claude)'!D$8 -> + | E29: ='AI#1 (Claude)'!E8 -> 모든 필터가 동시에 동작하는 파이프라인 병렬성으로 처리량이 올라간다. 반면 단계 간 복사로 항목별 지연이 커지고, 가장 느린 필터가 전체 속도를 제한한다. | F29: ='AI#1 (Claude)'!F$8 -> + | G29: ='AI#1 (Claude)'!G8 -> 각 제어 주기 안에서 예측 가능한 유계 응답 시간을 목표로 설계된다. 다만 높은 처리량을 노리는 스타일은 아니다.
A30: AI#2 | B30: ='AI#2(Gpt)'!B$8 -> -- | C30: ='AI#2(Gpt)'!C$8 -> 앞 단계가 완전히 끝나야 다음 단계가 시작되므로 병렬 처리가 어렵고 전체 처리 지연시간이 길어진다. 특히 대용량 데이터에서는 단점이 커진다. | D30: =#REF! -> #REF! | E30: =#REF! -> #REF! | F30: =#REF! -> #REF! | G30: =#REF! -> #REF!
A31: Human | B31: =Human!B$8 -> -- | C31: =Human!C$8 -> 앞 단계가 완전히 끝나야 다음 단계가 시작되므로 병렬 처리가 어렵고 전체 처리 지연시간이 길어진다. 특히 대용량 데이터에서는 단점이 커진다. | D31: =Human!D$8 -> + | E31: =Human!E$8 -> 여러 Filter가 동시에 서로 다른 데이터를 처리하는 Pipeline Parallelism이 가능하여 처리량이 높아질 수 있다. 다만 Filter 간 데이터 전달 비용이 발생한다. | F31: =Human!F$8 -> + | G31: =Human!G$8 -> 각 제어 주기 안에서 예측 가능한 유계 응답 시간을 목표로 설계된다. 다만 높은 처리량을 노리는 스타일은 아니다.
A33: Safety | B33: ='Detailed Reasoning'!B$9 | C33: ='Detailed Reasoning'!C$9 | D33: ='Detailed Reasoning'!D$9 | E33: ='Detailed Reasoning'!E$9 | F33: ='Detailed Reasoning'!F$9 | G33: ='Detailed Reasoning'!G$9
A34: AI#1 | B34: ='AI#1 (Claude)'!B$9 -> 0 | C34: ='AI#1 (Claude)'!C9 -> 동시성 없는 순차 결정적 실행이라 위험한 인터리빙이 없지만, 오류가 긴 실행이 끝난 뒤에야 발견되어 대응이 늦어진다. | D34: ='AI#1 (Claude)'!D$9 -> 0 | E34: ='AI#1 (Claude)'!E9 -> 필터 격리로 결함이 한 단계 안에 갇히지만, 전역 상태가 없어 시스템 전체 불변식이나 종단 간 오류 처리를 강제하기 어렵다. | F34: ='AI#1 (Claude)'!F$9 -> ++ | G34: ='AI#1 (Claude)'!G9 -> 제어 변수를 지속 감시해 편차를 즉시 감지하고 안전 상태로 되돌린다. 안전 필수 제어의 대표적인 스타일이다.
A35: AI#2 | B35: ='AI#2(Gpt)'!B$9 -> + | C35: ='AI#2(Gpt)'!C$9 -> 처리 과정이 순차적이고 결정적이어서 처리 순서와 결과를 추적하기 쉽다. 오류 발생 위치를 파악하고 특정 단계 이후의 실행을 차단하기도 비교적 쉽다. | D35: =#REF! -> #REF! | E35: =#REF! -> #REF! | F35: =#REF! -> #REF! | G35: =#REF! -> #REF!
A36: Human | B36: =Human!B$9 -> 0 | C36: =Human!C$9 -> 처리 과정이 순차적이고 결정적이어서 처리 순서와 결과를 추적하기 쉽지만, 오류가 긴 실행이 끝난 뒤에야 발견되어 대응이 늦어진다. | D36: =Human!D$9 -> + | E36: =Human!E$9 -> 각 처리 단계가 분리되어 있어 데이터 검증이나 오류 탐지 Filter를 독립적으로 둘 수 있고, 문제가 발생한 단계를 추적하기 쉽다. | F36: =Human!F$9 -> ++ | G36: =Human!G$9 -> 위험 상태를 지속적으로 감지하고 자동으로 보정하거나 안전한 상태로 제어할 수 있다. 과열, 압력 초과 등의 상황에 즉각 대응할 수 있어 Safety에 매우 유리하다.
A38: Security | B38: ='Detailed Reasoning'!B$10 | C38: ='Detailed Reasoning'!C$10 | D38: ='Detailed Reasoning'!D$10 | E38: ='Detailed Reasoning'!E$10 | F38: ='Detailed Reasoning'!F$10 | G38: ='Detailed Reasoning'!G$10
A39: AI#1 | B39: ='AI#1 (Claude)'!B$10 -> + | C39: ='AI#1 (Claude)'!C10 -> 네트워크 노출이 없고 단계가 격리되어 공격 표면이 작다. 다만 대용량 중간 파일이 디스크에 남으므로 보호와 삭제 관리가 필요하다. | D39: ='AI#1 (Claude)'!D$10 -> 0 | E39: ='AI#1 (Claude)'!E10 -> 작고 격리된 필터라 침해 시 피해 범위가 제한되지만, 파이프 하나하나가 보호해야 할 추가 데이터 채널이 된다. | F39: ='AI#1 (Claude)'!F$10 -> 0 | G39: ='AI#1 (Claude)'!G10 -> 보통 폐쇄망이나 물리적 분리 환경에서 동작하는 점은 유리하지만, 센서·액추에이터 신호 위조가 곧바로 물리적 피해로 이어진다.
A40: AI#2 | B40: ='AI#2(Gpt)'!B$10 -> 0 | C40: ='AI#2(Gpt)'!C$10 -> 단계별 접근통제를 적용하기 쉽다는 장점이 있지만, 중간 결과를 파일 등으로 저장할 경우 데이터 노출·변조 위험이 생긴다. 장단점이 모두 있다. | D40: =#REF! -> #REF! | E40: =#REF! -> #REF! | F40: =#REF! -> #REF! | G40: =#REF! -> #REF!
A41: Human | B41: =Human!B$10 -> + | C41: =Human!C$10 -> 단계별 접근통제를 적용하기 쉽다. | D41: =Human!D$10 -> 0 | E41: =Human!E$10 -> 인증·검증·필터링 단계를 별도로 추가할 수 있다는 장점이 있지만, Filter와 Pipe가 많아질수록 데이터 전달 구간과 공격 지점도 늘어날 수 있다. | F41: =Human!F$10 -> - | G41: =Human!G$10 -> 센서값이나 제어 명령이 공격자에게 조작되면 실제 장비의 동작까지 영향을 받을 수 있다. 센서·네트워크·액추에이터 등 보호해야 할 지점도 많다.
A43: Testability | B43: ='Detailed Reasoning'!B$11 | C43: ='Detailed Reasoning'!C$11 | D43: ='Detailed Reasoning'!D$11 | E43: ='Detailed Reasoning'!E$11 | F43: ='Detailed Reasoning'!F$11 | G43: ='Detailed Reasoning'!G$11
A44: AI#1 | B44: ='AI#1 (Claude)'!B$11 -> ++ | C44: ='AI#1 (Claude)'!C11 -> 각 단계가 입출력 파일이 명확한 결정적 프로그램이라 단독 테스트가 쉽고, 저장된 파일로 실행을 그대로 재현할 수 있다. | D44: ='AI#1 (Claude)'!D$11 -> ++ | E44: ='AI#1 (Claude)'!E11 -> 각 필터가 입출력 스트림이 정의된 무상태 단위라 기록된 스트림으로 단독 단위 테스트가 쉽다. | F44: ='AI#1 (Claude)'!F$11 -> - | G44: ='AI#1 (Claude)'!G11 -> 동작이 연속 상태, 타이밍, 물리 환경에 의존하므로 함수 호출 수준이 아니라 플랜트 시뮬레이션이 있어야 의미 있는 테스트가 가능하다.
A45: AI#2 | B45: ='AI#2(Gpt)'!B$11 -> ++ | C45: ='AI#2(Gpt)'!C$11 -> 각 단계에 정해진 입력을 넣고 출력을 확인할 수 있어 단위 테스트와 단계별 검증이 매우 쉽다. 중간 결과도 확인할 수 있어 오류 위치 추적도 쉽다. | D45: =#REF! -> #REF! | E45: =#REF! -> #REF! | F45: =#REF! -> #REF! | G45: =#REF! -> #REF!
A46: Human | B46: =Human!B$11 -> ++ | C46: =Human!C$11 -> 각 단계에 정해진 입력을 넣고 출력을 확인할 수 있어 단위 테스트와 단계별 검증이 매우 쉽다. 중간 결과도 확인할 수 있어 오류 위치 추적도 쉽다. | D46: =Human!D$11 -> ++ | E46: =Human!E$11 -> 각 Filter에 독립적으로 입력을 넣고 출력을 확인할 수 있어 단위 테스트가 매우 쉽다. Pipe별 중간 데이터도 확인할 수 있다. | F46: =Human!F$11 -> - | G46: =Human!G$11 -> 센서값, 시간, 환경 변화, Actuator의 실제 반응까지 함께 테스트해야 해서 단순한 입력-출력 테스트가 어렵다. 실제 장비나 시뮬레이터가 필요한 경우도 많다.
A48: Usability | B48: ='Detailed Reasoning'!B$12 | C48: ='Detailed Reasoning'!C$12 | D48: ='Detailed Reasoning'!D$12 | E48: ='Detailed Reasoning'!E$12 | F48: ='Detailed Reasoning'!F$12 | G48: ='Detailed Reasoning'!G$12
A49: AI#1 | B49: ='AI#1 (Claude)'!B$12 -> -- | C49: ='AI#1 (Claude)'!C12 -> 처리 중 사용자 상호작용이 전혀 없다. 진행 상황 확인도, 중간 개입도 불가능하며 결과는 전체 실행이 끝나야 나온다. | D49: ='AI#1 (Claude)'!D$12 -> - | E49: ='AI#1 (Claude)'!E12 -> 스트림 처리 지향이라 처리 도중 상호작용이나 사용자 피드백이 거의 없다. | F49: ='AI#1 (Claude)'!F$12 -> 0 | G49: ='AI#1 (Claude)'!G12 -> 운영자에게 설정값 수준의 제어와 모니터링을 제공해 단순하지만, 내부 제어 동작은 불투명해 해석하기 어렵다.
...

Sheet DC
A1: Data Centered | B1: Shared Repository | D1: Blackboard
B2: Effects | C2: Justification | D2: Effects | E2: Justification
A3: Availability | B3: ='Detailed Reasoning'!B16 | C3: ='Detailed Reasoning'!C16 | D3: ='Detailed Reasoning'!D16 | E3: ='Detailed Reasoning'!E16
A4: AI#1 | B4: ='AI#1 (Claude)'!B$16 -> - | C4: ='AI#1 (Claude)'!C16 -> 저장소가 단일 장애점이다. 별도의 복제를 붙이지 않는 한 저장소가 죽으면 모든 연산 컴포넌트가 멈춘다. | D4: ='AI#1 (Claude)'!D$16 -> - | E4: ='AI#1 (Claude)'!E16 -> 블랙보드 자체가 단일 장애점이다. 다만 개별 지식원이 실패해도 시스템은 계속 진행할 수 있다.
A5: AI#2 | B5: ='AI#2(Gpt)'!D$3 -> 0 | C5: ='AI#2(Gpt)'!E$3 -> Filter들이 독립적이라 일부를 교체·복구하기는 쉽지만, 파이프라인 중 하나의 Filter가 멈추면 전체 흐름이 막힐 수 있다. 장단점이 모두 존재한다. | D5: =#REF! -> #REF! | E5: =#REF! -> #REF!
A6: Human | B6: =Human!B$16 -> - | C6: =Human!C$16 -> 중앙 Repository에 장애가 발생하면 이를 사용하는 여러 컴포넌트가 동시에 영향을 받는다. 저장소가 Single Point of Failure가 되기 쉽다. | D6: =Human!D$16 -> - | E6: =Human!E$16 -> 중앙 Blackboard가 핵심 공유 지점이므로 Blackboard에 장애가 발생하면 여러 Knowledge Source가 동시에 영향을 받는다. 중앙 저장소 의존성이 크다.
A8: Deployability | B8: ='Detailed Reasoning'!B17 | C8: ='Detailed Reasoning'!C17 | D8: ='Detailed Reasoning'!D17 | E8: ='Detailed Reasoning'!E17
A9: AI#1 | B9: ='AI#1 (Claude)'!B$17 -> 0 | C9: ='AI#1 (Claude)'!C17 -> 연산 컴포넌트는 개별 배포가 가능하지만, 모두 하나의 저장소 인스턴스와 스키마 버전에 의존하므로 스키마 변경 시 배포를 함께 조율해야 한다. | D9: ='AI#1 (Claude)'!D$17 -> 0 | E9: ='AI#1 (Claude)'!E17 -> 지식원은 개별 배포·활성화가 가능하지만, 블랙보드와 제어 컴포넌트가 먼저 준비되어 있어야 한다.
A10: AI#2 | B10: ='AI#2(Gpt)'!D$4 -> + | C10: ='AI#2(Gpt)'!E$4 -> Filter가 독립된 처리 단위이므로 개별 Filter를 수정·배포하기 비교적 쉽다. 단, Pipe의 데이터 형식 호환성은 유지해야 한다. | D10: =#REF! -> #REF! | E10: =#REF! -> #REF!
A11: Human | B11: =Human!B$17 -> 0 | C11: =Human!C$17 -> 각 컴포넌트는 독립적으로 배포할 수 있지만, DB Schema나 Repository 구조가 변경되면 여러 컴포넌트를 함께 수정·배포해야 할 수 있다. | D11: =Human!D$17 -> 0 | E11: =Human!E$17 -> Knowledge Source는 비교적 독립적으로 추가·배포할 수 있지만, Blackboard의 데이터 표현 방식이나 제어 로직과의 호환성을 맞춰야 한다.
A13: Integrability | B13: ='Detailed Reasoning'!B18 | C13: ='Detailed Reasoning'!C18 | D13: ='Detailed Reasoning'!D18 | E13: ='Detailed Reasoning'!E18
A14: AI#1 | B14: ='AI#1 (Claude)'!B$18 -> ++ | C14: ='AI#1 (Claude)'!C18 -> 새 컴포넌트는 공유 데이터 구조를 읽고 쓰기만 하면 통합된다. 다른 컴포넌트를 전혀 알 필요가 없다. | D14: ='AI#1 (Claude)'!D$18 -> ++ | E14: ='AI#1 (Claude)'!E18 -> 새 지식원은 블랙보드 상태에 반응하는 방식으로 통합되며, 다른 지식원에 대한 직접 의존이나 지식이 필요 없다.
A15: AI#2 | B15: ='AI#2(Gpt)'!D$5 -> ++ | C15: ='AI#2(Gpt)'!E$5 -> Filter 간 연결이 명확한 입출력 인터페이스로 이루어져 새로운 Filter를 추가하거나 기존 Filter를 다른 컴포넌트로 교체하기 쉽다. | D15: =#REF! -> #REF! | E15: =#REF! -> #REF!
A16: Human | B16: =Human!B$18 -> ++ | C16: =Human!C$18 -> 여러 컴포넌트가 동일한 저장소를 통해 데이터를 공유하므로 시스템 간 데이터 통합이 매우 쉽다. 공통 데이터 모델만 맞으면 새로운 컴포넌트도 데이터를 쉽게 활용할 수 있다. | D16: =Human!D$18 -> ++ | E16: =Human!E$18 -> 새 지식원은 블랙보드 상태에 반응하는 방식으로 통합되며, 다른 지식원에 대한 직접 의존이나 지식이 필요 없다.
A18: Energy Efficiency | B18: ='Detailed Reasoning'!B$19 | C18: ='Detailed Reasoning'!C$19 | D18: ='Detailed Reasoning'!D$19 | E18: ='Detailed Reasoning'!E$19
A19: AI#1 | B19: ='AI#1 (Claude)'!B$19 -> 0 | C19: ='AI#1 (Claude)'!C19 -> 데이터를 중복 없이 한 번만 저장해 저장·전송 비용을 아끼지만, 저장소 폴링과 락 경합이 자원을 낭비한다. | D19: ='AI#1 (Claude)'!D$19 -> -- | E19: ='AI#1 (Claude)'!E19 -> 기회주의적 활성화 방식이라 많은 지식원이 블랙보드를 계속 살피며 중복 연산을 수행하고, 그 결과 상당수가 버려진다.
A20: AI#2 | B20: ='AI#2(Gpt)'!D$6 -> 0 | C20: ='AI#2(Gpt)'!E$6 -> 스트리밍과 병렬 처리로 자원을 효율적으로 사용할 수 있지만, 여러 Filter의 동시 실행과 Pipe/Buffer 관리에 추가 자원이 필요하다. | D20: =#REF! -> #REF! | E20: =#REF! -> #REF!
A21: Human | B21: =Human!B$19 -> 0 | C21: =Human!C$19 -> 데이터를 한곳에 집중시켜 중복 저장을 줄일 수 있지만, 모든 컴포넌트의 읽기·쓰기가 중앙 저장소에 집중되므로 DB 처리 비용도 커질 수 있다. | D21: =Human!D$19 -> -- | E21: =Human!E$19 -> 기회주의적 활성화 방식이라 많은 지식원이 블랙보드를 계속 살피며 중복 연산을 수행하고, 그 결과 상당수가 버려진다.
A23: Modifiability | B23: ='Detailed Reasoning'!B$20 | C23: ='Detailed Reasoning'!C$20 | D23: ='Detailed Reasoning'!D$20 | E23: ='Detailed Reasoning'!E$20
A24: AI#1 | B24: ='AI#1 (Claude)'!B$20 -> + | C24: ='AI#1 (Claude)'!C20 -> 컴포넌트끼리 분리되어 각자 독립적으로 바뀔 수 있다. 다만 공유 스키마가 전역 계약이라 데이터 모델 변경은 모두에게 영향을 준다. | D24: ='AI#1 (Claude)'!D$20 -> ++ | E24: ='AI#1 (Claude)'!E20 -> 지식원들이 완전히 분리되어 있어 다른 지식원을 고치지 않고 추가·제거·교체할 수 있다.
A25: AI#2 | B25: ='AI#2(Gpt)'!D$7 -> ++ | C25: ='AI#2(Gpt)'!E$7 -> 각 Filter가 특정 기능만 담당하고 서로 직접 의존하지 않으므로 Filter 추가·삭제·교체가 쉽다. Pipe and Filter의 대표적인 장점이다. | D25: =#REF! -> #REF! | E25: =#REF! -> #REF!
A26: Human | B26: =Human!B$20 -> 0 | C26: =Human!C$20 -> 컴포넌트끼리 분리되어 각자 독립적으로 바뀔 수 있지만, Repository의 데이터 구조나 Schema를 변경하면 이를 사용하는 여러 컴포넌트에 연쇄적인 변경이 발생할 수 있다. | D26: =Human!D$20 -> ++ | E26: =Human!E$20 -> 지식원들이 완전히 분리되어 있어 다른 지식원을 고치지 않고 추가·제거·교체할 수 있다.
A28: Performance | B28: ='Detailed Reasoning'!B$21 | C28: ='Detailed Reasoning'!C$21 | D28: ='Detailed Reasoning'!D$21 | E28: ='Detailed Reasoning'!E$21
A29: AI#1 | B29: ='AI#1 (Claude)'!B$21 -> 0 | C29: ='AI#1 (Claude)'!C21 -> 중앙 접근이라 인덱싱·캐싱·쿼리 최적화가 가능하지만, 동시성이 높아지면 저장소가 경합 병목이 된다. | D29: ='AI#1 (Claude)'!D$21 -> - | E29: ='AI#1 (Claude)'!E21 -> 비결정적 기회주의 제어와 반복적인 블랙보드 스캔이 오버헤드를 만들며, 응답 시간을 보장할 수 없다.
A30: AI#2 | B30: ='AI#2(Gpt)'!D$8 -> + | C30: ='AI#2(Gpt)'!E$8 -> 여러 Filter가 동시에 서로 다른 데이터를 처리하는 Pipeline Parallelism이 가능하여 처리량이 높아질 수 있다. 다만 Filter 간 데이터 전달 비용이 발생한다. | D30: =#REF! -> #REF! | E30: =#REF! -> #REF!
A31: Human | B31: =Human!B$21 -> - | C31: =Human!C$21 -> 모든 컴포넌트가 중앙 저장소에 접근하기 때문에 요청이 많아지면 Repository가 병목이 될 수 있다. 네트워크·DB I/O 비용도 발생한다. | D31: =Human!D$21 -> - | E31: =Human!E$21 -> Blackboard에 대한 반복적인 읽기/쓰기와 여러 Knowledge Source의 추론 과정 때문에 오버헤드가 발생한다. 어떤 모듈을 실행할지 결정하는 Control 비용도 있다.
A33: Safety | B33: ='Detailed Reasoning'!B$22 | C33: ='Detailed Reasoning'!C$22 | D33: ='Detailed Reasoning'!D$22 | E33: ='Detailed Reasoning'!E$22
A34: AI#1 | B34: ='AI#1 (Claude)'!B$22 -> 0 | C34: ='AI#1 (Claude)'!C22 -> 단일 권위 데이터 소스라 컴포넌트 간 불일치가 없지만, 데이터가 손상되면 즉시 모든 컴포넌트로 전파된다. | D34: ='AI#1 (Claude)'!D$22 -> - | E34: ='AI#1 (Claude)'!E22 -> 제어가 기회주의적이고 비결정적이라 최악의 동작과 종료 조건을 한정하거나 인증하기 어렵다.
A35: AI#2 | B35: ='AI#2(Gpt)'!D$9 -> + | C35: ='AI#2(Gpt)'!E$9 -> 각 처리 단계가 분리되어 있어 데이터 검증이나 오류 탐지 Filter를 독립적으로 둘 수 있고, 문제가 발생한 단계를 추적하기 쉽다. | D35: =#REF! -> #REF! | E35: =#REF! -> #REF!
A36: Human | B36: =Human!B$22 -> + | C36: =Human!C$22 -> 중요한 데이터를 중앙에서 일관되게 관리하고 무결성 제약, 트랜잭션 등을 적용하기 쉬워 데이터 오류를 줄이는 데 유리하다. | D36: =Human!D$22 -> - | E36: =Human!E$22 -> 중간 결과를 중앙에서 확인하고 검증할 수 있다는 장점은 있지만, 잘못된 Knowledge Source가 잘못된 정보를 Blackboard에 기록하면 다른 모듈에도 영향을 줄 수 있다.
A38: Security | B38: ='Detailed Reasoning'!B$23 | C38: ='Detailed Reasoning'!C$23 | D38: ='Detailed Reasoning'!D$23 | E38: ='Detailed Reasoning'!E$23
A39: AI#1 | B39: ='AI#1 (Claude)'!B$23 -> + | C39: ='AI#1 (Claude)'!C23 -> 접근 제어·암호화·감사를 컴포넌트마다가 아니라 한 곳에서 일괄 적용할 수 있다. 대신 그 한 곳이 고가치 표적이 된다. | D39: ='AI#1 (Claude)'!D$23 -> - | E39: ='AI#1 (Claude)'!E23 -> 모든 지식원이 공유 상태 전체를 읽을 수 있어 최소 권한과 정보 흐름 통제를 강제하기 어렵다.
A40: AI#2 | B40: ='AI#2(Gpt)'!D$10 -> 0 | C40: ='AI#2(Gpt)'!E$10 -> 인증·검증·필터링 단계를 별도로 추가할 수 있다는 장점이 있지만, Filter와 Pipe가 많아질수록 데이터 전달 구간과 공격 지점도 늘어날 수 있다. | D40: =#REF! -> #REF! | E40: =#REF! -> #REF!
A41: Human | B41: =Human!B$23 -> + | C41: =Human!C$23 -> 접근 권한, 인증, 감사 로그 등을 중앙 Repository에서 일관되게 적용할 수 있다. 다만 Repository가 침해되면 영향 범위가 매우 크다는 단점도 있다. | D41: =Human!D$23 -> - | E41: =Human!E$23 -> 여러 Knowledge Source가 하나의 Blackboard에 접근하므로 접근 지점과 권한 관리가 복잡하다. Blackboard가 침해되면 공유되는 지식 전체에 영향을 줄 수 있다.
A43: Testability | B43: ='Detailed Reasoning'!B$24 | C43: ='Detailed Reasoning'!C$24 | D43: ='Detailed Reasoning'!D$24 | E43: ='Detailed Reasoning'!E$24
A44: AI#1 | B44: ='AI#1 (Claude)'!B$24 -> + | C44: ='AI#1 (Claude)'!C24 -> 저장소에 데이터를 심어 테스트 시나리오를 구성하기 쉽지만, 공유 데이터를 통한 암묵적 결합 때문에 완전히 격리된 테스트는 어렵다. | D44: ='AI#1 (Claude)'!D$24 -> -- | E44: ='AI#1 (Claude)'!E24 -> 결과가 활성화 순서와 누적된 부분해에 의존하므로 테스트에서 동작을 결정적으로 재현하기 매우 어렵다.
A45: AI#2 | B45: ='AI#2(Gpt)'!D$11 -> ++ | C45: ='AI#2(Gpt)'!E$11 -> 각 Filter에 독립적으로 입력을 넣고 출력을 확인할 수 있어 단위 테스트가 매우 쉽다. Pipe별 중간 데이터도 확인할 수 있다. | D45: =#REF! -> #REF! | E45: =#REF! -> #REF!
A46: Human | B46: =Human!B$24 -> 0 | C46: =Human!C$24 -> 공통 데이터 상태를 기준으로 테스트하기는 쉽지만, 여러 컴포넌트가 같은 Repository를 사용하면 테스트 간 데이터 간섭이 생길 수 있고 DB 환경을 별도로 구성해야 할 수 있다. | D46: =Human!D$24 -> -- | E46: =Human!E$24 -> 결과가 활성화 순서와 누적된 부분해에 의존하므로 테스트에서 동작을 결정적으로 재현하기 매우 어렵다.
A48: Usability | B48: ='Detailed Reasoning'!B$25 | C48: ='Detailed Reasoning'!C$25 | D48: ='Detailed Reasoning'!D$25 | E48: ='Detailed Reasoning'!E$25
A49: AI#1 | B49: ='AI#1 (Claude)'!B$25 -> 0 | C49: ='AI#1 (Claude)'!C25 -> 사용자 인터페이스에 직접적인 영향은 없으나, 일관된 공유 데이터가 기능 간 일관된 화면을 뒷받침한다. | D49: ='AI#1 (Claude)'!D$25 -> 0 | E49: ='AI#1 (Claude)'!E25 -> 결정적 알고리즘이 없는 탐색적 문제를 풀 수 있다는 점은 가치 있지만, 도출 과정을 사용자에게 설명하기 어렵다.
...

Sheet II
A1: Implicit Invocation | B1: Non-Buffered Event Based | D1: Buffered Message Based
B2: Effects | C2: Justification | D2: Effects | E2: Justification
A3: Availability | B3: ='Detailed Reasoning'!B$29 | C3: ='Detailed Reasoning'!C$29 | D3: ='Detailed Reasoning'!D$29 | E3: ='Detailed Reasoning'!E$29
A4: AI#1 | B4: ='AI#1 (Claude)'!B$29 -> - | C4: ='AI#1 (Claude)'!C29 -> 발행 시점에 구독자가 없으면 이벤트가 유실되며, 영속화나 재시도가 없어 컴포넌트 중단 상황을 복구할 수 없다. | D4: ='AI#1 (Claude)'!D$29 -> ++ | E4: ='AI#1 (Claude)'!E29 -> 큐가 송수신자를 시간적으로 분리해 소비자가 죽어도 메시지가 유실되지 않고 복구 후 처리가 이어진다. 대신 브로커 자체가 이중화가 필요한 핵심 요소가 된다.
A5: AI#2 | B5: ='AI#2(Gpt)'!D$16 -> - | C5: ='AI#2(Gpt)'!E$16 -> 중앙 Blackboard가 핵심 공유 지점이므로 Blackboard에 장애가 발생하면 여러 Knowledge Source가 동시에 영향을 받는다. 중앙 저장소 의존성이 크다. | D5: =#REF! -> #REF! | E5: =#REF! -> #REF!
A6: Human | B6: =Human!B$29 -> - | C6: =Human!C$29 -> 리스너가 동작하지 않는 동안 발생한 이벤트를 보관했다가 복구 후 다시 전달하기 어렵다. 또한 동기식으로 리스너를 호출한다면 느린 처리나 예외가 발생자 또는 다른 리스너의 정상 동작에 영향을 줄 수 있어, 장애 시 기능을 계속 제공하는 데 불리하다. (Redis) | D6: =Human!D$29 -> ++ | E6: =Human!E$29 -> 큐가 송수신자를 시간적으로 분리해 소비자가 죽어도 메시지가 유실되지 않고 복구 후 처리가 이어진다. 대신 브로커 자체가 이중화가 필요한 핵심 요소가 된다.
A8: Deployability | B8: ='Detailed Reasoning'!B$30 | C8: ='Detailed Reasoning'!C$30 | D8: ='Detailed Reasoning'!D$30 | E8: ='Detailed Reasoning'!E$30
A9: AI#1 | B9: ='AI#1 (Claude)'!B$30 -> + | C9: ='AI#1 (Claude)'!C30 -> 발행자와 구독자가 개별 배포 가능한 독립 컴포넌트지만, 통신하려면 동시에 실행 중이어야 한다. | D9: ='AI#1 (Claude)'!D$30 -> ++ | E9: ='AI#1 (Claude)'!E30 -> 버퍼가 다운타임을 흡수하므로 생산자와 소비자를 독립적으로 배포·재시작·롤백할 수 있다.
A10: AI#2 | B10: ='AI#2(Gpt)'!D$17 -> 0 | C10: ='AI#2(Gpt)'!E$17 -> Knowledge Source는 비교적 독립적으로 추가·배포할 수 있지만, Blackboard의 데이터 표현 방식이나 제어 로직과의 호환성을 맞춰야 한다. | D10: =#REF! -> #REF! | E10: =#REF! -> #REF!
A11: Human | B11: =Human!B$30 -> 0 | C11: =Human!C$30 -> 기능을 분리하기는 좋지만, 각각 따로 배포할 수 있는지는 구현에 따라 다르다. | D11: =Human!D$30 -> ++ | E11: =Human!E$30 -> 버퍼가 다운타임을 흡수하므로 생산자와 소비자를 독립적으로 배포·재시작·롤백할 수 있다.
A13: Integrability | B13: ='Detailed Reasoning'!B$31 | C13: ='Detailed Reasoning'!C$31 | D13: ='Detailed Reasoning'!D$31 | E13: ='Detailed Reasoning'!E$31
A14: AI#1 | B14: ='AI#1 (Claude)'!B$31 -> ++ | C14: ='AI#1 (Claude)'!C31 -> 새 구독자는 이벤트에 등록만 하면 통합된다. 발행자 코드를 바꿀 필요가 없고 누가 듣는지 알 필요도 없다. | D14: ='AI#1 (Claude)'!D$31 -> ++ | E14: ='AI#1 (Claude)'!E31 -> 새 소비자가 생산자 변경 없이 기존 큐나 토픽에 붙을 수 있고, 이기종 시스템도 메시지 계약으로 통합된다.
A15: AI#2 | B15: ='AI#2(Gpt)'!D$18 -> + | C15: ='AI#2(Gpt)'!E$18 -> 서로 다른 알고리즘이나 모듈이 Blackboard라는 공통 공간을 통해 협력할 수 있어 이질적인 컴포넌트를 통합하기 좋다. | D15: =#REF! -> #REF! | E15: =#REF! -> #REF!
A16: Human | B16: =Human!B$31 -> + | C16: =Human!C$31 -> 같은 이벤트 규칙을 따르면 새로운 기능을 연결하기 쉽다. | D16: =Human!D$31 -> ++ | E16: =Human!E$31 -> 서로 다른 언어·플랫폼으로 구현된 시스템을 메시지 교환으로 연결하기 유리하다. 상대 시스템의 내부 구현이나 실행 시점에 대한 의존성을 줄일 수 있고, 필요하면 중간에서 메시지 형식을 변환할 수도 있다. 단, 메시지의 의미와 데이터 형식에 대한 합의는 필요하다. (Enterprise Integration Patterns)
A18: Energy Efficiency | B18: ='Detailed Reasoning'!B$32 | C18: ='Detailed Reasoning'!C$32 | D18: ='Detailed Reasoning'!D$32 | E18: ='Detailed Reasoning'!E$32
A19: AI#1 | B19: ='AI#1 (Claude)'!B$32 -> + | C19: ='AI#1 (Claude)'!C32 -> 이벤트가 실제로 발생할 때만 연산이 촉발되어 낭비적인 폴링을 피한다. 다만 관심 없는 구독자에게까지 브로드캐스트하는 만큼의 낭비는 남는다. | D19: ='AI#1 (Claude)'!D$32 -> 0 | E19: ='AI#1 (Claude)'!E32 -> 배치 처리와 부하 평준화로 자원 사용이 고르게 되어 과잉 프로비저닝을 피하지만, 메시지 영속화와 복제에 추가 저장·I/O 비용이 든다.
A20: AI#2 | B20: ='AI#2(Gpt)'!D$19 -> - | C20: ='AI#2(Gpt)'!E$19 -> 여러 Knowledge Source가 Blackboard의 상태를 지속적으로 확인하거나 반복적으로 추론할 수 있어 계산량과 자원 사용량이 증가하기 쉽다. | D20: =#REF! -> #REF! | E20: =#REF! -> #REF!
A21: Human | B21: =Human!B$32 -> 0 | C21: =Human!C$32 -> 이벤트를 저장하는 비용은 없지만, 실제 전력 소모는 실행되는 작업량에 따라 달라진다. | D21: =Human!D$32 -> 0 | E21: =Human!E$32 -> 부하를 평준화하여 순간 최대 부하에 맞춘 과도한 자원 확보를 줄일 여지가 있다. 반면 큐 운영과 메시지 저장·전달에도 자원이 필요하다. 이러한 상반된 효과가 있어, 구체적인 부하와 측정 결과 없이 전체 에너지 절감으로 판단하기는 어렵다. (Microsoft Learn)
A23: Modifiability | B23: ='Detailed Reasoning'!B$33 | C23: ='Detailed Reasoning'!C$33 | D23: ='Detailed Reasoning'!D$33 | E23: ='Detailed Reasoning'!E$33
A24: AI#1 | B24: ='AI#1 (Claude)'!B$33 -> ++ | C24: ='AI#1 (Claude)'!C33 -> 발행자가 구독자를 전혀 모르기 때문에 컴포넌트를 서로 독립적으로 추가·제거·교체할 수 있다. | D24: ='AI#1 (Claude)'!D$33 -> ++ | E24: ='AI#1 (Claude)'!E33 -> 메시지 스키마만이 결합점이라 생산자와 소비자 내부는 자유롭게 바꿀 수 있다.
A25: AI#2 | B25: ='AI#2(Gpt)'!D$20 -> + | C25: ='AI#2(Gpt)'!E$20 -> 기존 Knowledge Source와 직접 연결하지 않고 새로운 Knowledge Source를 추가하거나 교체할 수 있다. 기능 확장에 비교적 유리하다. | D25: =#REF! -> #REF! | E25: =#REF! -> #REF!
A26: Human | B26: =Human!B$33 -> ++ | C26: =Human!C$33 -> 발생자의 핵심 로직을 바꾸지 않고 리스너를 추가·교체·제거하여 동작을 확장하기 쉽다. 이벤트 계약이 유지된다면 발생자와 처리자의 내부 구현을 비교적 독립적으로 변경할 수 있어, 이 구조의 대표적인 장점이다. (Microsoft Learn) | D26: =Human!D$33 -> ++ | E26: =Human!E$33 -> 메시지 계약이 유지되면 생산자와 소비자의 내부 로직을 비교적 독립적으로 변경할 수 있다. 처리 기능을 다른 소비자로 교체하거나, 발행·구독 방식에서는 새로운 소비자를 추가하기도 쉽다. 다만 공통 메시지의 구조나 의미가 바뀌면 관련 구성요소에 변경이 전파될 수 있다. (Microsoft Learn)
A28: Performance | B28: ='Detailed Reasoning'!B$34 | C28: ='Detailed Reasoning'!C$34 | D28: ='Detailed Reasoning'!D$34 | E28: ='Detailed Reasoning'!E$34
A29: AI#1 | B29: ='AI#1 (Claude)'!B$34 -> + | C29: ='AI#1 (Claude)'!C34 -> 메모리 내 직접 디스패치라 큐잉 오버헤드 없이 지연이 매우 낮다. 반면 동기 전달이라 느린 구독자가 발행자를 막을 위험이 있다. | D29: ='AI#1 (Claude)'!D$34 -> + | E29: ='AI#1 (Claude)'!E34 -> 버퍼링으로 처리량이 높고 급격한 부하도 유실 없이 흡수한다. 대신 큐잉 때문에 종단 간 지연이 늘어난다.
A30: AI#2 | B30: ='AI#2(Gpt)'!D$21 -> - | C30: ='AI#2(Gpt)'!E$21 -> Blackboard에 대한 반복적인 읽기/쓰기와 여러 Knowledge Source의 추론 과정 때문에 오버헤드가 발생한다. 어떤 모듈을 실행할지 결정하는 Control 비용도 있다. | D30: =#REF! -> #REF! | E30: =#REF! -> #REF!
A31: Human | B31: =Human!B$34 -> + | C31: =Human!C$34 -> 메모리 내 직접 디스패치라 큐잉 오버헤드 없이 지연이 매우 낮다. 반면 동기 전달이라 느린 구독자가 발행자를 막을 위험이 있다. | D31: =Human!D$34 -> 0 | E31: =Human!E$34 -> 트래픽이 몰릴 때 요청을 큐에 저장해 서버 과부하를 막을 수 있지만, 대기 시간이 생기므로 처리 자체가 빨라지는 것은 아니다.
A33: Safety | B33: ='Detailed Reasoning'!B$35 | C33: ='Detailed Reasoning'!C$35 | D33: ='Detailed Reasoning'!D$35 | E33: ='Detailed Reasoning'!E$35
A34: AI#1 | B34: ='AI#1 (Claude)'!B$35 -> - | C34: ='AI#1 (Claude)'!C35 -> 전달·순서·완료가 보장되지 않고 이벤트가 조용히 유실될 수 있어 중요한 동작에는 부적합하다. | D34: ='AI#1 (Claude)'!D$35 -> + | E34: ='AI#1 (Claude)'!E35 -> 영속화와 확인응답으로 재시도와 최소 1회 전달이 가능해 중요한 작업이 조용히 사라지지 않는다. 다만 중복 전달은 소비자가 처리해야 한다.
A35: AI#2 | B35: ='AI#2(Gpt)'!D$22 -> 0 | C35: ='AI#2(Gpt)'!E$22 -> 중간 결과를 중앙에서 확인하고 검증할 수 있다는 장점은 있지만, 잘못된 Knowledge Source가 잘못된 정보를 Blackboard에 기록하면 다른 모듈에도 영향을 줄 수 있다. | D35: =#REF! -> #REF! | E35: =#REF! -> #REF!
A36: Human | B36: =Human!B$35 -> - | C36: =Human!C$35 -> 안전 관련 이벤트의 처리 누락이나 지연을 구조 자체가 방지하지 못한다. 예를 들어 위험 감지 알림을 해당 리스너가 처리하지 못하면 필요한 안전 동작이 실행되지 않을 수 있다. 이러한 용도라면 처리 확인이나 독립적인 안전 장치 같은 추가 설계가 필요하다는 판단이다. (Redis) | D36: =Human!D$35 -> + | E36: =Human!E$35 -> 영속화와 확인응답으로 재시도와 최소 1회 전달이 가능해 중요한 작업이 조용히 사라지지 않는다. 다만 중복 전달은 소비자가 처리해야 한다.
A38: Security | B38: ='Detailed Reasoning'!B$36 | C38: ='Detailed Reasoning'!C$36 | D38: ='Detailed Reasoning'!D$36 | E38: ='Detailed Reasoning'!E$36
A39: AI#1 | B39: ='AI#1 (Claude)'!B$36 -> - | C39: ='AI#1 (Claude)'!C36 -> 등록된 컴포넌트라면 브로드캐스트 이벤트를 받을 수 있어 누가 어떤 정보를 보는지 통제하기 어렵다. | D39: ='AI#1 (Claude)'!D$36 -> 0 | E39: ='AI#1 (Claude)'!E36 -> 중앙 브로커에서 인증·인가를 일괄 적용할 수 있지만, 큐에 쌓인 메시지 자체에 대한 보호가 따로 필요하다.
A40: AI#2 | B40: ='AI#2(Gpt)'!D$23 -> - | C40: ='AI#2(Gpt)'!E$23 -> 여러 Knowledge Source가 하나의 Blackboard에 접근하므로 접근 지점과 권한 관리가 복잡하다. Blackboard가 침해되면 공유되는 지식 전체에 영향을 줄 수 있다. | D40: =#REF! -> #REF! | E40: =#REF! -> #REF!
A41: Human | B41: =Human!B$36 -> 0 | C41: =Human!C$36 -> 이 방식 자체가 보안을 높여주지는 않는다. 인증과 접근 권한은 따로 설계해야 한다. | D41: =Human!D$36 -> 0 | E41: =Human!E$36 -> 브로커에서 메시지 발행·수신 권한을 관리할 수 있지만, 메시지 저장소와 전달 경로도 보호해야 한다. 비인가 메시지 삽입이나 열람을 막기 위한 인증·권한 관리·암호화가 별도로 필요하다. 따라서 버퍼링만으로 보안이 강화된다고 볼 수는 없다. (Microsoft Learn)
A43: Testability | B43: ='Detailed Reasoning'!B$37 | C43: ='Detailed Reasoning'!C$37 | D43: ='Detailed Reasoning'!D$37 | E43: ='Detailed Reasoning'!E$37
A44: AI#1 | B44: ='AI#1 (Claude)'!B$37 -> -- | C44: ='AI#1 (Claude)'!C37 -> 제어 흐름이 암묵적이고 등록 순서에 의존해서, 시나리오를 재현하려면 이벤트 토폴로지 전체를 재구성해야 한다. | D44: ='AI#1 (Claude)'!D$37 -> - | E44: ='AI#1 (Claude)'!E37 -> 비동기성과 타이밍 때문에 종단 간 테스트가 비결정적이다. 다만 양쪽 모두 가짜 큐를 두고 개별 테스트는 가능하다.
A45: AI#2 | B45: ='AI#2(Gpt)'!D$24 -> - | C45: ='AI#2(Gpt)'!E$24 -> 각각의 Knowledge Source 자체는 테스트할 수 있지만, 실제 실행 순서가 Blackboard의 현재 상태와 Control 전략에 따라 달라질 수 있어 전체 시스템 테스트가 어렵다. | D45: =#REF! -> #REF! | E45: =#REF! -> #REF!
A46: Human | B46: =Human!B$37 -> - | C46: =Human!C$37 -> 개별 기능은 시험하기 쉽지만, 여러 이벤트가 이어지는 전체 흐름은 확인하기 어렵다. | D46: =Human!D$37 -> - | E46: =Human!E$37 -> 개별 소비자는 정해진 메시지를 입력하여 독립적으로 시험하기 좋지만, 전체 흐름의 검증은 복잡해진다. 비동기 처리 완료 시점, 큐에 남은 메시지, 병렬 처리 순서 등을 고려해야 하고, 재전송 기능이 있다면 중복 처리도 검증해야 한다. 여러 구성요소에 걸친 실행을 추적하기도 상대적으로 어렵다. (Microsoft Learn)
A48: Usability | B48: ='Detailed Reasoning'!B$38 | C48: ='Detailed Reasoning'!C$38 | D48: ='Detailed Reasoning'!D$38 | E48: ='Detailed Reasoning'!E$38
A49: AI#1 | B49: ='AI#1 (Claude)'!B$38 -> + | C49: ='AI#1 (Claude)'!C38 -> 상태가 바뀌는 즉시 갱신되는 반응형 UI를 만들 수 있어 사용자 응답성이 좋다. | D49: ='AI#1 (Claude)'!D$38 -> 0 | E49: ='AI#1 (Claude)'!E38 -> 사용자는 즉시가 아닌 최종적 결과를 보게 되므로 UI가 처리 중 상태를 알려줘야 한다.
...

Sheet IO
A1: Interaction-Oriented | B1: MVC | D1: PAC
B2: Effects | C2: Justification | D2: Effects | E2: Justification
A3: Availability | B3: ='Detailed Reasoning'!B$42 | C3: ='Detailed Reasoning'!C$42 | D3: ='Detailed Reasoning'!D$42 | E3: ='Detailed Reasoning'!E$42
A4: AI#1 | B4: ='AI#1 (Claude)'!B$42 -> 0 | C4: ='AI#1 (Claude)'!C42 -> 스타일 자체가 이중화를 제공하지는 않지만, 분리 덕분에 뷰가 실패하거나 교체되어도 모델과 그 로직에는 영향이 없다. | D4: ='AI#1 (Claude)'!D$42 -> + | E4: ='AI#1 (Claude)'!E42 -> 에이전트가 자체 제어를 가진 독립 단위라 하나가 실패해도 해당 서브시스템만 저하되고 전체가 멈추지 않는다.
A5: AI#2 | B5: ='AI#2(Gpt)'!D$29 -> + | C5: ='AI#2(Gpt)'!E$29 -> 수신자가 일시적으로 중단되어도 큐가 정상이고 여유 공간이 있으면 메시지를 계속 접수할 수 있다. 수신자는 복구 후 대기 메시지를 처리할 수 있어 장애의 영향을 줄이기 유리하다. 다만 접수가 가능하다는 것과 실제 업무 처리가 계속된다는 것은 다르며, 큐 장애나 용량 초과도 고려해야 한다. (Microsoft Learn) | D5: ='AI#2(Gpt)'!D$42 -> ++ | E5: ='AI#2(Gpt)'!E$42 -> 기능과 정보가 나뉘어 있어 한 기능의 문제가 다른 기능까지 번지는 것을 줄이기 좋다. 다만 실제로 장애를 격리하도록 구현해야 한다.
A6: Human | B6: =Human!B$42 | C6: =Human!C$42 -> Human - MVC - Availability | D6: =Human!D$42 | E6: =Human!E$42 -> Human - PAC - Availability
A8: Deployability | B8: ='Detailed Reasoning'!B$43 | C8: ='Detailed Reasoning'!C$43 | D8: ='Detailed Reasoning'!D$43 | E8: ='Detailed Reasoning'!E$43
A9: AI#1 | B9: ='AI#1 (Claude)'!B$43 -> + | C9: ='AI#1 (Claude)'!C43 -> 뷰와 모델을 서로 다른 티어나 기기에 배포할 수 있고, 비즈니스 로직 재배포 없이 화면만 갱신할 수 있다. | D9: ='AI#1 (Claude)'!D$43 -> + | E9: ='AI#1 (Claude)'!E43 -> 에이전트가 완결된 단위라 여러 노드에 분산 배포할 수 있다. 다만 에이전트 계층 구조를 일관된 구성으로 배포해야 한다.
A10: AI#2 | B10: ='AI#2(Gpt)'!D$30 -> + | C10: ='AI#2(Gpt)'!E$30 -> 생산자·소비자가 별도 배포 단위라면, 메시지 형식의 호환성을 유지하면서 각각 배포하기 쉽다. 소비자 교체 중에는 메시지를 큐에 보관할 수 있다. 다만 메시지 형식을 호환되지 않게 변경하면 구버전·신버전 사이의 문제가 발생하므로 버전 관리가 필요하다. (Microsoft Learn) | D10: ='AI#2(Gpt)'!D$43 -> ++ | E10: ='AI#2(Gpt)'!E$43 -> 다른 기능의 내부에 대한 의존성이 적어 필요한 에이전트를 따로 교체하기 좋다. 실제 독립 배포를 하려면 배포 단위도 나눠야 한다.
A11: Human | B11: =Human!B$43 | C11: =Human!C$43 -> Human - MVC - Deployability | D11: =Human!D$43 | E11: =Human!E$43 -> Human - PAC - Deployability
A13: Integrability | B13: ='Detailed Reasoning'!B$44 | C13: ='Detailed Reasoning'!C$44 | D13: ='Detailed Reasoning'!D$44 | E13: ='Detailed Reasoning'!E$44
A14: AI#1 | B14: ='AI#1 (Claude)'!B$44 -> + | C14: ='AI#1 (Claude)'!C44 -> 새 뷰는 안정된 모델 인터페이스를 기준으로 통합된다. 다만 컨트롤러와 뷰의 결합 때문에 일부 통합은 까다로울 수 있다. | D14: ='AI#1 (Claude)'!D$44 -> + | E14: ='AI#1 (Claude)'!E44 -> 새 에이전트는 제어 컴포넌트를 통해 계층에 붙는다. 단점은 계층이 깊어지면 어디에 붙여야 할지 명확하지 않다는 점이다.
A15: AI#2 | B15: ='AI#2(Gpt)'!D$31 -> ++ | C15: ='AI#2(Gpt)'!E$31 -> 서로 다른 언어·플랫폼으로 구현된 시스템을 메시지 교환으로 연결하기 유리하다. 상대 시스템의 내부 구현이나 실행 시점에 대한 의존성을 줄일 수 있고, 필요하면 중간에서 메시지 형식을 변환할 수도 있다. 단, 메시지의 의미와 데이터 형식에 대한 합의는 필요하다. (Enterprise Integration Patterns) | D15: ='AI#2(Gpt)'!D$44 -> ++ | E15: ='AI#2(Gpt)'!E$44 -> 각 에이전트가 Control을 통해 연결되므로, 기존 기능의 내부를 크게 바꾸지 않고 새로운 기능을 추가·통합하기 쉽다.
A16: Human | B16: =Human!B$44 | C16: =Human!C$44 -> Human - MVC - Integrability | D16: =Human!D$44 | E16: =Human!E$44 -> Human - PAC - Integrability
A18: Energy Efficiency | B18: ='Detailed Reasoning'!B$45 | C18: ='Detailed Reasoning'!C$45 | D18: ='Detailed Reasoning'!D$45 | E18: ='Detailed Reasoning'!E$45
A19: AI#1 | B19: ='AI#1 (Claude)'!B$45 -> - | C19: ='AI#1 (Claude)'!C45 -> 변경 통지와 반복적인 뷰 갱신이, 상태를 한 번에 그리는 방식보다 오버헤드를 더한다. | D19: ='AI#1 (Claude)'!D$45 -> - | E19: ='AI#1 (Claude)'!E45 -> 모든 에이전트가 각자 표현·추상화·제어 부분을 갖고, 메시지가 계층을 여러 단계 거치면서 자원을 더 쓴다.
A20: AI#2 | B20: ='AI#2(Gpt)'!D$32 -> 0 | C20: ='AI#2(Gpt)'!E$32 -> 부하를 평준화하여 순간 최대 부하에 맞춘 과도한 자원 확보를 줄일 여지가 있다. 반면 큐 운영과 메시지 저장·전달에도 자원이 필요하다. 이러한 상반된 효과가 있어, 구체적인 부하와 측정 결과 없이 전체 에너지 절감으로 판단하기는 어렵다. (Microsoft Learn) | D20: ='AI#2(Gpt)'!D$45 -> -- | E20: ='AI#2(Gpt)'!E$45 -> 에이전트 사이에서 요청을 전달하고 데이터를 맞추는 추가 작업이 생긴다. 사진에서는 정보 분산과 약한 결합의 비용이 겹친다.
A21: Human | B21: =Human!B$45 | C21: =Human!C$45 -> Human - MVC - Energy Efficiency | D21: =Human!D$45 | E21: =Human!E$45 -> Human - PAC - Energy Efficiency
A23: Modifiability | B23: ='Detailed Reasoning'!B$46 | C23: ='Detailed Reasoning'!C$46 | D23: ='Detailed Reasoning'!D$46 | E23: ='Detailed Reasoning'!E$46
A24: AI#1 | B24: ='AI#1 (Claude)'!B$46 -> ++ | C24: ='AI#1 (Claude)'!C46 -> 비즈니스 로직을 건드리지 않고 UI를 변경하거나 통째로 교체할 수 있으며, 여러 뷰가 한 모델을 공유할 수 있다. | D24: ='AI#1 (Claude)'!D$46 -> ++ | E24: ='AI#1 (Claude)'!E46 -> 각 에이전트가 자기 데이터와 UI를 캡슐화하므로 변경이 해당 에이전트 안에 머물고 다른 곳으로 새지 않는다.
A25: AI#2 | B25: ='AI#2(Gpt)'!D$33 -> ++ | C25: ='AI#2(Gpt)'!E$33 -> 메시지 계약이 유지되면 생산자와 소비자의 내부 로직을 비교적 독립적으로 변경할 수 있다. 처리 기능을 다른 소비자로 교체하거나, 발행·구독 방식에서는 새로운 소비자를 추가하기도 쉽다. 다만 공통 메시지의 구조나 의미가 바뀌면 관련 구성요소에 변경이 전파될 수 있다. (Microsoft Learn) | D25: ='AI#2(Gpt)'!D$46 -> ++ | E25: ='AI#2(Gpt)'!E$46 -> 한 에이전트의 화면이나 처리 방식을 바꿔도 다른 에이전트의 수정은 줄이기 쉽다. 단, 서로 주고받는 규칙은 유지해야 한다.
A26: Human | B26: =Human!B$46 | C26: =Human!C$46 -> Human - MVC - Modifiability | D26: =Human!D$46 | E26: =Human!E$46 -> Human - PAC - Modifiability
A28: Performance | B28: ='Detailed Reasoning'!B$47 | C28: ='Detailed Reasoning'!C$47 | D28: ='Detailed Reasoning'!D$47 | E28: ='Detailed Reasoning'!E$47
A29: AI#1 | B29: ='AI#1 (Claude)'!B$47 -> - | C29: ='AI#1 (Claude)'!C47 -> 모델·뷰·컨트롤러 사이의 간접 참조가 상태 변경마다 통지와 갱신 오버헤드를 만든다. | D29: ='AI#1 (Claude)'!D$47 -> - | E29: ='AI#1 (Claude)'!E47 -> 에이전트 간 통신이 제어 컴포넌트를 거치므로 지연이 늘고, 계층이 깊을수록 더 심해진다.
A30: AI#2 | B30: ='AI#2(Gpt)'!D$34 -> 0 | C30: ='AI#2(Gpt)'!E$34 -> 순간적으로 몰리는 요청을 버퍼에 보관하고 처리 속도를 조절하여 과부하를 완화할 수 있다. 반면 큐 입출력과 대기 시간이 추가되고, 발생량이 처리량보다 계속 많으면 지연이 누적된다. 따라서 부하 대응에는 유리하지만 개별 요청의 완료 시간까지 빨라지는 것은 아니다. (Microsoft Learn) | D30: ='AI#2(Gpt)'!D$47 -> 0 | E30: ='AI#2(Gpt)'!E$47 -> 독립적인 작업을 함께 처리할 수 있지만, 여러 C를 거치는 전달과 데이터 조정 때문에 시간이 더 걸릴 수도 있다.
A31: Human | B31: =Human!B$47 | C31: =Human!C$47 -> Human - MVC - Performance | D31: =Human!D$47 | E31: =Human!E$47 -> Human - PAC - Performance
A33: Safety | B33: ='Detailed Reasoning'!B$48 | C33: ='Detailed Reasoning'!C$48 | D33: ='Detailed Reasoning'!D$48 | E33: ='Detailed Reasoning'!E$48
A34: AI#1 | B34: ='AI#1 (Claude)'!B$48 -> 0 | C34: ='AI#1 (Claude)'!C48 -> 단일 권위 모델 덕분에 뷰 사이의 상태 불일치는 없지만 결함 허용 메커니즘은 없어, 모델이 실패하면 모든 뷰가 함께 멈춘다. | D34: ='AI#1 (Claude)'!D$48 -> + | E34: ='AI#1 (Claude)'!E48 -> 에이전트 캡슐화가 한 서브시스템의 결함이 다른 서브시스템으로 번지는 것을 막는다.
A35: AI#2 | B35: ='AI#2(Gpt)'!D$35 -> - | C35: ='AI#2(Gpt)'!E$35 -> 안전 관련 제어에 적용할 경우, 긴급한 메시지가 큐에서 대기하면서 대응 시한을 놓칠 위험이 있다. 또한 여러 소비자가 병렬 처리하면 메시지의 최종 처리 순서가 달라질 수 있다. 버퍼링 자체는 최대 지연이나 안전한 실행 순서를 보장하지 않으므로 부정적으로 평가했다. (Microsoft Learn) | D35: ='AI#2(Gpt)'!D$48 -> + | E35: ='AI#2(Gpt)'!E$48 -> 중요한 처리 기능을 분리하여 오류의 영향을 제한하기 좋다. 다만 동시에 진행되는 작업의 순서와 데이터 상태는 따로 검증해야 한다.
A36: Human | B36: =Human!B$48 | C36: =Human!C$48 -> Human - MVC - Safety | D36: =Human!D$48 | E36: =Human!E$48 -> Human - PAC - Safety
A38: Security | B38: ='Detailed Reasoning'!B$49 | C38: ='Detailed Reasoning'!C$49 | D38: ='Detailed Reasoning'!D$49 | E38: ='Detailed Reasoning'!E$49
A39: AI#1 | B39: ='AI#1 (Claude)'!B$49 -> + | C39: ='AI#1 (Claude)'!C49 -> 검증과 비즈니스 규칙이 뷰마다 중복되지 않고 모델에 모인다. 다만 클라이언트 측 뷰만 믿어서는 안 된다. | D39: ='AI#1 (Claude)'!D$49 -> + | E39: ='AI#1 (Claude)'!E49 -> 각 에이전트의 제어 컴포넌트가 해당 서브시스템의 접근 규칙을 강제하기 좋은 지점이 된다.
A40: AI#2 | B40: ='AI#2(Gpt)'!D$36 -> 0 | C40: ='AI#2(Gpt)'!E$36 -> 브로커에서 메시지 발행·수신 권한을 관리할 수 있지만, 메시지 저장소와 전달 경로도 보호해야 한다. 비인가 메시지 삽입이나 열람을 막기 위한 인증·권한 관리·암호화가 별도로 필요하다. 따라서 버퍼링만으로 보안이 강화된다고 볼 수는 없다. (Microsoft Learn) | D40: ='AI#2(Gpt)'!D$49 -> + | E40: ='AI#2(Gpt)'!E$49 -> 데이터를 기능별로 나누고 C를 통하는 접근을 관리하기 좋다. 하지만 인증과 접근 권한이 자동으로 제공되는 것은 아니다.
A41: Human | B41: =Human!B$49 | C41: =Human!C$49 -> Human - MVC - Security | D41: =Human!D$49 | E41: =Human!E$49 -> Human - PAC - Security
A43: Testability | B43: ='Detailed Reasoning'!B$50 | C43: ='Detailed Reasoning'!C$50 | D43: ='Detailed Reasoning'!D$50 | E43: ='Detailed Reasoning'!E$50
A44: AI#1 | B44: ='AI#1 (Claude)'!B$50 -> ++ | C44: ='AI#1 (Claude)'!C50 -> 모델 로직을 UI 없이 헤드리스로 테스트할 수 있고, 뷰는 스텁 모델로 검증할 수 있다. | D44: ='AI#1 (Claude)'!D$50 -> + | E44: ='AI#1 (Claude)'!E50 -> 에이전트가 독립적으로 테스트 가능한 단위지만, 계층 간 상호작용은 여전히 통합 테스트가 필요하다.
A45: AI#2 | B45: ='AI#2(Gpt)'!D$37 -> - | C45: ='AI#2(Gpt)'!E$37 -> 개별 소비자는 정해진 메시지를 입력하여 독립적으로 시험하기 좋지만, 전체 흐름의 검증은 복잡해진다. 비동기 처리 완료 시점, 큐에 남은 메시지, 병렬 처리 순서 등을 고려해야 하고, 재전송 기능이 있다면 중복 처리도 검증해야 한다. 여러 구성요소에 걸친 실행을 추적하기도 상대적으로 어렵다. (Microsoft Learn) | D45: ='AI#2(Gpt)'!D$50 -> 0 | E45: ='AI#2(Gpt)'!E$50 -> 각 에이전트는 따로 시험하기 좋지만, 여러 에이전트가 함께 동작할 때의 처리 순서와 데이터 상태를 재현하기 어렵다.
A46: Human | B46: =Human!B$50 | C46: =Human!C$50 -> Human - MVC - Testability | D46: =Human!D$50 | E46: =Human!E$50 -> Human - PAC - Testability
A48: Usability | B48: ='Detailed Reasoning'!B$51 | C48: ='Detailed Reasoning'!C$51 | D48: ='Detailed Reasoning'!D$51 | E48: ='Detailed Reasoning'!E$51
A49: AI#1 | B49: ='AI#1 (Claude)'!B$51 -> ++ | C49: ='AI#1 (Claude)'!C51 -> 같은 데이터에 대한 여러 뷰를 동시에 제공하고 UI를 빠르게 개선할 수 있어 사용자 경험에 직접 도움이 된다. | D49: ='AI#1 (Claude)'!D$51 -> ++ | E49: ='AI#1 (Claude)'!E51 -> 독립적이고 상호작용이 풍부한 여러 UI 서브시스템을 지원해 복잡한 대화형 애플리케이션에 잘 맞는다.
...

Sheet H1
A1: Hierarchical | B1: Main-subroutine | D1: Master-Slave
B2: Effects | C2: Justification | D2: Effects | E2: Justification
A3: Availability | B3: ='Detailed Reasoning'!B$55 | C3: ='Detailed Reasoning'!C$55 | D3: ='Detailed Reasoning'!D$55 | E3: ='Detailed Reasoning'!E$55
A4: AI#1 | B4: ='AI#1 (Claude)'!B$55 -> -- | C4: ='AI#1 (Claude)'!C55 -> 이중화 없는 단일 프로세스다. 서브루틴 하나가 실패하면 프로그램 전체가 죽고 부분 동작도 불가능하다. | D4: ='AI#1 (Claude)'!D$55 -> + | E4: ='AI#1 (Claude)'!E55 -> 슬레이브가 이중화를 제공해 교체·승격이 가능하므로 슬레이브 장애로는 시스템이 멈추지 않는다. 다만 자동 failover가 없으면 마스터는 여전히 단일 장애점이다.
A5: AI#2 | B5: ='AI#2(Gpt)'!B$55 -> - | C5: ='AI#2(Gpt)'!C$55 -> 순서대로 강하게 연결되어 있어 한 함수의 장애가 전체 실행을 멈출 수 있다. | D5: ='AI#2(Gpt)'!D$55 -> + | E5: ='AI#2(Gpt)'!E$55 -> 작업을 나누어 일부 작업자의 장애 영향을 줄일 수 있지만 Master 장애는 남는다.
A6: Human | B6: =Human!B$55 -> -- | C6: =Human!C$55 -> 이중화 없는 단일 프로세스다. 서브루틴 하나가 실패하면 프로그램 전체가 죽고 부분 동작도 불가능하다. | D6: =Human!D$55 -> + | E6: =Human!E$55 -> 작업을 나누어 일부 작업자의 장애 영향을 줄일 수 있지만 Master 장애는 남는다.
A8: Deployability | B8: ='Detailed Reasoning'!B$56 | C8: ='Detailed Reasoning'!C$56 | D8: ='Detailed Reasoning'!D$56 | E8: ='Detailed Reasoning'!E$56
A9: AI#1 | B9: ='AI#1 (Claude)'!B$56 -> 0 | C9: ='AI#1 (Claude)'!C56 -> 단일 실행 파일이라 설치는 매우 간단하지만, 한 줄만 고쳐도 프로그램 전체를 다시 배포해야 한다. | D9: ='AI#1 (Claude)'!D$56 -> 0 | E9: ='AI#1 (Claude)'!E56 -> 슬레이브는 런타임에 추가·제거할 수 있지만, 마스터와 슬레이브가 호환 버전이어야 해서 업그레이드 시 순서를 맞춘 배포가 필요하다.
A10: AI#2 | B10: ='AI#2(Gpt)'!B$56 -> - | C10: ='AI#2(Gpt)'!C$56 -> 함수들이 같은 실행 프로그램에 묶여 있어 일부만 따로 배포하기 어렵다. | D10: ='AI#2(Gpt)'!D$56 -> + | E10: ='AI#2(Gpt)'!E$56 -> 작업자를 분리해 교체하기 좋지만 Master와 주고받는 규칙은 유지해야 한다.
A11: Human | B11: =Human!B$56 -> - | C11: =Human!C$56 -> 함수들이 같은 실행 프로그램에 묶여 있어 일부만 따로 배포하기 어렵다. | D11: =Human!D$56 -> + | E11: =Human!E$56 -> 작업자를 분리해 교체하기 좋지만 Master와 주고받는 규칙은 유지해야 한다.
A13: Integrability | B13: ='Detailed Reasoning'!B$57 | C13: ='Detailed Reasoning'!C$57 | D13: ='Detailed Reasoning'!D$57 | E13: ='Detailed Reasoning'!E$57
A14: AI#1 | B14: ='AI#1 (Claude)'!B$57 -> - | C14: ='AI#1 (Claude)'!C57 -> 직접 호출 결합과 공유 전역 데이터 때문에 외부·서드파티 컴포넌트를 통합하는 일이 침습적이다. | D14: ='AI#1 (Claude)'!D$57 -> 0 | E14: ='AI#1 (Claude)'!E57 -> 슬레이브는 마스터가 정의한 하나의 균일한 인터페이스로 통합되어 단순하다. 그러나 마스터는 작업을 어떻게 분할해 어디로 보낼지 알고 있어야 한다.
A15: AI#2 | B15: ='AI#2(Gpt)'!B$57 -> 0 | C15: ='AI#2(Gpt)'!C$57 -> 함수별 연결은 쉽지만 호출 규칙과 공통 데이터에 대한 의존성이 있다. | D15: ='AI#2(Gpt)'!D$57 -> 0 | E15: ='AI#2(Gpt)'!E$57 -> 같은 규칙의 작업자는 추가하기 쉽지만 다른 방식의 시스템을 연결하려면 조정이 필요하다.
A16: Human | B16: =Human!B$57 -> - | C16: =Human!C$57 -> 함수별 연결은 쉽지만 호출 규칙과 공통 데이터에 대한 의존성이 있다. | D16: =Human!D$57 -> 0 | E16: =Human!E$57 -> 같은 규칙의 작업자는 추가하기 쉽지만 다른 방식의 시스템을 연결하려면 조정이 필요하다.
A18: Energy Efficiency | B18: ='Detailed Reasoning'!B$58 | C18: ='Detailed Reasoning'!C$58 | D18: ='Detailed Reasoning'!D$58 | E18: ='Detailed Reasoning'!E$58
A19: AI#1 | B19: ='AI#1 (Claude)'!B$58 -> ++ | C19: ='AI#1 (Claude)'!C58 -> 하나의 주소 공간에서 직접 프로시저를 호출하므로 직렬화·IPC·네트워크 비용이 거의 없다. | D19: ='AI#1 (Claude)'!D$58 -> - | E19: ='AI#1 (Claude)'!E58 -> 복제와 대기 슬레이브 용량이 실제로 쓰이지 않을 때도 CPU·저장소·네트워크를 계속 소비한다.
A20: AI#2 | B20: ='AI#2(Gpt)'!B$58 -> ++ | C20: ='AI#2(Gpt)'!C$58 -> 직접 호출하고 정보를 함께 사용하므로 통신과 데이터 복사 비용이 적다. | D20: ='AI#2(Gpt)'!D$58 -> - | E20: ='AI#2(Gpt)'!E$58 -> 여러 작업자를 동시에 실행하고 결과를 모으는 데 추가 자원이 든다.
A21: Human | B21: =Human!B$58 -> ++ | C21: =Human!C$58 -> 직접 호출하고 정보를 함께 사용하므로 통신과 데이터 복사 비용이 적다. | D21: =Human!D$58 -> - | E21: =Human!E$58 -> 여러 작업자를 동시에 실행하고 결과를 모으는 데 추가 자원이 든다.
A23: Modifiability | B23: ='Detailed Reasoning'!B$59 | C23: ='Detailed Reasoning'!C$59 | D23: ='Detailed Reasoning'!D$59 | E23: ='Detailed Reasoning'!E$59
A24: AI#1 | B24: ='AI#1 (Claude)'!B$59 -> - | C24: ='AI#1 (Claude)'!C59 -> 계층적 호출 의존성과 공유 전역 데이터 때문에 변경의 영향이 여러 모듈로 퍼진다. | D24: ='AI#1 (Claude)'!D$59 -> 0 | E24: ='AI#1 (Claude)'!E59 -> 고정된 계약 뒤에서 슬레이브 구현은 자유롭게 바꿀 수 있지만, 계약이나 분할 전략을 바꾸면 마스터와 모든 슬레이브를 함께 고쳐야 한다.
A25: AI#2 | B25: ='AI#2(Gpt)'!B$59 -> - | C25: ='AI#2(Gpt)'!C$59 -> 기능은 나뉘어 있지만 호출 관계와 공통 데이터 변경이 다른 함수에도 영향을 준다. | D25: ='AI#2(Gpt)'!D$59 -> 0 | E25: ='AI#2(Gpt)'!E$59 -> 작업자는 따로 수정하기 쉽지만 Master의 작업 배분 방식과는 맞춰야 한다.
A26: Human | B26: =Human!B$59 -> - | C26: =Human!C$59 -> 기능은 나뉘어 있지만 호출 관계와 공통 데이터 변경이 다른 함수에도 영향을 준다. | D26: =Human!D$59 -> 0 | E26: =Human!E$59 -> 작업자는 따로 수정하기 쉽지만 Master의 작업 배분 방식과는 맞춰야 한다.
A28: Performance | B28: ='Detailed Reasoning'!B$60 | C28: ='Detailed Reasoning'!C$60 | D28: ='Detailed Reasoning'!D$60 | E28: ='Detailed Reasoning'!E$60
A29: AI#1 | B29: ='AI#1 (Claude)'!B$60 -> ++ | C29: ='AI#1 (Claude)'!C60 -> 인프로세스 호출이라 직렬화, 프로세스 간 통신, 네트워크 지연이 아예 없다. | D29: ='AI#1 (Claude)'!D$60 -> + | E29: ='AI#1 (Claude)'!E60 -> 슬레이브에 작업을 병렬 분산해 처리량과 읽기 확장성이 올라간다. 반면 마스터가 쓰기·조정 병목이 되고, 복제 지연으로 슬레이브 데이터가 낡는다.
A30: AI#2 | B30: ='AI#2(Gpt)'!B$60 -> 0 | C30: ='AI#2(Gpt)'!C$60 -> 직접 호출은 빠르지만 순차 실행 때문에 앞 작업이 끝날 때까지 기다려야 한다. | D30: ='AI#2(Gpt)'!D$60 -> ++ | E30: ='AI#2(Gpt)'!E$60 -> 독립적인 작업을 여러 작업자가 동시에 처리하므로 처리량을 높이기 좋다.
A31: Human | B31: =Human!B$60 -> 0 | C31: =Human!C$60 -> 직접 호출은 빠르지만 순차 실행 때문에 앞 작업이 끝날 때까지 기다려야 한다. | D31: =Human!D$60 -> + | E31: =Human!E$60 -> 슬레이브에 작업을 병렬 분산해 처리량과 읽기 확장성이 올라간다. 반면 마스터가 쓰기·조정 병목이 되고, 복제 지연으로 슬레이브 데이터가 낡는다.
A33: Safety | B33: ='Detailed Reasoning'!B$61 | C33: ='Detailed Reasoning'!C$61 | D33: ='Detailed Reasoning'!D$61 | E33: ='Detailed Reasoning'!E$61
A34: AI#1 | B34: ='AI#1 (Claude)'!B$61 -> - | C34: ='AI#1 (Claude)'!C61 -> 부분 간 격리가 전혀 없어 서브루틴 하나의 결함이 프로세스 전체를 오염시키고 그대로 중단시킨다. 결함 격리나 복구 수단이 없다. | D34: ='AI#1 (Claude)'!D$61 -> + | E34: ='AI#1 (Claude)'!E61 -> 중복된 슬레이브로 결과를 비교하고 슬레이브 결함 후에도 동작을 이어갈 수 있다. 다만 마스터가 죽으면 조정이 멈춘다.
A35: AI#2 | B35: ='AI#2(Gpt)'!B$61 -> + | C35: ='AI#2(Gpt)'!C$61 -> 실행 순서가 명확해 위험한 동작을 추적하고 점검하기 쉽다. | D35: ='AI#2(Gpt)'!D$61 -> 0 | E35: ='AI#2(Gpt)'!E$61 -> 작업을 나누어 오류 영향을 줄일 수 있지만 동시 실행과 결과 결합 오류는 점검해야 한다.
A36: Human | B36: =Human!B$61 -> - | C36: =Human!C$61 -> 부분 간 격리가 전혀 없어 서브루틴 하나의 결함이 프로세스 전체를 오염시키고 그대로 중단시킨다. 결함 격리나 복구 수단이 없다. | D36: =Human!D$61 -> + | E36: =Human!E$61 -> 작업을 나누어 오류 영향을 줄일 수 있지만 동시 실행과 결과 결합 오류는 점검해야 한다.
A38: Security | B38: ='Detailed Reasoning'!B$62 | C38: ='Detailed Reasoning'!C$62 | D38: ='Detailed Reasoning'!D$62 | E38: ='Detailed Reasoning'!E$62
A39: AI#1 | B39: ='AI#1 (Claude)'!B$62 -> 0 | C39: ='AI#1 (Claude)'!C62 -> 네트워크 노출 없는 단일 프로세스라 공격 표면은 작지만, 내부 권한 분리는 전혀 없다. | D39: ='AI#1 (Claude)'!D$62 -> 0 | E39: ='AI#1 (Claude)'!E62 -> 마스터가 정책을 강제할 단일 지점을 제공하지만, 마스터와 슬레이브 사이의 모든 복제 채널을 인증·암호화해야 한다.
A40: AI#2 | B40: ='AI#2(Gpt)'!B$62 -> 0 | C40: ='AI#2(Gpt)'!C$62 -> 순서대로 접근을 점검하기 쉽지만 공통 정보가 노출되면 피해가 커질 수 있다. | D40: ='AI#2(Gpt)'!D$62 -> 0 | E40: ='AI#2(Gpt)'!E$62 -> 역할별 권한을 나누기 좋지만 여러 작업자와 통신 경로를 함께 보호해야 한다.
A41: Human | B41: =Human!B$62 -> 0 | C41: =Human!C$62 -> 순서대로 접근을 점검하기 쉽지만 공통 정보가 노출되면 피해가 커질 수 있다. | D41: =Human!D$62 -> 0 | E41: =Human!E$62 -> 역할별 권한을 나누기 좋지만 여러 작업자와 통신 경로를 함께 보호해야 한다.
A43: Testability | B43: ='Detailed Reasoning'!B$63 | C43: ='Detailed Reasoning'!C$63 | D43: ='Detailed Reasoning'!D$63 | E43: ='Detailed Reasoning'!E$63
A44: AI#1 | B44: ='AI#1 (Claude)'!B$63 -> + | C44: ='AI#1 (Claude)'!C63 -> 개별 서브루틴 단위 테스트는 쉽지만, 공유 전역 상태 때문에 완전한 격리는 어렵다. | D44: ='AI#1 (Claude)'!D$63 -> + | E44: ='AI#1 (Claude)'!E63 -> 슬레이브 로직이 균일해 단독 테스트가 쉽지만, 타이밍과 복제 동작은 분산 테스트 환경이 있어야 검증할 수 있다.
A45: AI#2 | B45: ='AI#2(Gpt)'!B$63 -> + | C45: ='AI#2(Gpt)'!C$63 -> 입력과 실행 순서를 재현하기 쉽지만 연결된 함수를 따로 시험하기는 불편하다. | D45: ='AI#2(Gpt)'!D$63 -> -- | E45: ='AI#2(Gpt)'!E$63 -> 여러 작업자의 실행 순서와 분산된 결과를 똑같이 재현하기 어렵다.
A46: Human | B46: =Human!B$63 -> + | C46: =Human!C$63 -> 입력과 실행 순서를 재현하기 쉽지만 연결된 함수를 따로 시험하기는 불편하다. | D46: =Human!D$63 -> - | E46: =Human!E$63 -> 여러 작업자의 실행 순서와 분산된 결과를 똑같이 재현하기 어렵다.
A48: Usability | B48: ='Detailed Reasoning'!B$64 | C48: ='Detailed Reasoning'!C$64 | D48: ='Detailed Reasoning'!D$64 | E48: ='Detailed Reasoning'!E$64
A49: AI#1 | B49: ='AI#1 (Claude)'!B$64 -> 0 | C49: ='AI#1 (Claude)'!C64 -> 사용자가 시스템과 상호작용하는 방식에 본질적인 영향을 주지 않는다. | D49: ='AI#1 (Claude)'!D$64 -> 0 | E49: ='AI#1 (Claude)'!E64 -> 사용자에게는 구조가 보이지 않지만, 갱신 직후 복제 지연이 낡은 조회 결과로 드러날 수 있다.
...

Sheet H2
A1: Hierarchical | B1: Layered | D1: Virtual Machine | F1: Microkernel
B2: Effects | C2: Justification | D2: Effects | E2: Justification | F2: Effects | G2: Justification
A3: Availability | B3: ='Detailed Reasoning'!B$68 | C3: ='Detailed Reasoning'!C$68 | D3: ='Detailed Reasoning'!D$68 | E3: ='Detailed Reasoning'!E$68 | F3: ='Detailed Reasoning'!F$68 | G3: ='Detailed Reasoning'!G$68
A4: AI#1 | B4: ='AI#1 (Claude)'!B$68 -> - | C4: ='AI#1 (Claude)'!C68 -> 하위 계층의 장애가 위로 전파되어 그 위에 쌓인 모든 것을 무력화한다. 상위 계층이 하위를 우회할 수 없기 때문이다. | D4: ='AI#1 (Claude)'!D$68 -> + | E4: ='AI#1 (Claude)'!E68 -> 게스트 프로그램이 호스트로부터 격리되어 게스트 장애가 플랫폼을 무너뜨리지 않고, 인스턴스를 재시작하거나 이전할 수 있다. | F4: ='AI#1 (Claude)'!F$68 -> ++ | G4: ='AI#1 (Claude)'!G68 -> 서비스가 커널 밖에서 동작하므로 실패한 서비스만 재시작하면 되고 시스템 전체가 내려가지 않는다.
A5: AI#2 | B5: ='AI#2(Gpt)'!B$68 -> 0 | C5: ='AI#2(Gpt)'!C$68 -> 계층을 나누어도 하위 계층의 장애가 다른 계층에 영향을 줄 수 있다. | D5: ='AI#2(Gpt)'!D$68 -> 0 | E5: ='AI#2(Gpt)'!E$68 -> 실행 환경을 분리하기 좋지만 공통 가상 실행 기반의 장애는 여러 기능에 영향을 준다. | F5: ='AI#2(Gpt)'!F$68 -> + | G5: ='AI#2(Gpt)'!G$68 -> 부가 기능을 분리해 장애 영향을 줄이기 좋지만 핵심 커널의 장애는 남는다.
A6: Human | B6: =Human!B$68 -> - | C6: =Human!C$68 -> 하위 계층의 장애가 위로 전파되어 그 위에 쌓인 모든 것을 무력화한다. 상위 계층이 하위를 우회할 수 없기 때문이다. | D6: =Human!D$68 | E6: =Human!E$68 -> Human - Virtual Machine - Availability | F6: =Human!F$68 | G6: =Human!G$68 -> Human - Microkernel - Availability
A8: Deployability | B8: ='Detailed Reasoning'!B$69 | C8: ='Detailed Reasoning'!C$69 | D8: ='Detailed Reasoning'!D$69 | E8: ='Detailed Reasoning'!E$69 | F8: ='Detailed Reasoning'!F$69 | G8: ='Detailed Reasoning'!G$69
A9: AI#1 | B9: ='AI#1 (Claude)'!B$69 -> + | C9: ='AI#1 (Claude)'!C69 -> 플랫폼 의존 부분이 하위 계층에 모여 있어 그 계층만 교체하면 다른 환경으로 이식할 수 있다. 다만 엄격한 계층 구조 때문에 배포 시 계층 간 버전 호환성을 맞춰야 한다. | D9: ='AI#1 (Claude)'!D$69 -> ++ | E9: ='AI#1 (Claude)'!E69 -> 가상 머신만 있으면 동일한 이미지가 어디서든 실행되므로 호스트별 설치·설정 작업이 사라진다. | F9: ='AI#1 (Claude)'!F$69 -> ++ | G9: ='AI#1 (Claude)'!G69 -> 플러그인 서비스를 안정된 코어와 무관하게 배포·갱신·제거할 수 있다.
A10: AI#2 | B10: ='AI#2(Gpt)'!B$69 -> 0 | C10: ='AI#2(Gpt)'!C$69 -> 계층을 나누어도 각각 따로 배포할 수 있는지는 구현에 따라 달라진다. | D10: ='AI#2(Gpt)'!D$69 -> + | E10: ='AI#2(Gpt)'!E$69 -> 실행 환경의 차이를 감춰 같은 프로그램을 다른 환경에 배포하기 좋다. | F10: ='AI#2(Gpt)'!F$69 -> ++ | G10: ='AI#2(Gpt)'!G$69 -> 핵심과 부가 기능의 연결 규칙을 유지하면 필요한 기능만 교체·배포하기 좋다.
A11: Human | B11: =Human!B$69 -> 0 | C11: =Human!C$69 -> 계층을 나누어도 각각 따로 배포할 수 있는지는 구현에 따라 달라진다. | D11: =Human!D$69 | E11: =Human!E$69 -> Human - Virtual Machine - Deployability | F11: =Human!F$69 -> ++ | G11: =Human!G$69 -> 핵심과 부가 기능의 연결 규칙을 유지하면 필요한 기능만 교체·배포하기 좋다.
A13: Integrability | B13: ='Detailed Reasoning'!B$70 | C13: ='Detailed Reasoning'!C$70 | D13: ='Detailed Reasoning'!D$70 | E13: ='Detailed Reasoning'!E$70 | F13: ='Detailed Reasoning'!F$70 | G13: ='Detailed Reasoning'!G$70
A14: AI#1 | B14: ='AI#1 (Claude)'!B$70 -> + | C14: ='AI#1 (Claude)'!C70 -> 계층 인터페이스가 명확해 외부 컴포넌트를 어디에 붙일지 분명하다. 다만 여러 계층을 가로질러야 하는 통합은 비용이 크다. | D14: ='AI#1 (Claude)'!D$70 -> + | E14: ='AI#1 (Claude)'!E70 -> 균일한 실행 인터페이스가 플랫폼 차이를 감춰 이식성 있는 통합이 쉽다. 다만 호스트의 네이티브 서비스와 연동하려면 별도 브리지가 필요하다. | F14: ='AI#1 (Claude)'!F$70 -> ++ | G14: ='AI#1 (Claude)'!G70 -> 새 기능은 커널이 정의한 인터페이스를 따르는 플러그인으로 통합되며 코어를 수정할 필요가 없다.
A15: AI#2 | B15: ='AI#2(Gpt)'!B$70 -> + | C15: ='AI#2(Gpt)'!C$70 -> 계층 사이의 연결 규칙이 명확하면 새로운 기능을 연결하기 쉽다. | D15: ='AI#2(Gpt)'!D$70 -> + | E15: ='AI#2(Gpt)'!E$70 -> 공통 가상 실행 규칙을 따르면 서로 다른 환경의 기능을 연결하기 쉽다. | F15: ='AI#2(Gpt)'!F$70 -> ++ | G15: ='AI#2(Gpt)'!G$70 -> 정해진 확장 규칙을 통해 새로운 부가 기능을 연결하기 매우 쉽다.
A16: Human | B16: =Human!B$70 -> + | C16: =Human!C$70 -> 계층 사이의 연결 규칙이 명확하면 새로운 기능을 연결하기 쉽다. | D16: =Human!D$70 -> + | E16: =Human!E$70 -> 공통 가상 실행 규칙을 따르면 서로 다른 환경의 기능을 연결하기 쉽다. | F16: =Human!F$70 -> ++ | G16: =Human!G$70 -> 정해진 확장 규칙을 통해 새로운 부가 기능을 연결하기 매우 쉽다.
A18: Energy Efficiency | B18: ='Detailed Reasoning'!B$71 | C18: ='Detailed Reasoning'!C$71 | D18: ='Detailed Reasoning'!D$71 | E18: ='Detailed Reasoning'!E$71 | F18: ='Detailed Reasoning'!F$71 | G18: ='Detailed Reasoning'!G$71
A19: AI#1 | B19: ='AI#1 (Claude)'!B$71 -> - | C19: ='AI#1 (Claude)'!C71 -> 모든 요청이 여러 계층을 통과하며 계층마다 호출 오버헤드와 데이터 변환 비용을 더한다. | D19: ='AI#1 (Claude)'!D$71 -> -- | E19: ='AI#1 (Claude)'!E71 -> 해석 또는 에뮬레이션에 런타임 중복까지 더해져 네이티브 실행보다 CPU와 메모리를 훨씬 많이 쓴다. | F19: ='AI#1 (Claude)'!F$71 -> - | G19: ='AI#1 (Claude)'!G71 -> 커널과 모든 서비스 사이의 프로세스 간 메시지 전달이 상시 통신 오버헤드를 만든다.
A20: AI#2 | B20: ='AI#2(Gpt)'!B$71 -> 0 | C20: ='AI#2(Gpt)'!C$71 -> 계층 수와 호출 방식에 따라 추가 처리 비용이 달라진다. | D20: ='AI#2(Gpt)'!D$71 -> 0 | E20: ='AI#2(Gpt)'!E$71 -> 자원을 함께 쓰는 이점과 가상 실행 계층을 유지하는 비용이 함께 있다. | F20: ='AI#2(Gpt)'!F$71 -> - | G20: ='AI#2(Gpt)'!G$71 -> 기능 사이의 간접 호출과 통신에 추가 자원이 든다.
A21: Human | B21: =Human!B$71 -> 0 | C21: =Human!C$71 -> 계층 수와 호출 방식에 따라 추가 처리 비용이 달라진다. | D21: =Human!D$71 | E21: =Human!E$71 -> Human - Virtual Machine - Energy Efficiency | F21: =Human!F$71 -> - | G21: =Human!G$71 -> 기능 사이의 간접 호출과 통신에 추가 자원이 든다.
A23: Modifiability | B23: ='Detailed Reasoning'!B$72 | C23: ='Detailed Reasoning'!C$72 | D23: ='Detailed Reasoning'!D$72 | E23: ='Detailed Reasoning'!E$72 | F23: ='Detailed Reasoning'!F$72 | G23: ='Detailed Reasoning'!G$72
A24: AI#1 | B24: ='AI#1 (Claude)'!B$72 -> ++ | C24: ='AI#1 (Claude)'!C72 -> 인터페이스만 안정적이면 다른 계층에 영향을 주지 않고 한 계층을 재구현하거나 교체할 수 있다. | D24: ='AI#1 (Claude)'!D$72 -> + | E24: ='AI#1 (Claude)'!E72 -> 프로그램이 하위 플랫폼과 무관하게 발전할 수 있고, 반대로 플랫폼도 프로그램을 바꾸지 않고 교체할 수 있다. | F24: ='AI#1 (Claude)'!F$72 -> ++ | G24: ='AI#1 (Claude)'!G72 -> 최소한의 코어는 안정적으로 유지되고 서비스만 독립적으로 진화하므로 거의 모든 변경이 국소화된다.
A25: AI#2 | B25: ='AI#2(Gpt)'!B$72 -> + | C25: ='AI#2(Gpt)'!C$72 -> 계층별로 담당하는 기능이 나뉘어 특정 계층을 따로 수정하기 쉽다. | D25: ='AI#2(Gpt)'!D$72 -> + | E25: ='AI#2(Gpt)'!E$72 -> 프로그램과 실제 실행 환경을 분리해 한쪽 변경이 다른 쪽에 미치는 영향을 줄인다. | F25: ='AI#2(Gpt)'!F$72 -> ++ | G25: ='AI#2(Gpt)'!G$72 -> 핵심을 크게 바꾸지 않고 부가 기능을 추가하거나 교체하기 매우 쉽다.
A26: Human | B26: =Human!B$72 -> ++ | C26: =Human!C$72 -> 인터페이스만 안정적이면 다른 계층에 영향을 주지 않고 한 계층을 재구현하거나 교체할 수 있다. | D26: =Human!D$72 -> + | E26: =Human!E$72 -> 프로그램과 실제 실행 환경을 분리해 한쪽 변경이 다른 쪽에 미치는 영향을 줄인다. | F26: =Human!F$72 -> ++ | G26: =Human!G$72 -> 핵심을 크게 바꾸지 않고 부가 기능을 추가하거나 교체하기 매우 쉽다.
A28: Performance | B28: ='Detailed Reasoning'!B$73 | C28: ='Detailed Reasoning'!C$73 | D28: ='Detailed Reasoning'!D$73 | E28: ='Detailed Reasoning'!E$73 | F28: ='Detailed Reasoning'!F$73 | G28: ='Detailed Reasoning'!G$73
A29: AI#1 | B29: ='AI#1 (Claude)'!B$73 -> - | C29: ='AI#1 (Claude)'!C73 -> 계층 통과와 계층별 표현 간 반복 변환이 모든 연산에 지연을 더한다. | D29: ='AI#1 (Claude)'!D$73 -> -- | E29: ='AI#1 (Claude)'!E73 -> 모든 연산 위에 해석·변환 계층이 하나 더 얹히며, 이것이 이 스타일의 가장 큰 비용이다. | F29: ='AI#1 (Claude)'!F$73 -> - | G29: ='AI#1 (Claude)'!G73 -> 모든 서비스 상호작용이 직접 호출이 아니라 프로세스·메시지 경계를 넘어간다.
A30: AI#2 | B30: ='AI#2(Gpt)'!B$73 -> 0 | C30: ='AI#2(Gpt)'!C$73 -> 여러 계층을 거치는 비용은 있지만 실제 영향은 호출 방식에 따라 달라진다. | D30: ='AI#2(Gpt)'!D$73 -> - | E30: ='AI#2(Gpt)'!E$73 -> 실제 실행 사이에 변환이나 중간 처리가 추가되어 응답이 느려질 수 있다. | F30: ='AI#2(Gpt)'!F$73 -> - | G30: ='AI#2(Gpt)'!G$73 -> 기능이 커널이나 연결 경계를 거쳐 통신하므로 직접 호출보다 비용이 든다.
A31: Human | B31: =Human!B$73 -> - | C31: =Human!C$73 -> 계층 통과와 계층별 표현 간 반복 변환이 모든 연산에 지연을 더한다. | D31: =Human!D$73 | E31: =Human!E$73 -> Human - Virtual Machine - Performance | F31: =Human!F$73 -> - | G31: =Human!G$73 -> 기능이 커널이나 연결 경계를 거쳐 통신하므로 직접 호출보다 비용이 든다.
A33: Safety | B33: ='Detailed Reasoning'!B$74 | C33: ='Detailed Reasoning'!C$74 | D33: ='Detailed Reasoning'!D$74 | E33: ='Detailed Reasoning'!E$74 | F33: ='Detailed Reasoning'!F$74 | G33: ='Detailed Reasoning'!G$74
A34: AI#1 | B34: ='AI#1 (Claude)'!B$74 -> 0 | C34: ='AI#1 (Claude)'!C74 -> 계층 경계가 결함의 책임 범위를 분명히 해 원인 파악은 쉽지만, 결함 허용 메커니즘은 없고 하위 계층 장애가 상위로 그대로 전파된다. | D34: ='AI#1 (Claude)'!D$74 -> ++ | E34: ='AI#1 (Claude)'!E74 -> 강한 샌드박싱으로 결함이 VM 경계 안에 갇혀 호스트나 다른 게스트를 손상시키지 못한다. | F34: ='AI#1 (Claude)'!F$74 -> ++ | G34: ='AI#1 (Claude)'!G74 -> 커널과 서비스 간 결함 격리로 문제가 있는 서비스가 신뢰 코어를 오염시키지 못한다.
A35: AI#2 | B35: ='AI#2(Gpt)'!B$74 -> 0 | C35: ='AI#2(Gpt)'!C$74 -> 계층 구분만으로 오류 전파나 위험한 동작을 막는다고 보기는 어렵다. | D35: ='AI#2(Gpt)'!D$74 -> + | E35: ='AI#2(Gpt)'!E$74 -> 실행 경계에서 동작을 검사하고 잘못된 동작의 영향을 제한하기 좋다. | F35: ='AI#2(Gpt)'!F$74 -> + | G35: ='AI#2(Gpt)'!G$74 -> 중요한 핵심 기능을 작게 유지하고 부가 기능의 오류 영향을 제한하기 좋다.
A36: Human | B36: =Human!B$74 -> 0 | C36: =Human!C$74 -> 계층 구분만으로 오류 전파나 위험한 동작을 막는다고 보기는 어렵다. | D36: =Human!D$74 | E36: =Human!E$74 -> Human - Virtual Machine - Safety | F36: =Human!F$74 | G36: =Human!G$74 -> Human - Microkernel - Safety
A38: Security | B38: ='Detailed Reasoning'!B$75 | C38: ='Detailed Reasoning'!C$75 | D38: ='Detailed Reasoning'!D$75 | E38: ='Detailed Reasoning'!E$75 | F38: ='Detailed Reasoning'!F$75 | G38: ='Detailed Reasoning'!G$75
A39: AI#1 | B39: ='AI#1 (Claude)'!B$75 -> ++ | C39: ='AI#1 (Claude)'!C75 -> 계층이 자연스러운 다층 방어 경계가 되어 검증·인증·접근 제어를 단계적으로 강제할 수 있다. | D39: ='AI#1 (Claude)'!D$75 -> ++ | E39: ='AI#1 (Claude)'!E75 -> 격리 덕분에 침해된 게스트가 호스트 시스템에서 접근할 수 있는 범위가 엄격히 제한된다. | F39: ='AI#1 (Claude)'!F$75 -> ++ | G39: ='AI#1 (Claude)'!G75 -> 신뢰 컴퓨팅 기반(TCB)이 최소화되고 서비스가 최소 권한으로 동작해 공격 표면이 크게 줄어든다.
A40: AI#2 | B40: ='AI#2(Gpt)'!B$75 -> 0 | C40: ='AI#2(Gpt)'!C$75 -> 계층별 접근 통제를 둘 수 있지만 계층을 나눈 것만으로 보안이 높아지지는 않는다. | D40: ='AI#2(Gpt)'!D$75 -> + | E40: ='AI#2(Gpt)'!E$75 -> 가상 실행 경계를 통해 자원 접근을 제한하고 관리하기 좋다. | F40: ='AI#2(Gpt)'!F$75 -> + | G40: ='AI#2(Gpt)'!G$75 -> 핵심 기능과 부가 기능의 접근 경계를 나누어 권한을 관리하기 좋다.
A41: Human | B41: =Human!B$75 -> + | C41: =Human!C$75 -> 계층이 자연스러운 다층 방어 경계가 되어 검증·인증·접근 제어를 단계적으로 강제할 수 있다. | D41: =Human!D$75 | E41: =Human!E$75 -> Human - Virtual Machine - Security | F41: =Human!F$75 | G41: =Human!G$75 -> Human - Microkernel - Security
A43: Testability | B43: ='Detailed Reasoning'!B$76 | C43: ='Detailed Reasoning'!C$76 | D43: ='Detailed Reasoning'!D$76 | E43: ='Detailed Reasoning'!E$76 | F43: ='Detailed Reasoning'!F$76 | G43: ='Detailed Reasoning'!G$76
A44: AI#1 | B44: ='AI#1 (Claude)'!B$76 -> ++ | C44: ='AI#1 (Claude)'!C76 -> 하위 계층을 목(mock)으로 대체해 각 계층을 독립적으로 테스트할 수 있고, 계층 인터페이스가 좋은 테스트 이음새가 된다. | D44: ='AI#1 (Claude)'!D$76 -> ++ | E44: ='AI#1 (Claude)'!E76 -> 스냅샷이 가능한 완전 재현 환경이라 테스트가 결정적이고 초기화가 쉽다. | F44: ='AI#1 (Claude)'!F$76 -> ++ | G44: ='AI#1 (Claude)'!G76 -> 서비스가 작고, 좁고 안정적인 커널 인터페이스를 기준으로 독립 테스트가 가능하다.
A45: AI#2 | B45: ='AI#2(Gpt)'!B$76 -> + | C45: ='AI#2(Gpt)'!C$76 -> 계층 사이의 연결 규칙이 명확하면 각 계층을 따로 시험하기 쉽다. | D45: ='AI#2(Gpt)'!D$76 -> 0 | E45: ='AI#2(Gpt)'!E$76 -> 공통 실행 환경은 시험을 돕지만 동시 실행과 가상 계층의 영향도 확인해야 한다. | F45: ='AI#2(Gpt)'!F$76 -> 0 | G45: ='AI#2(Gpt)'!G$76 -> 부가 기능은 따로 시험하기 쉽지만 동시에 연결된 전체 동작은 복잡해진다.
A46: Human | B46: =Human!B$76 -> 0 | C46: =Human!C$76 -> 계층 사이의 연결 규칙이 명확하면 각 계층을 따로 시험하기 쉽다(단위 테스트). 다만 통합 테스트의 경우 어려움이 존재한다. | D46: =Human!D$76 | E46: =Human!E$76 -> Human - Virtual Machine - Testability | F46: =Human!F$76 | G46: =Human!G$76 -> Human - Microkernel - Testability
A48: Usability | B48: ='Detailed Reasoning'!B$77 | C48: ='Detailed Reasoning'!C$77 | D48: ='Detailed Reasoning'!D$77 | E48: ='Detailed Reasoning'!E$77 | F48: ='Detailed Reasoning'!F$77 | G48: ='Detailed Reasoning'!G$77
A49: AI#1 | B49: ='AI#1 (Claude)'!B$77 -> 0 | C49: ='AI#1 (Claude)'!C77 -> 사용자에게 직접적인 영향은 없으나, 일관된 계층 구조가 인터페이스 전반의 균일한 동작을 뒷받침한다. | D49: ='AI#1 (Claude)'!D$77 -> 0 | E49: ='AI#1 (Claude)'!E77 -> 최종 사용자에게는 투명하지만, 동일 애플리케이션을 여러 플랫폼에 배포하기가 훨씬 쉬워진다. | F49: ='AI#1 (Claude)'!F$77 -> + | G49: ='AI#1 (Claude)'!G77 -> 사용자와 통합 개발자가 재빌드 없이 플러그인으로 시스템을 확장하거나 맞춤화할 수 있다.
...

Sheet DA1
A1: Distributed | B1: Multi-Tier | D1: Client-Server
B2: Effects | C2: Justification | D2: Effects | E2: Justification
A3: Availability | B3: 0 | C3: 0 | D3: 0 | E3: 0
A4: AI#1 | B4: 0 | C4: ='AI#1 (Claude)'!C81 -> 각 티어를 독립적으로 복제하고 로드밸런싱할 수 있다. 다만 체인 중 한 티어라도 죽으면 요청은 실패한다. | D4: 0 | E4: ='AI#1 (Claude)'!E81 -> 서버를 로드밸런서 뒤에 복제해 가용성을 높일 수 있지만, 기본 형태에서는 서버 한 대의 장애가 모든 클라이언트를 동시에 마비시킨다.
A5: AI#2 | B5: 0 | C5: ='AI#2(Gpt)'!C81 -> 역할별 장애를 나누기 좋지만 공통 데이터 계층이 멈추면 여러 기능이 영향을 받는다. | D5: 0 | E5: ='AI#2(Gpt)'!E81 -> Client의 장애는 분리하기 좋지만 공통 Server가 멈추면 여러 사용자가 영향을 받는다.
A6: Human | B6: 0 | C6: =Human!C81 -> 역할별 장애를 나누기 좋지만 공통 데이터 계층이 멈추면 여러 기능이 영향을 받는다. | D6: 0 | E6: =Human!E81 -> Client의 장애는 분리하기 좋지만 공통 Server가 멈추면 여러 사용자가 영향을 받는다.
A8: Deployability | B8: 0 | C8: 0 | D8: 0 | E8: 0
A9: AI#1 | B9: 0 | C9: ='AI#1 (Claude)'!C82 -> 티어별로 별도 인프라에서 독립적으로 배포·확장·업그레이드할 수 있다. | D9: 0 | E9: ='AI#1 (Claude)'!E82 -> 서버 측 변경은 한 번 배포하면 모든 클라이언트에 즉시 반영된다. 별도 배포가 필요한 것은 진짜 클라이언트 측 변경뿐이다.
A10: AI#2 | B10: 0 | C10: ='AI#2(Gpt)'!C82 -> 역할별 실행 단위가 나뉘어 필요한 Tier를 따로 교체·배포하기 좋다. | D10: 0 | E10: ='AI#2(Gpt)'!E82 -> 연결 규칙을 유지하면 Client와 Server를 각각 교체·배포하기 좋다.
A11: Human | B11: 0 | C11: =Human!C82 -> 티어별로 별도 인프라에서 독립적으로 배포·확장·업그레이드할 수 있다. | D11: 0 | E11: =Human!E82 -> 서버 측 변경은 한 번 배포하면 모든 클라이언트에 즉시 반영된다. 별도 배포가 필요한 것은 진짜 클라이언트 측 변경뿐이다.
A13: Integrability | B13: 0 | C13: 0 | D13: 0 | E13: 0
A14: AI#1 | B14: 0 | C14: ='AI#1 (Claude)'!C83 -> 티어 경계가 명확해 통합 지점이 잘 정의된다. 반면 여러 티어를 가로지르는 통합은 인프로세스보다 손이 많이 간다. | D14: 0 | E14: ='AI#1 (Claude)'!E83 -> 공개된 서버 API가 잘 문서화된 자연스러운 통합 지점이 되어 다양한 종류의 클라이언트가 붙을 수 있다.
A15: AI#2 | B15: 0 | C15: ='AI#2(Gpt)'!C83 -> Tier 사이의 연결 규칙이 정해져 있어 새로운 기능을 연결하기 좋다. | D15: 0 | E15: ='AI#2(Gpt)'!E83 -> Server의 공개된 연결 규칙을 따르면 새로운 Client를 연결하기 쉽다.
A16: Human | B16: 0 | C16: =Human!C83 -> Tier 사이의 연결 규칙이 정해져 있어 새로운 기능을 연결하기 좋다. | D16: 0 | E16: =Human!E83 -> 공개된 서버 API가 잘 문서화된 자연스러운 통합 지점이 되어 다양한 종류의 클라이언트가 붙을 수 있다.
A18: Energy Efficiency | B18: 0 | C18: 0 | D18: 0 | E18: 0
A19: AI#1 | B19: 0 | C19: ='AI#1 (Claude)'!C84 -> 모든 요청이 티어 사이의 네트워크 경계를 넘으면서 직렬화와 전송 비용을 더한다. | D19: 0 | E19: ='AI#1 (Claude)'!E84 -> 무거운 연산을 효율적인 공용 서버에 집중시키고 씬 클라이언트는 전력을 거의 쓰지 않는다. 다만 상시 네트워크 통신 자체가 에너지를 소모한다.
A20: AI#2 | B20: 0 | C20: ='AI#2(Gpt)'!C84 -> 여러 Tier를 운영하고 서로 통신하는 데 추가 자원이 든다. | D20: 0 | E20: ='AI#2(Gpt)'!E84 -> Client와 Server를 따로 실행하고 통신하는 데 추가 자원이 든다.
A21: Human | B21: 0 | C21: =Human!C84 -> 여러 Tier를 운영하고 서로 통신하는 데 추가 자원이 든다. | D21: 0 | E21: =Human!E84 -> 무거운 연산을 효율적인 공용 서버에 집중시키고 씬 클라이언트는 전력을 거의 쓰지 않는다. 다만 상시 네트워크 통신 자체가 에너지를 소모한다.
A23: Modifiability | B23: 0 | C23: 0 | D23: 0 | E23: 0
