Workbook

Sheet QA 설명
A1: Quality Attribute | B1: 정의
A2: Availability (가용성) | B2: 임무(mission)가 요구되는 어느 시점에서든, 임무 시작 시 시스템이 정해진 동작 가능 상태에 있는 정도
A3: Modifiability (변경 용이성) | B3: 시스템에 변경을 얼마나 쉽게 가할 수 있는가의 정도
A4: Performance (성능) | B4: 이벤트가 발생했을 때 시스템이 특정 동작을 수행하는 데 걸리는 시간
A5: Security (보안) | B5: 악의적인 행위의 가능성과 정보의 도난·유실 가능성을 줄이는 시스템의 능력
A6: Testability (시험 용이성) | B6: 테스트를 통해 소프트웨어의 결함을 얼마나 쉽게 드러낼 수 있는가
A7: Usability (사용성) | B7: 사용자가 원하는 작업을 얼마나 쉽게 완수할 수 있는가
A8: Safety (안전성) | B8: 시스템이 사람·재산·환경에 피해를 주는 위험 상태(hazard)에 빠지지 않도록 하고, 빠졌을 때 피해를 억제·복구하는 능력
A9: Deployability (배포 용이성) | B9: 실행 가능한 소프트웨어를 예측 가능한 시간과 노력으로 운영 환경에 배치(또는 rollback)할 수 있는 정도
A10: Energy Efficiency (에너지 효율성) | B10: 요구된 기능을 수행하면서 에너지·계산 자원(CPU, memory, network)의 소비를 최소화하는 능력 — Resource Utilization
A11: Integrability (통합 용이성) | B11: 별도로 개발된 컴포넌트를 결합하는 데 드는 비용과 위험의 정도. 외부 시스템과 정보를 교환·활용하는 능력(Interoperability)을 포함

Sheet DF
B1: Batch Sequential | D1: Pipe and Filter | F1: Process Control
B2: Effects | C2: Justification | D2: Effects | E2: Justification | F2: Effects | G2: Justification
A3: Availability | B3: ='Detailed Reasoning'!B$3 | C3: ='Detailed Reasoning'!C$3 | D3: ='Detailed Reasoning'!D$3 | E3: ='Detailed Reasoning'!E$3 | F3: ='Detailed Reasoning'!F$3 | G3: ='Detailed Reasoning'!G$3
A4: AI#1 | B4: ='AI#1_GPT'!B$3 -> - | C4: ='AI#1_GPT'!C3 -> 한 단계가 실패하면 뒤 단계가 모두 대기하고, 긴 배치를 처음 또는 체크포인트부터 재처리해야 할 수 있다. | D4: ='AI#1_GPT'!D$3 -> 0 | E4: ='AI#1_GPT'!E3 -> 필터를 독립적으로 재시작할 수 있지만 한 필터가 중단되면 전체 파이프라인 흐름도 멈출 수 있다. | F4: ='AI#1_GPT'!F$3 -> + | G4: ='AI#1_GPT'!G3 -> 피드백 루프가 상태 변화를 감지해 보정할 수 있어 일부 환경 변화나 구성요소 편차에 대응하기 쉽다.
A5: AI#2 | B5: ='AI#2_Gemini'!B$3 -> 0 | C5: ='AI#2_Gemini'!C$3 -> 한 단계가 실패하면 전체 배치가 중단될 수 있으나, 실패 지점부터 재시작이 가능하므로 중립적임. | D5: ='AI#2_Gemini'!D$3 -> 0 | E5: ='AI#2_Gemini'!E$3 -> 필터 하나가 고장나면 파이프라인이 멈추지만, 상태를 유지하지 않아 재시작 및 복구가 비교적 단순함. | F5: ='AI#2_Gemini'!F$3 -> + | G5: ='AI#2_Gemini'!G$3 -> 시스템의 상태를 지속적으로 모니터링하고 목표 상태로 복구하려는 제어 루프 특성상 가용성 확보에 유리함.
A6: Human | B6: =Human!B3 -> - | C6: =Human!C3 -> 한 단계가 실패하면 중간부터 재시작 가능하다고 하더라도 뒤 단계가 모두 대기하거나 재시작 해야 하는 것이 치명적 | D6: =Human!D$3 -> - | E6: =Human!E$3 -> Filter별 독립적 행동이 보장되므로 문제가 발생하더라고, 전체 system에 영향이 있음. Pipe에 고장이 나면 뒤에 연결된 Filter도 사용할 수 없게 되므로 좋진 않음 | F6: =Human!F$3 -> + | G6: =Human!G$3 -> process unit or control unit 고장시, 오작동하여 시스템 전체에 문제가 발생할 수 있음
A8: Deployability | B8: ='Detailed Reasoning'!B$4 | C8: ='Detailed Reasoning'!C$4 | D8: ='Detailed Reasoning'!D$4 | E8: ='Detailed Reasoning'!E$4 | F8: ='Detailed Reasoning'!F$4 | G8: ='Detailed Reasoning'!G$4
A9: AI#1 | B9: ='AI#1_GPT'!B$4 -> 0 | C9: ='AI#1_GPT'!C4 -> 구조는 단순하지만 단계 간 데이터 형식과 실행 순서 의존성이 있어 배포 측면의 뚜렷한 이점은 제한적이다. | D9: ='AI#1_GPT'!D$4 -> + | E9: ='AI#1_GPT'!E4 -> 인터페이스가 안정적이면 필터를 독립적으로 교체·배포하기 쉬운 편이다. | F9: ='AI#1_GPT'!F$4 -> - | G9: ='AI#1_GPT'!G4 -> 제어기·센서·액추에이터가 함께 튜닝되어야 하므로 개별 구성요소를 독립 배포하기 어렵다.
A10: AI#2 | B10: ='AI#2_Gemini'!B$4 -> + | C10: ='AI#2_Gemini'!C$4 -> 각 배치 단계가 독립적인 실행 파일(프로그램)로 구성되어 개별 배포가 용이함. | D10: ='AI#2_Gemini'!D$4 -> + | E10: ='AI#2_Gemini'!E$4 -> 각 필터가 독립적인 컴포넌트이며 표준 I/O로 통신하므로 개별 배포 및 교체가 쉬움. | F10: ='AI#2_Gemini'!F$4 -> - | G10: ='AI#2_Gemini'!G$4 -> 하드웨어 센서 및 액추에이터와 강하게 결합되어 있어 소프트웨어 단독 배포나 환경 변경이 까다로움.
A11: Human | B11: =Human!B4 -> + | C11: =Human!C4 -> 구조가 단순한 것이 가장 큰 이점, 배포 시 개발자들에게 porting 등의 O/H가 적을 것으로 예상. | D11: =Human!D$4 -> + | E11: =Human!E$4 -> 필터는 서로 독립적인 개체이므로 개별 구성요소 별로 배포하기 쉬운 편이다. | F11: =Human!F$4 -> - | G11: =Human!G$4 -> 개별 구성요소를 독립 배포하기 어렵다.
A13: Integrability | B13: ='Detailed Reasoning'!B$5 | C13: ='Detailed Reasoning'!C$5 | D13: ='Detailed Reasoning'!D$5 | E13: ='Detailed Reasoning'!E$5 | F13: ='Detailed Reasoning'!F$5 | G13: ='Detailed Reasoning'!G$5
A14: AI#1 | B14: ='AI#1_GPT'!B$5 -> 0 | C14: ='AI#1_GPT'!C5 -> 파일·레코드 같은 단순한 교환 방식은 연결이 쉽지만, 단계들이 동일 데이터 형식에 의존하기 쉽다. | D14: ='AI#1_GPT'!D$5 -> ++ | E14: ='AI#1_GPT'!E5 -> 필터가 표준화된 입력·출력 스트림으로 연결되어 새로운 처리 단계를 조합하기 쉽다. | F14: ='AI#1_GPT'!F$5 -> - | G14: ='AI#1_GPT'!G5 -> 실시간 센서/액추에이터 프로토콜과 제어 주기 제약 때문에 일반 시스템과의 통합 비용이 커질 수 있다.
A15: AI#2 | B15: ='AI#2_Gemini'!B$5 -> + | C15: ='AI#2_Gemini'!C$5 -> 공통 데이터 포맷(주로 파일)만 맞추면 새로운 배치 단계를 시퀀스의 앞뒤에 쉽게 추가할 수 있음. | D15: ='AI#2_Gemini'!D$5 -> ++ | E15: ='AI#2_Gemini'!E$5 -> 파이프라는 표준화된 인터페이스를 사용하므로, 새로운 필터를 기존 파이프라인에 조립하고 연결하기 매우 쉬움. | F15: ='AI#2_Gemini'!F$5 -> - | G15: ='AI#2_Gemini'!G$5 -> 물리적 센서의 종류나 데이터 형태가 다양하고 실시간 제약이 있어 새로운 하드웨어/모듈 통합이 어려움.
A16: Human | B16: =Human!B$5 -> + | C16: =Human!C$5 -> 공통 데이터 포맷(주로 파일)만 맞추면 새로운 배치 단계를 시퀀스의 앞뒤에 쉽게 추가할 수 있음. | D16: =Human!D$5 -> ++ | E16: =Human!E$5 -> 표준화된 connector를 사용해서, 새로운 필터를 연결하기 매우 쉽다. | F16: =Human!F$5 -> - | G16: =Human!G$5 -> componenet에 따라 인터페이스가 달라(특정 환경에 맞춰져 있어서) 통합이 어렵다.
A18: Energy Efficiency | B18: ='Detailed Reasoning'!B$6 | C18: ='Detailed Reasoning'!C$6 | D18: ='Detailed Reasoning'!D$6 | E18: ='Detailed Reasoning'!E$6 | F18: ='Detailed Reasoning'!F$6 | G18: ='Detailed Reasoning'!G$6
A19: AI#1 | B19: ='AI#1_GPT'!B$6 -> ++ | C19: ='AI#1_GPT'!C6 -> 요청을 모아 일괄 처리하므로 초기화·통신 오버헤드를 여러 작업에 분산시킬 수 있다. | D19: ='AI#1_GPT'!D$6 -> 0 | E19: ='AI#1_GPT'!E6 -> 스트리밍은 불필요한 전체 적재를 줄이지만 필터 간 전달·직렬화 오버헤드도 발생한다. | F19: ='AI#1_GPT'!F$6 -> 0 | G19: ='AI#1_GPT'!G6 -> 지속 측정·제어는 자원을 쓰지만 제어 자체가 물리 시스템의 낭비를 줄일 수도 있어 영향이 상쇄된다.
A20: AI#2 | B20: ='AI#2_Gemini'!B$6 -> 0 | C20: ='AI#2_Gemini'!C$6 -> 아키텍처 자체보다는 처리할 데이터의 양과 배치 주기(스케줄링)에 따라 달라지므로 직접적 영향 없음. | D20: ='AI#2_Gemini'!D$6 -> 0 | E20: ='AI#2_Gemini'!E$6 -> 데이터 스트리밍 처리 방식 자체는 에너지 효율과 직접적인 연관성이 적음. | F20: ='AI#2_Gemini'!F$6 -> + | G20: ='AI#2_Gemini'!G$6 -> 목표 상태를 유지하기 위해 필요한 시점에만 액추에이터를 가동하도록 최적화하여 자원 및 에너지를 효율적으로 씀.
A21: Human | B21: =Human!B$6 -> 0 | C21: =Human!C$6 -> 1. 에너지, 혹은 처리량 총량의 차이가 있지, 총량 / Energy 값인 효율적 측면은 영향이 없다 | D21: =Human!D$6 -> 0 | E21: =Human!E$6 -> 데이터 처리 자체는 에너지 효율과 직접적인 연관성이 적다. | F21: =Human!F$6 -> + | G21: =Human!G$6 -> 필요한 시점에만 동작하므로 자원을 효율적으로 쓸 수 있다.
A23: Modifiability | B23: ='Detailed Reasoning'!B$7 | C23: ='Detailed Reasoning'!C$7 | D23: ='Detailed Reasoning'!D$7 | E23: ='Detailed Reasoning'!E$7 | F23: ='Detailed Reasoning'!F$7 | G23: ='Detailed Reasoning'!G$7
A24: AI#1 | B24: ='AI#1_GPT'!B$7 -> 0 | C24: ='AI#1_GPT'!C7 -> 단계 자체는 분리할 수 있으나 중간 데이터 형식이나 순서 변경이 후속 단계에 연쇄 영향을 줄 수 있다. | D24: ='AI#1_GPT'!D$7 -> ++ | E24: ='AI#1_GPT'!E7 -> 처리 기능이 독립 필터로 분리되어 특정 변환을 추가·삭제·교체하기 쉽다. | F24: ='AI#1_GPT'!F$7 -> - | G24: ='AI#1_GPT'!G7 -> 제어 로직 변경 시 안정성·응답 특성을 다시 튜닝하고 전체 루프를 재검증해야 할 가능성이 높다.
A25: AI#2 | B25: ='AI#2_Gemini'!B$7 -> + | C25: ='AI#2_Gemini'!C$7 -> 각 단계가 독립적이므로, 특정 단계의 로직을 수정해도 입출력 포맷만 같으면 다른 단계에 영향을 주지 않음. | D25: ='AI#2_Gemini'!D$7 -> ++ | E25: ='AI#2_Gemini'!E$7 -> 필터 간 결합도가 매우 낮아 특정 필터의 내부 로직 변경, 삭제, 순서 변경이 시스템 전체에 영향을 주지 않음. | F25: ='AI#2_Gemini'!F$7 -> - | G25: ='AI#2_Gemini'!G$7 -> 제어 변수나 알고리즘을 변경할 경우 제어 루프 전체의 타이밍과 물리적 피드백 시스템을 재설계해야 하므로 어려움.
A26: Human | B26: =Human!B$7 -> ++ | C26: =Human!C$7 -> 각 단계가 독립적으로, processing step간 대체가 용이하고 reusing이 가능한 것이 장점 | D26: =Human!D$7 -> ++ | E26: =Human!E$7 -> 필터는 서로 독립적인 개체이므로 개별 구성요소 별로 추가,삭체, 교체하기 쉬운 편이다. | F26: =Human!F$7 -> - | G26: =Human!G$7 -> Component가 변경 되면 시스템 전체에 영향을 주게 된다.
A28: Performance | B28: ='Detailed Reasoning'!B$8 | C28: ='Detailed Reasoning'!C$8 | D28: ='Detailed Reasoning'!D$8 | E28: ='Detailed Reasoning'!E$8 | F28: ='Detailed Reasoning'!F$8 | G28: ='Detailed Reasoning'!G$8
A29: AI#1 | B29: ='AI#1_GPT'!B$8 -> - | C29: ='AI#1_GPT'!C8 -> 단계가 순차적으로 실행되고 중간 결과 I/O가 발생해 병렬·스트리밍 처리보다 지연이 커지기 쉽다. | D29: ='AI#1_GPT'!D$8 -> + | E29: ='AI#1_GPT'!E8 -> 필터들을 파이프라인으로 병렬 실행할 수 있어 처리량을 높일 수 있으나 전달 오버헤드는 존재한다. | F29: ='AI#1_GPT'!F$8 -> ++ | G29: ='AI#1_GPT'!G8 -> 짧은 제어 주기와 즉각적인 피드백을 목표로 하므로 실시간 응답 성능에 매우 유리하다.
A30: AI#2 | B30: ='AI#2_Gemini'!B$8 -> -- | C30: ='AI#2_Gemini'!C$8 -> 한 단계가 완전히 끝나야 다음 단계가 시작(지연 시간 김)되며, 대규모 파일 I/O가 발생하여 병렬 처리가 불가함. | D30: ='AI#2_Gemini'!D$8 -> + | E30: ='AI#2_Gemini'!E$8 -> 여러 필터가 파이프를 통해 데이터를 주고받으며 동시에(병렬로) 실행될 수 있어 전체적인 Throughput(처리량)이 높음. | F30: ='AI#2_Gemini'!F$8 -> 0 | G30: ='AI#2_Gemini'!G$8 -> 실시간 처리에는 적합하나, 대규모 데이터 처리나 연산 성능 관점보다는 '정시성(Deadline)'에 초점이 맞춰져 있음.
A31: Human | B31: =Human!B$8 -> - | C31: =Human!C$8 -> 모든 단계가 sequential하게 되어 있으므로 단계마다 전체 데이터를 기다려야 하므로 latency가 좋지 않음 -> latency측면 영향성이 낮음 | D31: =Human!D$8 -> + | E31: =Human!E$8 -> Filter의 수가 많아질수록 Computational O/H가 증가하나, 병렬성이 존재하므로 장점이 더 큼 | F31: =Human!F$8 -> ++ | G31: =Human!G$8 -> 짧은 제어 주기와 즉각적인 피드백을 목표로 하므로 실시간 응답 성능에 매우 유리하다.
A33: Safety | B33: ='Detailed Reasoning'!B$9 | C33: ='Detailed Reasoning'!C$9 | D33: ='Detailed Reasoning'!D$9 | E33: ='Detailed Reasoning'!E$9 | F33: ='Detailed Reasoning'!F$9 | G33: ='Detailed Reasoning'!G$9
A34: AI#1 | B34: ='AI#1_GPT'!B$9 -> + | C34: ='AI#1_GPT'!C9 -> 처리 순서와 상태 전이가 비교적 결정적이어서 검증·감사 및 오류 지점 추적이 쉽다. | D34: ='AI#1_GPT'!D$9 -> + | E34: ='AI#1_GPT'!E9 -> 변환 책임과 데이터 흐름이 명확해 잘못된 처리 단계의 범위를 제한하고 검증하기 쉽다. | F34: ='AI#1_GPT'!F$9 -> ++ | G34: ='AI#1_GPT'!G9 -> 피드백, 제한값, 인터록을 통해 위험 상태를 감지하고 즉시 보정·차단하도록 설계하기 좋다.
A35: AI#2 | B35: ='AI#2_Gemini'!B$9 -> 0 | C35: 실시간으로 발생하는 물리적/환경적 위험 상태를 즉각적으로 감지하고 피해를 억제하거나 개입할 수 있는 메커니즘이 아키텍처 상에 존재하지 않습니다. | D35: ='AI#2_Gemini'!D$9 -> 0 | E35: 특정 필터에서 오류 데이터를 걸러낼 수는 있습니다. 하지만 시스템 외부 환경의 위험 상태를 인지하고 실시간으로 기계나 환경을 통제(피해 억제 및 복구)하는 제어 루프를 내재하고 있지 않습니다. | F35: ='AI#2_Gemini'!F$9 -> ++ | G35: 센서를 통해 외부 물리/환경 상태를 실시간으로 모니터링하고, 위험 임계치에 도달할 경우 즉시 액추에이터에 피드백 제어를 가하여 안전 상태로 강제 복구 및 피해를 억제하는 데 본질적으로 특화된 아키텍처입니다.
A36: Human | B36: =Human!B$9 -> 0 | C36: =Human!C$9 -> 직렬로 이루어져 있으므로 단일 장애가 전체 안전에 영향이 큰 점도 있으나, 오류 분석이 쉬운 장점도 있음 | D36: =Human!D$9 -> 0 | E36: =Human!E$9 -> 단계별 검증과 오류 격리를 통해 안전성에 간접적으로 기여할 수 있지만, 물리적 위험을 직접 감지·제어하는 아키텍처는 아니므로 Safety에 대한 직접적인 영향은 제한적이다. | F36: =Human!F$9 -> ++ | G36: =Human!G$9 -> 짧은 제어 주기와 즉각적인 피드백을 목표로 하므로 실시간 응답 성능에 매우 유리하다.
A38: Security | B38: ='Detailed Reasoning'!B$10 | C38: ='Detailed Reasoning'!C$10 | D38: ='Detailed Reasoning'!D$10 | E38: ='Detailed Reasoning'!E$10 | F38: ='Detailed Reasoning'!F$10 | G38: ='Detailed Reasoning'!G$10
A39: AI#1 | B39: ='AI#1_GPT'!B$10 -> 0 | C39: ='AI#1_GPT'!C10 -> 구조 자체의 보안 이점은 크지 않으며, 중간 파일을 사용하면 별도의 접근통제가 필요하다. | D39: ='AI#1_GPT'!D$10 -> 0 | E39: ='AI#1_GPT'!E10 -> 필터 경계에 통제를 넣을 수 있지만 연결 지점이 늘어나므로 구조만으로 보안이 향상되지는 않는다. | F39: ='AI#1_GPT'!F$10 -> - | G39: ='AI#1_GPT'!G10 -> 센서와 액추에이터 접점이 공격받으면 실제 제어 결과에 직접 영향을 주므로 공격면이 중요해진다.
A40: AI#2 | B40: ='AI#2_Gemini'!B$10 -> 0 | C40: ='AI#2_Gemini'!C$10 -> 시스템 외부와의 연결보다는 내부 파일 시스템 권한에 의존하므로 아키텍처 차원의 보안 이점은 없음. | D40: ='AI#2_Gemini'!D$10 -> 0 | E40: ='AI#2_Gemini'!E$10 -> 필터 간 통신 암호화 등이 추가로 필요하며, 스타일 자체에서 보안 기능을 내재하고 있지 않음. | F40: ='AI#2_Gemini'!F$10 -> 0 | G40: ='AI#2_Gemini'!G$10 -> 시스템 내부의 제어 루프 자체는 보안을 고려하지 않으며, 외부 네트워크 연결 시 별도의 보안 아키텍처가 필요함.
A41: Human | B41: =Human!B$10 -> - | C41: =Human!C$10 -> 병렬로 동작하는 시스템 대비 중간 파일 등이 공격받기 쉬운 구조이기 때문에 영향성이 큼 | D41: =Human!D$10 -> 0 | E41: =Human!E$10 -> 필터별 보안 검증을 분리해 적용할 수 있다는 장점은 있지만, 다수의 데이터 전달 경로가 추가적인 공격면이 될 수 있음 | F41: =Human!F$10 -> - | G41: =Human!G$10 -> 공격받으면 전체적인 제어에 직접 영향을 준다.
A43: Testability | B43: ='Detailed Reasoning'!B$11 | C43: ='Detailed Reasoning'!C$11 | D43: ='Detailed Reasoning'!D$11 | E43: ='Detailed Reasoning'!E$11 | F43: ='Detailed Reasoning'!F$11 | G43: ='Detailed Reasoning'!G$11
A44: AI#1 | B44: ='AI#1_GPT'!B$11 -> + | C44: ='AI#1_GPT'!C11 -> 각 단계에 고정 입력을 주고 결과를 비교하기 쉬워 재현 가능한 테스트에 유리하다. | D44: ='AI#1_GPT'!D$11 -> ++ | E44: ='AI#1_GPT'!E11 -> 각 필터를 독립 입력·출력으로 단위 테스트하고 전체 파이프라인도 단계별 검증하기 쉽다. | F44: ='AI#1_GPT'!F$11 -> - | G44: ='AI#1_GPT'!G11 -> 실시간 타이밍과 물리 환경을 함께 재현해야 해서 시뮬레이터·HIL 없이 테스트하기 어렵다.
A45: AI#2 | B45: ='AI#2_Gemini'!B$11 -> ++ | C45: ='AI#2_Gemini'!C$11 -> 각 배치 프로그램이 완전히 독립적이며, 테스트용 입력 파일을 주고 출력 파일을 검증하는 방식(블랙박스 테스트)이 매우 직관적임. | D45: ='AI#2_Gemini'!D$11 -> + | E45: ='AI#2_Gemini'!E$11 -> 개별 필터에 더미 데이터를 파이프 스트림으로 주입하여 독립적으로 테스트하기 용이함. | F45: ='AI#2_Gemini'!F$11 -> - | G45: ='AI#2_Gemini'!G$11 -> 물리적 환경(센서, 액추에이터)과 결합되어 있어, 이를 흉내 내는 복잡한 시뮬레이터(HIL 테스트 등)가 반드시 필요함.
A46: Human | B46: =Human!B$11 -> ++ | C46: =Human!C$11 -> 각 컴포넌트의 역할이 매우 잘 정의되어 있으므로 Test하기에도 용이, 통합 test측면에서도 좋음 | D46: =Human!D$11 -> 0 | E46: =Human!E$11 -> 각 필터별 독립 테스트 용이, batch sequence보다는 떨어짐, 0이나 -까지도 | F46: =Human!F$11 -> + | G46: =Human!G$11 -> 물리적인 테스트 환경이 필요하여 테스트하기 어렵다. 변경점 발생에 따른 결과가 바로보이기 때문에 통합 test는 용이함
A48: Usability | B48: ='Detailed Reasoning'!B$12 | C48: ='Detailed Reasoning'!C$12 | D48: ='Detailed Reasoning'!D$12 | E48: ='Detailed Reasoning'!E$12 | F48: ='Detailed Reasoning'!F$12 | G48: ='Detailed Reasoning'!G$12
A49: AI#1 | B49: ='AI#1_GPT'!B$12 -> - | C49: ='AI#1_GPT'!C12 -> 처리가 완료될 때까지 결과 피드백이 늦어 대화형·즉시 반응이 필요한 사용자 경험에는 불리하다. | D49: ='AI#1_GPT'!D$12 -> 0 | E49: ='AI#1_GPT'!E12 -> 주로 내부 데이터 처리 구조이므로 최종 사용자 인터랙션에 미치는 직접 영향은 제한적이다. | F49: ='AI#1_GPT'!F$12 -> + | G49: ='AI#1_GPT'!G12 -> 자동 제어가 정상 범위를 유지해 운영자의 지속적인 수동 개입을 줄일 수 있다.
...

Sheet DC
A1: Data Centered | B1: Shared Repository | D1: Blackboard
B2: Effects | C2: Justification | D2: Effects | E2: Justification
A3: Availability | B3: ='Detailed Reasoning'!B16 | C3: ='Detailed Reasoning'!C16 | D3: ='Detailed Reasoning'!D16 | E3: ='Detailed Reasoning'!E16
A4: AI#1 | B4: ='AI#1_GPT'!B$16 -> -- | C4: ='AI#1_GPT'!C16 -> 공유 저장소가 장애 나면 여러 구성요소가 동시에 영향을 받는 단일 장애점이 되기 쉽다. | D4: ='AI#1_GPT'!D$16 -> - | E4: ='AI#1_GPT'!E16 -> 중앙 블랙보드가 중단되면 지식 소스 간 협업 자체가 멈추기 쉬워 핵심 장애점이 된다.
A5: AI#2 | B5: ='AI#2_Gemini'!B$16 -> - | C5: ='AI#2_Gemini'!C$16 -> 중앙 저장소(DB 등)가 단일 장애점(SPOF)이 되므로, 저장소가 다운되면 시스템 전체가 마비됨. | D5: ='AI#2_Gemini'!D$16 -> - | E5: ='AI#2_Gemini'!E$16 -> 중앙 블랙보드(메모리/저장소)와 제어 컴포넌트가 다운되면 모든 Knowledge Source(KS)가 동작을 멈춤.
A6: Human | B6: =Human!B$16 -> -- | C6: =Human!C$16 -> 공유 저장소 장애 시 의존하는 모든 Client에 영향 | D6: 0 | E6: 중앙 블랙보드와 컨트롤러가 다운되면 모든 KS가 동작을 멈추지만, KS의 다운은 전체 시스템에 영향을 미치지 않는다.
A8: Deployability | B8: ='Detailed Reasoning'!B17 | C8: ='Detailed Reasoning'!C17 | D8: ='Detailed Reasoning'!D17 | E8: ='Detailed Reasoning'!E17
A9: AI#1 | B9: ='AI#1_GPT'!B$17 -> - | C9: ='AI#1_GPT'!C17 -> 여러 구성요소가 공통 스키마와 저장소 버전에 의존해 독립 배포가 제한될 수 있다. | D9: ='AI#1_GPT'!D$17 -> 0 | E9: ='AI#1_GPT'!E17 -> 지식 소스는 추가하기 쉽지만 공통 블랙보드 표현과 제어 규칙에 대한 호환성이 필요하다.
A10: AI#2 | B10: ='AI#2_Gemini'!B$17 -> 0 | C10: ='AI#2_Gemini'!C$17 -> 데이터베이스와 클라이언트를 분리해서 배포할 수 있으나, 스키마 변경 시 동시 배포가 필요할 수 있음. | D10: ='AI#2_Gemini'!D$17 -> 0 | E10: ='AI#2_Gemini'!E$17 -> KS들은 독립적 배포가 가능하나, 중앙 제어기와 데이터 구조가 맞물려 있어 제한적임.
A11: Human | B11: =Human!B$17 -> - | C11: =Human!C$17 -> 스키마 변경 시 관련 Client의 배포 조율 필요 | D11: 0 | E11: KS는 쉽게 변경 가능하나, 중앙 블랙보드와 컨트롤러는 모든 KS와 맞물려있어 제한적이다.
A13: Integrability | B13: ='Detailed Reasoning'!B18 | C13: ='Detailed Reasoning'!C18 | D13: ='Detailed Reasoning'!D18 | E13: ='Detailed Reasoning'!E18
A14: AI#1 | B14: ='AI#1_GPT'!B$18 -> ++ | C14: ='AI#1_GPT'!C18 -> 모든 구성요소가 공통 데이터 저장소와 모델을 사용하므로 데이터 공유와 연계가 매우 쉽다. | D14: ='AI#1_GPT'!D$18 -> + | E14: ='AI#1_GPT'!E18 -> 서로 다른 알고리즘·전문 모듈이 공통 블랙보드에 결과를 기록하는 방식으로 협업할 수 있다.
A15: AI#2 | B15: ='AI#2_Gemini'!B$18 -> + | C15: ='AI#2_Gemini'!C$18 -> 클라이언트 시스템 간에 직접적인 인터페이스를 맞출 필요 없이, 중앙 DB 스키마만 알면 데이터를 공유/통합할 수 있음. | D15: ='AI#2_Gemini'!D$18 -> ++ | E15: ='AI#2_Gemini'!E$18 -> 서로 다른 형태와 알고리즘을 가진 KS들이 중앙 블랙보드의 데이터만 바라보므로 이질적인 시스템을 통합하기 매우 좋음.
A16: Human | B16: =Human!B$18 -> + | C16: =Human!C$18 -> 공통 스키마를 따르는 Client를 저장소에 연결하여 통합 가능 | D16: + | E16: 각각의 KS들이 중앙 블랙보드의 데이터만 바라보므로 중앙 블랙보드 형식만 맞추면 되어 통합하기 쉽다.
A18: Energy Efficiency | B18: ='Detailed Reasoning'!B$19 | C18: ='Detailed Reasoning'!C$19 | D18: ='Detailed Reasoning'!D$19 | E18: ='Detailed Reasoning'!E$19
A19: AI#1 | B19: ='AI#1_GPT'!B$19 -> + | C19: ='AI#1_GPT'!C19 -> 중복 데이터 복제와 여러 저장소 운영을 줄여 자원 사용을 집중시킬 수 있다. | D19: ='AI#1_GPT'!D$19 -> - | E19: ='AI#1_GPT'!E19 -> 여러 지식 소스가 상태를 반복 관찰·추론하고 후보 해를 갱신하므로 계산 자원 소비가 커질 수 있다.
A20: AI#2 | B20: ='AI#2_Gemini'!B$19 -> 0 | C20: ='AI#2_Gemini'!C$19 -> 중앙 집중적 데이터 저장이 에너지 소비에 미치는 영향은 인프라 구성에 따라 다름. | D20: ='AI#2_Gemini'!D$19 -> - | E20: ='AI#2_Gemini'!E$19 -> 제어 컴포넌트가 지속적으로 블랙보드의 상태 변화를 모니터링하고 KS를 평가해야 하므로 연산 오버헤드(에너지 낭비)가 큼.
A21: Human | B21: =Human!B$19 -> - | C21: =Human!C$19 -> 중복 데이터 복제와 여러 저장소 운영을 줄여 자원 사용을 집중-> data쪽과의 동시성을 가지고 볼 경우 -로 볼 수 있음 | D21: - | E21: 컨트롤러가 지속적으로 블랙보드를 모니터링하고 KS를 제어하므로 오버헤드가 크다.
A23: Modifiability | B23: ='Detailed Reasoning'!B$20 | C23: ='Detailed Reasoning'!C$20 | D23: ='Detailed Reasoning'!D$20 | E23: ='Detailed Reasoning'!E$20
A24: AI#1 | B24: ='AI#1_GPT'!B$20 -> - | C24: ='AI#1_GPT'!C20 -> 공유 스키마 변경이 많은 소비자에게 동시에 영향을 주어 변경 파급 범위가 커질 수 있다. | D24: ='AI#1_GPT'!D$20 -> + | E24: ='AI#1_GPT'!E20 -> 새 지식 소스를 추가하거나 기존 추론 모듈을 교체하기 비교적 쉽다.
A25: AI#2 | B25: ='AI#2_Gemini'!B$20 -> + | C25: ='AI#2_Gemini'!C$20 -> 기존 클라이언트를 수정하지 않고도 새로운 클라이언트(기능)를 중앙 저장소에 연결하여 확장하기 쉬움. | D25: ='AI#2_Gemini'!D$20 -> ++ | E25: ='AI#2_Gemini'!E$20 -> 문제 해결 로직(KS)을 새롭게 추가하거나 제거하더라도 다른 KS나 시스템 전체의 구조를 변경할 필요가 없음.
A26: Human | B26: =Human!B$20 -> - | C26: =Human!C$20 -> 클라이언트, KS간 변경의 영향은 최소화 되지만 데이의 스키마 변경등은 모든 클라이언트에게 영향을 주는 점을 고려해보아야 합니다 | D26: + | E26: 각각의 KS들이 중앙 블랙보드의 데이터만 바라보므로 중앙 블랙보드 형식만 맞추면 되어 수정하기 쉽다.
A28: Performance | B28: ='Detailed Reasoning'!B$21 | C28: ='Detailed Reasoning'!C$21 | D28: ='Detailed Reasoning'!D$21 | E28: ='Detailed Reasoning'!E$21
A29: AI#1 | B29: ='AI#1_GPT'!B$21 -> 0 | C29: ='AI#1_GPT'!C21 -> 중앙 최적화·캐시의 이점이 있지만 동시 접근이 몰리면 저장소가 병목이 될 수 있다. | D29: ='AI#1_GPT'!D$21 -> - | E29: ='AI#1_GPT'!E21 -> 공유 상태 접근, 후보 평가, 스케줄링 등 협업 오버헤드 때문에 단순 직접 호출보다 느릴 수 있다.
A30: AI#2 | B30: ='AI#2_Gemini'!B$21 -> - | C30: ='AI#2_Gemini'!C$21 -> 클라이언트 수가 많아지거나 동시 데이터 접근이 발생하면 중앙 저장소에 병목(Bottleneck) 현상이 발생하여 성능이 저하됨. | D30: ='AI#2_Gemini'!D$21 -> -- | E30: ='AI#2_Gemini'!E$21 -> 휴리스틱 기반의 문제 해결 방식으로, 제어 컴포넌트의 빈번한 상태 평가와 동기화 문제로 인해 예측 가능한 성능을 기대하기 힘듦.
A31: Human | B31: =Human!B$21 -> - | C31: =Human!C$21 -> 공유 저장소에 동시 접근이 집중되면 병목 발생 가능 | D31: - | E31: 공유 상태 접근, 스케줄링 등 협업 오버헤드 때문에 단순 직접 호출보다 느리다.
A33: Safety | B33: ='Detailed Reasoning'!B$22 | C33: ='Detailed Reasoning'!C$22 | D33: ='Detailed Reasoning'!D$22 | E33: ='Detailed Reasoning'!E$22
A34: AI#1 | B34: ='AI#1_GPT'!B$22 -> + | C34: ='AI#1_GPT'!C22 -> 단일 기준 데이터(source of truth)를 유지하기 쉬워 불일치 상태를 줄이는 데 유리하다. | D34: ='AI#1_GPT'!D$22 -> 0 | E34: ='AI#1_GPT'!E22 -> 여러 지식 소스의 상호 검증은 도움이 되지만 비결정적 추론·우선순위 충돌은 안전 검증을 어렵게 한다.
A35: AI#2 | B35: ='AI#2_Gemini'!B$22 -> 0 | C35: 트랜잭션 관리를 통해 내부 '데이터'의 손상과 유실을 복구하는 데는 능하지만, 아키텍처 자체가 사람, 재산, 외부 환경에 미치는 물리적 위험을 모니터링하고 제어하여 피해를 억제하는 기능과는 무관합니다. | D35: - | E35: 위험 상태 발생 시 정해진 데드라인 내에 반드시 피해 억제/복구 로직이 실행된다는 '시간적 보장'을 할 수 없으므로, 인명/재산 피해가 발생할 위험성이 높습니다
A36: Human | B36: =Human!B$22 -> - | C36: =Human!C$22 -> 중앙 저장소가 단일 장애 지점은 보안성에서도 문제지만 안정성에서 문제가 됨 | D36: ='AI#1_GPT'!D$22 -> 0 | E36: 여러 지식 소스의 상호 검증은 도움이 되지만, 비결정적 추론/우선순위 충돌은 안전 검증을 어렵게 한다.
A38: Security | B38: ='Detailed Reasoning'!B$23 | C38: ='Detailed Reasoning'!C$23 | D38: ='Detailed Reasoning'!D$23 | E38: ='Detailed Reasoning'!E$23
A39: AI#1 | B39: ='AI#1_GPT'!B$23 -> 0 | C39: ='AI#1_GPT'!C23 -> 접근통제를 중앙화하기 쉽지만 침해 시 영향 범위도 커서 장점과 위험이 함께 존재한다. | D39: ='AI#1_GPT'!D$23 -> - | E39: ='AI#1_GPT'!E23 -> 많은 모듈이 공용 블랙보드를 읽고 쓰므로 권한 통제와 데이터 오염 방지가 복잡해진다.
A40: AI#2 | B40: ='AI#2_Gemini'!B$23 -> ++ | C40: ='AI#2_Gemini'!C$23 -> 데이터가 한 곳에 모여 있으므로, 데이터 접근 권한(Authorization) 및 인증(Authentication) 관리를 중앙에서 강력하게 통제할 수 있음. | D40: ='AI#2_Gemini'!D$23 -> 0 | E40: ='AI#2_Gemini'!E$23 -> 보안 관점보다는 미해결 문제에 대한 협력적 연산에 집중되어 있어 보안 통제가 기본으로 내장되어 있지 않음.
A41: Human | B41: =Human!B$23 -> - | C41: =Human!C$23 -> Data Store, Black Bd의 데이터가 모든 Data client, KS에 공개되어 있으므로, 보안에 취약 | D41: 0 | E41: 많은 KS가 공용 블랙보드 하나에 의존하므로 위험 지점이 하나여서 크다고 할 수도 있고, 작다고 할 수도 있다.
A43: Testability | B43: ='Detailed Reasoning'!B$24 | C43: ='Detailed Reasoning'!C$24 | D43: ='Detailed Reasoning'!D$24 | E43: ='Detailed Reasoning'!E$24
A44: AI#1 | B44: ='AI#1_GPT'!B$24 -> 0 | C44: ='AI#1_GPT'!C24 -> 테스트 데이터 준비는 쉽지만 여러 컴포넌트가 공유 상태를 사용하면 테스트 격리가 어려울 수 있다. | D44: ='AI#1_GPT'!D$24 -> - | E44: ='AI#1_GPT'!E24 -> 여러 지식 소스의 실행 순서와 공유 상태에 따라 결과가 달라질 수 있어 재현 테스트가 어렵다.
A45: AI#2 | B45: ='AI#2_Gemini'!B$24 -> - | C45: ='AI#2_Gemini'!C$24 -> 클라이언트를 테스트하기 위해 항상 실제 또는 모의 중앙 데이터베이스 환경(테스트 데이터 세팅 및 롤백)을 구축해야 하는 번거로움이 있음. | D45: ='AI#2_Gemini'!D$24 -> -- | E45: ='AI#2_Gemini'!E$24 -> 비결정론적(Non-deterministic) 실행 흐름을 가짐. 어떤 KS가 언제 실행될지 예측하기 어려워 재현 가능한 테스트 시나리오를 작성하기 매우 힘듦.
A46: Human | B46: =Human!B$24 -> - | C46: =Human!C$24 -> 공유 상태로 인해 Client 시험 간 간섭 발생 가능 | D46: -- | E46: 여러 지식 소스의 실행 순서와 공유 상태에 따라 결과가 달라질 수 있어 재현 및 테스트가 어렵다.
A48: Usability | B48: ='Detailed Reasoning'!B$25 | C48: ='Detailed Reasoning'!C$25 | D48: ='Detailed Reasoning'!D$25 | E48: ='Detailed Reasoning'!E$25
A49: AI#1 | B49: ='AI#1_GPT'!B$25 -> 0 | C49: ='AI#1_GPT'!C25 -> 데이터 중심 내부 구조이므로 사용자 인터페이스 품질에 직접 주는 영향은 제한적이다. | D49: ='AI#1_GPT'!D$25 -> 0 | E49: ='AI#1_GPT'!E25 -> 문제 해결 방식의 내부 구조라 최종 사용자 경험에 직접적인 영향은 크지 않다.
...

Sheet II
A1: Implicit Invocation | B1: Non-Buffered Event Based | D1: Buffered Message Based
B2: Effects | C2: Justification | D2: Effects | E2: Justification
A3: Availability | B3: ='Detailed Reasoning'!B$29 | C3: ='Detailed Reasoning'!C$29 | D3: ='Detailed Reasoning'!D$29 | E3: ='Detailed Reasoning'!E$29
A4: AI#1 | B4: ='AI#1_GPT'!B$29 -> - | C4: ='AI#1_GPT'!C29 -> 구독자가 잠시 중단된 동안 발생한 이벤트가 보존되지 않으면 정보 손실과 기능 누락이 생길 수 있다. | D4: ='AI#1_GPT'!D$29 -> ++ | E4: ='AI#1_GPT'!E29 -> 메시지를 큐에 보존해 소비자가 일시 중단되어도 복구 후 처리를 계속할 수 있다.
A5: AI#2 | B5: ='AI#2_Gemini'!B$29 -> 0 | C5: ='AI#2_Gemini'!C$29 -> 컴포넌트는 독립적이지만, 이벤트 발송 중 수신측이 다운되어 있거나 블로킹되면 시스템 흐름에 영향을 줄 수 있음. | D5: ='AI#2_Gemini'!D$29 -> ++ | E5: ='AI#2_Gemini'!E$29 -> 메시지 큐(브로커)가 메시지를 버퍼링하므로, 수신자가 다운되거나 일시적인 장애가 발생해도 데이터가 유실되지 않아 가용성이 매우 높음.
A6: Human | B6: - | C6: 수신 측이 다운되어 있을 동안 발생한 이벤트가 손실될 가능성이 있다. | D6: ++ | E6: 수신 측이 다운되어 있더라도 메시지가 버퍼에 보존되기 때문에 이벤트 손실의 가능성이 적다.
A8: Deployability | B8: ='Detailed Reasoning'!B$30 | C8: ='Detailed Reasoning'!C$30 | D8: ='Detailed Reasoning'!D$30 | E8: ='Detailed Reasoning'!E$30
A9: AI#1 | B9: ='AI#1_GPT'!B$30 -> + | C9: ='AI#1_GPT'!C30 -> 발행자와 구독자가 서로의 구현을 직접 알 필요가 없어 컴포넌트를 비교적 독립적으로 배포할 수 있다. | D9: ='AI#1_GPT'!D$30 -> ++ | E9: ='AI#1_GPT'!E30 -> 생산자와 소비자가 시간적으로 분리되어 한쪽을 중단·교체해도 다른 쪽의 배포를 계속할 수 있다.
A10: AI#2 | B10: ='AI#2_Gemini'!B$30 -> + | C10: ='AI#2_Gemini'!C$30 -> 이벤트 발행자(Publisher)와 구독자(Subscriber)가 독립적이므로 개별 마이크로서비스나 모듈 단위 배포가 용이함. | D10: ='AI#2_Gemini'!D$30 -> ++ | E10: ='AI#2_Gemini'!E$30 -> 발행자와 구독자가 물리적으로도 완전히 분리(비동기)되므로 브로커를 매개로 한 독립적 배포가 극대화됨.
A11: Human | B11: + | C11: 이벤트 발행자와 구독자가 상호독립적이므로 개별 배포가 용이하다. | D11: ++ | E11: 이벤트 발행자와 이벤트 구독자가 상호독립적이므로 배포에 서로 영향 받지 않는다.
A13: Integrability | B13: ='Detailed Reasoning'!B$31 | C13: ='Detailed Reasoning'!C$31 | D13: ='Detailed Reasoning'!D$31 | E13: ='Detailed Reasoning'!E$31
A14: AI#1 | B14: ='AI#1_GPT'!B$31 -> ++ | C14: ='AI#1_GPT'!C31 -> 이벤트 계약만 맞으면 새로운 구독자를 기존 발행자 수정 없이 쉽게 연결할 수 있다. | D14: ='AI#1_GPT'!D$31 -> ++ | E14: ='AI#1_GPT'!E31 -> 표준 메시지 계약을 통해 서로 다른 기술·언어의 시스템을 느슨하게 연결하기 좋다.
A15: AI#2 | B15: ='AI#2_Gemini'!B$31 -> + | C15: ='AI#2_Gemini'!C$31 -> 이벤트를 발행하는 컴포넌트를 수정하지 않고도 새로운 리스너(구독자)를 등록하여 기능을 통합하기 쉬움. | D15: ='AI#2_Gemini'!D$31 -> ++ | E15: ='AI#2_Gemini'!E$31 -> 다양한 플랫폼과 언어로 작성된 이질적인 시스템이라도 메시지 브로커의 프로토콜(AMQP, MQTT 등)만 맞추면 완벽히 통합 가능함.
A16: Human | B16: ++ | C16: 이벤트 발행의 수정 없이도 새로운 구독자를 추가적으로 등록하여 기능 통합에 용이하다. | D16: ++ | E16: 서로 다른 시스템일지라도 메시지 브로커의 프로토콜만 맞는다면 통합하기 용이하다.
A18: Energy Efficiency | B18: ='Detailed Reasoning'!B$32 | C18: ='Detailed Reasoning'!C$32 | D18: ='Detailed Reasoning'!D$32 | E18: ='Detailed Reasoning'!E$32
A19: AI#1 | B19: ='AI#1_GPT'!B$32 -> + | C19: ='AI#1_GPT'!C32 -> 메시지 저장·영속화 과정이 없어 버퍼드 방식보다 저장장치와 브로커 자원 오버헤드가 작다. | D19: ='AI#1_GPT'!D$32 -> - | E19: ='AI#1_GPT'!E32 -> 브로커, 메시지 영속화, 복제, 직렬화가 추가되어 직접 호출보다 자원 사용이 늘어난다.
A20: AI#2 | B20: ='AI#2_Gemini'!B$32 -> 0 | C20: ='AI#2_Gemini'!C$32 -> 시스템간 호출 방식 변경이 전체적인 전력 사용 최적화로 직결되지는 않음. | D20: ='AI#2_Gemini'!D$32 -> + | E20: ='AI#2_Gemini'!E$32 -> 비동기 처리 덕분에 컴포넌트들이 항상 활성화되어 대기할 필요 없이, 메시지가 큐에 쌓였을 때만 일괄 처리(Wake-up)하여 유휴 자원/에너지를 아낄 수 있음.
A21: Human | B21: =Human!B$32 -> - | C21: 메시지 저장·영속화에 따른 오버헤드는 적지만 이벤트가 발생할 때마다 즉시 처리되므로 Batch 처리나 자원 활성화 횟수 감소 등의 에너지 절감 효과는 보장되지 않아 전체적으로는 중립적이다. | D21: =Human!D$32 -> + | E21: =Human!E$32 -> 비동기 처리로 component가 항시 대기 필요없고, 메시지 queue도 일괄 처리 가능
A23: Modifiability | B23: ='Detailed Reasoning'!B$33 | C23: ='Detailed Reasoning'!C$33 | D23: ='Detailed Reasoning'!D$33 | E23: ='Detailed Reasoning'!E$33
A24: AI#1 | B24: ='AI#1_GPT'!B$33 -> ++ | C24: ='AI#1_GPT'!C33 -> 새 이벤트 소비자를 추가하거나 기존 소비자를 교체해도 발행자 변경이 거의 필요 없다. | D24: ='AI#1_GPT'!D$33 -> ++ | E24: ='AI#1_GPT'!E33 -> 새 소비자를 추가하거나 처리 로직을 변경해도 생산자와 강하게 결합되지 않는다.
A25: AI#2 | B25: ='AI#2_Gemini'!B$33 -> ++ | C25: ='AI#2_Gemini'!C$33 -> 시스템 구성 요소 간의 결합도가 매우 낮아, 이벤트 처리 로직을 수정하거나 새로운 이벤트 핸들러를 추가하는 작업이 기존 코드에 영향을 주지 않음. | D25: ='AI#2_Gemini'!D$33 -> ++ | E25: ='AI#2_Gemini'!E$33 -> 송신자와 수신자가 서로의 존재조차 알 필요가 없는 극단적인 느슨한 결합(Loose Coupling)으로 유연한 수정 및 시스템 확장이 가능함.
A26: Human | B26: =Human!B$33 -> - | C26: 이벤트를 구독하는 기존 소비자를 교체하거나 새로운 소비자를 추가하더라도 기존 코드에 영향을 주지 않는다. | D26: ++ | E26: publisher와 subscriber가 서로에 영향을 주지 않는 구조이기 때문에 시스템 수정 및 확장이 용이하다.
A28: Performance | B28: ='Detailed Reasoning'!B$34 | C28: ='Detailed Reasoning'!C$34 | D28: ='Detailed Reasoning'!D$34 | E28: ='Detailed Reasoning'!E$34
A29: AI#1 | B29: ='AI#1_GPT'!B$34 -> ++ | C29: ='AI#1_GPT'!C34 -> 영속 큐를 거치지 않고 이벤트를 바로 전달할 수 있어 낮은 지연시간에 유리하다. | D29: ='AI#1_GPT'!D$34 -> + | E29: ='AI#1_GPT'!E34 -> 버스트를 큐로 흡수하고 비동기 병렬 처리가 가능하지만 큐잉·영속화 지연은 추가된다.
A30: AI#2 | B30: ='AI#2_Gemini'!B$34 -> + | C30: ='AI#2_Gemini'!C$34 -> 중간에 브로커를 거치지 않아 이벤트 전달 지연(Latency)이 짧음. 단, 수신자가 많을 경우 발행자의 스레드가 차단될 수 있는 위험은 존재함. | D30: ='AI#2_Gemini'!D$34 -> 0 | E30: ='AI#2_Gemini'!E$34 -> 비동기 처리를 통해 시스템 전체의 Throughput(처리량)은 획기적으로 늘지만, 메시지가 큐를 거쳐가는 오버헤드로 인해 실시간성(Latency)은 다소 떨어짐.
A31: Human | B31: =Human!B$34 -> ++ | C31: =Human!C$34 -> 이벤트를 직접 전달 가능하여 전달 지연이 짧음 | D31: =Human!D$34 -> + | E31: =Human!E$34 -> 버퍼링과 Consumer 병렬화를 통해 부하를 평준화하고 높은 처리량을 확보할 수 있어 전체적인 Performance +
A33: Safety | B33: ='Detailed Reasoning'!B$35 | C33: ='Detailed Reasoning'!C$35 | D33: ='Detailed Reasoning'!D$35 | E33: ='Detailed Reasoning'!E$35
A34: AI#1 | B34: ='AI#1_GPT'!B$35 -> - | C34: ='AI#1_GPT'!C35 -> 이벤트 유실·순서 변화·중복 처리에 대한 보장이 약하면 중요 상태 전이가 누락될 위험이 있다. | D34: ='AI#1_GPT'!D$35 -> + | E34: ='AI#1_GPT'!E35 -> 내구성 있는 메시지와 재시도·재처리를 통해 중요 이벤트 손실을 줄일 수 있다.
A35: AI#2 | B35: - | C35: =Human!C$35 -> 중요 이벤트가 유실시 알수없음 | D35: - | E35: 브로커가 메시지를 버퍼링하므로 복구 이벤트의 유실은 막을 수(최종적 실행 보장) 있습니다. 하지만 큐 대기로 인해 필연적으로 지연(Latency)이 발생하므로, 사람이나 재산에 즉각적인 피해가 발생하기 직전의 '골든 타임' 내에 실시간 억제 개입을 하지 못할 위험이 존재합니다.
A36: Human | B36: =Human!B$35 -> - | C36: 일반 시스템에서는 Safety에 직접적인 영향이 크지 않지만, Safety-critical 이벤트를 전달하는 경우 버퍼 부재로 인한 이벤트 유실이나 처리 순서 문제가 위험 상태로 이어질 수 있다 | D36: =Human!D$35 -> - | E36: =Human!E$35 -> 중요 이벤트의 손실 방지와 재처리를 통해 안전성에 간접적으로 기여할 수 있지만, 시스템의 물리적 위험을 직접 제어하거나 Safety를 보장하는 구조는 아니므로 일반적인 영향은 중립적이다. buffer가 처리하는 지연 발생시, 실시간성에 부정적
A38: Security | B38: ='Detailed Reasoning'!B$36 | C38: ='Detailed Reasoning'!C$36 | D38: ='Detailed Reasoning'!D$36 | E38: ='Detailed Reasoning'!E$36
A39: AI#1 | B39: ='AI#1_GPT'!B$36 -> - | C39: ='AI#1_GPT'!C36 -> 여러 이벤트 발행·구독 지점이 생기므로 인증·권한·이벤트 위변조 통제를 일관되게 적용해야 한다. | D39: ='AI#1_GPT'!D$36 -> 0 | E39: ='AI#1_GPT'!E36 -> 브로커에서 인증·권한을 집중할 수 있지만 메시지 저장소와 브로커 자체가 추가 공격면이 된다.
A40: AI#2 | B40: ='AI#2_Gemini'!B$36 -> - | C40: ='AI#2_Gemini'!C$36 -> 버퍼나 브로커가 없으므로 악의적인 컴포넌트가 이벤트를 엿듣거나 가짜 이벤트를 발생시키는 것을 중앙에서 통제하기 어려움. | D40: ='AI#2_Gemini'!D$36 -> + | E40: ='AI#2_Gemini'!E$36 -> 메시지 브로커 단에서 토픽(Topic) 또는 큐(Queue) 단위의 엄격한 접근 제어 및 인증, 메시지 암호화를 적용하여 보안을 강화할 수 있음.
A41: Human | B41: =Human!B$36 -> + | C41: =Human!C$36 -> Non-Buff의 간한 결합(동기)은 정보의 유출 가능성을 줄여 준다 | D41: =Human!D$36 -> - | E41: =Human!E$36 -> 중앙 Broker를 통해 인증·인가와 보안 정책을 일관되게 적용할 수 있다는 장점이 있지만, Broker 및 저장된 메시지가 추가적인 공격면과 중요한 보안 자산이 되므로 전체적인 영향은 구성에 따라 달라진다. 다양한 listener가 붙을수 있기에 security측면에서 불리하다. 메시지를 중간에 가로채는 사례가 있음
A43: Testability | B43: ='Detailed Reasoning'!B$37 | C43: ='Detailed Reasoning'!C$37 | D43: ='Detailed Reasoning'!D$37 | E43: ='Detailed Reasoning'!E$37
A44: AI#1 | B44: ='AI#1_GPT'!B$37 -> - | C44: ='AI#1_GPT'!C37 -> 비동기 타이밍과 이벤트 순서가 결과에 영향을 줘 재현 가능한 테스트 작성이 어려워질 수 있다. | D44: ='AI#1_GPT'!D$37 -> + | E44: ='AI#1_GPT'!E37 -> 메시지를 기록·재생해 시나리오를 반복할 수 있어 비동기 시스템 중에서는 테스트가 비교적 용이하다.
A45: AI#2 | B45: ='AI#2_Gemini'!B$37 -> - | C45: ='AI#2_Gemini'!C$37 -> 컴포넌트 간 호출이 암시적이고 흐름이 분산되어 있어, 디버깅 및 전체적인 이벤트 실행 추적(Traceability)이 까다로움. | D45: ='AI#2_Gemini'!D$37 -> 0 | E45: ='AI#2_Gemini'!E$37 -> 비동기 통신으로 전체 흐름 추적(Distributed Tracing)은 여전히 어렵지만, 메시지 큐에 테스트용 메시지를 주입(Inject)하여 개별 컴포넌트를 분리 테스트하기는 비교적 수월함.
A46: Human | B46: =Human!B$37 -> + | C46: =Human!C$37 -> 동기 결합으로 test에 좋음 | D46: =Human!D$37 -> - | E46: =Human!E$37 -> 전체 비동기 흐름의 추적은 별도 Tracing이 필요. 통합 test환경 구축에 어려움
A48: Usability | B48: ='Detailed Reasoning'!B$38 | C48: ='Detailed Reasoning'!C$38 | D48: ='Detailed Reasoning'!D$38 | E48: ='Detailed Reasoning'!E$38
A49: AI#1 | B49: ='AI#1_GPT'!B$38 -> + | C49: ='AI#1_GPT'!C38 -> 사용자 입력이나 상태 변화에 즉시 반응하는 UI·알림 구현에 잘 맞는다. | D49: ='AI#1_GPT'!D$38 -> + | E49: ='AI#1_GPT'!E38 -> 긴 처리를 비동기로 넘겨 화면 응답성을 유지하고 완료 알림을 제공하기 좋다.
...

Sheet IO
A1: Interaction-Oriented | B1: MVC | D1: PAC
B2: Effects | C2: Justification | D2: Effects | E2: Justification
A3: Availability | B3: ='Detailed Reasoning'!B$42 | C3: ='Detailed Reasoning'!C$42 | D3: ='Detailed Reasoning'!D$42 | E3: ='Detailed Reasoning'!E$42
A4: AI#1 | B4: ='AI#1_GPT'!B$42 -> 0 | C4: ='AI#1_GPT'!C42 -> Model·View·Controller 분리는 장애 복구 자체를 제공하지 않아 가용성에 직접적인 영향은 작다. | D4: ='AI#1_GPT'!D$42 -> + | E4: ='AI#1_GPT'!E42 -> 에이전트가 계층적으로 분리되어 일부 에이전트 문제를 국소화할 수 있지만 상위 조정자 장애 영향은 남는다. | M4: MVC
A5: AI#2 | B5: ='AI#2_Gemini'!B$42 -> 0 | C5: ='AI#2_Gemini'!C$42 -> Model, View, Controller 간 결합도가 높아 특정 레이어의 장애가 전체 서비스 중단으로 이어질 수 있음 | D5: ='AI#2_Gemini'!D$42 -> + | E5: ='AI#2_Gemini'!E$42 -> 에이전트(Agent) 단위로 격리(Fault Isolation)되어 있어 특정 에이전트에 장애가 발생해도 타 에이전트가 정상 작동하여 전체 시스템 가용성 유지. | M5: 사용자 사용성고려
A6: Human | B6: =Human!B$42 | C6: =Human!C$42 -> Human - MVC - Availability | D6: =Human!D$42 | E6: =Human!E$42 -> Human - PAC - Availability | M6: view죽어도 시스템 죽지않음
M7: model/controller죽으면 시스템 죽음
A8: Deployability | B8: ='Detailed Reasoning'!B$43 | C8: ='Detailed Reasoning'!C$43 | D8: ='Detailed Reasoning'!D$43 | E8: ='Detailed Reasoning'!E$43
A9: AI#1 | B9: ='AI#1_GPT'!B$43 -> 0 | C9: ='AI#1_GPT'!C43 -> 관심사 분리는 도움이 되지만 일반적으로 하나의 애플리케이션 단위로 함께 배포되는 경우가 많다. | D9: ='AI#1_GPT'!D$43 -> + | E9: ='AI#1_GPT'!E43 -> Presentation·Abstraction·Control을 가진 에이전트 단위로 기능을 비교적 독립적으로 확장할 수 있다.
A10: AI#2 | B10: ='AI#2_Gemini'!B$43 -> - | C10: ='AI#2_Gemini'!C$43 -> 모듈 간 세로형/계층적 결합으로 인해 일부 로직 수정 시 전체 애플리케이션을 재배포해야 하는 경우가 많음. | D10: ='AI#2_Gemini'!D$43 -> + | E10: ='AI#2_Gemini'!E$43 -> 기능 단위의 독립적인 PAC 에이전트로 구성되어 있어 개별 모듈 단위의 핫 스왑(Hot-swap) 및 독립 배포가 쉬움.
A11: Human | B11: =Human!B$43 | C11: =Human!C$43 -> Human - MVC - Deployability | D11: =Human!D$43 | E11: =Human!E$43 -> Human - PAC - Deployability
A13: Integrability | B13: ='Detailed Reasoning'!B$44 | C13: ='Detailed Reasoning'!C$44 | D13: ='Detailed Reasoning'!D$44 | E13: ='Detailed Reasoning'!E$44
A14: AI#1 | B14: ='AI#1_GPT'!B$44 -> + | C14: ='AI#1_GPT'!C44 -> Controller와 Model의 책임이 명확해 외부 입력·서비스 연계를 특정 지점에 모으기 쉽다. | D14: ='AI#1_GPT'!D$44 -> + | E14: ='AI#1_GPT'!E44 -> 에이전트 간 Control을 통한 명확한 상호작용으로 복잡한 UI 구성요소를 결합하기 좋다.
A15: AI#2 | B15: ='AI#2_Gemini'!B$44 -> + | C15: ='AI#2_Gemini'!C$44 -> 중앙 집중식 Model과 명확히 구분된 단일 Controller 구조 덕분에 외부 API/DB 연동 인터페이스 적용이 단순함. | D15: ='AI#2_Gemini'!D$44 -> -- | E15: ='AI#2_Gemini'!E$44 -> 에이전트 간 계층적 통신 프로토콜 및 컨트롤러 메시지 라우팅이 복잡하여 외부 서비스 및 데이터베이스와의 통합 난이도가 매우 높음.
A16: Human | B16: =Human!B$44 | C16: =Human!C$44 -> Human - MVC - Integrability | D16: =Human!D$44 | E16: =Human!E$44 -> Human - PAC - Integrability
A18: Energy Efficiency | B18: ='Detailed Reasoning'!B$45 | C18: ='Detailed Reasoning'!C$45 | D18: ='Detailed Reasoning'!D$45 | E18: ='Detailed Reasoning'!E$45
A19: AI#1 | B19: ='AI#1_GPT'!B$45 -> 0 | C19: ='AI#1_GPT'!C45 -> 추가 계층의 호출 비용은 작고 에너지 효율을 좌우할 정도의 구조적 효과는 보통 크지 않다. | D19: ='AI#1_GPT'!D$45 -> - | E19: ='AI#1_GPT'!E45 -> 다수 에이전트와 Control 간 조정 메시지가 늘어 단순 UI 구조보다 런타임 오버헤드가 크다.
A20: AI#2 | B20: ='AI#2_Gemini'!B$45 -> + | C20: ='AI#2_Gemini'!C$45 -> 단일 흐름 형태의 가벼운 내부 메서드 호출로 CPU/메모리 오버헤드가 적음. | D20: ='AI#2_Gemini'!D$45 -> - | E20: ='AI#2_Gemini'!E$45 -> 트리 구조를 따르는 에이전트 간 상하 메시지 전달 및 이벤트 처리 비용으로 인해 리소스 및 에너지 소모가 큼.
A21: Human | B21: =Human!B$45 | C21: =Human!C$45 -> Human - MVC - Energy Efficiency | D21: =Human!D$45 | E21: =Human!E$45 -> Human - PAC - Energy Efficiency
A23: Modifiability | B23: ='Detailed Reasoning'!B$46 | C23: ='Detailed Reasoning'!C$46 | D23: ='Detailed Reasoning'!D$46 | E23: ='Detailed Reasoning'!E$46
A24: AI#1 | B24: ='AI#1_GPT'!B$46 -> ++ | C24: ='AI#1_GPT'!C46 -> 화면, 입력 처리, 도메인 상태를 분리해 한 영역의 변경이 다른 영역에 미치는 영향을 줄인다. | D24: ='AI#1_GPT'!D$46 -> ++ | E24: ='AI#1_GPT'!E46 -> 기능별 에이전트 내부에 표현·상태·제어를 캡슐화해 국소 변경에 유리하다.
A25: AI#2 | B25: ='AI#2_Gemini'!B$46 -> + | C25: ='AI#2_Gemini'!C$46 -> UI(View) 변경이나 데이터 구조(Model) 변경은 쉽지만, 새로운 대화형 기능 추가 시 컨트롤러가 거대해져 파급 효과가 큼 | D25: ='AI#2_Gemini'!D$46 -> ++ | E25: ='AI#2_Gemini'!E$46 -> 에이전트 단위로 완전히 독립되어 있어 기존 코드에 영향을 주지 않고 새로운 에이전트를 추가/수정하기가 훨씬 용이함.
A26: Human | B26: =Human!B$46 | C26: =Human!C$46 -> Human - MVC - Modifiability | D26: =Human!D$46 | E26: =Human!E$46 -> Human - PAC - Modifiability
A28: Performance | B28: ='Detailed Reasoning'!B$47 | C28: ='Detailed Reasoning'!C$47 | D28: ='Detailed Reasoning'!D$47 | E28: ='Detailed Reasoning'!E$47
A29: AI#1 | B29: ='AI#1_GPT'!B$47 -> 0 | C29: ='AI#1_GPT'!C47 -> 약간의 간접 호출은 생기지만 일반적인 애플리케이션에서 성능 영향은 제한적이다. | D29: ='AI#1_GPT'!D$47 -> - | E29: ='AI#1_GPT'!E47 -> 계층적인 에이전트 협력과 Control 간 통신으로 직접 연결보다 응답 경로가 길어진다.
A30: AI#2 | B30: ='AI#2_Gemini'!B$47 -> + | C30: =#REF! -> #REF! | D30: ='AI#2_Gemini'!D$47 -> - | E30: ='AI#2_Gemini'!E$47 -> 계층적 트리 구조에서 최상위-중간-하위 컨트롤러를 거치는 메시지 라우팅 오버헤드 때문에 응답 지연이 발생할 수 있음
A31: Human | B31: =Human!B$47 | C31: =Human!C$47 -> Human - MVC - Performance | D31: =Human!D$47 | E31: =Human!E$47 -> Human - PAC - Performance
A33: Safety | B33: ='Detailed Reasoning'!B$48 | C33: ='Detailed Reasoning'!C$48 | D33: ='Detailed Reasoning'!D$48 | E33: ='Detailed Reasoning'!E$48
A34: AI#1 | B34: ='AI#1_GPT'!B$48 -> + | C34: ='AI#1_GPT'!C48 -> 입력 검증·상태 변경 책임을 분리해 잘못된 UI 입력이 직접 도메인 상태를 훼손하는 것을 줄이기 쉽다. | D34: ='AI#1_GPT'!D$48 -> + | E34: ='AI#1_GPT'!E48 -> 기능별 상태와 제어가 캡슐화되어 한 UI 기능의 오류가 다른 기능으로 퍼지는 것을 제한하기 쉽다.
A35: AI#2 | B35: ='AI#2_Gemini'!B$48 -> 0 | C35: ='AI#2_Gemini'!C$47 -> 직접적인 메서드 호출 및 단순한 레이어 통과 구조로 처리 속도와 응답성이 뛰어남. | D35: ='AI#2_Gemini'!D$48 -> + | E35: ='AI#2_Gemini'!E$48 -> 에이전트 캡슐화를 통해 결함의 영향 범위를 한정 짓고 안전하게 예외 처리를 수행할 수 있음.
A36: Human | B36: =Human!B$48 | C36: =Human!C$48 -> Human - MVC - Safety | D36: =Human!D$48 | E36: =Human!E$48 -> Human - PAC - Safety
A38: Security | B38: ='Detailed Reasoning'!B$49 | C38: ='Detailed Reasoning'!C$49 | D38: ='Detailed Reasoning'!D$49 | E38: ='Detailed Reasoning'!E$49
A39: AI#1 | B39: ='AI#1_GPT'!B$49 -> + | C39: ='AI#1_GPT'!C49 -> Controller 같은 명확한 진입점에 인증·입력 검증·권한 검사를 집중하기 좋다. | D39: ='AI#1_GPT'!D$49 -> 0 | E39: ='AI#1_GPT'!E49 -> 에이전트 경계에 권한을 둘 수 있지만 구성요소와 통신 경로가 많아져 보안 복잡성도 증가한다.
A40: AI#2 | B40: ='AI#2_Gemini'!B$49 -> + | C40: ='AI#2_Gemini'!C$49 -> 데이터 접근(Model) 및 요청 제어(Controller) 경로가 일원화되어 있어 보안 정책(인증/인가/검증) 적용이 용이함. | D40: ='AI#2_Gemini'!D$49 -> - | E40: ='AI#2_Gemini'!E$49 -> 수많은 에이전트 간 독립적인 통신 채널이 생성되므로 데이터 유출 위험이 커지고 공격 접점(Attack Surface)이 확대됨.
A41: Human | B41: =Human!B$49 | C41: =Human!C$49 -> Human - MVC - Security | D41: =Human!D$49 | E41: =Human!E$49 -> Human - PAC - Security
A43: Testability | B43: ='Detailed Reasoning'!B$50 | C43: ='Detailed Reasoning'!C$50 | D43: ='Detailed Reasoning'!D$50 | E43: ='Detailed Reasoning'!E$50
A44: AI#1 | B44: ='AI#1_GPT'!B$50 -> ++ | C44: ='AI#1_GPT'!C50 -> Model과 Controller를 View와 분리해 단위 테스트와 Mock 기반 테스트가 쉽다. | D44: ='AI#1_GPT'!D$50 -> + | E44: ='AI#1_GPT'!E50 -> 에이전트 단위 테스트는 쉽지만 상·하위 Control의 상호작용 테스트는 추가로 필요하다.
A45: AI#2 | B45: ='AI#2_Gemini'!B$50 -> + | C45: ='AI#2_Gemini'!C$50 -> UI 없이 Model과 Controller를 독립적으로 단위 테스트(Unit Test)하기 매우 용이함. | D45: ='AI#2_Gemini'!D$50 -> - | E45: ='AI#2_Gemini'!E$50 -> 에이전트 간 비동기 메시지 교환 및 트리 구조의 상호작용 흐름을 추적하고 모킹(Mocking)하여 테스트하기 어려움.
A46: Human | B46: =Human!B$50 | C46: =Human!C$50 -> Human - MVC - Testability | D46: =Human!D$50 | E46: =Human!E$50 -> Human - PAC - Testability
A48: Usability | B48: ='Detailed Reasoning'!B$51 | C48: ='Detailed Reasoning'!C$51 | D48: ='Detailed Reasoning'!D$51 | E48: ='Detailed Reasoning'!E$51
...

Sheet H1
A1: Hierarchical | B1: Main-subroutine | D1: Master-Slave
B2: Effects | C2: Justification | D2: Effects | E2: Justification
A3: Availability | B3: ='Detailed Reasoning'!B$55 | C3: ='Detailed Reasoning'!C$55 | D3: ='Detailed Reasoning'!D$55 | E3: ='Detailed Reasoning'!E$55
A4: AI#1 | B4: ='AI#1_GPT'!B$55 -> - | C4: ='AI#1_GPT'!C55 -> 중앙 main과 직접 호출 체인에 의존하므로 핵심 함수 장애가 전체 프로그램 중단으로 이어지기 쉽다. | D4: ='AI#1_GPT'!D$55 -> + | E4: ='AI#1_GPT'!E55 -> 일부 worker(slave)가 실패해도 다른 worker로 작업을 재분배할 수 있지만 master 장애점은 남는다.
A5: AI#2 | B5: ='AI#2_Gemini'!B$55 -> -- | C5: ='AI#2_Gemini'!C$55 -> 단일 프로세스/스레드로 동작하므로 서브루틴 하나에서 에러 발생 시 전체 시스템이 중단됨 | D5: ='AI#2_Gemini'!D$55 -> + | E5: ='AI#2_Gemini'!E$55 -> 특정 Slave에 장애가 발생해도 타 Slave가 대신 처리하거나 Master가 해당 Slave만 재시작할 수 있어 가용성이 높음. (단, Master 단일 장애점(SPOF) 관리는 필요)
A6: Human | B6: =Human!B$55 -> - | C6: =Human!C$55 -> 중앙 main과 Subroutine간의 강한 coupling으로 인해 main의 장애가 전체 프로그램의 중단으로 이어질 수 있다. | D6: =Human!D$55 -> + | E6: =Human!E$55 -> 일부 Slave에 장애가 발생해도 다른 Slave가 대신 처리하거나 Master가 해당 Slave만 재시작할 수 있어 가용성이 높음
A8: Deployability | B8: ='Detailed Reasoning'!B$56 | C8: ='Detailed Reasoning'!C$56 | D8: ='Detailed Reasoning'!D$56 | E8: ='Detailed Reasoning'!E$56
A9: AI#1 | B9: ='AI#1_GPT'!B$56 -> -- | C9: ='AI#1_GPT'!C56 -> 보통 하나의 실행 단위로 강하게 결합되어 작은 변경도 전체 프로그램 재배포가 필요한 경우가 많다. | D9: ='AI#1_GPT'!D$56 -> + | E9: ='AI#1_GPT'!E56 -> worker를 개별 추가·교체·확장할 수 있어 계산 노드의 점진적 배포가 가능하다.
A10: AI#2 | B10: ='AI#2_Gemini'!B$56 -> - | C10: ='AI#2_Gemini'!C$56 -> 전체 코드가 단일 바이너리/프로세스로 강하게 결합되어 일부 수정 시 전체 재배포가 필요함. | D10: ='AI#2_Gemini'!D$56 -> + | E10: ='AI#2_Gemini'!E$56 -> 노드/프로세스를 독립적으로 배포하거나 동적으로 노드를 추가/제거(Scale-out)할 수 있음.
A11: Human | B11: =Human!B$56 -> - | C11: =Human!C$56 -> Procedure끼리의 tight coupling으로 인하여 작은 변경도 재배포가 필요한 경우가 생긴다. | D11: =Human!D$56 -> + | E11: =Human!E$56 -> 노드/프로세스를 독립적으로 배포하거나 동적으로 노드를 추가/제거할 수 있다
A13: Integrability | B13: ='Detailed Reasoning'!B$57 | C13: ='Detailed Reasoning'!C$57 | D13: ='Detailed Reasoning'!D$57 | E13: ='Detailed Reasoning'!E$57
A14: AI#1 | B14: ='AI#1_GPT'!B$57 -> - | C14: ='AI#1_GPT'!C57 -> 직접 함수 호출과 공유 자료구조에 의존하기 쉬워 외부 시스템을 느슨하게 연결하기 어렵다. | D14: ='AI#1_GPT'!D$57 -> 0 | E14: ='AI#1_GPT'!E57 -> master-worker 프로토콜은 명확하지만 일반 외부 시스템 통합을 특별히 쉽게 하지는 않는다.
A15: AI#2 | B15: ='AI#2_Gemini'!B$57 -> + | C15: ='AI#2_Gemini'!C$57 -> 함수 호출 규격(API)이 명확하여 라이브러리 형태의 모듈 통합이 매우 쉬움. | D15: ='AI#2_Gemini'!D$57 -> - | E15: ='AI#2_Gemini'!E$57 -> Master와 Slave 간 메시지 프로토콜, 데이터 분할/합성 로직 정의가 필요하여 외부 통합 난이도가 존재함.
A16: Human | B16: =Human!B$57 -> - | C16: =Human!C$57 -> 강한 결합 기반으로 외부 시스템을 통합 할 때의 flexibility가 떨어진다. | D16: =Human!D$57 -> - | E16: =Human!E$57 -> Slave가 Master의 작업·결과 규약에 맞아야 함
A18: Energy Efficiency | B18: ='Detailed Reasoning'!B$58 | C18: ='Detailed Reasoning'!C$58 | D18: ='Detailed Reasoning'!D$58 | E18: ='Detailed Reasoning'!E$58
A19: AI#1 | B19: ='AI#1_GPT'!B$58 -> ++ | C19: ='AI#1_GPT'!C58 -> 직접 호출 중심이라 메시징·직렬화·네트워크 같은 추가 런타임 오버헤드가 매우 작다. | D19: ='AI#1_GPT'!D$58 -> - | E19: ='AI#1_GPT'!E58 -> 여러 worker를 유지하고 작업 분배·동기화해야 하므로 유휴 자원과 통신 비용이 생길 수 있다.
A20: AI#2 | B20: ='AI#2_Gemini'!B$58 -> + | C20: ='AI#2_Gemini'!C$58 -> 프로세스 간 통신(IPC)이나 오버헤드 없이 메모리 스택 직접 접근만 수행하므로 CPU/메모리 자원 효율이 최상임. | D20: ='AI#2_Gemini'!D$58 -> - | E20: ='AI#2_Gemini'!E$58 -> 네트워크 통신, 데이터 분할 및 집계, 프로세스 동기화 오버헤드로 인해 소비 자원량이 큼.
A21: Human | B21: =Human!B$58 -> ++ | C21: =Human!C$58 -> 직접 호출되는 방식으로 procedure간 메시지 전송 등 추가 런타임 오버헤드가 매우 작다. | D21: =Human!D$58 -> - | E21: =Human!E$58 -> 작업 분배·결과 수집의 통신과 조정에 추가 에너지 소비
A23: Modifiability | B23: ='Detailed Reasoning'!B$59 | C23: ='Detailed Reasoning'!C$59 | D23: ='Detailed Reasoning'!D$59 | E23: ='Detailed Reasoning'!E$59
A24: AI#1 | B24: ='AI#1_GPT'!B$59 -> - | C24: ='AI#1_GPT'!C59 -> 상위 호출 구조와 하위 함수 간 의존성이 커지면 변경이 호출 계층 전체로 전파되기 쉽다. | D24: ='AI#1_GPT'!D$59 -> + | E24: ='AI#1_GPT'!E59 -> 동일 계약을 지키면 worker 구현이나 개수를 바꾸기 쉬운 편이다.
A25: AI#2 | B25: ='AI#2_Gemini'!B$59 -> 0 | C25: ='AI#2_Gemini'!C$59 -> 모듈화는 잘 되어 있으나, 하위 서브루틴의 파라미터 변경이 상위호출부에 연쇄 영향(Ripple Effect)을 줌. | D25: ='AI#2_Gemini'!D$59 -> + | E25: ='AI#2_Gemini'!E$59 -> 처리 로직이나 알고리즘을 독립적으로 개편하기 용이하며, 병렬 처리 노드 확장이 자유로움.
A26: Human | B26: =Human!B$59 -> - | C26: =Human!C$59 -> 강한 결합으로 특정 procedure의 변경에 대한 연쇄 변경 side effect가 일어날 수 있다. | D26: =Human!D$59 -> + | E26: =Human!E$59 -> 작업·결과 계약 유지 시 Slave 내부 처리 방식 변경 용이
A28: Performance | B28: ='Detailed Reasoning'!B$60 | C28: ='Detailed Reasoning'!C$60 | D28: ='Detailed Reasoning'!D$60 | E28: ='Detailed Reasoning'!E$60
A29: AI#1 | B29: ='AI#1_GPT'!B$60 -> ++ | C29: ='AI#1_GPT'!C60 -> 프로세스 내부 직접 함수 호출로 실행 경로가 짧고 통신 오버헤드가 거의 없다. | D29: ='AI#1_GPT'!D$60 -> ++ | E29: ='AI#1_GPT'!E60 -> 독립 작업을 여러 worker에 병렬 분산하여 처리량과 계산 성능을 크게 높일 수 있다.
A30: AI#2 | B30: ='AI#2_Gemini'!B$60 -> - | C30: ='AI#2_Gemini'!C$60 -> 단일 스레드/순차적 실행 구조이므로 대용량 데이터 처리나 멀티코어 활용에 한계가 있음. | D30: ='AI#2_Gemini'!D$60 -> ++ | E30: ='AI#2_Gemini'!E$60 -> 데이터를 병렬(Parallelism)로 동시에 처리하여 전체적인 작업 처리량(Throughput) 및 execution 시간을 획기적으로 단축함.
A31: Human | C31: =Human!C$60 -> 여러 서브루틴이 동일한 전역 데이터에 접근할 경우 데이터 동기화 및 경쟁 조건 처리 과정에서 처리 속도가 저하될 수 있습니다. | D31: ++ | E31: Slave 여러개에서 연산 후, 결과를 통합하기 때문에 연산의 정확도가 높음
A33: Safety | B33: ='Detailed Reasoning'!B$61 | C33: ='Detailed Reasoning'!C$61 | D33: ='Detailed Reasoning'!D$61 | E33: ='Detailed Reasoning'!E$61
A34: AI#1 | B34: ='AI#1_GPT'!B$61 -> + | C34: ='AI#1_GPT'!C61 -> 제어 흐름이 명시적이고 비교적 결정적이어서 실행 경로 분석과 검증이 쉽다. | D34: ='AI#1_GPT'!D$61 -> + | E34: ='AI#1_GPT'!E61 -> master가 작업 할당과 결과 취합·검증을 중앙에서 통제해 잘못된 worker 결과를 감지하기 쉽다.
A35: AI#2 | B35: ='AI#2_Gemini'!B$61 -> + | C35: ='AI#2_Gemini'!C$61 -> 제어 흐름이 명시적이여서 실행 경로 분석과 검증이 쉽다. | D35: ='AI#2_Gemini'!D$61 -> + | E35: ='AI#2_Gemini'!E$61 -> Slave들이 서로 격리된 프로세스/노드 환경에서 실행되므로 결함의 확산이 차단됨.
A36: Human | B36: =Human!B$61 -> + | C36: =Human!C$61 -> 제어 흐름이 명시적이여서 실행 경로 분석과 검증이 쉽다. | D36: - | E36: Master가 종료될 시, 서비스 전체가 동작하지 않음
A38: Security | B38: ='Detailed Reasoning'!B$62 | C38: ='Detailed Reasoning'!C$62 | D38: ='Detailed Reasoning'!D$62 | E38: ='Detailed Reasoning'!E$62
A39: AI#1 | B39: ='AI#1_GPT'!B$62 -> 0 | C39: ='AI#1_GPT'!C62 -> 외부 경계가 적다는 장점은 있지만 내부 함수 간 권한 분리는 약해 구조 자체 효과는 중립적이다. | D39: ='AI#1_GPT'!D$62 -> - | E39: ='AI#1_GPT'!E62 -> 분산 worker와 master 사이의 통신·노드 인증이 추가되어 공격면과 키 관리 복잡성이 증가한다.
A40: AI#2 | B40: ='AI#2_Gemini'!B$62 -> + | C40: ='AI#2_Gemini'!C$62 -> 메모리 공간이 단순하고 통신 채널 노출이 없어 공격 접점이 적음. | D40: ='AI#2_Gemini'!D$62 -> - | E40: ='AI#2_Gemini'!E$62 -> Master와 Slave 간 네트워크 메시지 교환 시 데이터 탈취/위변조 위험 및 접근 제어 복잡성이 증가함.
A41: Human | B41: =Human!B$62 -> + | C41: =Human!C$62 -> 컴포넌트간 직접 호출로 공격 접점이 적음. | D41: - | E41: Master, Slave간 통신 시 위험 존재
A43: Testability | B43: ='Detailed Reasoning'!B$63 | C43: ='Detailed Reasoning'!C$63 | D43: ='Detailed Reasoning'!D$63 | E43: ='Detailed Reasoning'!E$63
A44: AI#1 | B44: ='AI#1_GPT'!B$63 -> + | C44: ='AI#1_GPT'!C63 -> 잘 분리된 서브루틴은 독립 테스트가 쉽지만 전역 상태가 많아지면 장점이 줄어든다. | D44: ='AI#1_GPT'!D$63 -> + | E44: ='AI#1_GPT'!E63 -> worker 로직은 독립 테스트하기 쉽지만 분산 스케줄링·장애 시나리오 검증은 추가로 필요하다.
A45: AI#2 | B45: ='AI#2_Gemini'!B$63 -> ++ | C45: ='AI#2_Gemini'!C$63 -> 입출력이 명확한 동기식 호출 구조이므로 단위 테스트(Unit Test) 및 스텁(Stub) 작성이 매우 용이함. | D45: ='AI#2_Gemini'!D$63 -> - | E45: ='AI#2_Gemini'!E$63 -> 비동기/병렬 실행, 타이밍 이슈(Race Condition), 분산 환경에서의 상태 추적이 어려워 테스트 난이도가 높음.
A46: Human | B46: =Human!B$63 -> ++ | C46: =Human!C$63 -> 입출력이 명확하여 단위 테스트가 용이하다. | D46: =Human!D$63 -> - | E46: =Human!E$63 -> 여러 Slave가 병렬로 실행되므로 타이밍 문제, 레이스 조건(Race Condition), 데드락(Deadlock) 등 실행 시점마다 달라지는 비동기적 결함을 테스트하고 재현하기 어려움
A48: Usability | B48: ='Detailed Reasoning'!B$64 | C48: ='Detailed Reasoning'!C$64 | D48: ='Detailed Reasoning'!D$64 | E48: ='Detailed Reasoning'!E$64
A49: AI#1 | B49: ='AI#1_GPT'!B$64 -> 0 | C49: ='AI#1_GPT'!C64 -> 프로그램 내부 제어 구조이므로 사용자 인터페이스 품질에 직접적인 영향은 거의 없다. | D49: ='AI#1_GPT'!D$64 -> 0 | E49: ='AI#1_GPT'!E64 -> 주로 계산 분산 구조이므로 사용자 경험에 직접적인 영향은 제한적이다.
...

Sheet H2
A1: Hierarchical | B1: Layered | D1: Virtual Machine | F1: Microkernel
B2: Effects | C2: Justification | D2: Effects | E2: Justification | F2: Effects | G2: Justification
A3: Availability | B3: ='Detailed Reasoning'!B$68 | C3: ='Detailed Reasoning'!C$68 | D3: ='Detailed Reasoning'!D$68 | E3: ='Detailed Reasoning'!E$68 | F3: ='Detailed Reasoning'!F$68 | G3: ='Detailed Reasoning'!G$68
A4: AI#1 | B4: ='AI#1_GPT'!B$68 -> 0 | C4: ='AI#1_GPT'!C68 -> 계층 분리는 장애 위치를 구분하는 데 도움을 주지만 하위 계층 장애가 상위 계층에 전파될 수 있다. | D4: ='AI#1_GPT'!D$68 -> + | E4: ='AI#1_GPT'!E68 -> 게스트별 격리와 스냅샷·재시작은 복구에 유리하지만 호스트/하이퍼바이저 장애 영향은 남는다. | F4: ='AI#1_GPT'!F$68 -> ++ | G4: ='AI#1_GPT'!G68 -> 핵심 기능만 커널에 두고 나머지 서비스를 분리해 개별 서비스 장애를 재시작·격리하기 쉽다.
A5: AI#2 | B5: ='AI#2_Gemini'!B$68 -> 0 | C5: ='AI#2_Gemini'!C$68 -> 상위 계층이 하위 계층에 의존하므로 특정 계층 장애 시 전체 서비스 영향 가능. | D5: ='AI#2_Gemini'!D$68 -> + | E5: ='AI#2_Gemini'!E$68 -> 재해 상황 및 동작 모델 시뮬레이션을 지원하여 장애 대비 능력 향상. | F5: ='AI#2_Gemini'!F$68 -> ++ | G5: ='AI#2_Gemini'!G$68 -> 분산 구조에서 동일 Server를 여러 Machine에 실행하여 고가용성(HA) 확보 가능.
A6: Human | B6: =Human!B$68 -> - | C6: =Human!C$68 -> 특정 계층 장애가 전체 서비스에 부정적인 영향을 미칠 수 있다. | D6: =Human!D$68 | E6: =Human!E$68 -> Human - Virtual Machine - Availability | F6: =Human!F$68 | G6: =Human!G$68 -> Human - Microkernel - Availability
A8: Deployability | B8: ='Detailed Reasoning'!B$69 | C8: ='Detailed Reasoning'!C$69 | D8: ='Detailed Reasoning'!D$69 | E8: ='Detailed Reasoning'!E$69 | F8: ='Detailed Reasoning'!F$69 | G8: ='Detailed Reasoning'!G$69
A9: AI#1 | B9: ='AI#1_GPT'!B$69 -> + | C9: ='AI#1_GPT'!C69 -> 계층 경계와 인터페이스가 안정적이면 특정 계층을 독립적으로 교체·업데이트하기 쉬워진다. | D9: ='AI#1_GPT'!D$69 -> ++ | E9: ='AI#1_GPT'!E69 -> 애플리케이션과 실행 환경을 VM 이미지로 함께 패키징해 환경 차이를 줄이고 이동·배포하기 쉽다. | F9: ='AI#1_GPT'!F$69 -> ++ | G9: ='AI#1_GPT'!G69 -> 서버 기능을 독립 프로세스로 추가·교체할 수 있어 핵심을 건드리지 않고 확장하기 좋다.
A10: AI#2 | B10: ='AI#2_Gemini'!B$69 -> + | C10: ='AI#2_Gemini'!C$69 -> 각 Component를 서로 다른 일정으로 독립적으로 배포 및 갱신 가능. | D10: ='AI#2_Gemini'!D$69 -> + | E10: ='AI#2_Gemini'!E$69 -> 가상화 환경 덕분에 Platform 독립적인 이식·배포 용이. | F10: ='AI#2_Gemini'!F$69 -> ++ | G10: ='AI#2_Gemini'!G$69 -> 핵심 Kernel 변경 없이 External Server 단위의 독립적인 확장 및 배포 용이.
A11: Human | B11: =Human!B$69 -> + | C11: =Human!C$69 -> 계층이 분리되어있으므로 특정 계층 독립적으로 배포 가능하다. | D11: =Human!D$69 | E11: =Human!E$69 -> Human - Virtual Machine - Deployability | F11: =Human!F$69 | G11: =Human!G$69 -> Human - Microkernel - Deployability
A13: Integrability | B13: ='Detailed Reasoning'!B$70 | C13: ='Detailed Reasoning'!C$70 | D13: ='Detailed Reasoning'!D$70 | E13: ='Detailed Reasoning'!E$70 | F13: ='Detailed Reasoning'!F$70 | G13: ='Detailed Reasoning'!G$70
A14: AI#1 | B14: ='AI#1_GPT'!B$70 -> + | C14: ='AI#1_GPT'!C70 -> 명확한 계층 인터페이스를 통해 외부 기능을 특정 계층에 연결하고 의존 방향을 제한할 수 있다. | D14: ='AI#1_GPT'!D$70 -> + | E14: ='AI#1_GPT'!E70 -> 표준화된 가상 하드웨어와 네트워크 환경이 서로 다른 플랫폼 간 실행 환경 통합을 돕는다. | F14: ='AI#1_GPT'!F$70 -> + | G14: ='AI#1_GPT'!G70 -> 명확한 IPC 계약을 통해 새로운 서비스나 드라이버를 연결하기 쉬운 편이다.
A15: AI#2 | B15: ='AI#2_Gemini'!B$70 -> + | C15: ='AI#2_Gemini'!C$70 -> 하위 계층 인터페이스가 명확하여 외부 모듈/라이브러리 연동이 수월함. | D15: ='AI#2_Gemini'!D$70 -> 0 | E15: ='AI#2_Gemini'!E$70 -> 가상 플랫폼 규격에 맞춰 외부 요소 통합 가능. | F15: ='AI#2_Gemini'!F$70 -> -- | G15: ='AI#2_Gemini'!G$70 -> 서버 간 통신 프로토콜 및 커널 인터페이스 구성으로 인해 외부 시스템 연동 난이도가 높음.
A16: Human | B16: =Human!B$70 -> + | C16: =Human!C$70 -> 명확한 계층 인터페이스로 인하여 외부 모듈의 연동이 수월하다. | D16: =Human!D$70 | E16: =Human!E$70 -> Human - Virtual Machine - Integrability | F16: =Human!F$70 | G16: =Human!G$70 -> Human - Microkernel - Integrability
A18: Energy Efficiency | B18: ='Detailed Reasoning'!B$71 | C18: ='Detailed Reasoning'!C$71 | D18: ='Detailed Reasoning'!D$71 | E18: ='Detailed Reasoning'!E$71 | F18: ='Detailed Reasoning'!F$71 | G18: ='Detailed Reasoning'!G$71
A19: AI#1 | B19: ='AI#1_GPT'!B$71 -> - | C19: ='AI#1_GPT'!C71 -> 여러 계층을 통과하는 호출·데이터 변환이 추가되어 직접 구현보다 오버헤드가 증가한다. | D19: ='AI#1_GPT'!D$71 -> -- | E19: ='AI#1_GPT'!E71 -> 게스트 OS가 중복되고 가상화 계층이 추가되어 컨테이너나 네이티브보다 메모리·CPU 자원 소비가 크다. | F19: ='AI#1_GPT'!F$71 -> - | G19: ='AI#1_GPT'!G71 -> 서비스 간 IPC와 컨텍스트 스위칭이 빈번해 단일 커널 구조보다 추가 자원 비용이 발생한다.
A20: AI#2 | B20: ='AI#2_Gemini'!B$71 -> - | C20: ='AI#2_Gemini'!C$71 -> 층 통과 시 발생하는 함수 호출 오버헤드로 에너지 소모 존재. | D20: ='AI#2_Gemini'!D$71 -> -- | E20: ='AI#2_Gemini'!E$71 -> 인터프리터 방식 및 추가 계층 레이어로 인해 CPU/메모리 자원 및 에너지 소모가 가장 큼. | F20: ='AI#2_Gemini'!F$71 -> - | G20: ='AI#2_Gemini'!G$71 -> 버 간 IPC(프로세스 간 통신) 오버헤드로 인해 에너지 효율이 낮음.
A21: Human | B21: =Human!B$71 -> - | C21: =Human!C$71 -> 여러 계층을 통과하는 과정에서 호출 및 데이터 변환에 의한 오버헤드가 발생한다. | D21: =Human!D$71 | E21: =Human!E$71 -> Human - Virtual Machine - Energy Efficiency | F21: =Human!F$71 | G21: =Human!G$71 -> Human - Microkernel - Energy Efficiency
A23: Modifiability | B23: ='Detailed Reasoning'!B$72 | C23: ='Detailed Reasoning'!C$72 | D23: ='Detailed Reasoning'!D$72 | E23: ='Detailed Reasoning'!E$72 | F23: ='Detailed Reasoning'!F$72 | G23: ='Detailed Reasoning'!G$72
A24: AI#1 | B24: ='AI#1_GPT'!B$72 -> ++ | C24: ='AI#1_GPT'!C72 -> 변경을 해당 책임 계층에 국소화할 수 있어 다른 부분에 대한 파급을 크게 줄인다. | D24: ='AI#1_GPT'!D$72 -> + | E24: ='AI#1_GPT'!E72 -> OS·미들웨어 의존성을 VM 내부에 캡슐화해 호스트 환경 변경의 영향을 줄일 수 있다. | F24: ='AI#1_GPT'!F$72 -> ++ | G24: ='AI#1_GPT'!G72 -> 최소 커널을 유지하면서 주변 서비스만 변경할 수 있어 변경 파급 범위가 매우 작다.
A25: AI#2 | B25: ='AI#2_Gemini'!B$72 -> + | C25: ='AI#2_Gemini'!C$72 -> 높은 응집도와 하위 계층에만 결합된 구조로 Layer 교체/대체가 쉬움 | D25: ='AI#2_Gemini'!D$72 -> + | E25: ='AI#2_Gemini'!E$72 -> 하드웨어 변경에 영향받지 않는 소프트웨어 개발 및 수정 단순화. | F25: ='AI#2_Gemini'!F$72 -> ++ | G25: ='AI#2_Gemini'!G$72 -> 새로운 View 필요 시 External Server, 기능 추가 시 Internal Server만 추가/확장하면 되어 가장 우수
A26: Human | B26: =Human!B$72 -> + | C26: =Human!C$72 -> 특정 계층에 변경을 국소화할 수 있으므로 상위 계층에 대한 파급이 적을 수 있다. | D26: =Human!D$72 | E26: =Human!E$72 -> Human - Virtual Machine - Modifiability | F26: =Human!F$72 | G26: =Human!G$72 -> Human - Microkernel - Modifiability
A28: Performance | B28: ='Detailed Reasoning'!B$73 | C28: ='Detailed Reasoning'!C$73 | D28: ='Detailed Reasoning'!D$73 | E28: ='Detailed Reasoning'!E$73 | F28: ='Detailed Reasoning'!F$73 | G28: ='Detailed Reasoning'!G$73
A29: AI#1 | B29: ='AI#1_GPT'!B$73 -> - | C29: ='AI#1_GPT'!C73 -> 요청이 여러 계층을 거치며 간접 호출·변환이 누적되어 지연이 늘어날 수 있다. | D29: ='AI#1_GPT'!D$73 -> - | E29: ='AI#1_GPT'!E73 -> 하드웨어 가상화 오버헤드와 추가 I/O 경로로 네이티브보다 성능 손실이 발생할 수 있다. | F29: ='AI#1_GPT'!F$73 -> -- | G29: ='AI#1_GPT'!G73 -> 시스템 호출이 여러 IPC·컨텍스트 전환을 거칠 수 있어 모놀리식 구조보다 지연이 커지기 쉽다.
A30: AI#2 | B30: ='AI#2_Gemini'!B$73 -> - | C30: ='AI#2_Gemini'!C$73 -> Layer가 너무 많아지면 요청 전달 시 호출 Overhead 발생 | D30: ='AI#2_Gemini'!D$73 -> -- | E30: ='AI#2_Gemini'!E$73 -> 인터프리터 방식 특성 및 새 계층 추가에 따른 Overhead로 실행 속도가 가장 느림. | F30: ='AI#2_Gemini'!F$73 -> - | G30: ='AI#2_Gemini'!G$73 -> 모놀리식 시스템(Monolithic) 대비 서버 간 IPC(통신) Overhead로 인해 성능 감소.
A31: Human | B31: =Human!B$73 -> - | C31: =Human!C$73 -> 계층 누적에 따른 오버헤드 발생 | D31: =Human!D$73 | E31: =Human!E$73 -> Human - Virtual Machine - Performance | F31: =Human!F$73 | G31: =Human!G$73 -> Human - Microkernel - Performance
A33: Safety | B33: ='Detailed Reasoning'!B$74 | C33: ='Detailed Reasoning'!C$74 | D33: ='Detailed Reasoning'!D$74 | E33: ='Detailed Reasoning'!E$74 | F33: ='Detailed Reasoning'!F$74 | G33: ='Detailed Reasoning'!G$74
A34: AI#1 | B34: ='AI#1_GPT'!B$74 -> + | C34: ='AI#1_GPT'!C74 -> 입력 검증, 업무 규칙, 데이터 접근을 계층별로 분리해 잘못된 접근 경로를 통제하기 좋다. | D34: ='AI#1_GPT'!D$74 -> ++ | E34: ='AI#1_GPT'!E74 -> 게스트 간 강한 격리를 통해 한 실행환경의 오류가 다른 환경으로 전파되는 것을 제한한다. | F34: ='AI#1_GPT'!F$74 -> ++ | G34: ='AI#1_GPT'!G74 -> 서비스를 사용자 공간에 격리해 드라이버·서비스 오류가 시스템 전체를 손상시키는 위험을 줄인다.
A35: AI#2 | B35: ='AI#2_Gemini'!B$74 -> 0 | C35: ='AI#2_Gemini'!C$74 -> 계층별 하부 구조 의존으로 오류 파급 제어는 제한적임. | D35: ='AI#2_Gemini'!D$74 -> + | E35: ='AI#2_Gemini'!E$74 -> 호스트 시스템과의 가상 격리를 통해 하드웨어/시스템 안전성 확보. | F35: ='AI#2_Gemini'!F$74 -> + | G35: ='AI#2_Gemini'!G$74 -> 핵심 커널과 서버 기능의 분리로 특정 서버의 결함이 전체 커널 시스템으로 전이되지 않음.
A36: Human | B36: =Human!B$74 -> 0 | C36: =Human!C$74 -> 하위 계층에만 결합되어 있어 변경/장애의 확산을 일부 제한할 수 있으나, 최하위 핵심 계층(예: DB/Infra Layer)에 오류가 발생하면 상위 계층 전체에 영향을 줄 수 있어 제어 범위가 제한적임. | D36: =Human!D$74 | E36: =Human!E$74 -> Human - Virtual Machine - Safety | F36: =Human!F$74 | G36: =Human!G$74 -> Human - Microkernel - Safety
A38: Security | B38: ='Detailed Reasoning'!B$75 | C38: ='Detailed Reasoning'!C$75 | D38: ='Detailed Reasoning'!D$75 | E38: ='Detailed Reasoning'!E$75 | F38: ='Detailed Reasoning'!F$75 | G38: ='Detailed Reasoning'!G$75
A39: AI#1 | B39: ='AI#1_GPT'!B$75 -> ++ | C39: ='AI#1_GPT'!C75 -> 계층별 검증·인가를 겹쳐 적용하는 defense-in-depth 구조를 만들기 좋다. | D39: ='AI#1_GPT'!D$75 -> + | E39: ='AI#1_GPT'!E75 -> VM 경계가 강한 격리를 제공하지만 하이퍼바이저 취약점은 공통 위험이 된다. | F39: ='AI#1_GPT'!F$75 -> ++ | G39: ='AI#1_GPT'!G75 -> 작은 trusted computing base와 최소 권한의 서비스 분리가 공격 표면과 침해 범위를 줄인다.
A40: AI#2 | B40: ='AI#2_Gemini'!B$75 -> + | C40: ='AI#2_Gemini'!C$75 -> 계층 간 내부 정보 은닉(Information Hiding)을 통해 상위/하위 보안 유지. | D40: ='AI#2_Gemini'!D$75 -> + | E40: ='AI#2_Gemini'!E$75 -> 격리된 샌드박스 환경을 제공하여 외부 공격 및 이상 동작 차단. | F40: ='AI#2_Gemini'!F$75 -> + | G40: ='AI#2_Gemini'!G$75 -> 최소 권한의 커널 구동 및 서브시스템 격리로 보안 침범 범위 최소화.
A41: Human | B41: =Human!B$75 -> + | C41: =Human!C$75 -> layer별 private정보를 다른 layer에서 확인 어렵기 때문에 security 좋음 | D41: =Human!D$75 | E41: =Human!E$75 -> Human - Virtual Machine - Security | F41: =Human!F$75 | G41: =Human!G$75 -> Human - Microkernel - Security
A43: Testability | B43: ='Detailed Reasoning'!B$76 | C43: ='Detailed Reasoning'!C$76 | D43: ='Detailed Reasoning'!D$76 | E43: ='Detailed Reasoning'!E$76 | F43: ='Detailed Reasoning'!F$76 | G43: ='Detailed Reasoning'!G$76
A44: AI#1 | B44: ='AI#1_GPT'!B$76 -> ++ | C44: ='AI#1_GPT'!C76 -> 각 계층을 Mock으로 격리해 단위 테스트하고 계층 간 계약을 별도로 검증하기 쉽다. | D44: ='AI#1_GPT'!D$76 -> ++ | E44: ='AI#1_GPT'!E76 -> 동일한 VM 이미지를 반복 생성해 재현 가능한 테스트 환경과 스냅샷 기반 복구를 제공하기 쉽다. | F44: ='AI#1_GPT'!F$76 -> + | G44: ='AI#1_GPT'!G76 -> 개별 서비스는 격리 테스트하기 쉽지만 IPC와 전체 시스템 통합 테스트는 여전히 필요하다.
A45: AI#2 | B45: ='AI#2_Gemini'!B$76 -> + | C45: ='AI#2_Gemini'!C$76 -> 각 계층 및 컴포넌트를 독립적으로 분리하여 테스트(Mocking)하기 쉬움. | D45: ='AI#2_Gemini'!D$76 -> + | E45: ='AI#2_Gemini'!E$76 -> 테스트 환경 시뮬레이션 및 가상 상태 캡처/복원이 용이함. | F45: ='AI#2_Gemini'!F$76 -> 0 | G45: ='AI#2_Gemini'!G$76 -> 서버 간 비동기 메시지 교환 및 복잡한 상호작용으로 인해 종합 테스트 난이도가 존재함.
A46: Human | B46: =Human!B$76 -> + | C46: =Human!C$76 -> 독립된 layer별 test에 용이 | D46: =Human!D$76 | E46: =Human!E$76 -> Human - Virtual Machine - Testability | F46: =Human!F$76 | G46: =Human!G$76 -> Human - Microkernel - Testability
A48: Usability | B48: ='Detailed Reasoning'!B$77 | C48: ='Detailed Reasoning'!C$77 | D48: ='Detailed Reasoning'!D$77 | E48: ='Detailed Reasoning'!E$77 | F48: ='Detailed Reasoning'!F$77 | G48: ='Detailed Reasoning'!G$77
A49: AI#1 | B49: ='AI#1_GPT'!B$77 -> + | C49: ='AI#1_GPT'!C77 -> Presentation 계층을 업무 로직과 분리하면 UI 변경과 다양한 클라이언트 지원이 쉬워진다. | D49: ='AI#1_GPT'!D$77 -> 0 | E49: ='AI#1_GPT'!E77 -> 실행환경 일관성은 운영자에게 유용하지만 최종 사용자 UX에는 직접 영향이 크지 않다. | F49: ='AI#1_GPT'!F$77 -> 0 | G49: ='AI#1_GPT'!G77 -> OS 내부 구조의 장점이 주로 운영·안정성에 나타나며 최종 사용자 인터페이스에는 간접적이다.
...

Sheet DA1
A1: Distributed | B1: Multi-Tier | D1: Client-Server
B2: Effects | C2: Justification | D2: Effects | E2: Justification
A3: Availability | B3: 0 | C3: 0 | D3: 0 | E3: 0
A4: AI#1 | B4: ='AI#1_GPT'!B$81 -> + | C4: ='AI#1_GPT'!C81 -> 각 tier를 복제·스케일아웃해 장애를 우회할 수 있지만 tier 간 의존성 때문에 완전한 격리는 어렵다. | D4: ='AI#1_GPT'!D$81 -> - | E4: ='AI#1_GPT'!E81 -> 중앙 서버가 중단되면 많은 클라이언트가 동시에 서비스를 잃는 장애점이 되기 쉽다.
A5: AI#2 | B5: ='AI#2_Gemini'!B$81 -> 0 | C5: ='AI#2_Gemini'!C81 -> 계층 증가로 관리 요소는 늘어나지만, Middle tier의 분산 및 이중화 구성을 통해 가용성 위험을 보완 가능함. | D5: ='AI#2_Gemini'!D$81 -> - | E5: ='AI#2_Gemini'!E81 -> 서버가 단일 실패점(Single Point of Failure, SPOF)이 될 수 있어 서버 장애 시 전체 시스템 중단 위험이 큼.
A6: Human | B6: =Human!B$81 -> - | C6: =Human!C81 -> Tier가 증가할 수록 위험성이 증가하여 관리 요소가 늘어날 수 있음. | D6: =Human!D$81 -> - | E6: =Human!E81 -> 서버가 단일 실패점이 될 수 있어 서버 장애 시 전체 시스템 중단될 수 있다.
A8: Deployability | B8: 0 | C8: 0 | D8: 0 | E8: 0
A9: AI#1 | B9: ='AI#1_GPT'!B$82 -> + | C9: ='AI#1_GPT'!C82 -> Presentation·Business·Data tier를 별도 배포할 수 있으나 버전 호환과 순서 조정이 필요할 수 있다. | D9: ='AI#1_GPT'!D$82 -> 0 | E9: ='AI#1_GPT'!E82 -> 클라이언트와 서버를 따로 배포할 수 있지만 API 호환성과 클라이언트 버전 관리가 필요하다.
A10: AI#2 | B10: ='AI#2_Gemini'!B$82 -> + | C10: ='AI#2_Gemini'!C82 -> Business Logic이 포함된 Middle tier 중심으로 독립적 배포 및 스케일링이 수월함. | D10: ='AI#2_Gemini'!D$82 -> + | E10: ='AI#2_Gemini'!E82 -> UI 표현과 Business Logic 처리가 분리되어 클라이언트와 서버를 각각 독립적으로 배포 가능함.
A11: Human | B11: =Human!B$82 -> + | C11: =Human!C82 -> 각 Tier별 기능이 나누어져 있으므로 Tier에 해당하는 시스템의 단독 배포가 용이하다. | D11: =Human!D$82 -> + | E11: =Human!E82 -> 클라이언트와 서버를 각각 독립적으로 배포가 가능하다.
A13: Integrability | B13: 0 | C13: 0 | D13: 0 | E13: 0
A14: AI#1 | B14: ='AI#1_GPT'!B$83 -> + | C14: ='AI#1_GPT'!C83 -> tier 간 명확한 네트워크 인터페이스를 통해 외부 시스템 연결 지점을 분리하기 좋다. | D14: ='AI#1_GPT'!D$83 -> + | E14: ='AI#1_GPT'!E83 -> 서버가 명확한 API를 제공하면 다양한 클라이언트와 외부 시스템을 동일 인터페이스로 연결하기 쉽다.
A15: AI#2 | B15: ='AI#2_Gemini'!B$83 -> + | C15: ='AI#2_Gemini'!C83 -> Presentation, Application, Data 계층이 명확히 분리되어 외부 서비스 및 DB 통합이 매우 용이함. | D15: ='AI#2_Gemini'!D$83 -> + | E15: ='AI#2_Gemini'!E83 -> 클라이언트와 서버 간의 역할 분담 및 표준화된 요청-응답 구조로 연동이 용이함.
A16: Human | B16: =Human!B$83 -> + | C16: =Human!C83 -> Tier마다 서로 다른 기능 및 책임을 부여하여 외부 서비스의 확장에 용이하다. | D16: =Human!D$83 -> + | E16: =Human!E83 -> 서버가 API를 제공한다면 표준화된 요청-응답 구조로 클라이언트를 연결하기 쉽다.
A18: Energy Efficiency | B18: 0 | C18: 0 | D18: 0 | E18: 0
A19: AI#1 | B19: ='AI#1_GPT'!B$84 -> - | C19: ='AI#1_GPT'!C84 -> 여러 서버 계층과 네트워크 홉을 유지하므로 단일 프로세스 구조보다 자원 소비가 증가한다. | D19: ='AI#1_GPT'!D$84 -> 0 | E19: ='AI#1_GPT'!E84 -> 서버에 자원을 집중할 수 있지만 네트워크 통신과 상시 서버 운영 비용이 발생한다.
A20: AI#2 | B20: ='AI#2_Gemini'!B$84 -> - | C20: ='AI#2_Gemini'!C84 -> tier 간 request/reply 통신으로 복잡성과 오버헤드가 발생한다. | D20: ='AI#2_Gemini'!D$84 -> 0 | E20: ='AI#2_Gemini'!E84 -> 이 아키텍처 스타일이 해당 품질속성을 직접 좌우하지 않음.
A21: Human | B21: =Human!B$84 -> - | C21: =Human!C84 -> 여러 서버 tier를 유지해야 하며, middle tier의 다중화가 적용된다면 Energy 소모량이 많아진다. | D21: =Human!D$84 -> + | E21: =Human!E84 -> 많은 client가 고성능 server에 접근할 때 자원을 효과적으로 사용한다.
A23: Modifiability | B23: 0 | C23: 0 | D23: 0 | E23: 0
A24: AI#1 | B24: ='AI#1_GPT'!B$85 -> + | C24: ='AI#1_GPT'!C85 -> 책임을 tier별로 나눠 UI·업무·데이터 변경을 어느 정도 독립적으로 수행할 수 있다. | D24: ='AI#1_GPT'!D$85 -> + | E24: ='AI#1_GPT'!E85 -> 서버 로직과 클라이언트 UI를 분리해 한쪽 변경을 독립적으로 수행할 여지가 있다.
A25: AI#2 | B25: ='AI#2_Gemini'!B$85 -> + | C25: ='AI#2_Gemini'!C85 -> 비즈니스 관련 변경은 중간 tier에만 적용되어 재사용성·수정 용이성이 높다(reusability and modifiability). | D25: ='AI#2_Gemini'!D$85 -> + | E25: ='AI#2_Gemini'!E85 -> 책임이 분리되고(UI 표현 vs 비즈니스 로직) server 컴포넌트를 재사용할 수 있다.
A26: Human | B26: =Human!B$85 -> + | C26: =Human!C85 -> 각 Tier간 책임이 분산되어 있으므로 재사용성이 높고 수정에 용이하다. | D26: =Human!D$85 -> + | E26: =Human!E85 -> UI표현과 business logic 처리 같은 책임이 분리되어 있고 서버 컴포넌트 재사용할 수 있다.
A28: Performance | B28: 0 | C28: 0 | D28: 0 | E28: 0
A29: AI#1 | B29: ='AI#1_GPT'!B$86 -> 0 | C29: ='AI#1_GPT'!C86 -> 네트워크 지연은 늘지만 각 tier를 독립 확장해 병목을 완화할 수 있어 효과가 상쇄된다. | D29: ='AI#1_GPT'!D$86 -> 0 | E29: ='AI#1_GPT'!E86 -> 중앙 서버 최적화의 장점이 있지만 네트워크 지연과 서버 병목이 동시에 존재한다.
A30: AI#2 | B30: ='AI#2_Gemini'!B$86 -> 0 | C30: ='AI#2_Gemini'!C86 -> [+] 교안: 중간 tier가 확장성·성능을 위한 멀티스레딩을 지원한다. [-] 복잡성과 오버헤드가 있다. | D30: ='AI#2_Gemini'!D$86 -> 0 | E30: ='AI#2_Gemini'!E86 -> [+] 교안: 동시성·확장성의 잠재력이 있고 다수 client가 고성능 server에 접근할 때 자원을 효과적으로 쓴다. [-] server가 성능 병목이 될 수 있다.
A31: Human | B31: =Human!B$86 -> 0 | C31: =Human!C86 -> Multithread, 다중화를 시키는 것으로 Performance의 확장이 가능하나, tier간 통신에 의한 O/H, tier가 너무 많아지면 추가로 O/H가 증가할 위험성이 있다. | D31: =Human!D$86 -> 0 | E31: =Human!E86 -> 동시성과 확정성의 가능성이 있으나 서버가 bottleneck이 될 수 있다.
A33: Safety | B33: 0 | C33: 0 | D33: 0 | E33: 0
A34: AI#1 | B34: ='AI#1_GPT'!B$87 -> + | C34: ='AI#1_GPT'!C87 -> 업무 규칙과 데이터 접근을 별도 tier로 통제해 잘못된 요청이 핵심 데이터에 직접 닿지 않게 할 수 있다. | D34: ='AI#1_GPT'!D$87 -> + | E34: ='AI#1_GPT'!E87 -> 중요한 업무 규칙과 데이터 검증을 서버에서 일관되게 강제할 수 있다.
A35: AI#2 | B35: ='AI#2_Gemini'!B$87 -> 0 | C35: ='AI#2_Gemini'!C87 -> 이 아키텍처 스타일이 해당 품질속성을 직접 좌우하지 않음. | D35: ='AI#2_Gemini'!D$87 -> 0 | E35: ='AI#2_Gemini'!E87 -> 이 아키텍처 스타일이 해당 품질속성을 직접 좌우하지 않음.
A36: Human | B36: =Human!B$87 -> 0 | C36: =Human!C87 -> Tier 분리를 통해 오류를 검증·격리할 수 있어 Safety에 긍정적이지만, Tier가 많아지거나 계층 간 장애 전파 가능성이 존재할 경우 상쇄된다. | D36: =Human!D$87 -> + | E36: =Human!E87 -> 서버와 클라이언트가 분리되어 있어 장애의 직접적인 전파 및 영향 범위를 제한할 수 있다.
A38: Security | B38: 0 | C38: 0 | D38: 0 | E38: 0
