Workbook

Sheet DF
B1: Batch Sequential | D1: Pipe and Filter | F1: Process Control
B2: Effects | C2: Justification | D2: Effects | E2: Justification | F2: Effects | G2: Justification
A3: Availability | B3: ='Detailed Reasoning'!B$3 | C3: ='Detailed Reasoning'!C$3 | D3: ='Detailed Reasoning'!D$3 | E3: ='Detailed Reasoning'!E$3 | F3: ='Detailed Reasoning'!F$3 | G3: ='Detailed Reasoning'!G$3
A4: 1조 | B4: ='1조'!B$3 -> -- | C4: ='1조'!C3 -> 각 컴포넌트에서 장애가 발생시 전체 data flow의 중단으로 이어질 수 있다 | D4: ='1조'!D$3 -> + | E4: ='1조'!E3 -> Pipe에 Buffer/Queue를 적용하면 장애 격리 및 재처리 가능 | F4: ='1조'!F$3 -> ++ | G4: ='1조'!G3 -> Controller가 Process의 상태를 지속적으로 확인하고 장애나 상태 변화에 동적으로 대응할 수 있음
A5: 2조 | B5: ='2조'!B$3 -> -- | C5: ='2조'!C$3 -> 앞에 단계가 끝나야 다음 단계이므로 한 단계 실패 시 전체 중단, 복구도 오래 걸림 | D5: ='2조'!D$3 | E5: ='2조'!E$3 | F5: ='2조'!F$3 -> 0 | G5: ='2조'!G$3 -> 장애시 피드백 루프 자체는 동작 가능하지만, 컨트롤러 장애 시 제어 불능 상태가 됨
A6: 3조 | B6: ='3조'!B$3 -> -- | C6: ='3조'!C$3 -> sequence 중 하나라도 에러가 발생하면 모든 시스템이 먹통이 된다 | D6: ='3조'!D$3 | E6: ='3조'!E$3 -> 3조 - Pipe and Filter - Availability | F6: ='3조'!F$3 | G6: ='3조'!G$3 -> 3조 - Process Control - Availability
A7: 4조 | B7: ='4조'!B$3 -> -- | C7: ='4조'!C$3 -> 하나의 processing step이 fault 발생시 의존하는 다른 step이 진행될 수가 없음 | D7: ='4조'!D$3 | E7: ='4조'!E$3 -> 4조 - Pipe and Filter - Availability | F7: ='4조'!F$3 | G7: ='4조'!G$3 -> 4조 - Process Control - Availability
A8: 5조숙 | B8: ='5조'!B$3 -> -- | C8: ='5조'!C$3 -> 한 단계에서 문제 발생시 모든 시퀀스가 기다려야 함 | D8: ='5조'!D$3 -> -- | E8: ='5조'!E$3 -> flow 일부가 망가지면 전체 동작 불가능해짐 | F8: ='5조'!F$3 | G8: ='5조'!G$3 -> 5조 - Process Control - Availability
A9: 6조 | B9: ='6조'!B$3 -> -- | C9: ='6조'!C$3 -> 순차적 파이프라인 구조상 특정 단계에서 장애나 에러가 발생하면 후속 단계가 진행되지 못하고 전체 데이터 흐름이 중단되며, 오류 복구 및 재수행에도 오랜 시간이 소요됨. | D9: ='6조'!D$3 -> + | E9: ='6조'!E$3 -> Pipe에 Buffer/Queue를 적용하면 장애 격리 및 재처리 가능 | F9: ='6조'!F$3 -> 0 | G9: ='6조'!G$3 -> 장애시 피드백 루프 자체는 동작 가능하지만, 컨트롤러 장애 시 제어 불능 상태가 됨
A10: 7조 | B10: ='7조'!B$3 | C10: ='7조'!C$3 -> 7조 - Batch Sequential - Availability | D10: ='7조'!D$3 | E10: ='7조'!E$3 -> 7조 - Pipe and Filter - Availability | F10: ='7조'!F$3 | G10: ='7조'!G$3 -> 7조 - Process Control - Availability
A11: 8조 | B11: ='8조'!B$3 | C11: ='8조'!C$3 -> 8조 - Batch Sequential - Availability | D11: ='8조'!D$3 | E11: ='8조'!E$3 -> 8조 - Pipe and Filter - Availability | F11: ='8조'!F$3 | G11: ='8조'!G$3 -> 8조 - Process Control - Availability
A12: 9조 | B12: ='9조'!B$3 | C12: ='9조'!C$3 -> 9조 - Batch Sequential - Availability | D12: ='9조'!D$3 | E12: ='9조'!E$3 -> 9조 - Pipe and Filter - Availability | F12: ='9조'!F$3 | G12: ='9조'!G$3 -> 9조 - Process Control - Availability
A14: Deployability | B14: ='Detailed Reasoning'!B$4 | C14: ='Detailed Reasoning'!C$4 | D14: ='Detailed Reasoning'!D$4 | E14: ='Detailed Reasoning'!E$4 | F14: ='Detailed Reasoning'!F$4 | G14: ='Detailed Reasoning'!G$4
A15: 1조 | B15: ='1조'!B$4 -> + | C15: ='1조'!C4 -> 단계별 독립 배포가 가능하다. 다만 단계간 결합도가 낮을수록 배포가 쉬워진다 | D15: ='1조'!D$4 -> ++ | E15: ='1조'!E4 -> 각 필터가 독립적인 컴포넌트로 분리되어 있고, 파이프의 표준 인터페이스를 준수하므로 특정 필터만 개별적으로 무중단 배포하기 용이함 | F15: ='1조'!F$4 -> - | G15: ='1조'!G4 -> 런타임 제어가 중단되면 물리적/시스템적 위험이 생길 수 있으므로, 제어 루프가 도는 도중에 무중단 배포를 적용하기가 까다로움. 또한 Controller의 제어 로직을 변경하면 Process의 동작에 영향
A16: 2조 | B16: ='2조'!B$4 -> -- | C16: ='2조'!C$4 -> 전체 파이프라인이 하나로 묶여 있어 부분 배포와 롤백이 어려움 | D16: ='2조'!D$4 | E16: ='2조'!E$4 -> 2조 - Pipe and Filter - Deployability | F16: ='2조'!F$4 -> - | G16: ='2조'!G$4 -> 하드웨어(센서/액추에이터)와 제어 로직이 긴밀히 결합되어 있어 독립 배포가 어려움
A17: 3조 | B17: ='3조'!B$4 -> ++ | C17: ='3조'!C$4 -> 항상 같은 sequence가 반복되기 때문에 input에 따른 동작, 시간, 비용 예측이 쉬울 것 같다 | D17: ='3조'!D$4 | E17: ='3조'!E$4 -> 3조 - Pipe and Filter - Deployability | F17: ='3조'!F$4 | G17: ='3조'!G$4 -> 3조 - Process Control - Deployability
A18: 4조 | B18: ='4조'!B$4 -> 0 | C18: ='4조'!C$4 -> 순차적으로 실행되기 때문에 전체 수행시간이 예측 가능함. 하지만 수행시간이 너무 긴 작업일 경우 제한된 운영 환경에서는 이식되기 어려울 수 있음. | D18: ='4조'!D$4 | E18: ='4조'!E$4 -> 4조 - Pipe and Filter - Deployability | F18: ='4조'!F$4 | G18: ='4조'!G$4 -> 4조 - Process Control - Deployability
A19: 5조 | B19: ='5조'!B$4 -> ++ | C19: ='5조'!C$4 -> 각 단계별 중간산출물을 명확히 파악 가능 | D19: ='5조'!D$4 -> + | E19: ='5조'!E$4 -> test 환경과 운영환경이 크게 달라질 일 없음 | F19: ='5조'!F$4 | G19: ='5조'!G$4 -> 5조 - Process Control - Deployability
A20: 6조 | B20: ='6조'!B$4 -> + | C20: ='6조'!C$4 -> 단계별 경계와 중간 산출물이 명확하여 결합도가 낮을 경우 개별 배치 프로그램을 독립적으로 배포·교체하기 용이함. 다만 전체 파이프라인이 하나로 묶여 관리되는 환경에서는 부분 배포 및 롤백이 어려울 수 있음. | D20: ='6조'!D$4 -> ++ | E20: ='6조'!E$4 -> 각 필터가 독립적인 컴포넌트로 분리되어 있고, 파이프의 표준 인터페이스를 준수하므로 특정 필터만 개별적으로 무중단 배포하기 용이함 | F20: ='6조'!F$4 -> - | G20: ='6조'!G$4 -> 하드웨어(센서/액추에이터)와 제어 로직이 긴밀히 결합되어 있어 독립 배포가 어려움
A21: 7조 | B21: ='7조'!B$4 | C21: ='7조'!C$4 -> 7조 - Batch Sequential - Deployability | D21: ='7조'!D$4 | E21: ='7조'!E$4 -> 7조 - Pipe and Filter - Deployability | F21: ='7조'!F$4 | G21: ='7조'!G$4 -> 7조 - Process Control - Deployability
A22: 8조 | B22: ='8조'!B$4 | C22: ='8조'!C$4 -> 8조 - Batch Sequential - Deployability | D22: ='8조'!D$4 | E22: ='8조'!E$4 -> 8조 - Pipe and Filter - Deployability | F22: ='8조'!F$4 | G22: ='8조'!G$4 -> 8조 - Process Control - Deployability
A23: 9조 | B23: ='9조'!B$4 | C23: ='9조'!C$4 -> 9조 - Batch Sequential - Deployability | D23: ='9조'!D$4 | E23: ='9조'!E$4 -> 9조 - Pipe and Filter - Deployability | F23: ='9조'!F$4 | G23: ='9조'!G$4 -> 9조 - Process Control - Deployability
A25: Integrability | B25: ='Detailed Reasoning'!B$5 | C25: ='Detailed Reasoning'!C$5 | D25: ='Detailed Reasoning'!D$5 | E25: ='Detailed Reasoning'!E$5 | F25: ='Detailed Reasoning'!F$5 | G25: ='Detailed Reasoning'!G$5
A26: 1조 | B26: ='1조'!B$5 -> + | C26: ='1조'!C5 -> interface가 잘 정의되어 있다면 입력->처리->출력 형태로 명확하게 나눌수있기에 integrability가 높다. | D26: ='1조'!D$5 -> ++ | E26: ='1조'!E5 -> 파이프를 흐르는 데이터의 인터페이스가 표준화되어 있어, 서로 다른 언어/기술로 작성된 새로운 필터나 외부 시스템을 파이프라인 중간에 쉽게 끼워 넣을 수 있음 | F26: ='1조'!F$5 -> 0 | G26: ='1조'!G5 -> sensor, Controller, Process, Actuator 간 명확한 Interface가 중요. 장치별 Protocol이나 데이터 형식에 강하게 의존하면 통합성이 떨어짐
A27: 2조 | B27: ='2조'!B$5 -> - | C27: ='2조'!C$5 -> 단계 간 강한 순서와 데이터 의존성으로 신규 컴포넌트 끼워넣기 어려움 | D27: ='2조'!D$5 | E27: ='2조'!E$5 -> 2조 - Pipe and Filter - Integrability | F27: ='2조'!F$5 -> 0 | G27: ='2조'!G$5 -> 하드웨어(센서/액추에이터)가 표준 인터페이스를 따르면 교체 가능하나, 제어 루프의 재구성은 쉽지 않음
A28: 3조 | B28: ='3조'!B$5 -> - | C28: ='3조'!C$5 -> sequence가 정해져 있어서 다른 시스템, 컴포넌트와 통합되기 힘들어 보인다 | D28: ='3조'!D$5 | E28: ='3조'!E$5 -> 3조 - Pipe and Filter - Integrability | F28: ='3조'!F$5 | G28: ='3조'!G$5 -> 3조 - Process Control - Integrability
A29: 4조 | B29: ='4조'!B$5 -> ++ | C29: ='4조'!C$7 -> 실행되는 step의 입력 데이터와 출력 데이터 간의 파일 형식만 맞추면 다른 형태로 쉽게 교체가 가능함 | D29: ='4조'!D$5 | E29: ='4조'!E$5 -> 4조 - Pipe and Filter - Integrability | F29: ='4조'!F$5 | G29: ='4조'!G$5 -> 4조 - Process Control - Integrability
A30: 5조 | B30: ='5조'!B$5 -> ++ | C30: ='5조'!C$5 -> sequence당 중간 산출물이 명확하여 모듈 구성이 용이 | D30: ='5조'!D$5 -> + | E30: ='5조'!E$5 -> 중간 산출물의 형태가 비교적 명확히 정의되어있음 | F30: ='5조'!F$5 | G30: ='5조'!G$5 -> 5조 - Process Control - Integrability
A31: 6조 | B31: ='6조'!B$5 -> + | C31: ='6조'!C$5 -> 각 단계 간 입력/출력 데이터 파일 포맷만 표준화되어 있으면 새로운 컴포넌트를 연계하거나 교체하기 용이함. 반면, 강한 실행 순서 및 데이터 의존성 때문에 파이프라인 중간에 임의의 컴포넌트를 동적으로 삽입하기는 까다롭다는 지적도 존재함. | D31: ='6조'!D$5 -> ++ | E31: ='6조'!E$5 -> 파이프를 흐르는 데이터의 인터페이스가 표준화되어 있어, 서로 다른 언어/기술로 작성된 새로운 필터나 외부 시스템을 파이프라인 중간에 쉽게 끼워 넣을 수 있음 | F31: ='6조'!F$5 -> 0 | G31: ='6조'!G$5 -> 하드웨어(센서/액추에이터)가 표준 인터페이스를 따르면 교체 가능하나, 제어 루프의 재구성은 쉽지 않음
A32: 7조 | B32: ='7조'!B$5 | C32: ='7조'!C$5 -> 7조 - Batch Sequential - Integrability | D32: ='7조'!D$5 | E32: ='7조'!E$5 -> 7조 - Pipe and Filter - Integrability | F32: ='7조'!F$5 | G32: ='7조'!G$5 -> 7조 - Process Control - Integrability
A33: 8조 | B33: ='8조'!B$5 | C33: ='8조'!C$5 -> 8조 - Batch Sequential - Integrability | D33: ='8조'!D$5 | E33: ='8조'!E$5 -> 8조 - Pipe and Filter - Integrability | F33: ='8조'!F$5 | G33: ='8조'!G$5 -> 8조 - Process Control - Integrability
A34: 9조 | B34: ='9조'!B$5 | C34: ='9조'!C$5 -> 9조 - Batch Sequential - Integrability | D34: ='9조'!D$5 | E34: ='9조'!E$5 -> 9조 - Pipe and Filter - Integrability | F34: ='9조'!F$5 | G34: ='9조'!G$5 -> 9조 - Process Control - Integrability
A36: Energy Efficiency | B36: ='Detailed Reasoning'!B$6 | C36: ='Detailed Reasoning'!C$6 | D36: ='Detailed Reasoning'!D$6 | E36: ='Detailed Reasoning'!E$6 | F36: ='Detailed Reasoning'!F$6 | G36: ='Detailed Reasoning'!G$6
A37: 1조 | B37: ='1조'!B$6 -> 0 | C37: ='1조'!C6 -> 동시 자원사용량을 낮출 수 있고 과도한 컴퓨팅 자원 사용을 줄일 수 있으나, sequential 구조로 처리시간이 길어지므로 소비된 총 에너지는 크게 유리하지 않음. | D37: ='1조'!D$6 -> 0 | E37: ='1조'!E6 -> Filter 병렬화로 처리시간 단축 가능하지만 동시 실행으로 자원 소비 증가 | F37: ='1조'!F$6 -> ++ | G37: ='1조'!G6 -> 시스템의 현재 상태를 보고 필요한 만큼만 자원을 사용할 수 있습니다.
A38: 2조 | B38: ='2조'!B$6 -> + | C38: ='2조'!C$6 -> 유휴 없이 몰아서 처리하므로 자원 활용률 높다 | D38: ='2조'!D$6 | E38: ='2조'!E$6 -> 2조 - Pipe and Filter - Energy Efficiency | F38: ='2조'!F$6 -> -- | G38: ='2조'!G$6 -> 지속적인 센싱과 연산이 필요한 구조라 유휴 상태 없이 상시 자원 소모함
A39: 3조 | B39: ='3조'!B$6 -> 0 | C39: ='3조'!C$6 -> 특별히 에너지와 관계 없어 보인다 | D39: ='3조'!D$6 | E39: ='3조'!E$6 -> 3조 - Pipe and Filter - Energy Efficiency | F39: ='3조'!F$6 | G39: ='3조'!G$6 -> 3조 - Process Control - Energy Efficiency
A40: 4조 | B40: ='4조'!B$6 -> - | C40: ='4조'!C$6 -> Utilization이라는 측면을 고려했을 때 시스템 자원 사용성이 순차실행이기 때문에 떨어질 수 있음. | D40: ='4조'!D$6 | E40: ='4조'!E$6 -> 4조 - Pipe and Filter - Energy Efficiency | F40: ='4조'!F$6 | G40: ='4조'!G$6 -> 4조 - Process Control - Energy Efficiency
A41: 5조 | B41: ='5조'!B$6 -> -- | C41: ='5조'!C$6 -> sequence 대기중 낭비되는 시간자원 큼 | D41: ='5조'!D$6 -> + | E41: ='5조'!E$6 -> 낭비자원 없이 pipeline가동할 것으로 예상 | F41: ='5조'!F$6 | G41: ='5조'!G$6 -> 5조 - Process Control - Energy Efficiency
A42: 6조 | B42: ='6조'!B$6 -> 0 | C42: ='6조'!C$6 -> 특정 시점에 대량 데이터를 한 번에 처리하므로 유휴 상태 없이 컴퓨팅 자원 활용률을 높일 수 있다는 긍정적 측면과, 선행 작업 종료 시까지 후속 작업이 대기하고 순차 실행으로 인해 전체 소요 시간이 늘어나 총 에너지 절감에는 불리하다는 관점이 상충함. | D42: ='6조'!D$6 -> 0 | E42: ='6조'!E$6 -> Filter 병렬화로 처리시간 단축 가능하지만 동시 실행으로 자원 소비 증가 | F42: ='6조'!F$6 -> -- | G42: ='6조'!G$6 -> 지속적인 센싱과 연산이 필요한 구조라 유휴 상태 없이 상시 자원 소모함
A43: 7조 | B43: ='7조'!B$6 | C43: ='7조'!C$6 -> 7조 - Batch Sequential - Energy Efficiency | D43: ='7조'!D$6 | E43: ='7조'!E$6 -> 7조 - Pipe and Filter - Energy Efficiency | F43: ='7조'!F$6 | G43: ='7조'!G$6 -> 7조 - Process Control - Energy Efficiency
...

Sheet DC
A1: Data Centered | B1: Shared Repository | D1: Blackboard
B2: Effects | C2: Justification | D2: Effects | E2: Justification
A3: Availability | B3: ='Detailed Reasoning'!B16 | C3: ='Detailed Reasoning'!C16 | D3: ='Detailed Reasoning'!D16 | E3: ='Detailed Reasoning'!E16
A4: 1조 | B4: ='1조'!B$16 | C4: ='1조'!C16 -> 1조 - Shared Respository - Availability | D4: ='1조'!D$16 | E4: ='1조'!E16 -> 1조 - Blackboard - Availability
A5: 2조 | B5: ='2조'!B$16 | C5: ='2조'!C$16 -> 2조 - Shared Respository - Availability | D5: ='2조'!D$16 | E5: ='2조'!E$16 -> 2조 - Blackboard - Availability
A6: 3조 | B6: ='3조'!B$16 -> - | C6: ='3조'!C$16 -> Repository에 문제가 생기면 모든 client의 동작이 마비된다. | D6: ='3조'!D$16 | E6: ='3조'!E$16 -> 3조 - Blackboard - Availability
A7: 4조 | B7: ='4조'!B$16 | C7: ='4조'!C$16 -> 4조 - Shared Respository - Availability | D7: ='4조'!D$16 -> -- | E7: ='4조'!E$16 -> 단일 공유 블랙보드가 단일 장애점
A8: 5조 | B8: ='5조'!B$16 | C8: ='5조'!C$16 -> 5조 - Shared Respository - Availability | D8: ='5조'!D$16 | E8: ='5조'!E$16 -> 5조 - Blackboard - Availability
A9: 6조 | B9: ='6조'!B$16 -> - | C9: ='6조'!C$16 -> Repository에 문제가 생기면 모든 client의 동작이 마비된다. | D9: ='6조'!D$16 -> -- | E9: ='6조'!E$16 -> 단일 공유 블랙보드가 단일 장애점
A10: 7조 | B10: ='7조'!B$16 | C10: ='7조'!C$16 -> 7조 - Shared Respository - Availability | D10: ='7조'!D$16 | E10: ='7조'!E$16 -> 7조 - Blackboard - Availability
A11: 8조 | B11: ='8조'!B$16 | C11: ='8조'!C$16 -> 8조 - Shared Respository - Availability | D11: ='8조'!D$16 | E11: ='8조'!E$16 -> 8조 - Blackboard - Availability
A12: 9조 | B12: ='9조'!B$16 | C12: ='9조'!C$16 -> 9조 - Shared Respository - Availability | D12: ='9조'!D$16 | E12: ='9조'!E$16 -> 9조 - Blackboard - Availability
A14: Deployability | B14: ='Detailed Reasoning'!B17 | C14: ='Detailed Reasoning'!C17 | D14: ='Detailed Reasoning'!D17 | E14: ='Detailed Reasoning'!E17
A15: 1조 | B15: ='1조'!B$17 | C15: ='1조'!C17 -> 1조 - Shared Respository - Deployability | D15: ='1조'!D$17 | E15: ='1조'!E17 -> 1조 - Blackboard - Deployability
A16: 2조 | B16: ='2조'!B$17 | C16: ='2조'!C$17 -> 2조 - Shared Respository - Deployability | D16: ='2조'!D$17 | E16: ='2조'!E$17 -> 2조 - Blackboard - Deployability
A17: 3조 | B17: ='3조'!B$17 -> - | C17: ='3조'!C$17 -> 한 component의 변경이 시스템 전체에 영향을 미칠 수 있고 배포 용이성에 영향을 미친다. | D17: ='3조'!D$17 | E17: ='3조'!E$17 -> 3조 - Blackboard - Deployability
A18: 4조 | B18: ='4조'!B$17 | C18: ='4조'!C$17 -> 4조 - Shared Respository - Deployability | D18: ='4조'!D$17 -> - | E18: ='4조'!E$17 -> 모든 지식원이 블랙보드/제어 컴포넌트에 강결합
A19: 5조 | B19: ='5조'!B$17 | C19: ='5조'!C$17 -> 5조 - Shared Respository - Deployability | D19: ='5조'!D$17 | E19: ='5조'!E$17 -> 5조 - Blackboard - Deployability
A20: 6조 | B20: ='6조'!B$17 -> - | C20: ='6조'!C$17 -> 한 component의 변경이 시스템 전체에 영향을 미칠 수 있고 배포 용이성에 영향을 미친다. | D20: ='6조'!D$17 -> - | E20: ='6조'!E$17 -> 모든 지식원이 블랙보드/제어 컴포넌트에 강결합
A21: 7조 | B21: ='7조'!B$17 | C21: ='7조'!C$17 -> 7조 - Shared Respository - Deployability | D21: ='7조'!D$17 | E21: ='7조'!E$17 -> 7조 - Blackboard - Deployability
A22: 8조 | B22: ='8조'!B$17 | C22: ='8조'!C$17 -> 8조 - Shared Respository - Deployability | D22: ='8조'!D$17 | E22: ='8조'!E$17 -> 8조 - Blackboard - Deployability
A23: 9조 | B23: ='9조'!B$17 | C23: ='9조'!C$17 -> 9조 - Shared Respository - Deployability | D23: ='9조'!D$17 | E23: ='9조'!E$17 -> 9조 - Blackboard - Deployability
A25: Integrability | B25: ='Detailed Reasoning'!B18 | C25: ='Detailed Reasoning'!C18 | D25: ='Detailed Reasoning'!D18 | E25: ='Detailed Reasoning'!E18
A26: 1조 | B26: ='1조'!B$18 | C26: ='1조'!C18 -> 1조 - Shared Respository - Integrability | D26: ='1조'!D$18 | E26: ='1조'!E18 -> 1조 - Blackboard - Integrability
A27: 2조 | B27: ='2조'!B$18 | C27: ='2조'!C$18 -> 2조 - Shared Respository - Integrability | D27: ='2조'!D$18 | E27: ='2조'!E$18 -> 2조 - Blackboard - Integrability
A28: 3조 | B28: ='3조'!B$18 -> - | C28: ='3조'!C$18 -> repository의 있는 그대로를 사용하는 client가 추가되는 것이 쉽기 때문에 통합 용이성은 좋다. | D28: ='3조'!D$18 | E28: ='3조'!E$18 -> 3조 - Blackboard - Integrability
A29: 4조 | B29: ='4조'!B$18 | C29: ='4조'!C$18 -> 4조 - Shared Respository - Integrability | D29: ='4조'!D$18 -> + | E29: ='4조'!E$18 -> 외부 컴포넌트도 또다른 Data Client로 추가하기 용이하다.
A30: 5조 | B30: ='5조'!B$18 | C30: ='5조'!C$18 -> 5조 - Shared Respository - Integrability | D30: ='5조'!D$18 | E30: ='5조'!E$18 -> 5조 - Blackboard - Integrability
A31: 6조 | B31: ='6조'!B$18 -> - | C31: ='6조'!C$18 -> repository의 있는 그대로를 사용하는 client가 추가되는 것이 쉽기 때문에 통합 용이성은 좋다. | D31: ='6조'!D$18 -> + | E31: ='6조'!E$18 -> 외부 컴포넌트도 또다른 Data Client로 추가하기 용이하다.
A32: 7조 | B32: ='7조'!B$18 | C32: ='7조'!C$18 -> 7조 - Shared Respository - Integrability | D32: ='7조'!D$18 | E32: ='7조'!E$18 -> 7조 - Blackboard - Integrability
A33: 8조 | B33: ='8조'!B$18 | C33: ='8조'!C$18 -> 8조 - Shared Respository - Integrability | D33: ='8조'!D$18 | E33: ='8조'!E$18 -> 8조 - Blackboard - Integrability
A34: 9조 | B34: ='9조'!B$18 | C34: ='9조'!C$18 -> 9조 - Shared Respository - Integrability | D34: ='9조'!D$18 | E34: ='9조'!E$18 -> 9조 - Blackboard - Integrability
A36: Energy Efficiency | B36: ='Detailed Reasoning'!B$19 | C36: ='Detailed Reasoning'!C$19 | D36: ='Detailed Reasoning'!D$19 | E36: ='Detailed Reasoning'!E$19
A37: 1조 | B37: ='1조'!B$19 | C37: ='1조'!C19 -> 1조 - Shared Respository - Energy Efficiency | D37: ='1조'!D$19 | E37: ='1조'!E19 -> 1조 - Blackboard - Energy Efficiency
A38: 2조 | B38: ='2조'!B$19 | C38: ='2조'!C$19 -> 2조 - Shared Respository - Energy Efficiency | D38: ='2조'!D$19 | E38: ='2조'!E$19 -> 2조 - Blackboard - Energy Efficiency
A39: 3조 | B39: ='3조'!B$19 -> + | C39: ='3조'!C$19 -> repository 하나를 공유하며 각 client가 독립적이기 때문에 낭비가 적어 에너지 효율성은 좋을 것 같다. | D39: ='3조'!D$19 | E39: ='3조'!E$19 -> 3조 - Blackboard - Energy Efficiency
A40: 4조 | B40: ='4조'!B$19 | C40: ='4조'!C$19 -> 4조 - Shared Respository - Energy Efficiency | D40: ='4조'!D$19 -> - | E40: ='4조'!E$19 -> 제어 컴포넌트의 지속적 폴링/모니터링 오버헤드
A41: 5조 | B41: ='5조'!B$19 | C41: ='5조'!C$19 -> 5조 - Shared Respository - Energy Efficiency | D41: ='5조'!D$19 | E41: ='5조'!E$19 -> 5조 - Blackboard - Energy Efficiency
A42: 6조 | B42: ='6조'!B$19 -> + | C42: ='6조'!C$19 -> repository 하나를 공유하며 각 client가 독립적이기 때문에 낭비가 적어 에너지 효율성은 좋을 것 같다. | D42: ='6조'!D$19 -> - | E42: ='6조'!E$19 -> 제어 컴포넌트의 지속적 폴링/모니터링 오버헤드
A43: 7조 | B43: ='7조'!B$19 | C43: ='7조'!C$19 -> 7조 - Shared Respository - Energy Efficiency | D43: ='7조'!D$19 | E43: ='7조'!E$19 -> 7조 - Blackboard - Energy Efficiency
...

Sheet II
A1: Implicit Invocation | B1: Non-Buffered Event Based | D1: Buffered Message Based
B2: Effects | C2: Justification | D2: Effects | E2: Justification
A3: Availability | B3: ='Detailed Reasoning'!B$29 | C3: ='Detailed Reasoning'!C$29 | D3: ='Detailed Reasoning'!D$29 | E3: ='Detailed Reasoning'!E$29
A4: 1조 | B4: ='1조'!B$29 | C4: ='1조'!C29 -> 1조 - Non-Buffered Event Based - Availability | D4: ='1조'!D$29 | E4: ='1조'!E29 -> 1조 - Buffered Message Based - Availability
A5: 2조 | B5: ='2조'!B$29 | C5: ='2조'!C$29 -> 2조 - Non-Buffered Event Based - Availability | D5: ='2조'!D$29 | E5: ='2조'!E$29 -> 2조 - Buffered Message Based - Availability
A6: 3조 | B6: ='3조'!B$29 | C6: ='3조'!C$29 -> 3조 - Non-Buffered Event Based - Availability | D6: ='3조'!D$29 | E6: ='3조'!E$29 -> 3조 - Buffered Message Based - Availability
A7: 4조 | B7: ='4조'!B$29 | C7: ='4조'!C$29 -> 4조 - Non-Buffered Event Based - Availability | D7: ='4조'!D$29 | E7: ='4조'!E$29 -> 4조 - Buffered Message Based - Availability
A8: 5조 | B8: ='5조'!B$29 -> -- | C8: ='5조'!C$29 -> producer가 어느 한 custormer에 잡혀있을 경우 producer 가 블로킹된다. | D8: ='5조'!D$29 | E8: ='5조'!E$29 -> 5조 - Buffered Message Based - Availability
A9: 6조 | B9: ='6조'!B$29 -> -- | C9: ='6조'!C$29 -> producer가 어느 한 custormer에 잡혀있을 경우 producer 가 블로킹된다. | D9: ='6조'!D$29 -> + | E9: ='6조'!E$29 -> 메시지가 버퍼에 저장되므로 Consumer가 일시적으로 중단되어도 복구 후 처리를 계속할 수 있다.
A10: 7조 | B10: ='7조'!B$29 | C10: ='7조'!C$29 -> 7조 - Non-Buffered Event Based - Availability | D10: ='7조'!D$29 | E10: ='7조'!E$29 -> 7조 - Buffered Message Based - Availability
A11: 8조 | B11: ='8조'!B$29 | C11: ='8조'!C$29 -> 8조 - Non-Buffered Event Based - Availability | D11: ='8조'!D$29 | E11: ='8조'!E$29 -> 8조 - Buffered Message Based - Availability
A12: 9조 | B12: ='9조'!B$29 | C12: ='9조'!C$29 -> 9조 - Non-Buffered Event Based - Availability | D12: ='9조'!D$29 | E12: ='9조'!E$29 -> 9조 - Buffered Message Based - Availability
A14: Deployability | B14: ='Detailed Reasoning'!B$30 | C14: ='Detailed Reasoning'!C$30 | D14: ='Detailed Reasoning'!D$30 | E14: ='Detailed Reasoning'!E$30
A15: 1조 | B15: ='1조'!B$30 | C15: ='1조'!C30 -> 1조 - Non-Buffered Event Based - Deployability | D15: ='1조'!D$30 | E15: ='1조'!E30 -> 1조 - Buffered Message Based - Deployability
A16: 2조 | B16: ='2조'!B$30 | C16: ='2조'!C$30 -> 2조 - Non-Buffered Event Based - Deployability | D16: ='2조'!D$30 | E16: ='2조'!E$30 -> 2조 - Buffered Message Based - Deployability
A17: 3조 | B17: ='3조'!B$30 | C17: ='3조'!C$30 -> 3조 - Non-Buffered Event Based - Deployability | D17: ='3조'!D$30 | E17: ='3조'!E$30 -> 3조 - Buffered Message Based - Deployability
A18: 4조 | B18: ='4조'!B$30 | C18: ='4조'!C$30 -> 4조 - Non-Buffered Event Based - Deployability | D18: ='4조'!D$30 | E18: ='4조'!E$30 -> 4조 - Buffered Message Based - Deployability
A19: 5조 | B19: ='5조'!B$30 -> + | C19: ='5조'!C$30 -> customer 확장이 자유롭다 | D19: ='5조'!D$30 | E19: ='5조'!E$30 -> 5조 - Buffered Message Based - Deployability
A20: 6조 | B20: ='6조'!B$30 -> + | C20: ='6조'!C$30 -> customer 확장이 자유롭다 | D20: ='6조'!D$30 -> ++ | E20: ='6조'!E$30 -> Producer와 Consumer를 독립적으로 배포·교체할 수 있다.
A21: 7조 | B21: ='7조'!B$30 | C21: ='7조'!C$30 -> 7조 - Non-Buffered Event Based - Deployability | D21: ='7조'!D$30 | E21: ='7조'!E$30 -> 7조 - Buffered Message Based - Deployability
A22: 8조 | B22: ='8조'!B$30 | C22: ='8조'!C$30 -> 8조 - Non-Buffered Event Based - Deployability | D22: ='8조'!D$30 | E22: ='8조'!E$30 -> 8조 - Buffered Message Based - Deployability
A23: 9조 | B23: ='9조'!B$30 | C23: ='9조'!C$30 -> 9조 - Non-Buffered Event Based - Deployability | D23: ='9조'!D$30 | E23: ='9조'!E$30 -> 9조 - Buffered Message Based - Deployability
A25: Integrability | B25: ='Detailed Reasoning'!B$31 | C25: ='Detailed Reasoning'!C$31 | D25: ='Detailed Reasoning'!D$31 | E25: ='Detailed Reasoning'!E$31
A26: 1조 | B26: ='1조'!B$31 | C26: ='1조'!C31 -> 1조 - Non-Buffered Event Based - Integrability | D26: ='1조'!D$31 | E26: ='1조'!E31 -> 1조 - Buffered Message Based - Integrability
A27: 2조 | B27: ='2조'!B$31 | C27: ='2조'!C$31 -> 2조 - Non-Buffered Event Based - Integrability | D27: ='2조'!D$31 | E27: ='2조'!E$31 -> 2조 - Buffered Message Based - Integrability
A28: 3조 | B28: ='3조'!B$31 | C28: ='3조'!C$31 -> 3조 - Non-Buffered Event Based - Integrability | D28: ='3조'!D$31 | E28: ='3조'!E$31 -> 3조 - Buffered Message Based - Integrability
A29: 4조 | B29: ='4조'!B$31 | C29: ='4조'!C$31 -> 4조 - Non-Buffered Event Based - Integrability | D29: ='4조'!D$31 | E29: ='4조'!E$31 -> 4조 - Buffered Message Based - Integrability
A30: 5조 | B30: ='5조'!B$31 -> + | C30: ='5조'!C$31 -> customer 확장이 자유롭다 | D30: ='5조'!D$31 | E30: ='5조'!E$31 -> 5조 - Buffered Message Based - Integrability
A31: 6조 | B31: ='6조'!B$31 -> + | C31: ='6조'!C$31 -> customer 확장이 자유롭다 | D31: ='6조'!D$31 -> + | E31: ='6조'!E$31 -> producer/consumer가 서로의 신원을 몰라도 되는 익명성 덕분에 새로운 서비스를 붙이기 쉽다
A32: 7조 | B32: ='7조'!B$31 | C32: ='7조'!C$31 -> 7조 - Non-Buffered Event Based - Integrability | D32: ='7조'!D$31 | E32: ='7조'!E$31 -> 7조 - Buffered Message Based - Integrability
A33: 8조 | B33: ='8조'!B$31 | C33: ='8조'!C$31 -> 8조 - Non-Buffered Event Based - Integrability | D33: ='8조'!D$31 | E33: ='8조'!E$31 -> 8조 - Buffered Message Based - Integrability
A34: 9조 | B34: ='9조'!B$31 | C34: ='9조'!C$31 -> 9조 - Non-Buffered Event Based - Integrability | D34: ='9조'!D$31 | E34: ='9조'!E$31 -> 9조 - Buffered Message Based - Integrability
A36: Energy Efficiency | B36: ='Detailed Reasoning'!B$32 | C36: ='Detailed Reasoning'!C$32 | D36: ='Detailed Reasoning'!D$32 | E36: ='Detailed Reasoning'!E$32
A37: 1조 | B37: ='1조'!B$32 | C37: ='1조'!C32 -> 1조 - Non-Buffered Event Based - Energy Efficiency | D37: ='1조'!D$32 | E37: ='1조'!E32 -> 1조 - Buffered Message Based - Energy Efficiency
A38: 2조 | B38: ='2조'!B$32 | C38: ='2조'!C$32 -> 2조 - Non-Buffered Event Based - Energy Efficiency | D38: ='2조'!D$32 | E38: ='2조'!E$32 -> 2조 - Buffered Message Based - Energy Efficiency
A39: 3조 | B39: ='3조'!B$32 | C39: ='3조'!C$32 -> 3조 - Non-Buffered Event Based - Energy Efficiency | D39: ='3조'!D$32 | E39: ='3조'!E$32 -> 3조 - Buffered Message Based - Energy Efficiency
A40: 4조 | B40: ='4조'!B$32 | C40: ='4조'!C$32 -> 4조 - Non-Buffered Event Based - Energy Efficiency | D40: ='4조'!D$32 | E40: ='4조'!E$32 -> 4조 - Buffered Message Based - Energy Efficiency
A41: 5조 | B41: ='5조'!B$32 -> -- | C41: ='5조'!C$32 -> prooducer 동작 시 customer 가 통신을 받지 않는 이상은 이벤트가 낭비된다. | D41: ='5조'!D$32 | E41: ='5조'!E$32 -> 5조 - Buffered Message Based - Energy Efficiency
A42: 6조 | B42: ='6조'!B$32 -> -- | C42: ='6조'!C$32 -> prooducer 동작 시 customer 가 통신을 받지 않는 이상은 이벤트가 낭비된다. | D42: ='6조'!D$32 -> - | E42: ='6조'!E$32 -> 메시지 저장과 전달, 직렬화·역직렬화, Broker 운영 및 재시도 처리에 추가적인 계산·저장·통신 자원이 필요하다.
A43: 7조 | B43: ='7조'!B$32 | C43: ='7조'!C$32 -> 7조 - Non-Buffered Event Based - Energy Efficiency | D43: ='7조'!D$32 | E43: ='7조'!E$32 -> 7조 - Buffered Message Based - Energy Efficiency
...

Sheet IO
A1: Interaction-Oriented | B1: MVC | D1: PAC
B2: Effects | C2: Justification | D2: Effects | E2: Justification
A3: Availability | B3: ='Detailed Reasoning'!B$42 | C3: ='Detailed Reasoning'!C$42 | D3: ='Detailed Reasoning'!D$42 | E3: ='Detailed Reasoning'!E$42
A4: 1조 | B4: ='1조'!B$42 | C4: ='1조'!C42 -> 1조 - MVC - Availability | D4: ='1조'!D$42 | E4: ='1조'!E42 -> 1조 - PAC - Availability
A5: 2조 | B5: ='2조'!B$42 | C5: ='2조'!C$42 -> 2조 - MVC - Availability | D5: ='2조'!D$42 | E5: ='2조'!E$42 -> 2조 - PAC - Availability
A6: 3조 | B6: ='3조'!B$42 | C6: ='3조'!C$42 -> 3조 - MVC - Availability | D6: ='3조'!D$42 | E6: ='3조'!E$42 -> 3조 - PAC - Availability
A7: 4조 | B7: ='4조'!B$42 | C7: ='4조'!C$42 -> 4조 - MVC - Availability | D7: ='4조'!D$42 | E7: ='4조'!E$42 -> 4조 - PAC - Availability
A8: 5조 | B8: ='5조'!B$42 | C8: ='5조'!C$42 -> 5조 - MVC - Availability | D8: ='5조'!D$42 | E8: ='5조'!E$42 -> 5조 - PAC - Availability
A9: 6조 | B9: ='6조'!B$42 | C9: ='6조'!C$42 -> 6조 - MVC - Availability | D9: ='6조'!D$42 | E9: ='6조'!E$42 -> 6조 - PAC - Availability
A10: 7조 | B10: ='7조'!B$42 | C10: ='7조'!C$42 -> 7조 - MVC - Availability | D10: ='7조'!D$42 | E10: ='7조'!E$42 -> 7조 - PAC - Availability
A11: 8조 | B11: ='8조'!B$42 | C11: ='8조'!C$42 -> 8조 - MVC - Availability | D11: ='8조'!D$42 | E11: ='8조'!E$42 -> 8조 - PAC - Availability
A12: 9조 | B12: ='9조'!B$42 | C12: ='9조'!C$42 -> 9조 - MVC - Availability | D12: ='9조'!D$42 | E12: ='9조'!E$42 -> 9조 - PAC - Availability
A14: Deployability | B14: ='Detailed Reasoning'!B$43 | C14: ='Detailed Reasoning'!C$43 | D14: ='Detailed Reasoning'!D$43 | E14: ='Detailed Reasoning'!E$43
A15: 1조 | B15: ='1조'!B$43 | C15: ='1조'!C43 -> 1조 - MVC - Deployability | D15: ='1조'!D$43 | E15: ='1조'!E43 -> 1조 - PAC - Deployability
A16: 2조 | B16: ='2조'!B$43 | C16: ='2조'!C$43 -> 2조 - MVC - Deployability | D16: ='2조'!D$43 | E16: ='2조'!E$43 -> 2조 - PAC - Deployability
A17: 3조 | B17: ='3조'!B$43 | C17: ='3조'!C$43 -> 3조 - MVC - Deployability | D17: ='3조'!D$43 | E17: ='3조'!E$43 -> 3조 - PAC - Deployability
A18: 4조 | B18: ='4조'!B$43 | C18: ='4조'!C$43 -> 4조 - MVC - Deployability | D18: ='4조'!D$43 | E18: ='4조'!E$43 -> 4조 - PAC - Deployability
A19: 5조 | B19: ='5조'!B$43 | C19: ='5조'!C$43 -> 5조 - MVC - Deployability | D19: ='5조'!D$43 | E19: ='5조'!E$43 -> 5조 - PAC - Deployability
A20: 6조 | B20: ='6조'!B$43 -> + | C20: ='6조'!C$43 -> 비즈니스 로직은 그대로 유지하고 룩앤필만 유지할 수 있게 구현만 하면 된다. | D20: ='6조'!D$43 | E20: ='6조'!E$43 -> 6조 - PAC - Deployability
A21: 7조 | B21: ='7조'!B$43 | C21: ='7조'!C$43 -> 7조 - MVC - Deployability | D21: ='7조'!D$43 | E21: ='7조'!E$43 -> 7조 - PAC - Deployability
A22: 8조 | B22: ='8조'!B$43 | C22: ='8조'!C$43 -> 8조 - MVC - Deployability | D22: ='8조'!D$43 | E22: ='8조'!E$43 -> 8조 - PAC - Deployability
A23: 9조 | B23: ='9조'!B$43 | C23: ='9조'!C$43 -> 9조 - MVC - Deployability | D23: ='9조'!D$43 | E23: ='9조'!E$43 -> 9조 - PAC - Deployability
A25: Integrability | B25: ='Detailed Reasoning'!B$44 | C25: ='Detailed Reasoning'!C$44 | D25: ='Detailed Reasoning'!D$44 | E25: ='Detailed Reasoning'!E$44
A26: 1조 | B26: ='1조'!B$44 | C26: ='1조'!C44 -> 1조 - MVC - Integrability | D26: ='1조'!D$44 | E26: ='1조'!E44 -> 1조 - PAC - Integrability
A27: 2조 | B27: ='2조'!B$44 | C27: ='2조'!C$44 -> 2조 - MVC - Integrability | D27: ='2조'!D$44 | E27: ='2조'!E$44 -> 2조 - PAC - Integrability
A28: 3조 | B28: ='3조'!B$44 | C28: ='3조'!C$44 -> 3조 - MVC - Integrability | D28: ='3조'!D$44 | E28: ='3조'!E$44 -> 3조 - PAC - Integrability
A29: 4조 | B29: ='4조'!B$44 | C29: ='4조'!C$44 -> 4조 - MVC - Integrability | D29: ='4조'!D$44 | E29: ='4조'!E$44 -> 4조 - PAC - Integrability
A30: 5조 | B30: ='5조'!B$44 | C30: ='5조'!C$44 -> 5조 - MVC - Integrability | D30: ='5조'!D$44 | E30: ='5조'!E$44 -> 5조 - PAC - Integrability
A31: 6조 | B31: ='6조'!B$44 | C31: ='6조'!C$44 -> 6조 - MVC - Integrability | D31: ='6조'!D$44 | E31: ='6조'!E$44 -> 6조 - PAC - Integrability
A32: 7조 | B32: ='7조'!B$44 | C32: ='7조'!C$44 -> 7조 - MVC - Integrability | D32: ='7조'!D$44 | E32: ='7조'!E$44 -> 7조 - PAC - Integrability
A33: 8조 | B33: ='8조'!B$44 | C33: ='8조'!C$44 -> 8조 - MVC - Integrability | D33: ='8조'!D$44 | E33: ='8조'!E$44 -> 8조 - PAC - Integrability
A34: 9조 | B34: ='9조'!B$44 | C34: ='9조'!C$44 -> 9조 - MVC - Integrability | D34: ='9조'!D$44 | E34: ='9조'!E$44 -> 9조 - PAC - Integrability
A36: Energy Efficiency | B36: ='Detailed Reasoning'!B$45 | C36: ='Detailed Reasoning'!C$45 | D36: ='Detailed Reasoning'!D$45 | E36: ='Detailed Reasoning'!E$45
A37: 1조 | B37: ='1조'!B$45 | C37: ='1조'!C45 -> 1조 - MVC - Energy Efficiency | D37: ='1조'!D$45 | E37: ='1조'!E45 -> 1조 - PAC - Energy Efficiency
A38: 2조 | B38: ='2조'!B$45 | C38: ='2조'!C$45 -> 2조 - MVC - Energy Efficiency | D38: ='2조'!D$45 | E38: ='2조'!E$45 -> 2조 - PAC - Energy Efficiency
A39: 3조 | B39: ='3조'!B$45 | C39: ='3조'!C$45 -> 3조 - MVC - Energy Efficiency | D39: ='3조'!D$45 | E39: ='3조'!E$45 -> 3조 - PAC - Energy Efficiency
A40: 4조 | B40: ='4조'!B$45 | C40: ='4조'!C$45 -> 4조 - MVC - Energy Efficiency | D40: ='4조'!D$45 | E40: ='4조'!E$45 -> 4조 - PAC - Energy Efficiency
A41: 5조 | B41: ='5조'!B$45 | C41: ='5조'!C$45 -> 5조 - MVC - Energy Efficiency | D41: ='5조'!D$45 | E41: ='5조'!E$45 -> 5조 - PAC - Energy Efficiency
A42: 6조 | B42: ='6조'!B$45 | C42: ='6조'!C$45 -> 6조 - MVC - Energy Efficiency | D42: ='6조'!D$45 | E42: ='6조'!E$45 -> 6조 - PAC - Energy Efficiency
A43: 7조 | B43: ='7조'!B$45 | C43: ='7조'!C$45 -> 7조 - MVC - Energy Efficiency | D43: ='7조'!D$45 | E43: ='7조'!E$45 -> 7조 - PAC - Energy Efficiency
...

Sheet H1
A1: Hierarchical | B1: Main-subroutine | D1: Master-Slave
B2: Effects | C2: Justification | D2: Effects | E2: Justification
A3: Availability | B3: ='Detailed Reasoning'!B$55 | C3: ='Detailed Reasoning'!C$55 | D3: ='Detailed Reasoning'!D$55 | E3: ='Detailed Reasoning'!E$55
A4: 1조 | B4: ='1조'!B$55 | C4: ='1조'!C55 | D4: ='1조'!D$55 | E4: ='1조'!E55
A5: 2조 | B5: ='2조'!B$55 | C5: ='2조'!C$55 -> 2조 - Main-subroutine - Availability | D5: ='2조'!D$55 | E5: ='2조'!E$55 -> 2조 - Master-Slave - Availability
A6: 3조 | B6: ='3조'!B$55 | C6: ='3조'!C$55 -> 3조 - Main-subroutine - Availability | D6: ='3조'!D$55 | E6: ='3조'!E$55 -> 3조 - Master-Slave - Availability
A7: 4조 | B7: ='4조'!B$55 | C7: ='4조'!C$55 -> 4조 - Main-subroutine - Availability | D7: ='4조'!D$55 | E7: ='4조'!E$55 -> 4조 - Master-Slave - Availability
A8: 5조 | B8: ='5조'!B$55 | C8: ='5조'!C$55 -> 5조 - Main-subroutine - Availability | D8: ='5조'!D$55 | E8: ='5조'!E$55 -> 5조 - Master-Slave - Availability
A9: 6조 | B9: ='6조'!B$55 -> - | C9: ='6조'!C$55 -> Main이 여러 subroutine을 순차적으로 호출하는 구조라서 한 subroutine에 장애가 발생하면 전체 실행 흐름에 영향을 줄 가능성이 높음 | D9: ='6조'!D$55 -> 0 | E9: ='6조'!E$55 -> Fault Tolerence 특징이 있지만 Master 단일 포인트 Fail 시 가용성이 훼손될 수 있다.
A10: 7조 | B10: ='7조'!B$55 | C10: ='7조'!C$55 -> 7조 - Main-subroutine - Availability | D10: ='7조'!D$55 | E10: ='7조'!E$55 -> 7조 - Master-Slave - Availability
A11: 8조 | B11: ='8조'!B$55 | C11: ='8조'!C$55 -> 8조 - Main-subroutine - Availability | D11: ='8조'!D$55 | E11: ='8조'!E$55 -> 8조 - Master-Slave - Availability
A12: 9조 | B12: ='9조'!B$55 | C12: ='9조'!C$55 -> 9조 - Main-subroutine - Availability | D12: ='9조'!D$55 | E12: ='9조'!E$55 -> 9조 - Master-Slave - Availability
A14: Deployability | B14: ='Detailed Reasoning'!B$56 | C14: ='Detailed Reasoning'!C$56 | D14: ='Detailed Reasoning'!D$56 | E14: ='Detailed Reasoning'!E$56
A15: 1조 | B15: ='1조'!B$56 | C15: ='1조'!C56 | D15: ='1조'!D$56 | E15: ='1조'!E56
A16: 2조 | B16: ='2조'!B$56 | C16: ='2조'!C$56 -> 2조 - Main-subroutine - Deployability | D16: ='2조'!D$56 | E16: ='2조'!E$56 -> 2조 - Master-Slave - Deployability
A17: 3조 | B17: ='3조'!B$56 | C17: ='3조'!C$56 -> 3조 - Main-subroutine - Deployability | D17: ='3조'!D$56 | E17: ='3조'!E$56 -> 3조 - Master-Slave - Deployability
A18: 4조 | B18: ='4조'!B$56 | C18: ='4조'!C$56 -> 4조 - Main-subroutine - Deployability | D18: ='4조'!D$56 | E18: ='4조'!E$56 -> 4조 - Master-Slave - Deployability
A19: 5조 | B19: ='5조'!B$56 | C19: ='5조'!C$56 -> 5조 - Main-subroutine - Deployability | D19: ='5조'!D$56 | E19: ='5조'!E$56 -> 5조 - Master-Slave - Deployability
A20: 6조 | B20: ='6조'!B$56 -> - | C20: ='6조'!C$56 -> Main과 subroutine이 하나의 바이너리로 강하게 묶여있어 특정 서브루틴만 독립적 배포 불가. 특정 서브루틴 고치면 전체 시스템 재빌드 및 재배포 필요. 배포시 무중단 배포가 불가능하다. | D20: ='6조'!D$56 -> 0 | E20: ='6조'!E$56 -> Slave를 교체할 때는 배포에 장점이 있지만, Slave-Master와의 호환성 문제가 생길 시 혹은 Master 교체 시 배포용이성이 떨어진다.
A21: 7조 | B21: ='7조'!B$56 | C21: ='7조'!C$56 -> 7조 - Main-subroutine - Deployability | D21: ='7조'!D$56 | E21: ='7조'!E$56 -> 7조 - Master-Slave - Deployability
A22: 8조 | B22: ='8조'!B$56 | C22: ='8조'!C$56 -> 8조 - Main-subroutine - Deployability | D22: ='8조'!D$56 | E22: ='8조'!E$56 -> 8조 - Master-Slave - Deployability
A23: 9조 | B23: ='9조'!B$56 | C23: ='9조'!C$56 -> 9조 - Main-subroutine - Deployability | D23: ='9조'!D$56 | E23: ='9조'!E$56 -> 9조 - Master-Slave - Deployability
A25: Integrability | B25: ='Detailed Reasoning'!B$57 | C25: ='Detailed Reasoning'!C$57 | D25: ='Detailed Reasoning'!D$57 | E25: ='Detailed Reasoning'!E$57
A26: 1조 | B26: ='1조'!B$57 | C26: ='1조'!C57 | D26: ='1조'!D$57 | E26: ='1조'!E57
A27: 2조 | B27: ='2조'!B$57 | C27: ='2조'!C$57 -> 2조 - Main-subroutine - Integrability | D27: ='2조'!D$57 | E27: ='2조'!E$57 -> 2조 - Master-Slave - Integrability
A28: 3조 | B28: ='3조'!B$57 | C28: ='3조'!C$57 -> 3조 - Main-subroutine - Integrability | D28: ='3조'!D$57 | E28: ='3조'!E$57 -> 3조 - Master-Slave - Integrability
A29: 4조 | B29: ='4조'!B$57 | C29: ='4조'!C$57 -> 4조 - Main-subroutine - Integrability | D29: ='4조'!D$57 | E29: ='4조'!E$57 -> 4조 - Master-Slave - Integrability
A30: 5조 | B30: ='5조'!B$57 | C30: ='5조'!C$57 -> 5조 - Main-subroutine - Integrability | D30: ='5조'!D$57 | E30: ='5조'!E$57 -> 5조 - Master-Slave - Integrability
A31: 6조 | B31: ='6조'!B$57 -> - | C31: ='6조'!C$57 -> Subroutine 간 interface를 통해 통합할 수 있지만, 기본적으로 호출 관계가 강하게 결합되어 있다. 새로운 외부 시스템이나 component를 추가하려면 기존 main/subroutine 구조를 수정해야 할 가능성이 있다. | D31: ='6조'!D$57 -> 0 | E31: ='6조'!E$57 -> 다른 component를 slave로 추가할 componet의 인터페이스, 프로토콜 호환성이 중요하게 작용한다. 같은 규약을 가진 componet의 경우 통합용이성이 좋다.
A32: 7조 | B32: ='7조'!B$57 | C32: ='7조'!C$57 -> 7조 - Main-subroutine - Integrability | D32: ='7조'!D$57 | E32: ='7조'!E$57 -> 7조 - Master-Slave - Integrability
A33: 8조 | B33: ='8조'!B$57 | C33: ='8조'!C$57 -> 8조 - Main-subroutine - Integrability | D33: ='8조'!D$57 | E33: ='8조'!E$57 -> 8조 - Master-Slave - Integrability
A34: 9조 | B34: ='9조'!B$57 | C34: ='9조'!C$57 -> 9조 - Main-subroutine - Integrability | D34: ='9조'!D$57 | E34: ='9조'!E$57 -> 9조 - Master-Slave - Integrability
A36: Energy Efficiency | B36: ='Detailed Reasoning'!B$58 | C36: ='Detailed Reasoning'!C$58 | D36: ='Detailed Reasoning'!D$58 | E36: ='Detailed Reasoning'!E$58
A37: 1조 | B37: ='1조'!B$58 | C37: ='1조'!C58 | D37: ='1조'!D$58 | E37: ='1조'!E58
A38: 2조 | B38: ='2조'!B$58 | C38: ='2조'!C$58 -> 2조 - Main-subroutine - Energy Efficiency | D38: ='2조'!D$58 | E38: ='2조'!E$58 -> 2조 - Master-Slave - Energy Efficiency
A39: 3조 | B39: ='3조'!B$58 | C39: ='3조'!C$58 -> 3조 - Main-subroutine - Energy Efficiency | D39: ='3조'!D$58 | E39: ='3조'!E$58 -> 3조 - Master-Slave - Energy Efficiency
A40: 4조 | B40: ='4조'!B$58 | C40: ='4조'!C$58 -> 4조 - Main-subroutine - Energy Efficiency | D40: ='4조'!D$58 | E40: ='4조'!E$58 -> 4조 - Master-Slave - Energy Efficiency
A41: 5조 | B41: ='5조'!B$58 | C41: ='5조'!C$58 -> 5조 - Main-subroutine - Energy Efficiency | D41: ='5조'!D$58 | E41: ='5조'!E$58 -> 5조 - Master-Slave - Energy Efficiency
A42: 6조 | B42: ='6조'!B$58 -> ++ | C42: ='6조'!C$58 -> 불필요한 communication이나 middleware layer가 거의 없기 때문에 효율적 | D42: ='6조'!D$58 -> - | E42: ='6조'!E$58 -> master-slave간 통신에서 overhead가 발생하여 추가적인 에너지 소모가 있을 수 있다.
A43: 7조 | B43: ='7조'!B$58 | C43: ='7조'!C$58 -> 7조 - Main-subroutine - Energy Efficiency | D43: ='7조'!D$58 | E43: ='7조'!E$58 -> 7조 - Master-Slave - Energy Efficiency
...

Sheet H2
A1: Hierarchical | B1: Layered | D1: Virtual Machine | F1: Microkernel
B2: Effects | C2: Justification | D2: Effects | E2: Justification | F2: Effects | G2: Justification
A3: Availability | B3: ='Detailed Reasoning'!B$68 | C3: ='Detailed Reasoning'!C$68 | D3: ='Detailed Reasoning'!D$68 | E3: ='Detailed Reasoning'!E$68 | F3: ='Detailed Reasoning'!F$68 | G3: ='Detailed Reasoning'!G$68
A4: 1조 | B4: ='1조'!B$68 | C4: ='1조'!C68 | D4: ='1조'!D$68 | E4: ='1조'!E68 | F4: ='1조'!F$68 | G4: ='1조'!G68
A5: 2조 | B5: ='2조'!B$68 | C5: ='2조'!C$68 -> 2조 - Layered - Availability | D5: ='2조'!D$68 | E5: ='2조'!E$68 -> 2조 - Virtual Machine - Availability | F5: ='2조'!F$68 | G5: ='2조'!G$68 -> 2조 - Microkernel - Availability
A6: 3조 | B6: ='3조'!B$68 | C6: ='3조'!C$68 -> 3조 - Layered - Availability | D6: ='3조'!D$68 | E6: ='3조'!E$68 -> 3조 - Virtual Machine - Availability | F6: ='3조'!F$68 | G6: ='3조'!G$68 -> 3조 - Microkernel - Availability
A7: 4조 | B7: ='4조'!B$68 | C7: ='4조'!C$68 -> 4조 - Layered - Availability | D7: ='4조'!D$68 | E7: ='4조'!E$68 -> 4조 - Virtual Machine - Availability | F7: ='4조'!F$68 | G7: ='4조'!G$68 -> 4조 - Microkernel - Availability
A8: 5조 | B8: ='5조'!B$68 | C8: ='5조'!C$68 -> 5조 - Layered - Availability | D8: ='5조'!D$68 | E8: ='5조'!E$68 -> 5조 - Virtual Machine - Availability | F8: ='5조'!F$68 | G8: ='5조'!G$68 -> 5조 - Microkernel - Availability
A9: 6조 | B9: ='6조'!B$68 -> 0 | C9: ='6조'!C$68 -> 계층 분리는 결함의 위치 파악과 복구에 도움이 되지만, 하위 Layer에 장애가 발생하면 이를 사용하는 모든 상위 Layer가 영향을 받는다. | D9: ='6조'!D$68 | E9: ='6조'!E$68 -> 6조 - Virtual Machine - Availability | F9: ='6조'!F$68 | G9: ='6조'!G$68 -> 6조 - Microkernel - Availability
A10: 7조 | B10: ='7조'!B$68 | C10: ='7조'!C$68 -> 7조 - Layered - Availability | D10: ='7조'!D$68 | E10: ='7조'!E$68 -> 7조 - Virtual Machine - Availability | F10: ='7조'!F$68 | G10: ='7조'!G$68 -> 7조 - Microkernel - Availability
A11: 8조 | B11: ='8조'!B$68 | C11: ='8조'!C$68 -> 8조 - Layered - Availability | D11: ='8조'!D$68 | E11: ='8조'!E$68 -> 8조 - Virtual Machine - Availability | F11: ='8조'!F$68 | G11: ='8조'!G$68 -> 8조 - Microkernel - Availability
A12: 9조 | B12: ='9조'!B$68 | C12: ='9조'!C$68 -> 9조 - Layered - Availability | D12: ='9조'!D$68 | E12: ='9조'!E$68 -> 9조 - Virtual Machine - Availability | F12: ='9조'!F$68 | G12: ='9조'!G$68 -> 9조 - Microkernel - Availability
A14: Deployability | B14: ='Detailed Reasoning'!B$69 | C14: ='Detailed Reasoning'!C$69 | D14: ='Detailed Reasoning'!D$69 | E14: ='Detailed Reasoning'!E$69 | F14: ='Detailed Reasoning'!F$69 | G14: ='Detailed Reasoning'!G$69
A15: 1조 | B15: ='1조'!B$69 | C15: ='1조'!C69 | D15: ='1조'!D$69 | E15: ='1조'!E69 | F15: ='1조'!F$69 | G15: ='1조'!G69
A16: 2조 | B16: ='2조'!B$69 | C16: ='2조'!C$69 -> 2조 - Layered - Deployability | D16: ='2조'!D$69 | E16: ='2조'!E$69 -> 2조 - Virtual Machine - Deployability | F16: ='2조'!F$69 | G16: ='2조'!G$69 -> 2조 - Microkernel - Deployability
A17: 3조 | B17: ='3조'!B$69 | C17: ='3조'!C$69 -> 3조 - Layered - Deployability | D17: ='3조'!D$69 | E17: ='3조'!E$69 -> 3조 - Virtual Machine - Deployability | F17: ='3조'!F$69 | G17: ='3조'!G$69 -> 3조 - Microkernel - Deployability
A18: 4조 | B18: ='4조'!B$69 | C18: ='4조'!C$69 -> 4조 - Layered - Deployability | D18: ='4조'!D$69 | E18: ='4조'!E$69 -> 4조 - Virtual Machine - Deployability | F18: ='4조'!F$69 | G18: ='4조'!G$69 -> 4조 - Microkernel - Deployability
A19: 5조 | B19: ='5조'!B$69 | C19: ='5조'!C$69 -> 5조 - Layered - Deployability | D19: ='5조'!D$69 | E19: ='5조'!E$69 -> 5조 - Virtual Machine - Deployability | F19: ='5조'!F$69 | G19: ='5조'!G$69 -> 5조 - Microkernel - Deployability
A20: 6조 | B20: ='6조'!B$69 -> + | C20: ='6조'!C$69 -> 계층별 책임과 인터페이스가 분리되어 있어 변경된 Layer를 비교적 독립적으로 배포·교체할 수 있다. 다만 하위 인터페이스 변경 시 상위 Layer도 함께 배포해야 할 수 있다. | D20: ='6조'!D$69 | E20: ='6조'!E$69 -> 6조 - Virtual Machine - Deployability | F20: ='6조'!F$69 | G20: ='6조'!G$69 -> 6조 - Microkernel - Deployability
A21: 7조 | B21: ='7조'!B$69 | C21: ='7조'!C$69 -> 7조 - Layered - Deployability | D21: ='7조'!D$69 | E21: ='7조'!E$69 -> 7조 - Virtual Machine - Deployability | F21: ='7조'!F$69 | G21: ='7조'!G$69 -> 7조 - Microkernel - Deployability
A22: 8조 | B22: ='8조'!B$69 | C22: ='8조'!C$69 -> 8조 - Layered - Deployability | D22: ='8조'!D$69 | E22: ='8조'!E$69 -> 8조 - Virtual Machine - Deployability | F22: ='8조'!F$69 | G22: ='8조'!G$69 -> 8조 - Microkernel - Deployability
A23: 9조 | B23: ='9조'!B$69 | C23: ='9조'!C$69 -> 9조 - Layered - Deployability | D23: ='9조'!D$69 | E23: ='9조'!E$69 -> 9조 - Virtual Machine - Deployability | F23: ='9조'!F$69 | G23: ='9조'!G$69 -> 9조 - Microkernel - Deployability
A25: Integrability | B25: ='Detailed Reasoning'!B$70 | C25: ='Detailed Reasoning'!C$70 | D25: ='Detailed Reasoning'!D$70 | E25: ='Detailed Reasoning'!E$70 | F25: ='Detailed Reasoning'!F$70 | G25: ='Detailed Reasoning'!G$70
A26: 1조 | B26: ='1조'!B$70 | C26: ='1조'!C70 | D26: ='1조'!D$70 | E26: ='1조'!E70 | F26: ='1조'!F$70 | G26: ='1조'!G70
A27: 2조 | B27: ='2조'!B$70 | C27: ='2조'!C$70 -> 2조 - Layered - Integrability | D27: ='2조'!D$70 | E27: ='2조'!E$70 -> 2조 - Virtual Machine - Integrability | F27: ='2조'!F$70 | G27: ='2조'!G$70 -> 2조 - Microkernel - Integrability
A28: 3조 | B28: ='3조'!B$70 | C28: ='3조'!C$70 -> 3조 - Layered - Integrability | D28: ='3조'!D$70 | E28: ='3조'!E$70 -> 3조 - Virtual Machine - Integrability | F28: ='3조'!F$70 | G28: ='3조'!G$70 -> 3조 - Microkernel - Integrability
A29: 4조 | B29: ='4조'!B$70 | C29: ='4조'!C$70 -> 4조 - Layered - Integrability | D29: ='4조'!D$70 | E29: ='4조'!E$70 -> 4조 - Virtual Machine - Integrability | F29: ='4조'!F$70 | G29: ='4조'!G$70 -> 4조 - Microkernel - Integrability
A30: 5조 | B30: ='5조'!B$70 | C30: ='5조'!C$70 -> 5조 - Layered - Integrability | D30: ='5조'!D$70 | E30: ='5조'!E$70 -> 5조 - Virtual Machine - Integrability | F30: ='5조'!F$70 | G30: ='5조'!G$70 -> 5조 - Microkernel - Integrability
A31: 6조 | B31: ='6조'!B$70 -> + | C31: ='6조'!C$70 -> 각 layer가 정의된 인터페이스로 서비스를 제공하므로(약한 결합), 그 인터페이스만 유지되면 아래 구현을 새 컴포넌트로 교체하거나 다른 시스템과 연동하기 쉽다 | D31: ='6조'!D$70 | E31: ='6조'!E$70 -> 6조 - Virtual Machine - Integrability | F31: ='6조'!F$70 | G31: ='6조'!G$70 -> 6조 - Microkernel - Integrability
A32: 7조 | B32: ='7조'!B$70 | C32: ='7조'!C$70 -> 7조 - Layered - Integrability | D32: ='7조'!D$70 | E32: ='7조'!E$70 -> 7조 - Virtual Machine - Integrability | F32: ='7조'!F$70 | G32: ='7조'!G$70 -> 7조 - Microkernel - Integrability
A33: 8조 | B33: ='8조'!B$70 | C33: ='8조'!C$70 -> 8조 - Layered - Integrability | D33: ='8조'!D$70 | E33: ='8조'!E$70 -> 8조 - Virtual Machine - Integrability | F33: ='8조'!F$70 | G33: ='8조'!G$70 -> 8조 - Microkernel - Integrability
A34: 9조 | B34: ='9조'!B$70 | C34: ='9조'!C$70 -> 9조 - Layered - Integrability | D34: ='9조'!D$70 | E34: ='9조'!E$70 -> 9조 - Virtual Machine - Integrability | F34: ='9조'!F$70 | G34: ='9조'!G$70 -> 9조 - Microkernel - Integrability
A36: Energy Efficiency | B36: ='Detailed Reasoning'!B$71 | C36: ='Detailed Reasoning'!C$71 | D36: ='Detailed Reasoning'!D$71 | E36: ='Detailed Reasoning'!E$71 | F36: ='Detailed Reasoning'!F$71 | G36: ='Detailed Reasoning'!G$71
A37: 1조 | B37: ='1조'!B$71 | C37: ='1조'!C71 | D37: ='1조'!D$71 | E37: ='1조'!E71 | F37: ='1조'!F$71 | G37: ='1조'!G71
A38: 2조 | B38: ='2조'!B$71 | C38: ='2조'!C$71 -> 2조 - Layered - Energy Efficiency | D38: ='2조'!D$71 | E38: ='2조'!E$71 -> 2조 - Virtual Machine - Energy Efficiency | F38: ='2조'!F$71 | G38: ='2조'!G$71 -> 2조 - Microkernel - Energy Efficiency
A39: 3조 | B39: ='3조'!B$71 | C39: ='3조'!C$71 -> 3조 - Layered - Energy Efficiency | D39: ='3조'!D$71 | E39: ='3조'!E$71 -> 3조 - Virtual Machine - Energy Efficiency | F39: ='3조'!F$71 | G39: ='3조'!G$71 -> 3조 - Microkernel - Energy Efficiency
A40: 4조 | B40: ='4조'!B$71 | C40: ='4조'!C$71 -> 4조 - Layered - Energy Efficiency | D40: ='4조'!D$71 | E40: ='4조'!E$71 -> 4조 - Virtual Machine - Energy Efficiency | F40: ='4조'!F$71 | G40: ='4조'!G$71 -> 4조 - Microkernel - Energy Efficiency
A41: 5조 | B41: ='5조'!B$71 | C41: ='5조'!C$71 -> 5조 - Layered - Energy Efficiency | D41: ='5조'!D$71 | E41: ='5조'!E$71 -> 5조 - Virtual Machine - Energy Efficiency | F41: ='5조'!F$71 | G41: ='5조'!G$71 -> 5조 - Microkernel - Energy Efficiency
A42: 6조 | B42: ='6조'!B$71 -> - | C42: ='6조'!C$71 -> Layer 수가 많을수록 요청이 여러 Layer를 순차적으로 통과하면서 반복적인 호출, 데이터 변환 및 중간 처리에 추가 자원이 소모된다. | D42: ='6조'!D$71 | E42: ='6조'!E$71 -> 6조 - Virtual Machine - Energy Efficiency | F42: ='6조'!F$71 | G42: ='6조'!G$71 -> 6조 - Microkernel - Energy Efficiency
A43: 7조 | B43: ='7조'!B$71 | C43: ='7조'!C$71 -> 7조 - Layered - Energy Efficiency | D43: ='7조'!D$71 | E43: ='7조'!E$71 -> 7조 - Virtual Machine - Energy Efficiency | F43: ='7조'!F$71 | G43: ='7조'!G$71 -> 7조 - Microkernel - Energy Efficiency
...

Sheet DA1
A1: Distributed | B1: Multi-Tier | D1: Client-Server
B2: Effects | C2: Justification | D2: Effects | E2: Justification
A3: Availability | B3: 0 | C3: 0 | D3: 0 | E3: 0
A4: 1조 | B4: 0 | C4: ='1조'!C81 -> Tier별로 서버를 분리하고 여러 인스턴스를 운영하면 장애를 격리하고 이중화하기 좋다. 특히 Application Tier를 여러 대로 구성하면 일부 서버 장애에도 서비스 지속이 가능하다. 다만 특정 Tier가 단일 장애점(SPOF)이 되면 전체 서비스가 영향을 받을 수 있다. | D4: 0 | E4: ='1조'!E81 -> 1조 - Client-Server - Availability
A5: 2조 | B5: 0 | C5: ='2조'!C81 -> 2조 - Multi-tier - Availability | D5: 0 | E5: ='2조'!E81 -> 서버 이중화로 개선 가능하나, 기본 구조는 서버가 단일 장애점이라서 문제 가능성 있음
A6: 3조 | B6: 0 | C6: ='3조'!C81 -> 3조 - Multi-tier - Availability | D6: 0 | E6: ='3조'!E81 -> 3조 - Client-Server - Availability
A7: 4조 | B7: 0 | C7: ='4조'!C81 -> 4조 - Multi-tier - Availability | D7: 0 | E7: ='4조'!E81 -> 4조 - Client-Server - Availability
A8: 5조 | B8: 0 | C8: ='5조'!C81 -> 5조 - Multi-tier - Availability | D8: 0 | E8: ='5조'!E81 -> 5조 - Client-Server - Availability
A9: 6조 | B9: 0 | C9: ='6조'!C81 -> Tier별로 서버를 분리하고 여러 인스턴스를 운영하면 장애를 격리하고 이중화하기 좋다. 특히 Application Tier를 여러 대로 구성하면 일부 서버 장애에도 서비스 지속이 가능하다. 다만 특정 Tier가 단일 장애점(SPOF)이 되면 전체 서비스가 영향을 받을 수 있다. | D9: 0 | E9: ='6조'!E81 -> 서버 이중화로 개선 가능하나, 기본 구조는 서버가 단일 장애점이라서 문제 가능성 있음
A10: 7조 | B10: 0 | C10: ='7조'!C81 -> 7조 - Multi-tier - Availability | D10: 0 | E10: ='7조'!E81 -> 7조 - Client-Server - Availability
A11: 8조 | B11: 0 | C11: ='8조'!C81 -> 8조 - Multi-tier - Availability | D11: 0 | E11: ='8조'!E81 -> 8조 - Client-Server - Availability
A12: 9조 | B12: 0 | C12: ='9조'!C81 -> 9조 - Multi-tier - Availability | D12: 0 | E12: ='9조'!E81 -> 9조 - Client-Server - Availability
A14: Deployability | B14: 0 | C14: 0 | D14: 0 | E14: 0
A15: 1조 | B15: 0 | C15: ='1조'!C82 -> 각 Tier가 독립적으로 배포될 수 있어 변경 범위를 제한하기 쉽다. 예를 들어 Presentation Tier와 Data Tier를 별도로 배포할 수 있다. 반면 Tier 간 인터페이스나 버전 의존성이 있으면 동시 배포가 필요할 수 있다. | D15: 0 | E15: ='1조'!E82 -> 1조 - Client-Server - Deployability
A16: 2조 | B16: 0 | C16: ='2조'!C82 -> 2조 - Multi-tier - Deployability | D16: 0 | E16: ='2조'!E82 -> 클라이언트와 서버가 독립 배포 가능함
A17: 3조 | B17: 0 | C17: ='3조'!C82 -> 3조 - Multi-tier - Deployability | D17: 0 | E17: ='3조'!E82 -> 3조 - Client-Server - Deployability
A18: 4조 | B18: 0 | C18: ='4조'!C82 -> 4조 - Multi-tier - Deployability | D18: 0 | E18: ='4조'!E82 -> 4조 - Client-Server - Deployability
A19: 5조 | B19: 0 | C19: ='5조'!C82 -> 5조 - Multi-tier - Deployability | D19: 0 | E19: ='5조'!E82 -> 5조 - Client-Server - Deployability
A20: 6조 | B20: 0 | C20: ='6조'!C82 -> 각 Tier가 독립적으로 배포될 수 있어 변경 범위를 제한하기 쉽다. 예를 들어 Presentation Tier와 Data Tier를 별도로 배포할 수 있다. 반면 Tier 간 인터페이스나 버전 의존성이 있으면 동시 배포가 필요할 수 있다. | D20: 0 | E20: ='6조'!E82 -> 클라이언트와 서버가 독립 배포 가능함
A21: 7조 | B21: 0 | C21: ='7조'!C82 -> 7조 - Multi-tier - Deployability | D21: 0 | E21: ='7조'!E82 -> 7조 - Client-Server - Deployability
A22: 8조 | B22: 0 | C22: ='8조'!C82 -> 8조 - Multi-tier - Deployability | D22: 0 | E22: ='8조'!E82 -> 8조 - Client-Server - Deployability
A23: 9조 | B23: 0 | C23: ='9조'!C82 -> 9조 - Multi-tier - Deployability | D23: 0 | E23: ='9조'!E82 -> 9조 - Client-Server - Deployability
A25: Integrability | B25: 0 | C25: 0 | D25: 0 | E25: 0
A26: 1조 | B26: 0 | C26: ='1조'!C83 -> Tier 사이에 명확한 인터페이스/API를 두기 때문에 외부 시스템이나 다른 컴포넌트와 통합하기 좋다. | D26: 0 | E26: ='1조'!E83 -> 1조 - Client-Server - Integrability
A27: 2조 | B27: 0 | C27: ='2조'!C83 -> 2조 - Multi-tier - Integrability | D27: 0 | E27: ='2조'!E83 -> 표준 프로토콜로 통신하므로 새 클라이언트와 서버 추가가 비교적 쉬움
A28: 3조 | B28: 0 | C28: ='3조'!C83 -> 3조 - Multi-tier - Integrability | D28: 0 | E28: ='3조'!E83 -> 3조 - Client-Server - Integrability
A29: 4조 | B29: 0 | C29: ='4조'!C83 -> 4조 - Multi-tier - Integrability | D29: 0 | E29: ='4조'!E83 -> 4조 - Client-Server - Integrability
A30: 5조 | B30: 0 | C30: ='5조'!C83 -> 5조 - Multi-tier - Integrability | D30: 0 | E30: ='5조'!E83 -> 5조 - Client-Server - Integrability
A31: 6조 | B31: 0 | C31: ='6조'!C83 -> Tier 사이에 명확한 인터페이스/API를 두기 때문에 외부 시스템이나 다른 컴포넌트와 통합하기 좋다. | D31: 0 | E31: ='6조'!E83 -> 표준 프로토콜로 통신하므로 새 클라이언트와 서버 추가가 비교적 쉬움
A32: 7조 | B32: 0 | C32: ='7조'!C83 -> 7조 - Multi-tier - Integrability | D32: 0 | E32: ='7조'!E83 -> 7조 - Client-Server - Integrability
A33: 8조 | B33: 0 | C33: ='8조'!C83 -> 8조 - Multi-tier - Integrability | D33: 0 | E33: ='8조'!E83 -> 8조 - Client-Server - Integrability
A34: 9조 | B34: 0 | C34: ='9조'!C83 -> 9조 - Multi-tier - Integrability | D34: 0 | E34: ='9조'!E83 -> 9조 - Client-Server - Integrability
A36: Energy Efficiency | B36: 0 | C36: 0 | D36: 0 | E36: 0
A37: 1조 | B37: 0 | C37: ='1조'!C84 -> 물리적으로 분리된 노드 간 네트워크 통신이 빈번하게 발생하여, 단일 프로세스 기반 아키텍처에 비해 네트워크 장비 및 서버의 전력 소모량이 큼. | D37: 0 | E37: ='1조'!E84 -> 1조 - Client-Server - Energy Efficiency
A38: 2조 | B38: 0 | C38: ='2조'!C84 -> 2조 - Multi-tier - Energy Efficiency | D38: 0 | E38: ='2조'!E84 -> 네트워크 통신 오버헤드가 발생하나, 클라이언트가 가벼우면 전체적으로 효율적임
A39: 3조 | B39: 0 | C39: ='3조'!C84 -> 3조 - Multi-tier - Energy Efficiency | D39: 0 | E39: ='3조'!E84 -> 3조 - Client-Server - Energy Efficiency
A40: 4조 | B40: 0 | C40: ='4조'!C84 -> 4조 - Multi-tier - Energy Efficiency | D40: 0 | E40: ='4조'!E84 -> 4조 - Client-Server - Energy Efficiency
A41: 5조 | B41: 0 | C41: ='5조'!C84 -> 5조 - Multi-tier - Energy Efficiency | D41: 0 | E41: ='5조'!E84 -> 5조 - Client-Server - Energy Efficiency
A42: 6조 | B42: 0 | C42: ='6조'!C84 -> 물리적으로 분리된 노드 간 네트워크 통신이 빈번하게 발생하여, 단일 프로세스 기반 아키텍처에 비해 네트워크 장비 및 서버의 전력 소모량이 큼. | D42: 0 | E42: ='6조'!E84 -> 네트워크 통신 오버헤드가 발생하나, 클라이언트가 가벼우면 전체적으로 효율적임
A43: 7조 | B43: 0 | C43: ='7조'!C84 -> 7조 - Multi-tier - Energy Efficiency | D43: 0 | E43: ='7조'!E84 -> 7조 - Client-Server - Energy Efficiency
...

Sheet DA2
A1: Distributed | B1: Broker | D1: Dispatcher
B2: Effects | C2: Justification | D2: Effects | E2: Justification
A3: Availability | B3: 0 | C3: 0 | D3: 0 | E3: 0
A4: 1조 | B4: 0 | C4: ='1조'!C94 -> 1조 - Broker - Availability | D4: 0 | E4: ='1조'!E94 -> 1조 - Dispatcher - Availability
A5: 2조 | B5: 0 | C5: ='2조'!C94 -> 2조 - Broker - Availability | D5: 0 | E5: ='2조'!E94 -> 2조 - Dispatcher - Availability
A6: 3조 | B6: 0 | C6: ='3조'!C94 -> 3조 - Broker - Availability | D6: 0 | E6: ='3조'!E94 -> 3조 - Dispatcher - Availability
A7: 4조 | B7: 0 | C7: ='4조'!C94 -> 4조 - Broker - Availability | D7: 0 | E7: ='4조'!E94 -> 4조 - Dispatcher - Availability
A8: 5조 | B8: 0 | C8: ='5조'!C94 -> 5조 - Broker - Availability | D8: 0 | E8: ='5조'!E94 -> 5조 - Dispatcher - Availability
A9: 6조 | B9: 0 | C9: ='6조'!C94 -> broker의 장애가 모든 client-server간의 통신에 영향을 주기 때문에 전체 시스템이 먹통이 될 수 있다. 또한 특정 server에 장애가 생길 경우에도 전체 application이 영향을 받을 수 있다. | D9: 0 | E9: ='6조'!E94 -> 기본적으로 동등한 대상에 대해서 이중화가 이루어지기 때문에 장애로부터 복구되기 용이하기 때문에 장애 복구 시간이 짧다.
A10: 7조 | B10: 0 | C10: ='7조'!C94 -> 7조 - Broker - Availability | D10: 0 | E10: ='7조'!E94 -> 7조 - Dispatcher - Availability
A11: 8조 | B11: 0 | C11: ='8조'!C94 -> 8조 - Broker - Availability | D11: 0 | E11: ='8조'!E94 -> 8조 - Dispatcher - Availability
A12: 9조 | B12: 0 | C12: ='9조'!C94 -> 9조 - Broker - Availability | D12: 0 | E12: ='9조'!E94 -> 9조 - Dispatcher - Availability
A14: Deployability | B14: 0 | C14: 0 | D14: 0 | E14: 0
A15: 1조 | B15: 0 | C15: ='1조'!C95 -> 1조 - Broker - Deployability | D15: 0 | E15: ='1조'!E95 -> 1조 - Dispatcher - Deployability
A16: 2조 | B16: 0 | C16: ='2조'!C95 -> 2조 - Broker - Deployability | D16: 0 | E16: ='2조'!E95 -> 2조 - Dispatcher - Deployability
A17: 3조 | B17: 0 | C17: ='3조'!C95 -> 3조 - Broker - Deployability | D17: 0 | E17: ='3조'!E95 -> 3조 - Dispatcher - Deployability
A18: 4조 | B18: 0 | C18: ='4조'!C95 -> 4조 - Broker - Deployability | D18: 0 | E18: ='4조'!E95 -> 4조 - Dispatcher - Deployability
A19: 5조 | B19: 0 | C19: ='5조'!C95 -> 5조 - Broker - Deployability | D19: 0 | E19: ='5조'!E95 -> 5조 - Dispatcher - Deployability
A20: 6조 | B20: 0 | C20: ='6조'!C95 -> runtime 중 server의 추가/삭제가 용이하다. | D20: 0 | E20: ='6조'!E95 -> 클라이언트가 연결되어 있지 않은 상황에서 다른 머신에 배포시키기가 수월.
A21: 7조 | B21: 0 | C21: ='7조'!C95 -> 7조 - Broker - Deployability | D21: 0 | E21: ='7조'!E95 -> 7조 - Dispatcher - Deployability
A22: 8조 | B22: 0 | C22: ='8조'!C95 -> 8조 - Broker - Deployability | D22: 0 | E22: ='8조'!E95 -> 8조 - Dispatcher - Deployability
A23: 9조 | B23: 0 | C23: ='9조'!C95 -> 9조 - Broker - Deployability | D23: 0 | E23: ='9조'!E95 -> 9조 - Dispatcher - Deployability
A25: Integrability | B25: 0 | C25: 0 | D25: 0 | E25: 0
A26: 1조 | B26: 0 | C26: ='1조'!C96 -> 1조 - Broker - Integrability | D26: 0 | E26: ='1조'!E96 -> 1조 - Dispatcher - Integrability
A27: 2조 | B27: 0 | C27: ='2조'!C96 -> 2조 - Broker - Integrability | D27: 0 | E27: ='2조'!E96 -> 2조 - Dispatcher - Integrability
A28: 3조 | B28: 0 | C28: ='3조'!C96 -> 3조 - Broker - Integrability | D28: 0 | E28: ='3조'!E96 -> 3조 - Dispatcher - Integrability
A29: 4조 | B29: 0 | C29: ='4조'!C96 -> 4조 - Broker - Integrability | D29: 0 | E29: ='4조'!E96 -> 4조 - Dispatcher - Integrability
A30: 5조 | B30: 0 | C30: ='5조'!C96 -> 5조 - Broker - Integrability | D30: 0 | E30: ='5조'!E96 -> 5조 - Dispatcher - Integrability
A31: 6조 | B31: 0 | C31: ='6조'!C96 -> bridge를 통해 다른 format의 protocol을 사용하는 여러 broker를 연결할 수 있다. | D31: 0 | E31: ='6조'!E96 -> 동일 인터페이스인 인스턴스를 추가하는 비용은 거의 없지만 호환되지 않는 인터페이스라면 통합되기 어려움 (이건 브로커의 역할)
A32: 7조 | B32: 0 | C32: ='7조'!C96 -> 7조 - Broker - Integrability | D32: 0 | E32: ='7조'!E96 -> 7조 - Dispatcher - Integrability
A33: 8조 | B33: 0 | C33: ='8조'!C96 -> 8조 - Broker - Integrability | D33: 0 | E33: ='8조'!E96 -> 8조 - Dispatcher - Integrability
A34: 9조 | B34: 0 | C34: ='9조'!C96 -> 9조 - Broker - Integrability | D34: 0 | E34: ='9조'!E96 -> 9조 - Dispatcher - Integrability
A36: Energy Efficiency | B36: 0 | C36: 0 | D36: 0 | E36: 0
A37: 1조 | B37: 0 | C37: ='1조'!C97 -> 1조 - Broker - Energy Efficiency | D37: 0 | E37: ='1조'!E97 -> 1조 - Dispatcher - Energy Efficiency
A38: 2조 | B38: 0 | C38: ='2조'!C97 -> 2조 - Broker - Energy Efficiency | D38: 0 | E38: ='2조'!E97 -> 2조 - Dispatcher - Energy Efficiency
A39: 3조 | B39: 0 | C39: ='3조'!C97 -> 3조 - Broker - Energy Efficiency | D39: 0 | E39: ='3조'!E97 -> 3조 - Dispatcher - Energy Efficiency
A40: 4조 | B40: 0 | C40: ='4조'!C97 -> 4조 - Broker - Energy Efficiency | D40: 0 | E40: ='4조'!E97 -> 4조 - Dispatcher - Energy Efficiency
A41: 5조 | B41: 0 | C41: ='5조'!C97 -> 5조 - Broker - Energy Efficiency | D41: 0 | E41: ='5조'!E97 -> 5조 - Dispatcher - Energy Efficiency
A42: 6조 | B42: 0 | C42: ='6조'!C97 -> 동시성을 띄고 broker와의 통신 overhead 때문에 에너지 소모가 높다. | D42: 0 | E42: ='6조'!E97 -> Dispatcher와 발생되는 통신비용이 오버헤드가 될 수 있지만 누구와 통신을 할지 식별이 된 이후에는 Dispatcher를 거치지 않음
A43: 7조 | B43: 0 | C43: ='7조'!C97 -> 7조 - Broker - Energy Efficiency | D43: 0 | E43: ='7조'!E97 -> 7조 - Dispatcher - Energy Efficiency
...

Sheet DA3
A1: Distributed | B1: SOA | D1: Micro-service
B2: Effects | C2: Justification | D2: Effects | E2: Justification
A3: Availability | B3: 0 | C3: 0 | D3: 0 | E3: 0
A4: 1조 | B4: 0 | C4: ='1조'!C107 -> 1조 - SOA - Availability | D4: 0 | E4: ='1조'!E107 -> 1조 - Mico-Service - Availability
A5: 2조 | B5: 0 | C5: ='2조'!C107 -> 2조 - SOA - Availability | D5: 0 | E5: ='2조'!E107 -> 2조 - Mico-Service - Availability
A6: 3조 | B6: 0 | C6: ='3조'!C107 -> 3조 - SOA - Availability | D6: 0 | E6: ='3조'!E107 -> 3조 - Mico-Service - Availability
A7: 4조 | B7: 0 | C7: ='4조'!C107 -> 4조 - SOA - Availability | D7: 0 | E7: ='4조'!E107 -> 4조 - Mico-Service - Availability
A8: 5조 | B8: 0 | C8: ='5조'!C107 -> intermediary가 연결을 해줄뿐이지 실 availability 가 service provider에 영향을 받는 경우가 많음 | D8: 0 | E8: ='5조'!E107 -> 5조 - Mico-Service - Availability
A9: 6조 | B9: 0 | C9: ='6조'!C107 -> intermediary가 연결을 해줄뿐이지 실 availability 가 service provider에 영향을 받는 경우가 많음 | D9: 0 | E9: ='6조'!E107 -> 각 서비스가 독립 프로세스로 격리되어 있어, 하나의 microservice가 죽어도 upstream 서비스가 장애를 올바르게 처리하도록 설계되어 있다면 전체는 계속 동작한다
A10: 7조 | B10: 0 | C10: ='7조'!C107 -> 7조 - SOA - Availability | D10: 0 | E10: ='7조'!E107 -> 7조 - Mico-Service - Availability
A11: 8조 | B11: 0 | C11: ='8조'!C107 -> 8조 - SOA - Availability | D11: 0 | E11: ='8조'!E107 -> 8조 - Mico-Service - Availability
A12: 9조 | B12: 0 | C12: ='9조'!C107 -> 9조 - SOA - Availability | D12: 0 | E12: ='9조'!E107 -> 9조 - Mico-Service - Availability
A14: Deployability | B14: 0 | C14: 0 | D14: 0 | E14: 0
A15: 1조 | B15: 0 | C15: ='1조'!C108 -> 1조 - SOA - Deployability | D15: 0 | E15: ='1조'!E108 -> 1조 - Mico-Service - Deployability
A16: 2조 | B16: 0 | C16: ='2조'!C108 -> 2조 - SOA - Deployability | D16: 0 | E16: ='2조'!E108 -> 2조 - Mico-Service - Deployability
A17: 3조 | B17: 0 | C17: ='3조'!C108 -> 3조 - SOA - Deployability | D17: 0 | E17: ='3조'!E108 -> 3조 - Mico-Service - Deployability
A18: 4조 | B18: 0 | C18: ='4조'!C108 -> 4조 - SOA - Deployability | D18: 0 | E18: ='4조'!E108 -> 4조 - Mico-Service - Deployability
A19: 5조 | B19: 0 | C19: ='5조'!C108 -> 중앙 intermediary에 의존하는 시스템은 이중화 보장이 되어있지 않은 이상 deployability 가 좋다고 볼 수 없음 | D19: 0 | E19: ='5조'!E108 -> 5조 - Mico-Service - Deployability
A20: 6조 | B20: 0 | C20: ='6조'!C108 -> 중앙 intermediary에 의존하는 시스템은 이중화 보장이 되어있지 않은 이상 deployability 가 좋다고 볼 수 없음 | D20: 0 | E20: ='6조'!E108 -> 서비스별로 별도 독립 배포가 가능해, 전체 application을 재배포하지 않고 서비스 하나만 갱신·롤백할 수 있다
A21: 7조 | B21: 0 | C21: ='7조'!C108 -> 7조 - SOA - Deployability | D21: 0 | E21: ='7조'!E108 -> 7조 - Mico-Service - Deployability
A22: 8조 | B22: 0 | C22: ='8조'!C108 -> 8조 - SOA - Deployability | D22: 0 | E22: ='8조'!E108 -> 8조 - Mico-Service - Deployability
A23: 9조 | B23: 0 | C23: ='9조'!C108 -> 9조 - SOA - Deployability | D23: 0 | E23: ='9조'!E108 -> 9조 - Mico-Service - Deployability
A25: Integrability | B25: 0 | C25: 0 | D25: 0 | E25: 0
A26: 1조 | B26: 0 | C26: ='1조'!C109 -> 1조 - SOA - Integrability | D26: 0 | E26: ='1조'!E109 -> 1조 - Mico-Service - Integrability
A27: 2조 | B27: 0 | C27: ='2조'!C109 -> 2조 - SOA - Integrability | D27: 0 | E27: ='2조'!E109 -> 2조 - Mico-Service - Integrability
A28: 3조 | B28: 0 | C28: ='3조'!C109 -> 3조 - SOA - Integrability | D28: 0 | E28: ='3조'!E109 -> 3조 - Mico-Service - Integrability
A29: 4조 | B29: 0 | C29: ='4조'!C109 -> 4조 - SOA - Integrability | D29: 0 | E29: ='4조'!E109 -> 4조 - Mico-Service - Integrability
A30: 5조 | B30: 0 | C30: ='5조'!C109 -> 표준화된 통신이 보장되기 때문에 service provider, service customer 확장이 용이함. | D30: 0 | E30: ='5조'!E109 -> 5조 - Mico-Service - Integrability
A31: 6조 | B31: 0 | C31: ='6조'!C109 -> 표준화된 통신이 보장되기 때문에 service provider, service customer 확장이 용이함. | D31: 0 | E31: ='6조'!E109 -> 서비스마다 기술 스택·언어·프레임워크를 자유롭게 선택할 수 있어, 서비스 일관성 유지와 버저닝 관리가 어려움
A32: 7조 | B32: 0 | C32: ='7조'!C109 -> 7조 - SOA - Integrability | D32: 0 | E32: ='7조'!E109 -> 7조 - Mico-Service - Integrability
A33: 8조 | B33: 0 | C33: ='8조'!C109 -> 8조 - SOA - Integrability | D33: 0 | E33: ='8조'!E109 -> 8조 - Mico-Service - Integrability
A34: 9조 | B34: 0 | C34: ='9조'!C109 -> 9조 - SOA - Integrability | D34: 0 | E34: ='9조'!E109 -> 9조 - Mico-Service - Integrability
A36: Energy Efficiency | B36: 0 | C36: 0 | D36: 0 | E36: 0
A37: 1조 | B37: 0 | C37: ='1조'!C110 -> 1조 - SOA - Energy Efficiency | D37: 0 | E37: ='1조'!E110 -> 1조 - Mico-Service - Energy Efficiency
A38: 2조 | B38: 0 | C38: ='2조'!C110 -> 2조 - SOA - Energy Efficiency | D38: 0 | E38: ='2조'!E110 -> 2조 - Mico-Service - Energy Efficiency
A39: 3조 | B39: 0 | C39: ='3조'!C110 -> 3조 - SOA - Energy Efficiency | D39: 0 | E39: ='3조'!E110 -> 3조 - Mico-Service - Energy Efficiency
A40: 4조 | B40: 0 | C40: ='4조'!C110 -> 4조 - SOA - Energy Efficiency | D40: 0 | E40: ='4조'!E110 -> 4조 - Mico-Service - Energy Efficiency
A41: 5조 | B41: 0 | C41: ='5조'!C110 -> middleware의 존재로 성능 효율이 좋은 편이라고 볼 수 없음 | D41: 0 | E41: ='5조'!E110 -> 5조 - Mico-Service - Energy Efficiency
A42: 6조 | B42: 0 | C42: ='6조'!C110 -> middleware의 존재로 성능 효율이 좋은 편이라고 볼 수 없음 | D42: 0 | E42: ='6조'!E110 -> 서비스 수만큼 프로세스/컨테이너가 늘어나고 서비스 간 네트워크 통신이 잦아져, 인프라·통신 오버헤드가 커진다
A43: 7조 | B43: 0 | C43: ='7조'!C110 -> 7조 - SOA - Energy Efficiency | D43: 0 | E43: ='7조'!E110 -> 7조 - Mico-Service - Energy Efficiency
...

Sheet Dep
A1: Deployment | B1: Container-based | D1: Cloud-based | F1: Edge-based
B2: Effects | C2: Justification | D2: Effects | E2: Justification | F2: Effects | G2: Justification
A3: Availability | B3: 0 | C3: 0 | D3: 0 | E3: 0 | F3: 0 | G3: 0
A4: 1조 | B4: 0 | C4: ='1조'!C120 -> 1조 - Container-based - Availability | D4: 0 | E4: ='1조'!E120 -> 1조 - Cloud-based - Availability | F4: 0 | G4: ='6조'!G120 -> 중앙 서버에 모든 처리를 의존하지 않고 여러 Edge에서 서비스를 제공할 수 있어 장애 격리에 유리하다. 하지만 특정 Edge 장비가 고장나면 해당 지역 사용자가 영향을 받을 수 있다.
A5: 2조 | B5: 0 | C5: ='2조'!C120 -> 2조 - Container-based - Availability | D5: 0 | E5: ='2조'!E120 -> 2조 - Cloud-based - Availability | F5: 0 | G5: ='2조'!G120 -> 중앙 서버와 네트워크 연결이 끊겨도 엣지 노드가 로컬에서 자체 동작 가능함
A6: 3조 | B6: 0 | C6: ='3조'!C120 -> 3조 - Container-based - Availability | D6: 0 | E6: ='3조'!E120 -> 3조 - Cloud-based - Availability | F6: 0 | G6: ='3조'!G120 -> 3조 - Edge-based - Availability
A7: 4조 | B7: 0 | C7: ='4조'!C120 -> 4조 - Container-based - Availability | D7: 0 | E7: ='4조'!E120 -> 4조 - Cloud-based - Availability | F7: 0 | G7: ='4조'!G120 -> 4조 - Edge-based - Availability
A8: 5조 | B8: 0 | C8: ='5조'!C120 -> 5조 - Container-based - Availability | D8: 0 | E8: ='5조'!E120 -> 5조 - Cloud-based - Availability | F8: 0 | G8: ='5조'!G120 -> 5조 - Edge-based - Availability
