Workbook

Sheet Ex3.1 (Raw QAS)
A1: [Ex3.1] Raw QAS (Raw Quality Attribute Scenario) 발굴
A2: Scenario Brainstorming: 팀당 10개 내외(1인당 2건↑ 필수)의 Quality Attribute Raw 시나리오를 작성하세요.
A3: Voting: 팀당 4개 이상의 Scenario를 선정. 단, 다양한 품질 속성(3개 이상)이 나오도록 할 것
A5: Member | B5: Quality Attribute | C5: Raw Quality Attribute Scenario | E5: VOTE | F5: 팀원2 | G5: 팀원3 | H5: 팀원4 | I5: 팀원5 | J5: 팀원6 | K5: 팀원6
A6: 김XX | B6: Performance | C6: 많은 사용자가 피크 시간대에 동시에 로그인을 시도하는 경우에도, 시스템이 원활하게 로그인 요청을 처리해야 한다. | E6: =SUM(F6:K6) -> 4 | F6: 1 | H6: 1 | I6: 1 | K6: 1
A7: 김XX | E7: =SUM(F7:K7) -> 4 | F7: 1 | G7: 1 | I7: 1 | J7: 1
A8: 이XX | E8: =SUM(F8:K8) -> 3 | F8: 1 | H8: 1 | J8: 1
A9: 이XX | E9: =SUM(F9:K9) -> 3 | F9: 1 | I9: 1 | J9: 1
A10: 박XX | E10: =SUM(F10:K10) -> 4 | G10: 1 | H10: 1 | J10: 1 | K10: 1
A11: 박XX | E11: =SUM(F11:K11) -> 2 | H11: 1 | I11: 1
E12: =SUM(F12:K12) -> 2 | F12: 1 | G12: 1
E13: =SUM(F13:K13) -> 5 | G13: 1 | H13: 1 | I13: 1 | J13: 1 | K13: 1
E14: =SUM(F14:K14) -> 2 | G14: 1 | K14: 1
E15: =SUM(F15:K15) -> 1 | K15: 1
E16: . Voting: 개인별로 4~5개 항목에 Voting

Sheet Ex3.2 (QAS)
A1: [Ex3.2] QAS (Quality Attribute Scenario) 작성
A2: Scenario Refinement: 선택된 시나리오에 대해서 품질 속성 시나리오(QAS)를 작성하세요
D3: 예시
A4: Requirement-ID | B4: QA_001 (작성자: 이민경) | D4: Requirement-ID | E4: QA_002 (작성자: 김ㅇㅇ)
A5: Quality Attribute | B5: Availability | D5: Quality Attribute | E5: 관련된 Quality Attribute가 무엇인지( ex. Performance, Reliability, Security 등등)
A6: Source | B6: 다수의 사용자로 인한 트래픽 유입 | D6: Source | E6: Stimulus를 발생시키는 주체가 무엇인지 기술
A7: Stimulus | B7: 트래픽 증가(평소 대비 10배 이상)로 인한 서비스 장애 | D7: Stimulus | E7: 시스템에 입력되는 내외부 자극이 무엇인지 기술
A8: Environment | B8: 정상 운영 모드 | D8: Environment | E8: 해당 Stimulus 발생시 시스템의 환경(운영모드일 수도 있고, 그 외 다양한 상황 가능)
A9: Artifacts | B9: 플랫폼 전체 | D9: Artifacts | E9: Stimulus의 영향을 받는 시스템의 내부 모듈, 컴포넌트, 혹은 시스템 전체
A10: Response | B10: 플랫폼 장애를 알리고, 서비스를 비활성화 한 뒤 플랫폼 복구를 진행 | D10: Response | E10: 기술된 Environment에서 Artifact이 Stimulus를 받아들인 후 취하는 Action이 무엇인지
A11: Response Measure | B11: 복구에 걸리는 시간이 30분 이내 | D11: Response Measure | E11: 위의 Response의 정도를 측정하는 단위가 무엇인지 (ex. 초당 데이터 처리량, 반응시간(시간일 경우 Hr인지, Min인지, Sec인지 등등))
A12: Priority | B12: =('Ex3.3 (Utility Tree)'!D5) -> 1 | D12: Priority | E12: Quality Attribute Tree 상에서의 우선순위
A13: Description | B13: 플랫폼이 정상적으로 운영되는 상황에서 다수의 사용자로 인한 트래픽의 증가로 인해 (평소 대비 10배 이상) 플랫폼 접근 불가 등의 장애가 발생하는 경우, 플랫폼 장애를 알리고 서비스를 일시적으로 비활성화 한 뒤에 플랫폼 복구를 진행해야 하며, 복구는 30분 이내로 완료되어야 한다. | D13: Description | E13: 위 Source부터 Response Measure의 내용을 한 문장으로 요약해서 기술
A15: Requirement-ID | B15: QA_002 (작성자: 김유리)
A16: Quality Attribute | B16: Security
A17: Source | B17: External(사용자)
A18: Stimulus | B18: 비인가 결제 요청
A19: Environment | B19: 정상적인 운영 모드(normal operation mode)
A20: Artifacts | B20: 시스템의 인증 및 결제 모듈
A21: Response | B21: 인증 여부를 확인하고 결제 거부
A22: Response Measure | B22: 비인가 결제 요청 항상 차단
A23: Priority | B23: =('Ex3.3 (Utility Tree)'!D6) -> 2
A24: Description | B24: 지역화페 시스템의 인증 및 결제 모듈이 정상적인 운영모드일 때, 사용자로부터 비인가 결제가 요청 될 경우, 시스템은 인증 여부를 확인하고 결제 요청을 항상 차단한다.
A26: Requirement-ID | B26: QA_003 (작성자: 최재웅)
A27: Quality Attribute | B27: Performance
A28: Source | B28: External (사용자)
A29: Stimulus | B29: 사용자가 지역 상품권 결제 플랫폼에서 결제를 시도한다. (sporadic)
A30: Environment | B30: 정상적인 운영모두 (normal operation mode)
A31: Artifacts | B31: 시스템 (artifacts)
A32: Response | B32: 정상 결제 승인 알람을 수신한다. (process event)
A33: Response Measure | B33: 처리 시간 (latency)
A34: Priority | B34: =('Ex3.3 (Utility Tree)'!D7) -> 4
A35: Description | B35: 지역 상품권 결제 플랫폼이 normal operation mode일 때, 사용자가 결제를 시도하면 정상 결제 승인 알람을 수신할 때 까지 걸리는 시간은 2초 미만이다
A37: Requirement-ID | B37: QA_004 (작성자: 오세완)
A38: Quality Attribute | B38: Usabiliy
A39: Source | B39: users
A40: Stimulus | B40: 정기 충전 설정
A41: Environment | B41: 설정 모드
A42: Artifacts | B42: 시스템의 충전 모듈
A43: Response | B43: 연계된 은행 계좌나 카드사로 원터치만으로 정기 충전 설정이 가능하게 한다.
...

Sheet Ex3.3 (Utility Tree)
A1: [Ex3.3] Utility Tree 작성
A2: Prioritizing: 작성된 시나리오에 대해서 Importance/Difficulty를 부여하고 우선순위를 도출하세요. (Voting 등)
A4: Quality Attribute | B4: Quality Attribute Scenario | C4: (I, D) | D4: Priority | F4: I | G4: 김유리 | H4: 박형용 | I4: 오세완 | J4: 이민경 | K4: 최재웅 | L4: D | M4: 김유리 | N4: 박형용 | O4: 오세완 | P4: 이민경 | Q4: 최재웅
A5: Availability | B5: 플랫폼이 정상적으로 운영되는 상황에서 다수의 사용자로 인한 트래픽의 증가로 인해 (1달 평균치 대비 10배 이상) 플랫폼 접근 불가 등의 장애가 발생하는 경우, 플랫폼 장애를 알리고 서비스를 일시적으로 비활성화 한 뒤에 플랫폼 복구를 진행해야 하며, 복구는 30분 이내로 완료되어야 한다. | C5: (H,H) | D5: 1 | F5: =round(AVERAGE(G5:K5),3) -> 2.8 | G5: 3 | H5: 3 | I5: 3 | J5: 2 | K5: 3 | L5: =round(AVERAGE(M5:Q5),3) -> 3 | M5: 3 | N5: 3 | O5: 3 | P5: 3 | Q5: 3
A6: Security | B6: 지역화페 시스템의 인증 및 결제 모듈이 normal operation mode일 때, 사용자로부터 비인가 결제가 요청 될 경우, 시스템은 인증 여부를 확인하고 결제 요청을 항상 차단한다. | C6: (H,M) | D6: 2 | F6: =round(AVERAGE(G6:K6),3) -> 3 | G6: 3 | H6: 3 | I6: 3 | J6: 3 | K6: 3 | L6: =round(AVERAGE(M6:Q6),3) -> 2.2 | M6: 2 | N6: 3 | O6: 2 | P6: 2 | Q6: 2
A7: Performance | B7: 지역 상품권 결제 플랫폼이 normal operation mode일 때, 사용자가 결제를 시도하면 정상 결제 승인 알람을 수신할 때 까지 걸리는 시간은 2초 미만이다 | C7: (M,H) | D7: 4 | F7: =round(AVERAGE(G7:K7),3) -> 2.2 | G7: 2 | H7: 1 | I7: 3 | J7: 2 | K7: 3 | L7: =round(AVERAGE(M7:Q7),3) -> 2.6 | M7: 3 | N7: 2 | O7: 2 | P7: 3 | Q7: 3
A8: Usabiliy | B8: 설정 모드 상황에서 사용자에 의한 연계된 은행 계좌나 카드사로 정기 충전 설정이 충전 모듈에 의해서 받아질 때 원터치만으로 정기 충전 설정되어 충전 설정을 처음하는 사용자도 사용 만족도가 95% 이상 나오게 한다. | C8: (L,M) | D8: 5 | F8: =round(AVERAGE(G8:K8),3) -> 1.8 | G8: 2 | H8: 2 | I8: 2 | J8: 2 | K8: 1 | L8: =round(AVERAGE(M8:Q8),3) -> 2.2 | M8: 2 | N8: 2 | O8: 2 | P8: 2 | Q8: 3
A9: Availability | B9: 지역 상품권 결제 플랫폼이 normal operation 동작 중에 금융시스템이 정기점검에 중이면, 금융시스템의 상태를 사용자에게 알리면서 금융 시스템과 연관된 기능에 대해 접근을 막고, 그 외의 기능은 정상적으로 작동 되어야한다. | C9: (H,L) | D9: 3 | F9: =round(AVERAGE(G9:K9),3) -> 2.6 | G9: 3 | H9: 3 | I9: 2 | J9: 3 | K9: 2 | L9: =round(AVERAGE(M9:Q9),3) -> 1.8 | M9: 1 | N9: 2 | O9: 2 | P9: 2 | Q9: 2
F10: . Importance: 개인별 Voting (1:Low, 2:Med, 3:High) 후 평균값으로 최종 결정 (평균 2.5↑ H, 2↑ M, 이외 L)
F11: . Difficulty: 개인별 Voting (1:Low, 2:Med, 3:High) 후 평균값으로 최종 결정 (평균 2.5↑ H, 2↑ M, 이외 L)
F12: . Priority: Importance와 Difficulty를 고려하여, 최종 우선순위 결정
